File: 01_Data/MDF/STA/N2/10K_min/MDF_STA_N2_10KData_210310_R2.csv
##Temp./Â°C,Time/min,DSC/(mW/mg),Mass/%,Sensit./(uV/mW)
47.581,10.00917,-0.02189091,99.86377,1.0895700000000001
47.597,10.109169999999999,-0.02232595,99.86377,1.0895700000000001
47.594,10.20917,-0.02261587,99.88427,1.0895700000000001
47.593,10.30917,-0.02305078,99.88427,1.0895700000000001
47.595,10.40917,-0.0230508,99.88427,1.0895700000000001
47.614,10.50917,-0.02334089,99.88427,1.08956
47.634,10.609169999999999,-0.02145637,99.85714,1.08955
47.673,10.70917,-0.01913701,99.88447,1.08954
47.708,10.80917,-0.01826736,99.87764,1.0895299999999999
47.754,10.90917,-0.01652786,99.87743,1.08951
47.82,11.00917,-0.01420847,99.88427,1.08949
47.914,11.109169999999999,-0.01087417,99.88447,1.08945
47.997,11.20917,-0.007104653000000001,99.88427,1.08942
48.117,11.30917,-0.0049299570000000004,99.87743,1.08938
48.276,11.40917,-0.0002900128,99.88447,1.08932
48.437,11.50917,0.0047854690000000005,99.86377,1.0892600000000001
48.65,11.609169999999999,0.009861674,99.88447,1.08918
48.848,11.70917,0.01363321,99.88654,1.08911
49.063,11.80917,0.01900084,99.88654,1.08903
49.365,11.90917,0.02480514,99.85942,1.08892
49.647,12.00917,0.03003012,99.88903,1.0888200000000001
49.937,12.109169999999999,0.03482091,99.89336999999999,1.08871
50.276,12.20917,0.04033882,99.86605,1.08859
50.66,12.30917,0.04585869,99.86625,1.08845
51.034,12.40917,0.05050897,99.84576,1.08831
51.45,12.50917,0.05646767,99.86605,1.08816
51.868,12.609169999999999,0.06184737,99.84576,1.0880100000000001
52.336,12.70917,0.06447086,99.83892,1.0878299999999999
52.779,12.80917,0.07072529,99.83892,1.0876700000000001
53.274,12.90917,0.07538523,99.83872,1.08749
53.788,13.00917,0.07873978,99.86625,1.0873
54.294,13.10917,0.08456543,99.83892,1.08711
54.81,13.20917,0.08835886,99.80932,1.08692
55.377,13.309170000000002,0.0920099,99.83209000000001,1.08671
55.954,13.409170000000001,0.09566274,99.77991999999999,1.08649
56.497,13.509170000000001,0.10192999999999999,99.80704,1.08629
57.13,13.60917,0.10443,99.79337,1.08605
57.684,13.70917,0.10779000000000001,99.77971,1.08584
58.326,13.809170000000002,0.11291,99.77991999999999,1.0856
58.946,13.909170000000001,0.1173,99.80020999999999,1.0853700000000002
59.561,14.009170000000001,0.12111,99.77991999999999,1.08514
60.21,14.10917,0.12347000000000001,99.75259,1.08489
60.866,14.20917,0.12685,99.75941999999999,1.08464
61.564,14.309170000000002,0.12892,99.76605,1.08438
62.247,14.409170000000001,0.13317,99.75259,1.08412
62.945,14.509170000000001,0.13641,99.75259,1.08385
63.617,14.60917,0.13994,99.75259,1.08359
64.355,14.70917,0.14202,99.74576,1.08331
65.059,14.809170000000002,0.14629,99.72547,1.08304
65.776,14.909170000000001,0.14982,99.72525999999999,1.08276
66.513,15.009170000000001,0.1538,99.67764,1.0824799999999999
67.277,15.10917,0.15617999999999999,99.69814000000001,1.08218
68.034,15.20917,0.15841,99.67101,1.08189
68.8,15.309170000000002,0.1624,99.67081,1.08159
69.593,15.409170000000001,0.16639,99.67081,1.08128
70.346,15.509170000000001,0.16935999999999998,99.67081,1.08099
71.166,15.60917,0.17115999999999998,99.64348000000001,1.08067
71.95,15.70917,0.17399,99.64348000000001,1.08036
72.732,15.809170000000002,0.17638,99.62319000000001,1.08005
73.567,15.909170000000001,0.17804,99.61636,1.07972
74.396,16.00917,0.17985,99.59586,1.07939
75.236,16.109170000000002,0.18225,99.61636,1.0790600000000001
76.052,16.20917,0.18465,99.58903000000001,1.07873
76.953,16.30917,0.18705,99.58923,1.07837
77.752,16.40917,0.18916,99.54141,1.07805
78.634,16.50917,0.19113,99.5617,1.0777
79.503,16.609170000000002,0.19441,99.54824,1.07735
80.38,16.70917,0.19330999999999998,99.53458,1.077
81.263,16.80917,0.19572,99.50745,1.07664
82.163,16.90917,0.19798,99.50725,1.07628
83.052,17.00917,0.19996,99.50725,1.0759100000000001
83.967,17.109170000000002,0.19959000000000002,99.51408,1.07554
84.874,17.20917,0.20142000000000002,99.50062,1.0751700000000002
85.784,17.30917,0.20267000000000002,99.48012,1.0748
86.722,17.40917,0.20362,99.48012,1.07441
87.648,17.50917,0.20501999999999998,99.48012,1.0740299999999998
88.585,17.609170000000002,0.20626999999999998,99.48012,1.07364
89.525,17.70917,0.20561,99.48012,1.07326
90.475,17.80917,0.20670999999999998,99.453,1.0728600000000001
91.42,17.90917,0.2087,99.43913,1.07247
92.374,18.00917,0.20922,99.4528,1.07207
93.359,18.109170000000002,0.21048000000000003,99.42546999999999,1.07166
94.295,18.20917,0.21070999999999998,99.42567,1.07126
95.299,18.30917,0.21094000000000002,99.43251,1.07084
96.284,18.40917,0.2119,99.42546999999999,1.07043
97.231,18.50917,0.21198000000000003,99.37101,1.07002
98.23,18.609170000000002,0.21414,99.39151,1.0696
99.249,18.70917,0.21495999999999998,99.37101,1.0691700000000002
100.208,18.80917,0.2149,99.37101,1.06876
101.223,18.90917,0.21764,99.37122,1.0683200000000002
102.227,19.00917,0.21906,99.39834,1.06789
103.205,19.109170000000002,0.22166999999999998,99.37101,1.0674700000000001
104.205,19.20917,0.22324000000000002,99.35051999999999,1.06704
105.218,19.30917,0.2254,99.35051999999999,1.0666
106.247,19.40917,0.22624,99.34389,1.06616
107.241,19.50917,0.22855,99.35072,1.0657299999999998
108.266,19.609170000000002,0.22968000000000002,99.34389,1.06528
109.271,19.70917,0.22993000000000002,99.36418,1.06484
110.293,19.80917,0.23076999999999998,99.34389,1.06439
111.32,19.90917,0.23116,99.37122,1.0639399999999999
112.335,20.00917,0.23156,99.34389,1.06349
113.368,20.109170000000002,0.23165,99.34389,1.06304
114.403,20.20917,0.23101,99.31656,1.0625799999999999
115.44,20.30917,0.23349,99.34369000000001,1.0621200000000002
116.466,20.40917,0.23478000000000002,99.31656,1.06166
117.507,20.50917,0.23459000000000002,99.31656,1.0612
118.548,20.609170000000002,0.23692,99.31656,1.06073
119.608,20.70917,0.23643000000000003,99.31656,1.06025
120.643,20.80917,0.23713,99.28923,1.05979
121.667,20.90917,0.23754,99.28944,1.0593299999999999
122.713,21.00917,0.24003000000000002,99.28944,1.05885
123.765,21.109170000000002,0.24029,99.29607,1.0583799999999999
124.842,21.20917,0.2395,99.29607,1.05789
125.881,21.30917,0.2408,99.28923,1.05741
126.957,21.40917,0.24195999999999998,99.28944,1.05692
128.01601000000002,21.50917,0.24356999999999998,99.28944,1.05644
129.071,21.609170000000002,0.24398000000000003,99.26210999999999,1.05595
130.14799,21.70917,0.24484,99.24845,1.05546
131.20799,21.80917,0.24585,99.24845,1.05497
132.28,21.90917,0.24791999999999997,99.24845,1.05447
133.368,22.00917,0.24878000000000003,99.23499,1.05397
134.448,22.109170000000002,0.24935,99.26210999999999,1.0534700000000001
135.537,22.20917,0.25111999999999995,99.23478,1.0529600000000001
136.61099,22.30917,0.2541,99.26210999999999,1.05246
137.69501,22.40917,0.25467,99.23478,1.05195
138.77901,22.50917,0.25614000000000003,99.23478,1.05144
139.864,22.609170000000002,0.25837,99.23478,1.05093
140.97301000000002,22.70917,0.2594,99.22816,1.0504
142.05,22.80917,0.26194,99.20745,1.0499
143.174,22.90917,0.26147,99.20745,1.04936
144.235,23.00917,0.26295,99.22795,1.0488600000000001
145.34,23.109170000000002,0.26444,99.20745,1.04833
146.44099,23.20917,0.26653000000000004,99.21429,1.0478
147.543,23.30917,0.26711999999999997,99.194,1.04728
148.642,23.40917,0.2674,99.20766,1.04675
149.74698999999998,23.50917,0.26844,99.20766,1.0462200000000001
150.858,23.609170000000002,0.26783,99.20766,1.04568
151.955,23.70917,0.26811,99.18715999999999,1.04515
153.061,23.80917,0.2678,99.19379,1.04461
154.161,23.90917,0.26611999999999997,99.18033,1.04408
155.276,24.00917,0.26716999999999996,99.20766,1.04354
156.379,24.109170000000002,0.26655,99.153,1.043
157.48599,24.20917,0.26668000000000003,99.153,1.04246
158.592,24.30917,0.26666999999999996,99.18033,1.0419200000000002
159.72,24.40917,0.2656,99.18033,1.04136
160.811,24.50917,0.26604,99.15983,1.04082
161.935,24.609170000000002,0.26633,99.15983,1.04027
163.052,24.70917,0.26648,99.13954,1.03972
164.157,24.80917,0.26859,99.13954,1.0391700000000001
165.28,24.90917,0.26798,99.15321,1.03861
166.39,25.00917,0.27071,99.12588000000001,1.03806
167.48199,25.109170000000002,0.27039,99.12588000000001,1.03751
168.604,25.20917,0.27176,99.12588000000001,1.03695
169.714,25.30917,0.27205999999999997,99.11905,1.03639
170.83501,25.40917,0.27251,99.11905,1.03583
171.963,25.50917,0.27266,99.12567,1.03526
173.08,25.609170000000002,0.27296,99.11905,1.0347
174.17999,25.70917,0.27433,99.10538000000001,1.03414
175.297,25.80917,0.27555,99.10538000000001,1.03357
176.412,25.90917,0.27662,99.05072,1.03301
177.54401000000001,26.00917,0.27692,99.07805,1.03243
178.65601,26.109170000000002,0.27860999999999997,99.05756,1.03186
179.767,26.20917,0.27968000000000004,99.06439,1.03129
180.897,26.30917,0.28214,99.07122,1.03071
182.026,26.40917,0.28245,99.05093000000001,1.03013
183.159,26.50917,0.28368000000000004,99.01698,1.02955
184.269,26.609170000000002,0.28553,99.01677,1.02898
185.38901,26.70917,0.28907,98.98965,1.0284
186.498,26.80917,0.28769,98.98965,1.0278200000000002
187.634,26.90917,0.28893,98.98965,1.0272299999999999
188.76801,27.00917,0.29156,98.98965,1.02664
189.886,27.109170000000002,0.29373,98.98965,1.02606
191.024,27.20917,0.29559,98.93499,1.02547
192.15401,27.30917,0.29730999999999996,98.93499,1.02488
193.291,27.40917,0.30025999999999997,98.9147,1.0242799999999999
194.418,27.50917,0.30058,98.90104000000001,1.02369
195.541,27.609170000000002,0.3023,98.88736999999999,1.0231
196.67799,27.70917,0.30665,98.88736999999999,1.0225
197.804,27.80917,0.30729,98.86686999999999,1.0219
198.94298999999998,27.90917,0.30964,98.85342,1.0213
200.05901,28.00917,0.31183,98.79876,1.0207
201.19701,28.109170000000002,0.31232,98.77143000000001,1.0201
202.356,28.20917,0.31468,98.77143000000001,1.01948
203.463,28.30917,0.31656999999999996,98.75093000000001,1.01889
204.599,28.40917,0.31893,98.71718,1.0182799999999999
205.742,28.50917,0.32051999999999997,98.70352,1.01767
206.883,28.609170000000002,0.32304,98.68986,1.01706
208.01199,28.70917,0.32681,98.6354,1.01645
209.129,28.80917,0.32654,98.60807,1.01585
210.27,28.90917,0.32954,98.58075,1.0152299999999999
211.388,29.00917,0.33036,98.55362,1.01463
212.547,29.109170000000002,0.33134,98.51263,1.014
213.66,29.20917,0.33247,98.47164000000001,1.01339
214.79201,29.30917,0.33376999999999996,98.44451,1.01278
215.923,29.40917,0.33505999999999997,98.41718,1.01216
217.05701000000002,29.50917,0.33574,98.36294000000001,1.0115399999999999
218.19,29.609170000000002,0.33829000000000004,98.33561,1.01092
219.323,29.70917,0.33787,98.30828000000001,1.0103
220.45598999999999,29.80917,0.33964,98.27433,1.00968
221.59599,29.90917,0.34142,98.19917,1.00905
222.71001,30.00917,0.34335,98.17205,1.00844
223.879,30.109170000000002,0.34357,98.1176,1.00779
224.99899,30.20917,0.34409,98.06294,1.0071700000000001
226.11501,30.30917,0.3454,98.03582,1.00655
227.25301000000002,30.40917,0.34672,97.95383000000001,1.0059200000000001
228.388,30.50917,0.34379,97.91304000000001,1.00529
229.519,30.609170000000002,0.34149,97.84265,1.00466
230.63699,30.70917,0.34092,97.81532,1.00403
231.786,30.80917,0.34193,97.77453,1.00339
232.89999,30.90917,0.33962,97.68613,1.0027700000000002
234.026,31.00917,0.34141,97.62029,1.00214
235.166,31.109170000000002,0.34052,97.56335,1.0015
236.29601,31.20917,0.34169,97.4793,1.00086
237.44099,31.30917,0.34159,97.41573000000001,1.00021
238.584,31.40917,0.34229,97.3499,0.9995700000000001
239.69298999999998,31.50917,0.34108,97.29545,0.9989399999999999
240.82899,31.609170000000002,0.33971999999999997,97.21366,0.9983
241.96001,31.70917,0.34136,97.11386999999999,0.99766
243.09399,31.80917,0.34079,96.99565,0.9970100000000001
244.213,31.90917,0.33974,96.90269,0.9963700000000001
245.345,32.009170000000005,0.33901,96.78903000000001,0.9957299999999999
246.5,32.10917,0.34018000000000004,96.72547,0.9950700000000001
247.61301,32.20917,0.3377,96.60518,0.9944299999999999
248.739,32.30917,0.33744,96.49606999999999,0.9937799999999999
249.869,32.40917,0.3356,96.38944000000001,0.9931399999999999
250.989,32.509170000000005,0.33486,96.29172,0.99249
252.11,32.60917,0.33587,96.16667,0.99185
253.26199,32.70917,0.3369,96.0236,0.99118
254.39,32.80917,0.33361,95.91242,0.9905299999999999
255.509,32.90917,0.33558000000000004,95.73975,0.98988
256.63199,33.009170000000005,0.33437,95.6648,0.9892299999999999
257.767,33.10917,0.33155,95.50373,0.9885700000000001
258.89401000000004,33.20917,0.32953000000000005,95.33354,0.98792
260.01999,33.30917,0.33071,95.17909,0.98726
261.14801,33.40917,0.32885,95.01325,0.9866
262.27398999999997,33.509170000000005,0.33019,94.84741,0.9859399999999999
263.39898999999997,33.60917,0.33041,94.67495,0.98529
264.535,33.70917,0.33016,94.4795,0.98462
265.673,33.80917,0.33326999999999996,94.26831999999999,0.98395
266.797,33.90917,0.33574,94.07308,0.98329
267.94901,34.009170000000005,0.33935,93.8528,0.98261
269.064,34.10917,0.34762,93.65528,0.98196
270.21701,34.20917,0.3609,93.394,0.9812799999999999
271.349,34.30917,0.38128,93.13747,0.98061
272.48801000000003,34.40917,0.3917,92.89669,0.97993
273.62201,34.509170000000005,0.39842,92.62422,0.97926
274.758,34.60917,0.39902,92.32878000000001,0.9785799999999999
275.91,34.70917,0.39639,92.07909000000001,0.9779
277.01001,34.80917,0.38777,91.79751999999999,0.97724
278.13599,34.90917,0.37703000000000003,91.48199,0.97657
279.25,35.009170000000005,0.36272,91.17536,0.97591
280.39001,35.10917,0.34257,90.86646,0.9752299999999999
281.48001,35.20917,0.32059,90.53271,0.97457
282.604,35.30917,0.29568,90.22609,0.9739
283.70001,35.40917,0.27218000000000003,89.86957,0.97324
284.814,35.509170000000005,0.25125,89.52671,0.97257
285.953,35.60917,0.23388,89.18592,0.97188
287.04199,35.70917,0.22168000000000002,88.82712,0.9712299999999999
288.17499,35.80917,0.21256,88.4706,0.97054
289.27499,35.90917,0.20309000000000002,88.10041,0.96988
290.397,36.009170000000005,0.19785999999999998,87.73023,0.9692
291.522,36.10917,0.19115,87.37143,0.96852
292.621,36.20917,0.19177,87.00352,0.96785
293.75299,36.30917,0.19354000000000002,86.61967,0.96716
294.86899,36.40917,0.19237,86.22712,0.9664799999999999
295.98599,36.509170000000005,0.19643,85.82733,0.9658
297.103,36.60917,0.20082,85.42546999999999,0.9651200000000001
298.21301,36.70917,0.20686,85.00745,0.96444
299.35598999999996,36.80917,0.21111,84.61014,0.9637399999999999
300.47,36.90917,0.21454,84.1853,0.96306
301.55801,37.009170000000005,0.22158000000000003,83.81076999999999,0.96239
302.703,37.10917,0.22913000000000003,83.34741,0.9616899999999999
303.806,37.20917,0.23603000000000002,82.9205,0.96101
304.918,37.30917,0.24327,82.49586,0.9603200000000001
306.03799,37.40917,0.2497,82.01884,0.9596299999999999
307.15701,37.509170000000005,0.25565,81.58282,0.95894
308.26401,37.60917,0.26061,81.13333,0.95826
309.39001,37.70917,0.26657,80.67226,0.9575600000000001
310.48901,37.80917,0.27271,80.20206999999999,0.95688
311.608,37.90917,0.27819,79.73872,0.9561799999999999
312.716,38.009170000000005,0.28534,79.2619,0.9555
313.84,38.10917,0.29034,78.78282,0.9548
314.94501,38.20917,0.29651,78.32174,0.95411
316.047,38.30917,0.30335,77.81988,0.95342
317.15601000000004,38.40917,0.31103000000000003,77.3,0.95273
318.26599,38.509170000000005,0.3179,76.80725,0.9520299999999999
319.38,38.60917,0.32527,76.29855,0.95134
320.47299,38.70917,0.33265,75.79896,0.95065
321.57999,38.80917,0.33954,75.26522,0.94996
322.69101,38.90917,0.34645,74.72008000000001,0.94926
323.80399,39.009170000000005,0.35353,74.20248000000001,0.9485600000000001
324.89999,39.10917,0.36279,73.64141,0.9478700000000001
326.004,39.20917,0.37006,73.0942,0.9471700000000001
327.12601,39.30917,0.37868,72.51056,0.94647
328.224,39.40917,0.38647,71.92464,0.9457700000000001
329.33401000000003,39.509170000000005,0.39445,71.33188,0.9450700000000001
330.44199,39.60917,0.40394,70.72795,0.94437
331.54199,39.70917,0.41311000000000003,70.07826,0.9436700000000001
332.64999,39.80917,0.42246999999999996,69.45611,0.9429700000000001
333.746,39.90917,0.4325,68.83168,0.94227
334.87201,40.009170000000005,0.44238999999999995,68.14576,0.94155
335.98801000000003,40.10917,0.45011,67.44865,0.94084
337.08701,40.20917,0.46053,66.77866999999999,0.94014
338.16199,40.30917,0.47163,66.09751999999999,0.9394600000000001
339.28101000000004,40.40917,0.4836,65.32981,0.93874
340.388,40.509170000000005,0.49171000000000004,64.60766,0.9380299999999999
341.48001,40.60917,0.50117,63.83996,0.93734
342.59799,40.70917,0.5138699999999999,63.05651999999999,0.9366200000000001
343.68399,40.80917,0.52522,62.24576,0.9359200000000001
344.80301000000003,40.90917,0.53796,61.43975,0.9352
345.91598999999997,41.009170000000005,0.54851,60.56066,0.9344899999999999
346.99899,41.10917,0.55907,59.7205,0.93379
348.09,41.20917,0.5715100000000001,58.8236,0.93309
349.20499,41.30917,0.58195,57.92195,0.93237
350.28,41.40917,0.5937399999999999,57.00683000000001,0.9316700000000001
351.37799,41.509170000000005,0.6038600000000001,56.00745,0.93096
352.47101000000004,41.60917,0.61349,55.037890000000004,0.9302600000000001
353.60199,41.70917,0.62247,54.02961,0.9295200000000001
354.67499,41.80917,0.63229,53.00538,0.9288299999999999
355.77398999999997,41.90917,0.6392399999999999,51.947,0.92811
356.85901,42.009170000000005,0.6416,50.91387,0.9274100000000001
357.944,42.10917,0.6460100000000001,49.85776,0.9267
359.03601000000003,42.20917,0.64804,48.783640000000005,0.92599
360.125,42.30917,0.64752,47.716359999999995,0.9252799999999999
361.229,42.40917,0.64563,46.64224,0.92456
362.327,42.509170000000005,0.63553,45.563559999999995,0.92385
363.427,42.60917,0.62422,44.50311,0.9231299999999999
364.51198999999997,42.70917,0.61254,43.40145,0.92242
365.608,42.80917,0.59434,42.35031,0.9217
366.702,42.90917,0.57302,41.33975,0.9209799999999999
367.79501,43.009170000000005,0.5432600000000001,40.354040000000005,0.92027
368.862,43.10917,0.50931,39.44099,0.91956
369.95901000000003,43.20917,0.4731,38.53499,0.91884
371.047,43.30917,0.43149,37.70166,0.9181299999999999
372.13698999999997,43.40917,0.38499,36.947829999999996,0.9174100000000001
373.233,43.509170000000005,0.33376999999999996,36.25735,0.91669
374.328,43.60917,0.28403,35.64865,0.91596
375.397,43.70917,0.23609000000000002,35.15818,0.9152600000000001
376.47699,43.80917,0.19085,34.67909,0.9145399999999999
377.55301000000003,43.90917,0.14883,34.32029,0.9138299999999999
378.65799,44.009170000000005,0.11175,34.03416,0.9131
379.72699,44.10917,0.0815423,33.78427,0.9123899999999999
380.823,44.20917,0.0576969,33.57308,0.91166
381.90302,44.30917,0.03710768,33.37101,0.91095
382.98999,44.40917,0.0196098,33.21884,0.91022
384.08401000000003,44.509170000000005,0.006947078000000001,33.08489,0.9095
385.146,44.60917,-0.008690606,32.95093,0.90879
386.23599,44.70917,-0.02104809,32.81242,0.9080600000000001
387.33499,44.80917,-0.03203288,32.69648,0.90733
388.42499,44.90917,-0.04268672,32.569359999999996,0.9066
389.491,45.009170000000005,-0.05196183,32.455690000000004,0.90589
390.55801,45.10917,-0.06317118,32.3559,0.90517
391.63901,45.20917,-0.07090614,32.260459999999995,0.90445
392.724,45.30917,-0.08005206,32.153620000000004,0.9037200000000001
393.797,45.40917,-0.08851228,32.01967,0.903
394.88501,45.509170000000005,-0.0955866,31.924429999999997,0.9022700000000001
395.94601,45.60917,-0.10214,31.856309999999997,0.90156
397.039,45.70917,-0.1117,31.73354,0.9008299999999999
398.10501,45.80917,-0.11775,31.624640000000003,0.9001100000000001
399.17999,45.90917,-0.1254,31.51097,0.8993899999999999
400.242,46.009170000000005,-0.13112000000000001,31.42257,0.8986700000000001
401.327,46.10917,-0.13809000000000002,31.32712,0.89794
402.396,46.20917,-0.14595,31.24762,0.89722
403.45599,46.30917,-0.15012,31.138509999999997,0.8965
404.53,46.40917,-0.15835,31.047829999999998,0.8957700000000001
405.599,46.509170000000005,-0.16342,30.96605,0.89505
406.685,46.60917,-0.16902999999999999,30.86605,0.89431
407.76099,46.70917,-0.17323,30.772879999999997,0.8935799999999999
408.815,46.80917,-0.18098,30.679920000000003,0.89287
409.88698999999997,46.90917,-0.1852,30.58675,0.8921399999999999
410.94698999999997,47.009170000000005,-0.18925,30.498140000000003,0.8914200000000001
412.017,47.10917,-0.19543,30.404970000000002,0.89069
413.091,47.20917,-0.19932,30.31884,0.8899600000000001
414.168,47.30917,-0.20321,30.232509999999998,0.88923
415.216,47.40917,-0.20836,30.132509999999996,0.8885200000000001
416.27499,47.509170000000005,-0.21084,30.04161,0.88779
417.33898999999997,47.60917,-0.21404,29.960040000000003,0.88707
418.39801,47.70917,-0.21689,29.87598,0.88634
419.46799000000004,47.80917,-0.2201,29.8147,0.88561
420.53101,47.90917,-0.22153,29.71925,0.8848799999999999
421.59,48.009170000000005,-0.226,29.594409999999996,0.8841600000000001
422.65399,48.10917,-0.22779000000000002,29.54203,0.8834299999999999
423.698,48.20917,-0.23066,29.45818,0.88271
424.76401,48.30917,-0.23551,29.36957,0.8819799999999999
425.82901,48.40917,-0.23696,29.287779999999998,0.88125
426.88699,48.509170000000005,-0.24128000000000002,29.240170000000003,0.8805200000000001
427.94100999999995,48.60917,-0.24201999999999999,29.16749,0.8798
429.01000999999997,48.70917,-0.2451,29.081159999999997,0.8790600000000001
430.06600999999995,48.80917,-0.24781999999999998,28.981370000000002,0.87834
431.11899000000005,48.90917,-0.2491,28.897309999999997,0.87761
432.18201,49.009170000000005,-0.25056999999999996,28.822359999999996,0.8768799999999999
433.23400999999996,49.10917,-0.25186,28.75631,0.87615
434.29400999999996,49.20917,-0.25081,28.717809999999997,0.8754200000000001
435.349,49.30917,-0.25373,28.62712,0.87469
436.41101,49.40917,-0.25484,28.52257,0.87395
437.47601,49.509170000000005,-0.25578,28.463559999999998,0.8732200000000001
438.51999000000006,49.60917,-0.25581,28.388609999999996,0.87249
439.57901,49.70917,-0.26128,28.31594,0.8717600000000001
440.634,49.80917,-0.26223,28.23188,0.87103
441.68201,49.90917,-0.26516999999999996,28.17288,0.8703
442.746,50.009170000000005,-0.26431,28.09565,0.86956
443.79400999999996,50.10917,-0.26616,28.027540000000002,0.8688299999999999
444.84399,50.20917,-0.26839,27.968320000000002,0.8681
445.88599000000005,50.30917,-0.2708,27.875359999999997,0.8673799999999999
446.94199000000003,50.40917,-0.27121,27.85466,0.86664
447.98900999999995,50.509170000000005,-0.27399,27.76625,0.8659100000000001
449.043,50.60917,-0.27404,27.68447,0.86518
450.09,50.70917,-0.27446,27.62091,0.86445
451.146,50.80917,-0.2725,27.573290000000004,0.8637100000000001
452.19699,50.90917,-0.272,27.51884,0.8629700000000001
453.23400999999996,51.009170000000005,-0.27223,27.44845,0.86225
454.31,51.10917,-0.2732,27.37805,0.8615
455.33499000000006,51.20917,-0.27287,27.32112,0.8607799999999999
456.39300999999995,51.30917,-0.27384000000000003,27.237270000000002,0.8600399999999999
457.436,51.40917,-0.27536,27.18944,0.85931
458.47299000000004,51.509170000000005,-0.27578,27.134990000000002,0.8585799999999999
459.53200999999996,51.60917,-0.27841,27.075979999999998,0.8578399999999999
460.59601,51.70917,-0.27884000000000003,27.012420000000002,0.85709
461.63100999999995,51.80917,-0.28018000000000004,26.95797,0.85636
462.67801,51.90917,-0.28024,26.903309999999998,0.8556299999999999
463.71899,52.009170000000005,-0.28085,26.84886,0.8548899999999999
464.776,52.10917,-0.28073000000000004,26.79441,0.85415
465.802,52.20917,-0.27837,26.737679999999997,0.8534299999999999
466.85999000000004,52.30917,-0.27936,26.671840000000003,0.8526799999999999
467.91699000000006,52.40917,-0.28071,26.62402,0.85193
468.94299,52.50917,-0.28262,26.5764,0.85121
469.97601,52.60917,-0.28565,26.50145,0.8504799999999999
471.03101,52.70916999999999,-0.28497,26.446790000000004,0.8497399999999999
472.069,52.809169999999995,-0.28726,26.39917,0.849
473.125,52.909169999999996,-0.29199,26.35155,0.84825
474.16101,53.00917,-0.29373,26.2971,0.84752
475.21300999999994,53.10917,-0.2938,26.242440000000002,0.84678
476.259,53.20916999999999,-0.2991,26.18799,0.84603
477.289,53.309169999999995,-0.30029,26.160870000000003,0.8453
478.34698,53.409169999999996,-0.30262,26.113039999999998,0.84455
479.383,53.50917,-0.304,26.05176,0.8438200000000001
480.41699000000006,53.60917,-0.30577,26.03789,0.8430799999999999
481.44699,53.70916999999999,-0.30996999999999997,25.96315,0.84235
482.48499000000004,53.809169999999995,-0.31024,25.90166,0.8416100000000001
483.539,53.909169999999996,-0.31315,25.83375,0.84086
484.57599000000005,54.00917,-0.31549,25.79296,0.8401299999999999
485.625,54.10917,-0.31916,25.7383,0.8393799999999999
486.647,54.20916999999999,-0.31887,25.71118,0.83865
487.698,54.309169999999995,-0.32255,25.64969,0.8379
488.746,54.409169999999996,-0.32397,25.60207,0.83715
489.76999000000006,54.50917,-0.3269,25.56812,0.83642
490.79199000000006,54.60917,-0.32681,25.52029,0.8356899999999999
491.828,54.70916999999999,-0.32899,25.490679999999998,0.83495
492.85599,54.809169999999995,-0.33041,25.43623,0.8342200000000001
493.90302,54.909169999999996,-0.33185,25.35466,0.83347
494.935,55.00917,-0.33176,25.32733,0.83273
495.96300999999994,55.10917,-0.33775,25.272879999999997,0.83199
497.00201,55.20916999999999,-0.33749,25.27267,0.83125
498.02399,55.309169999999995,-0.34045,25.21594,0.83052
499.06699000000003,55.409169999999996,-0.34228000000000003,25.13437,0.8297700000000001
500.091,55.50917,-0.3441,25.107039999999998,0.8290299999999999
501.13100999999995,55.60917,-0.34651,25.05259,0.82829
502.16699000000006,55.70916999999999,-0.35083000000000003,25.05238,0.8275399999999999
503.185,55.809169999999995,-0.35305,24.98447,0.82681
504.21700999999996,55.909169999999996,-0.35413,24.9118,0.8260700000000001
505.25100999999995,56.00917,-0.35464,24.904970000000002,0.82532
506.27802,56.10917,-0.35554,24.85735,0.8245899999999999
507.328,56.20916999999999,-0.36046999999999996,24.77536,0.82383
508.34299000000004,56.309169999999995,-0.36424,24.741410000000002,0.8231
509.39000999999996,56.409169999999996,-0.37072,24.741410000000002,0.82234
510.41101,56.50917,-0.37374,24.68696,0.8216100000000001
511.44100999999995,56.60917,-0.37832,24.605179999999997,0.82086
512.47601,56.70916999999999,-0.38366999999999996,24.57785,0.8201200000000001
513.50403,56.809169999999995,-0.38594,24.52112,0.81937
514.5189799999999,56.909169999999996,-0.38764,24.48716,0.8186399999999999
515.56,57.00917,-0.39166999999999996,24.46667,0.81789
516.60498,57.10917,-0.39532,24.41222,0.81713
517.59698,57.20916999999999,-0.39992,24.38489,0.8164100000000001
518.63599,57.309169999999995,-0.40358,24.33043,0.81566
519.66998,57.409169999999996,-0.40492,24.30311,0.81491
520.70203,57.50917,-0.40801,24.27598,0.81417
521.70502,57.60917,-0.41323000000000004,24.22133,0.8134399999999999
522.75098,57.70916999999999,-0.41556000000000004,24.16687,0.8126800000000001
523.76398,57.809169999999995,-0.42021000000000003,24.16687,0.81194
524.79401,57.909169999999996,-0.42177,24.13975,0.8112
525.83099,58.00917,-0.42528,24.08509,0.8104399999999999
526.85101,58.10917,-0.42878999999999995,24.037470000000003,0.8097
527.88098,58.20916999999999,-0.43075,24.01014,0.80895
528.90399,58.309169999999995,-0.43232,23.98302,0.80821
529.9279799999999,58.409169999999996,-0.43604,23.98282,0.80747
530.95398,58.50917,-0.43899,23.92836,0.80672
531.97302,58.60917,-0.44077,23.88758,0.80598
532.98602,58.70916999999999,-0.4451,23.83313,0.80524
534.00598,58.809169999999995,-0.44806,23.8058,0.8045
535.02899,58.909169999999996,-0.44847,23.803520000000002,0.80375
536.04498,59.00917,-0.45086000000000004,23.74907,0.80301
537.0700099999999,59.10917,-0.45423,23.74886,0.8022600000000001
538.08398,59.20916999999999,-0.45642,23.69441,0.80152
539.11298,59.309169999999995,-0.45843,23.667289999999998,0.80077
540.12,59.409169999999996,-0.45983999999999997,23.61284,0.80003
541.15503,59.50917,-0.46284,23.614910000000002,0.79928
542.16699,59.60917,-0.46268000000000004,23.61511,0.7985399999999999
543.2139900000001,59.70916999999999,-0.46391000000000004,23.56046,0.79777
544.22101,59.809169999999995,-0.46731999999999996,23.53333,0.79703
545.22699,59.909169999999996,-0.46953,23.503729999999997,0.7963
546.255,60.00917,-0.47176,23.4764,0.7955399999999999
547.27399,60.10917,-0.47498999999999997,23.43561,0.7948
548.29199,60.20916999999999,-0.47703,23.394820000000003,0.79405
549.31598,60.309169999999995,-0.47748,23.36749,0.7933
550.3389900000001,60.409169999999996,-0.48072,23.34017,0.79255
551.354,60.50917,-0.48396999999999996,23.31304,0.79181
552.35901,60.60917,-0.48241999999999996,23.28571,0.7910699999999999
553.40002,60.70916999999999,-0.48508999999999997,23.258589999999998,0.7903
554.396,60.809169999999995,-0.48994,23.2381,0.78957
555.42603,60.909169999999996,-0.49041,23.19027,0.78882
556.435,61.00917,-0.49187,23.17681,0.7880699999999999
557.4420200000001,61.10917,-0.49253,23.14948,0.78733
558.448,61.20916999999999,-0.49621000000000004,23.095029999999998,0.78659
559.47998,61.309169999999995,-0.4989,23.08137,0.78583
560.47699,61.409169999999996,-0.49996999999999997,23.05424,0.7851
561.5,61.50917,-0.49904,23.02692,0.78435
562.4979900000001,61.60917,-0.5007199999999999,22.999589999999998,0.78361
563.505,61.70916999999999,-0.50422,22.97246,0.78287
564.53003,61.809169999999995,-0.50552,22.91781,0.7821100000000001
565.52197,61.909169999999996,-0.5080100000000001,22.89048,0.78138
566.5380200000001,62.00917,-0.51032,22.89068,0.78063
567.54199,62.10917,-0.5110100000000001,22.88385,0.77989
568.57703,62.20916999999999,-0.51313,22.83623,0.77913
569.57898,62.309169999999995,-0.5130100000000001,22.8089,0.7783899999999999
570.58398,62.409169999999996,-0.51594,22.781570000000002,0.77764
571.59198,62.50917,-0.51623,22.774739999999998,0.7769
572.604,62.60917,-0.51937,22.747410000000002,0.77615
573.59497,62.70916999999999,-0.51945,22.69979,0.77542
574.604,62.809169999999995,-0.52505,22.72008,0.77467
575.617,62.909169999999996,-0.5259699999999999,22.6793,0.7739199999999999
576.633,63.00917,-0.52566,22.67246,0.77317
577.63599,63.10917,-0.5271899999999999,22.63851,0.7724300000000001
578.64001,63.20916999999999,-0.53179,22.611179999999997,0.77168
579.65302,63.309169999999995,-0.53149,22.611179999999997,0.77093
580.64899,63.409169999999996,-0.53098,22.56356,0.7701899999999999
581.65399,63.50917,-0.53293,22.53623,0.76945
582.672,63.60917,-0.53571,22.52277,0.76869
583.664,63.70916999999999,-0.53561,22.50911,0.7679600000000001
584.664,63.809169999999995,-0.53777,22.48178,0.7672100000000001
585.66699,63.909169999999996,-0.5385,22.45466,0.76647
586.68402,64.00917,-0.5411,22.427329999999998,0.76571
587.68799,64.10916999999999,-0.54038,22.4,0.7649699999999999
588.69098,64.20917,-0.54195,22.37288,0.76422
589.70502,64.30917,-0.54683,22.35238,0.76347
590.69299,64.40916999999999,-0.5485899999999999,22.37288,0.76273
591.7119799999999,64.50917,-0.5483100000000001,22.34555,0.76198
592.72198,64.60916999999999,-0.55072,22.31843,0.7612300000000001
593.70398,64.70917,-0.55083,22.31822,0.76049
594.71997,64.80917,-0.55388,22.2911,0.75974
595.70801,64.90916999999999,-0.5535800000000001,22.27743,0.759
596.7130099999999,65.00917,-0.55413,22.21615,0.75825
597.729,65.10916999999999,-0.55781,22.236439999999998,0.7575
598.72601,65.20917,-0.5573100000000001,22.20932,0.75675
599.7189900000001,65.30917,-0.55786,22.20932,0.7560100000000001
600.71503,65.40916999999999,-0.56134,22.202479999999998,0.75527
601.7139900000001,65.50917,-0.56147,22.18199,0.75453
602.72101,65.60916999999999,-0.56098,22.1412,0.7537699999999999
603.71802,65.70917,-0.56133,22.113870000000002,0.75303
604.724,65.80917,-0.56105,22.08675,0.7522800000000001
605.7130099999999,65.90916999999999,-0.56076,22.08675,0.75154
606.7139900000001,66.00917,-0.55984,22.059420000000003,0.75079
607.71997,66.10916999999999,-0.56062,22.059420000000003,0.7500399999999999
608.71698,66.20917,-0.55928,22.059420000000003,0.7493
609.71002,66.30917,-0.55709,22.00497,0.74855
610.7119799999999,66.40916999999999,-0.5561699999999999,21.97764,0.7478100000000001
611.7189900000001,66.50917,-0.5544,21.95031,0.74705
612.72998,66.60916999999999,-0.55242,21.95052,0.7463
613.72198,66.70917,-0.55128,21.93685,0.74555
614.70599,66.80917,-0.54992,21.89586,0.7448199999999999
615.71002,66.90916999999999,-0.54814,21.91636,0.74407
616.71002,67.00917,-0.54614,21.889229999999998,0.74332
617.70599,67.10916999999999,-0.54371,21.86874,0.74257
618.71002,67.20917,-0.54277,21.84141,0.74182
619.69299,67.30917,-0.54182,21.84141,0.7410800000000001
620.711,67.40916999999999,-0.5381100000000001,21.81429,0.74032
621.69397,67.50917,-0.5341600000000001,21.78696,0.73958
622.68597,67.60916999999999,-0.5351199999999999,21.78696,0.7388399999999999
623.67401,67.70917,-0.53095,21.759629999999998,0.7381
624.66699,67.80917,-0.52742,21.73251,0.73735
625.6619900000001,67.90916999999999,-0.52474,21.7323,0.73661
626.66602,68.00917,-0.51905,21.7323,0.73585
627.6630200000001,68.10916999999999,-0.5174300000000001,21.68468,0.7351
628.646,68.20917,-0.5142899999999999,21.67785,0.73437
629.6279900000001,68.30917,-0.5152399999999999,21.63685,0.73363
630.633,68.40916999999999,-0.51297,21.60973,0.73287
631.61798,68.50917,-0.51025,21.60973,0.7321300000000001
632.60901,68.60916999999999,-0.5062399999999999,21.58923,0.73139
633.59998,68.70917,-0.50567,21.5824,0.73064
634.5819700000001,68.80917,-0.50402,21.52795,0.7299100000000001
635.578,68.90916999999999,-0.5028,21.55528,0.72916
636.5869799999999,69.00917,-0.49877,21.534779999999998,0.7284
637.58002,69.10916999999999,-0.4969,21.51429,0.72765
638.5720200000001,69.20917,-0.4961,21.48033,0.7269
639.54901,69.30917,-0.49246999999999996,21.45983,0.72617
640.54199,69.40916999999999,-0.48971000000000003,21.4735,0.72542
641.52698,69.50917,-0.48913,21.43251,0.72468
642.53198,69.60916999999999,-0.48527,21.43271,0.72392
643.52002,69.70917,-0.4849,21.405379999999997,0.72318
644.5189799999999,69.80917,-0.47818999999999995,21.405379999999997,0.72243
645.48901,69.90916999999999,-0.47561000000000003,21.38489,0.7217