File: 02_Data/Polyurethane_Foam/STA/N2/30K_min/Polyurethane_Foam_STA_N2_30KData_210225_R2.csv
##Temp./Â°C,Time/min,DSC/(mW/mg),Mass/%,Sensit./(uV/mW)
48.706,10.00667,0.01779391,99.54758000000001,1.0679299999999998
48.704,10.10667,0.01646599,99.57212,1.0679299999999998
48.711,10.206669999999999,0.01620046,99.60892,1.06792
48.721,10.30667,0.01726286,99.68253,1.06792
48.728,10.40667,0.02044993,99.65799,1.06792
48.757,10.50667,0.02204371,99.58439,1.0679
48.819,10.60667,0.02496585,99.53569,1.06787
48.891,10.706669999999999,0.02841948,99.57212,1.06784
49.01,10.80667,0.03904564,99.48216,1.06778
49.158,10.90667,0.05047047,99.57212,1.06771
49.384,11.00667,0.06057064,99.60483,1.0676
49.659,11.10667,0.08023932,99.58848,1.0674700000000001
50.007,11.206669999999999,0.09885312,99.53532,1.06731
50.441,11.30667,0.12385999999999998,99.51524,1.0671
50.975,11.40667,0.15127000000000002,99.53123000000001,1.06685
51.596,11.50667,0.17764000000000002,99.54349,1.06656
52.323,11.60667,0.21015,99.54758000000001,1.06621
53.144,11.706669999999999,0.24216,99.49851,1.06582
54.081,11.80667,0.27766,99.47398000000001,1.06538
55.144,11.90667,0.31455,99.5026,1.06487
56.297,12.00667,0.35495,99.53569,1.0643200000000002
57.565,12.10667,0.39115,99.48662,1.06372
58.947,12.206669999999999,0.42794,99.46208,1.0630600000000001
60.394,12.30667,0.464,99.48662,1.06236
61.954,12.40667,0.49932,99.4948,1.06162
63.594,12.50667,0.5312399999999999,99.46616999999999,1.06083
65.312,12.60667,0.56724,99.51524,1.0600100000000001
67.089,12.706669999999999,0.5942,99.48216,1.05916
68.924,12.80667,0.62364,99.50296999999999,1.05827
70.842,12.90667,0.64967,99.53532,1.05735
72.741,13.00667,0.6735899999999999,99.59257,1.05643
74.718,13.10667,0.69812,99.54349,1.05548
76.761,13.20667,0.72244,99.55167,1.05449
78.821,13.30667,0.74305,99.54349,1.05349
80.927,13.406670000000002,0.75913,99.59665,1.05247
83.062,13.506670000000002,0.7803800000000001,99.54758000000001,1.0514299999999999
85.255,13.606670000000001,0.80169,99.46616999999999,1.05037
87.485,13.70667,0.82496,99.55204,1.04928
89.771,13.80667,0.84424,99.49888,1.04816
92.086,13.906670000000002,0.8643799999999999,99.49851,1.04703
94.443,14.006670000000002,0.88459,99.48662,1.04588
96.865,14.106670000000001,0.90976,99.49070999999999,1.04469
99.312,14.20667,0.92929,99.42936999999999,1.04348
101.789,14.30667,0.9546,99.4171,1.04227
104.341,14.406670000000002,0.97809,99.48253000000001,1.04101
106.94,14.506670000000002,1.00248,99.50669,1.03972
109.557,14.606670000000001,1.02504,99.43346,1.03843
112.226,14.70667,1.0474,99.43346,1.03711
114.924,14.80667,1.0720299999999998,99.40892,1.03577
117.675,14.906670000000002,1.09484,99.45799,1.0344
120.483,15.006670000000002,1.11801,99.49070999999999,1.033
123.314,15.106670000000001,1.14209,99.45353,1.03159
126.205,15.20667,1.16571,99.49070999999999,1.03014
129.127,15.30667,1.18695,99.5026,1.0286799999999998
132.08,15.406670000000002,1.2113,99.55204,1.0272
135.08701000000002,15.506670000000002,1.2365899999999999,99.50296999999999,1.02568
138.11501,15.606670000000001,1.26031,99.49033,1.02416
141.19701,15.70667,1.2846899999999999,99.50296999999999,1.0226
144.3,15.80667,1.3088899999999999,99.51487,1.02104
147.43401,15.906670000000002,1.33263,99.50296999999999,1.01945
150.595,16.00667,1.352,99.55204,1.01785
153.80901,16.10667,1.3709200000000001,99.60074,1.01621
157.024,16.206670000000003,1.38795,99.55167,1.01457
160.261,16.30667,1.40421,99.55167,1.01292
163.532,16.406670000000002,1.41943,99.50296999999999,1.01125
166.814,16.50667,1.43472,99.55204,1.00957
170.116,16.60667,1.45205,99.50296999999999,1.0078799999999999
173.438,16.706670000000003,1.4655,99.5026,1.00617
176.8,16.80667,1.47989,99.5026,1.00444
180.17101,16.906670000000002,1.4915100000000001,99.50296999999999,1.0027
183.575,17.00667,1.51142,99.55167,1.00094
187.004,17.10667,1.52375,99.5881,0.99916
190.45399,17.206670000000003,1.53815,99.5881,0.9973700000000001
193.93401,17.30667,1.55946,99.58848,0.99556
197.43401,17.406670000000002,1.57089,99.58848,0.99374
200.931,17.50667,1.58264,99.55167,0.9919100000000001
204.463,17.60667,1.59505,99.53941,0.99006
208.00101,17.706670000000003,1.61239,99.58848,0.98821
211.55,17.80667,1.6234899999999999,99.55204,0.98635
215.12,17.906670000000002,1.63581,99.50296999999999,0.9844700000000001
218.69701,18.00667,1.6551099999999999,99.51524,0.9825799999999999
222.287,18.10667,1.6695900000000001,99.51524,0.9806799999999999
225.895,18.206670000000003,1.68705,99.46616999999999,0.97877
229.513,18.30667,1.71272,99.50296999999999,0.97685
233.159,18.406670000000002,1.7353299999999998,99.4539,0.97491
236.767,18.50667,1.7617900000000002,99.4539,0.9729899999999999
240.41499,18.60667,1.7919,99.35613000000001,0.97104
244.063,18.706670000000003,1.83473,99.30705999999999,0.96909
247.72,18.80667,1.8783400000000001,99.25799,0.9671299999999999
251.392,18.906670000000002,1.9244900000000003,99.20929,0.96515
255.062,19.00667,1.9841,99.0461,0.9631799999999999
258.74301,19.10667,2.04544,98.93196999999999,0.96119
262.41598999999997,19.206670000000003,2.12449,98.70781,0.9592
266.121,19.30667,2.22555,98.52006999999999,0.95719
269.82101,19.406670000000002,2.33327,98.33234,0.9551799999999999
273.51401,19.50667,2.46495,97.95761999999999,0.9531700000000001
277.20401,19.60667,2.6231400000000002,97.51301,0.95115
280.909,19.706670000000003,2.80416,96.97881,0.9491299999999999
284.60598999999996,19.80667,3.01919,96.371,0.9471
288.311,19.906670000000002,3.2621900000000004,95.67398,0.94506
292.01599,20.00667,3.5399300000000005,94.66245,0.9430200000000001
295.72299,20.10667,3.8357900000000003,93.64312,0.9409700000000001
299.436,20.206670000000003,4.145969999999999,92.26914000000001,0.93891
303.13599,20.30667,4.45568,90.82565,0.93686
306.84201,20.406670000000002,4.75102,89.01561,0.93479
310.56,20.50667,5.01884,87.13569,0.9327200000000001
314.272,20.60667,5.23666,85.01933000000001,0.9306399999999999
317.95801,20.706670000000003,5.29444,82.9316,0.9285700000000001
321.64401000000004,20.80667,5.10853,80.70929,0.9265
325.34698,20.906670000000002,4.58683,78.7316,0.9244100000000001
329.01901000000004,21.00667,3.8908199999999997,76.93383,0.9223399999999999
332.689,21.10667,3.1282,75.53903000000001,0.9202600000000001
336.34601000000004,21.206670000000003,2.44181,74.56468000000001,0.9181799999999999
340.00699,21.30667,1.9659400000000002,73.85093,0.9161
343.664,21.406670000000002,1.6647900000000002,73.27620999999999,0.91401
347.31799,21.50667,1.48635,72.91747,0.91191
350.96799,21.60667,1.39002,72.51338,0.9098200000000001
354.60101000000003,21.706670000000003,1.3472899999999999,72.17918,0.9077299999999999
358.246,21.80667,1.3523,71.82454,0.9056200000000001
361.88501,21.906670000000002,1.41855,71.3513,0.9035200000000001
365.50601,22.00667,1.54582,70.81747,0.90141
369.146,22.10667,1.72482,70.1855,0.8993
372.76198999999997,22.206670000000003,1.96597,69.34535,0.8971899999999999
376.38599,22.30667,2.26342,68.14647,0.8950600000000001
380.013,22.406670000000002,2.6432900000000004,66.74795999999999,0.89294
383.64499,22.50667,3.1587400000000003,64.74571999999999,0.8908
387.30099,22.60667,3.8267599999999997,62.0342,0.88864
390.96398999999997,22.706670000000003,4.52304,58.47063000000001,0.8864700000000001
394.57001,22.80667,5.03784,54.06691,0.88433
398.16299,22.906670000000002,5.42138,48.60706,0.8821899999999999
401.745,23.00667,5.6624099999999995,42.28253,0.88005
405.298,23.10667,5.69616,35.27323,0.8779299999999999
408.82999,23.206670000000003,5.47711,28.2803,0.8758
412.388,23.30667,5.05781,21.666539999999998,0.87366
415.85901,23.406670000000002,4.49594,16.06803,0.87156
419.345,23.50667,3.87794,11.62342,0.86945
422.823,23.60667,3.28439,8.36989,0.86734
426.28601,23.706670000000003,2.75121,6.01673,0.8652299999999999
429.73099,23.80667,2.26864,4.45911,0.86313
433.14999000000006,23.906670000000002,1.81893,3.41115,0.86103
436.56600999999995,24.00667,1.41591,2.8487,0.85893
439.979,24.10667,1.09764,2.44089,0.85683
443.39800999999994,24.206670000000003,0.8826700000000001,2.14312,0.8547100000000001
446.82199,24.30667,0.73916,1.9594799999999999,0.85259
450.25699000000003,24.406670000000002,0.6449699999999999,1.8494400000000002,0.85046
453.67599,24.50667,0.57806,1.8007400000000002,0.8483200000000001
457.095,24.60667,0.5372899999999999,1.75167,0.84619
460.51099000000005,24.706670000000003,0.50337,1.62937,0.84404
463.91500999999994,24.80667,0.48173999999999995,1.60483,0.8419
467.31,24.906670000000002,0.45831000000000005,1.55576,0.8397600000000001
470.70499,25.00667,0.43477,1.65799,0.8376100000000001
474.07999,25.10667,0.41823,1.65799,0.83547
477.46399,25.206670000000003,0.4057,1.52342,0.8333200000000001
480.82999,25.30667,0.39071,1.4620799999999998,0.8311700000000001
484.186,25.406670000000002,0.37975,1.49888,0.8290200000000001
487.539,25.50667,0.36701999999999996,1.4501899999999999,0.8268700000000001
490.88100999999995,25.60667,0.35869,1.4011200000000001,0.82471
494.22299000000004,25.706670000000003,0.34791,1.43792,0.82255
497.577,25.80667,0.33984000000000003,1.43792,0.8203799999999999
500.892,25.906670000000002,0.33276,1.43792,0.81823
504.18399000000005,26.00667,0.33016,1.38885,0.81608
507.49300999999997,26.10667,0.32545999999999997,1.37658,0.81392
510.793,26.206670000000003,0.31864000000000003,1.33978,0.81176
514.09497,26.30667,0.31459000000000004,1.32751,0.8095899999999999
517.37402,26.406670000000002,0.30876,1.27881,0.80742
520.64099,26.50667,0.30501,1.29071,0.8052600000000001
523.90802,26.60667,0.29877,1.26654,0.8031
527.1680299999999,26.706670000000003,0.29108,1.24201,0.80093
530.42102,26.80667,0.28406,1.26654,0.79876
533.67102,26.906670000000002,0.2738,1.21784,0.7965899999999999
536.91602,27.00667,0.25955,1.21784,0.7944100000000001
540.1610099999999,27.10667,0.24486999999999998,1.21784,0.79223
543.383,27.206670000000003,0.22616,1.21784,0.79005
546.604,27.30667,0.20590999999999998,1.1810399999999999,0.78788
549.81897,27.406670000000002,0.18950999999999998,1.1319700000000001,0.78569
553.0310099999999,27.50667,0.17484,1.18067,0.78351
556.23199,27.60667,0.15827,1.22974,0.78133
559.43103,27.706670000000003,0.14706,1.1810399999999999,0.7791399999999999
562.63202,27.80667,0.13251,1.2052,0.77694
565.81799,27.906670000000002,0.11640999999999999,1.18067,0.77475
568.99597,28.00667,0.09728645,1.0829,0.77256
572.19598,28.10667,0.09277971,1.08699,0.77035
575.35999,28.206670000000003,0.0804911,1.14015,0.76815
578.539,28.30667,0.07220673,1.12788,0.76594
581.69897,28.406670000000002,0.06684467,1.07881,0.76374
584.85999,28.50667,0.06629379,1.07881,0.76153
588.01703,28.60667,0.06536646,1.07881,0.75931
591.17401,28.706670000000003,0.06593267,1.03011,0.7570899999999999
594.31201,28.80667,0.06988299,1.14424,0.75488
597.45398,28.906670000000002,0.08214748,1.14424,0.75266
600.5880099999999,29.00667,0.09637426,1.14424,0.75044
603.7310200000001,29.10667,0.10424000000000001,1.14424,0.74821
606.84698,29.206670000000003,0.1247,1.09517,0.7459899999999999
609.97198,29.30667,0.13957,1.0461,0.7437600000000001
613.0880099999999,29.406670000000002,0.16102,1.0461,0.74153
616.2000099999999,29.50667,0.17455,1.0461,0.73929
619.31,29.60667,0.1874,1.0342,0.73706
622.40503,29.706670000000003,0.20456,1.0342,0.73482
625.51099,29.80667,0.22145,1.0342,0.73258
628.612,29.906670000000002,0.23573000000000002,0.98513,0.73033