File: 01_Data/Polyurethane_Foam/STA/N2/10K_min/Polyurethane_Foam_STA_N2_10KData_210301_R3.csv
##Temp./Â°C,Time/min,DSC/(mW/mg),Mass/%,Sensit./(uV/mW)
47.69,10.01,0.01456984,100.34246,1.0895299999999999
47.694,10.11,0.01590791,100.34246,1.0895299999999999
47.698,10.21,0.01679996,100.34246,1.0895299999999999
47.705,10.31,0.01635399,100.34246,1.0895299999999999
47.712,10.41,0.0165027,100.31444,1.0895299999999999
47.725,10.51,0.01635409,100.35648,1.08952
47.745,10.61,0.018733,100.36348000000001,1.08951
47.761,10.71,0.0199225,100.36348000000001,1.08951
47.805,10.81,0.02200428,100.3913,1.08949
47.86,10.91,0.02319412,100.36327,1.0894700000000002
47.923,11.01,0.02810116,100.36348000000001,1.08945
48.001,11.11,0.03196776,100.36327,1.08942
48.095,11.21,0.03628083,100.36327,1.0893899999999999
48.219,11.31,0.04074328,100.33546,1.08934
48.369,11.41,0.04595001,100.36348000000001,1.0892899999999999
48.526,11.51,0.05056253,100.33546,1.08923
48.713,11.61,0.05547354,100.36348000000001,1.0891600000000001
48.925,11.71,0.06291412,100.38429000000001,1.0890799999999998
49.144,11.81,0.06946348,100.36348000000001,1.089
49.415,11.91,0.07556884,100.37049,1.08891
49.695,12.01,0.0825682,100.36093000000001,1.0888
49.996,12.11,0.08956952,100.36348000000001,1.08869
50.333,12.21,0.09582941,100.39618,1.08857
50.705,12.31,0.10313,100.37495,1.08843
51.116,12.41,0.10955,100.36794,1.08828
51.479,12.51,0.117,100.36815,1.08815
51.905,12.61,0.12372000000000001,100.38429000000001,1.08799
52.344,12.71,0.13014,100.40064,1.0878299999999999
52.819,12.81,0.13612,100.39363,1.08766
53.282,12.91,0.14121,100.37961999999999,1.08748
53.777,13.01,0.14719000000000002,100.40064,1.0873
54.302,13.11,0.15317999999999998,100.42866,1.08711
54.83,13.21,0.15827,100.42866,1.08691
55.382,13.31,0.16352,100.40764,1.0867
55.948,13.41,0.16727999999999998,100.42866,1.08649
56.527,13.51,0.17149,100.42845,1.08628
57.109,13.61,0.17659,100.41230999999999,1.08606
57.713,13.71,0.17901,100.42633000000001,1.0858299999999999
58.303,13.81,0.18383,100.45414,1.08561
58.938,13.91,0.1876,100.45414,1.0853700000000002
59.576,14.01,0.19047999999999998,100.41230999999999,1.08513
60.227,14.11,0.19321,100.42633000000001,1.0848799999999998
60.889,14.21,0.19713,100.42633000000001,1.08463
61.528,14.31,0.20106,100.42611,1.08439
62.234,14.41,0.2038,100.45435,1.08412
62.91,14.51,0.20579,100.45414,1.08386
63.63,14.61,0.20824,100.41230999999999,1.08359
64.331,14.71,0.21173000000000003,100.41230999999999,1.08332
65.054,14.81,0.21552,100.42633000000001,1.08304
65.781,14.91,0.21871999999999997,100.45435,1.08276
66.521,15.01,0.22252,100.45414,1.08247
67.27,15.11,0.22512,100.45414,1.08218
68.033,15.21,0.22773000000000002,100.45435,1.08189
68.791,15.31,0.23064,100.45414,1.08159
69.545,15.41,0.23354,100.45414,1.0813
70.33,15.51,0.23721,100.45435,1.08099
71.137,15.61,0.23893000000000003,100.45414,1.0806799999999999
71.94,15.71,0.24184,100.45435,1.08036
72.74,15.81,0.24491,100.48217,1.08005
73.562,15.91,0.24784,100.48217,1.07972
74.394,16.01,0.25061,100.48217,1.07939
75.206,16.11,0.25414000000000003,100.48217,1.07907
76.047,16.21,0.25572,100.48217,1.07874
76.909,16.31,0.25971,100.45414,1.07839
77.765,16.41,0.2616,100.50998,1.07805
78.62,16.51,0.26258000000000004,100.50318,1.07771
79.488,16.61,0.26582,100.48217,1.07736
80.369,16.71,0.26816999999999996,100.48217,1.077
81.262,16.81,0.26931,100.51019000000001,1.07664
82.136,16.91,0.27331,100.50318,1.07629
83.043,17.01,0.27416,100.48217,1.07592
83.965,17.11,0.27757,100.51019000000001,1.07554
84.862,17.21,0.27917,100.51019000000001,1.07518
85.784,17.31,0.28153,100.51019000000001,1.0748
86.687,17.41,0.28253,100.50998,1.07443
87.649,17.51,0.28369,100.538,1.0740299999999998
88.562,17.61,0.28635,100.5242,1.07365
89.507,17.71,0.28765999999999997,100.538,1.07326
90.441,17.81,0.29034,100.538,1.0728799999999998
91.381,17.91,0.2912,100.51019000000001,1.0724799999999999
92.35,18.01,0.29418,100.53822,1.07208
93.313,18.11,0.29489,100.538,1.07168
94.284,18.21,0.29803,100.56603,1.0712700000000002
95.266,18.31,0.29799000000000003,100.538,1.0708600000000001
96.224,18.41,0.30159,100.53822,1.07045
97.211,18.51,0.3017,100.538,1.07003
98.197,18.61,0.30394,100.55202,1.06961
99.184,18.71,0.30618,100.538,1.0692
100.191,18.81,0.30737,100.54500999999999,1.06877
101.169,18.91,0.31082,100.54500999999999,1.06835
102.167,19.01,0.3117,100.56603,1.06792
103.164,19.11,0.31259000000000003,100.538,1.06749
104.19,19.21,0.31590999999999997,100.53822,1.06705
105.199,19.31,0.31588,100.53822,1.06661
106.208,19.41,0.31784,100.56603,1.06617
107.219,19.51,0.31994,100.54500999999999,1.0657299999999998
108.225,19.61,0.32281,100.538,1.0653
109.244,19.71,0.32249,100.538,1.06485
110.272,19.81,0.3246,100.531,1.0644
111.305,19.91,0.32627,100.5172,1.06395
112.321,20.01,0.32716,100.51019000000001,1.0635
113.351,20.11,0.3273,100.531,1.06304
114.376,20.21,0.32958000000000004,100.538,1.06259
115.414,20.31,0.33048,100.56603,1.06213
116.463,20.41,0.33276999999999995,100.56603,1.06166
117.485,20.51,0.33337,100.538,1.06121
118.54,20.61,0.33626,100.538,1.06073
119.578,20.71,0.33931,100.56603,1.06027
120.623,20.81,0.34176,100.56603,1.0598
121.678,20.91,0.3413,100.56603,1.05932
122.714,21.01,0.34298,100.56603,1.05885
123.764,21.11,0.34665,100.58684000000001,1.0583799999999999
124.833,21.21,0.34589000000000003,100.55901999999999,1.05789
125.879,21.31,0.34758,100.59406,1.05742
126.944,21.41,0.34774,100.56603,1.05693
128.009,21.51,0.35189000000000004,100.58705,1.05644
129.07899,21.61,0.35205,100.57304,1.05595
130.144,21.71,0.35406,100.59384,1.05546
131.213,21.81,0.35561,100.61486,1.05497
132.283,21.91,0.35746,100.59406,1.05447
133.35001,22.01,0.35871,100.59406,1.05398
134.444,22.11,0.36134,100.62187,1.0534700000000001
135.51801,22.21,0.36167,100.59384,1.0529700000000002
136.591,22.31,0.3623,100.62187,1.05247
137.69701,22.41,0.36571,100.60085,1.05195
138.765,22.51,0.36589,100.62187,1.05145
139.86301,22.61,0.36761,100.62187,1.05093
140.946,22.71,0.36948000000000003,100.62187,1.0504200000000001
142.049,22.81,0.37106,100.64968,1.0499
143.142,22.91,0.37124,100.62187,1.04938
144.239,23.01,0.3722,100.61486,1.0488600000000001
145.366,23.11,0.37439,100.61486,1.0483200000000001
146.44298999999998,23.21,0.37489,100.64289000000001,1.0478
147.537,23.31,0.37353000000000003,100.64289000000001,1.04728
148.63699,23.41,0.37542,100.64968,1.04675
149.758,23.51,0.37746999999999997,100.62187,1.04621
150.84801000000002,23.61,0.37905,100.62187,1.04569
151.95,23.71,0.37754,100.64289000000001,1.04515
153.073,23.81,0.37805,100.61486,1.04461
154.177,23.91,0.37995,100.62187,1.04407
155.289,24.01,0.38045999999999996,100.60085,1.0435299999999998
156.394,24.11,0.37988,100.62187,1.0429899999999999
157.498,24.21,0.38147,100.64968,1.04245
158.601,24.31,0.38369000000000003,100.62187,1.0419100000000001
159.72301000000002,24.41,0.38452,100.64989,1.04136
160.819,24.51,0.38441,100.64989,1.04082
161.933,24.61,0.38523,100.62187,1.04027
163.056,24.71,0.38606,100.62187,1.0397100000000001
164.175,24.81,0.38783,100.63588,1.03916
165.283,24.91,0.38928,100.64289000000001,1.03861
166.384,25.01,0.3898,100.64289000000001,1.03806
167.50101,25.11,0.39000999999999997,100.61486,1.0375
168.612,25.21,0.39115,100.62187,1.03694
169.73,25.31,0.39137,100.62187,1.0363799999999999
170.842,25.41,0.39298,100.67771,1.03582
171.955,25.51,0.39382,100.70551999999999,1.03526
173.07401000000002,25.61,0.39623,100.68471,1.0347
174.19901000000002,25.71,0.39676,100.69171999999999,1.03413
175.30701000000002,25.81,0.3976,100.71253,1.03357
176.422,25.91,0.39860999999999996,100.71274,1.033
177.543,26.01,0.39914,100.74076,1.03243
178.661,26.11,0.4014,100.71274,1.03186
179.791,26.21,0.40005999999999997,100.74055,1.03128
180.912,26.31,0.40169,100.69193,1.03071
182.034,26.41,0.40239,100.76858,1.03013
183.161,26.51,0.40513000000000005,100.76858,1.02955
184.286,26.61,0.40458,100.74076,1.0289700000000002
185.40198999999998,26.71,0.40731999999999996,100.76879,1.02839
186.534,26.81,0.40676999999999996,100.76879,1.0278100000000001
187.658,26.91,0.40653,100.74776999999999,1.02722
188.78,27.01,0.40897,100.76156999999999,1.02664
189.907,27.11,0.40983,100.76858,1.02605
191.043,27.21,0.41133000000000003,100.7966,1.02546
192.186,27.31,0.41062,100.7966,1.02486
193.308,27.41,0.41323000000000004,100.79639,1.02427
194.435,27.51,0.41331,100.7896,1.02368
195.564,27.61,0.41481999999999997,100.7896,1.02308
196.69901000000002,27.71,0.41633000000000003,100.76156999999999,1.0224799999999998
197.823,27.81,0.41736,100.76156999999999,1.02189
198.966,27.91,0.42094,100.76156999999999,1.02129
200.08501,28.01,0.42118999999999995,100.76156999999999,1.0206899999999999
201.222,28.11,0.42223,100.76156999999999,1.02009
202.366,28.21,0.42328000000000005,100.74076,1.01948
203.371,28.31,0.42541,100.70573,1.01894
204.505,28.41,0.42708999999999997,100.70573,1.01833
205.638,28.51,0.42862,100.67771,1.01773
206.767,28.61,0.42791999999999997,100.70573,1.01712
207.894,28.71,0.43151999999999996,100.67792,1.01651
209.033,28.81,0.4345,100.69873,1.0159
210.161,28.91,0.43603000000000003,100.6707,1.01529
211.291,29.01,0.43996999999999997,100.64289000000001,1.01468
212.422,29.11,0.44103000000000003,100.62187,1.01407
213.547,29.21,0.44354,100.59384,1.01345
214.686,29.31,0.44588999999999995,100.59384,1.01283
215.80701000000002,29.41,0.44888,100.59384,1.0122200000000001
216.936,29.51,0.45059,100.57304,1.0116100000000001
218.069,29.61,0.45215,100.54500999999999,1.01099
219.214,29.71,0.45708000000000004,100.54500999999999,1.0103600000000001
220.345,29.81,0.45832,100.531,1.0097399999999999
221.467,29.91,0.46116999999999997,100.531,1.00912
222.59599,30.01,0.46274,100.5242,1.0085
223.73801,30.11,0.46721,100.48917,1.00787
224.854,30.21,0.47039,100.44013000000001,1.00725
225.98199,30.31,0.47453999999999996,100.46115,1.00663
227.13,30.41,0.47806000000000004,100.43312,1.00599
228.241,30.51,0.48255,100.40531,1.00537
229.37601,30.61,0.48591000000000006,100.42611,1.00474
230.49698999999998,30.71,0.49057,100.3983,1.00411
231.62801000000002,30.81,0.49427,100.3845,1.00348
232.769,30.91,0.49895,100.38429000000001,1.00284
233.88499,31.01,0.50298,100.35625999999999,1.00222
235.01199,31.11,0.51073,100.32845,1.00158
236.149,31.21,0.51608,100.30064,1.00094
237.26401,31.31,0.52353,100.28641,1.00031
238.40601,31.41,0.52727,100.28641,0.9996700000000001
239.53,31.51,0.5323,100.27261,0.99903
240.65601,31.61,0.54027,100.24459,0.9984
241.783,31.71,0.54597,100.21656,0.9977600000000001
242.903,31.81,0.55185,100.18875,0.9971200000000001
244.036,31.91,0.56033,100.13991999999999,0.9964700000000001
245.17,32.01,0.56818,100.10488000000001,0.9958299999999999
246.289,32.11,0.57636,100.05605,0.99519
247.41,32.21,0.58422,100.00721999999999,0.99455
248.54201,32.31,0.5935600000000001,99.95116999999999,0.9939
249.677,32.41,0.60488,99.89299,0.99325
250.80299,32.51,0.61507,99.83482,0.9926
251.927,32.61,0.62625,99.77898,0.99195
253.058,32.71,0.63532,99.67175999999999,0.9913
254.18401,32.81,0.64685,99.59023,0.99065
255.314,32.91,0.6593899999999999,99.49235999999999,0.9899899999999999
256.43701,33.01,0.6711199999999999,99.38769,0.98934
257.56299,33.11,0.68303,99.32951,0.98869
258.68201,33.21,0.6974199999999999,99.19193,0.9880399999999999
259.84299,33.31,0.71217,99.07325,0.98736
260.936,33.41,0.7275699999999999,98.94501,0.9867299999999999
262.061,33.51,0.74415,98.79363000000001,0.9860700000000001
263.186,33.61,0.7622399999999999,98.67495,0.98541
264.31601,33.71,0.78051,98.51189000000001,0.98475
265.43399,33.81,0.7996300000000001,98.37451999999999,0.9840899999999999
266.55801,33.91,0.81911,98.21146,0.9834299999999999
267.69601,34.01,0.8391200000000001,98.0603,0.9827600000000001
268.819,34.11,0.8622799999999999,97.92971999999999,0.9821
269.936,34.21,0.88349,97.70616,0.98144
271.06201,34.31,0.90804,97.4431,0.9807799999999999
272.185,34.41,0.9334399999999999,97.23355,0.98011
273.29999,34.51,0.9607,97.04013,0.97945
274.423,34.61,0.9885,96.78408,0.9787799999999999
275.543,34.71,1.01583,96.53482,0.9781200000000001
276.67499,34.81,1.04719,96.24840999999999,0.97744
277.79999,34.91,1.07876,95.97834,0.97677
278.91699,35.01,1.1092,95.71975,0.97611
280.026,35.11,1.14034,95.43333,0.97544
281.151,35.21,1.17486,95.11189,0.97477
282.26501,35.31,1.20859,94.77431,0.9741
283.37799,35.41,1.24403,94.43652,0.9734299999999999
284.48801000000003,35.51,1.27836,94.06156999999999,0.97277
285.612,35.61,1.31207,93.70064,0.97209
286.72101000000004,35.71,1.3458299999999999,93.30020999999999,0.9714200000000001
287.841,35.81,1.38347,92.88556,0.9707399999999999
288.961,35.91,1.41683,92.46645,0.9700700000000001
290.08301,36.01,1.45559,92.00998,0.96939
291.18399,36.11,1.49204,91.52569,0.96872
292.32501,36.21,1.53176,91.0155,0.96803
293.436,36.31,1.5669899999999999,90.50551999999999,0.96735
294.547,36.41,1.60546,89.93036,0.9666799999999999
295.66199,36.51,1.64297,89.37856,0.966
296.77802,36.61,1.6839,88.82887,0.9653200000000001
297.92801000000003,36.71,1.72291,88.22335,0.9646100000000001
299.01001,36.81,1.7585400000000002,87.57366999999999,0.96395
300.12701,36.91,1.7925799999999998,86.96348,0.9632700000000001
301.23401,37.01,1.8275,86.31846999999999,0.96259
302.34799,37.11,1.8599599999999998,85.67345999999999,0.9619
303.46398999999997,37.21,1.8899299999999999,84.98875,0.9612200000000001
304.58499,37.31,1.9147299999999998,84.32038,0.9605299999999999
305.67401,37.41,1.92839,83.5845,0.95986
306.79501,37.51,1.9193099999999998,82.91145999999999,0.95916
307.88199,37.61,1.8797599999999999,82.23609,0.95849
308.996,37.71,1.81025,81.59108,0.9578
310.10598999999996,37.81,1.7328599999999998,80.97155,0.9571200000000001
311.20801,37.91,1.66347,80.37536999999999,0.9564299999999999
312.323,38.01,1.5992600000000001,79.80488000000001,0.9557399999999999
313.44101,38.11,1.53003,79.22251,0.95504
314.55099,38.21,1.45306,78.7104,0.95435
315.65701,38.31,1.36256,78.16072,0.9536600000000001
316.77802,38.41,1.2598799999999999,77.68089,0.95296
317.90398999999996,38.51,1.16181,77.26879,0.95226
319.00601,38.61,1.06511,76.85648,0.95157
320.11099,38.71,0.98156,76.55393000000001,0.95088
321.21898999999996,38.81,0.91409,76.2535,0.9501799999999999
322.33401000000003,38.91,0.85744,75.97155,0.9494799999999999
323.44,39.01,0.80788,75.7482,0.9487899999999999
324.55899,39.11,0.7722600000000001,75.49427,0.9480799999999999
325.67001,39.21,0.74547,75.29618,0.9473799999999999
326.77898999999996,39.31,0.72035,75.14968,0.94668
327.884,39.41,0.69863,74.9259,0.94599
329.0,39.51,0.6806399999999999,74.76773,0.9452799999999999
330.104,39.61,0.66657,74.61168,0.94458
331.21898999999996,39.71,0.65574,74.46476,0.9438799999999999
332.31799,39.81,0.643,74.31805,0.9431799999999999
333.42899,39.91,0.63781,74.1482,0.94247
334.52701,40.01,0.629,74.02718,0.9417700000000001
335.647,40.11,0.62569,73.87558,0.94106
336.73401,40.21,0.62063,73.74289,0.94037
337.85598999999996,40.31,0.61938,73.6172,0.93965
338.95801,40.41,0.61795,73.45881,0.93895
340.04999,40.51,0.61962,73.3051,0.93825
341.168,40.61,0.61992,73.17707,0.9375399999999999
342.26599,40.71,0.62384,72.99320999999999,0.9368299999999999
343.36401,40.81,0.62743,72.84183,0.9361299999999999
344.461,40.91,0.63275,72.67175999999999,0.93542
345.57999,41.01,0.63947,72.48323,0.9347
346.66598999999997,41.11,0.64463,72.27134000000001,0.934
347.77398999999997,41.21,0.65068,72.06156999999999,0.93329
348.86099,41.31,0.6609,71.81253000000001,0.9325899999999999
349.953,41.41,0.67965,71.52845,0.9318799999999999
351.086,41.51,0.72611,71.27452,0.93115
352.16501,41.61,0.75956,70.9414,0.93045
353.26599,41.71,0.7721600000000001,70.62951,0.92974
354.35699,41.81,0.79227,70.27325,0.9290299999999999
355.461,41.91,0.82325,69.87961999999999,0.92832
356.54098999999997,42.01,0.8533799999999999,69.48365,0.9276200000000001
357.646,42.11,0.88865,69.00616,0.9269
358.72299,42.21,0.9230700000000001,68.50085,0.9262
359.83099,42.31,0.9568700000000001,67.94904,0.92548
360.90799,42.41,0.9978899999999999,67.40403,0.9247700000000001
362.005,42.51,1.03722,66.76136,0.92406
363.09601000000004,42.61,1.0796,66.05796,0.9233399999999999
364.17099,42.71,1.11958,65.31274,0.92264
365.26901000000004,42.81,1.16086,64.46518,0.9219200000000001
366.35101000000003,42.91,1.2023700000000002,63.589380000000006,0.9212100000000001
367.43301,43.01,1.2441200000000001,62.6276,0.9205
368.548,43.11,1.28386,61.619319999999995,0.9197700000000001
369.59201,43.21,1.32535,60.517830000000004,0.9190799999999999
370.677,43.31,1.36589,59.339490000000005,0.91837
371.758,43.41,1.4079,58.07495,0.91766
372.84201,43.51,1.44716,56.69851,0.91694
373.91299,43.61,1.48682,55.247769999999996,0.9162399999999999
375.004,43.71,1.52196,53.7293,0.9155200000000001
376.06699,43.81,1.55818,52.14098,0.91481
377.14099,43.91,1.59005,50.43631,0.9141
378.215,44.01,1.617,48.62229,0.9133899999999999
379.28101000000004,44.11,1.63689,46.815290000000005,0.91269
380.36401,44.21,1.65683,44.90552,0.9119700000000001
381.44,44.31,1.6684400000000001,42.98662,0.91125
382.49899,44.41,1.6756,40.91401,0.91055
383.582,44.51,1.67212,38.89045,0.9098299999999999
384.66199,44.61,1.66685,36.819959999999995,0.9091100000000001
385.724,44.71,1.6513900000000001,34.763690000000004,0.9084
386.80399,44.81,1.62771,32.73758,0.9076799999999999
387.87201,44.91,1.59863,30.755840000000003,0.90697
388.95001,45.01,1.56254,28.7949,0.90625
390.01599,45.11,1.51726,26.876009999999997,0.90554
391.095,45.21,1.46727,25.01996,0.9048200000000001
392.17401,45.31,1.41255,23.25011,0.90409
393.24701,45.41,1.35432,21.57558,0.9033700000000001
394.33401000000003,45.51,1.29189,19.9758,0.90264
395.41199,45.61,1.22827,18.49236,0.90192
396.48801000000003,45.71,1.16563,17.132270000000002,0.9012
397.55701,45.81,1.10162,15.830570000000002,0.90048
398.64301,45.91,1.03752,14.60552,0.89975
399.724,46.01,0.9753,13.504029999999998,0.89902
400.798,46.11,0.92055,12.50276,0.8982899999999999
401.875,46.21,0.8621,11.56178,0.8975700000000001
402.952,46.31,0.8133100000000001,10.711889999999999,0.89684
404.04501,46.41,0.76445,9.947980000000001,0.8961
405.104,46.51,0.71586,9.23546,0.89538
406.18701,46.61,0.67389,8.59257,0.89465
407.245,46.71,0.63095,8.01507,0.8939299999999999
408.31601,46.81,0.59428,7.4934199999999995,0.8932100000000001
409.39801,46.91,0.55557,7.02527,0.8924700000000001
410.46898999999996,47.01,0.5211399999999999,6.60382,0.89175
411.54001,47.11,0.48938999999999994,6.24522,0.89102
412.617,47.21,0.45686000000000004,5.90977,0.8902899999999999
413.67801000000003,47.31,0.42591,5.64204,0.88956
414.74399,47.41,0.39802,5.38811,0.88884
415.814,47.51,0.36951999999999996,5.17389,0.8881100000000001
416.88599,47.61,0.34628000000000003,5.01783,0.88738
417.94501,47.71,0.32464,4.8316300000000005,0.88665
419.02499,47.81,0.30462,4.68025,0.8859100000000001
420.07999,47.91,0.28583000000000003,4.5660300000000005,0.8851899999999999
421.14300999999995,48.01,0.27123,4.44034,0.88446
422.20499,48.11,0.25826,4.37282,0.88374
423.267,48.21,0.24618,4.28684,0.8830100000000001
424.32999,48.31,0.23646999999999999,4.22611,0.88228
425.383,48.41,0.22546,4.17028,0.88156
426.448,48.51,0.21975999999999998,4.11444,0.8808299999999999
427.51401,48.61,0.21295,4.03057,0.8800899999999999
428.573,48.71,0.2087,4.00955,0.87936
429.63699,48.81,0.20593000000000003,3.9724,0.8786299999999999
430.702,48.91,0.20389000000000002,3.9443699999999997,0.8779
431.763,49.01,0.20313,3.9443699999999997,0.8771700000000001
432.83099000000004,49.11,0.20146,3.91635,0.8764299999999999
433.87600999999995,49.21,0.20088,3.8885400000000003,0.87571
434.948,49.31,0.19772,3.8885400000000003,0.87497
436.01401,49.41,0.19789,3.8885400000000003,0.87423
437.06799,49.51,0.19379000000000002,3.8327,0.8735
438.13100999999995,49.61,0.18894,3.84671,0.8727600000000001
439.186,49.71,0.18,3.8116800000000004,0.87203
440.23199000000005,49.81,0.17140999999999998,3.8046699999999998,0.87131
441.29099,49.91,0.1615,3.77665,0.8705700000000001
442.35900999999996,50.01,0.15512,3.7768599999999997,0.8698299999999999
443.41199000000006,50.11,0.14705,3.79766,0.8691
444.46200999999996,50.21,0.14513,3.74183,0.8683700000000001
445.52300999999994,50.31,0.1417,3.73503,0.8676299999999999
446.578,50.41,0.13977,3.70701,0.8669
447.625,50.51,0.13895,3.70701,0.8661700000000001
448.67599,50.61,0.13682,3.67898,0.8654299999999999
449.729,50.71,0.136,3.67898,0.8647
450.784,50.81,0.13705,3.67898,0.8639600000000001
451.83401,50.91,0.13623,3.67898,0.8632299999999999
452.883,51.01,0.13372,3.6231400000000002,0.8625
453.936,51.11,0.13252,3.5951199999999996,0.8617600000000001
454.98400999999996,51.21,0.13094,3.5743099999999997,0.8610200000000001
456.035,51.31,0.13124,3.5673,0.86029
457.078,51.41,0.12909,3.5673,0.85956
458.13901,51.51,0.12939,3.5951199999999996,0.8588100000000001
459.17801,51.61,0.12988,3.5673,0.85808
460.224,51.71,0.13055,3.59745,0.85735
461.267,51.81,0.13104000000000002,3.6252699999999995,0.85662
462.315,51.91,0.12983,3.61826,0.85588
463.35199000000006,52.01,0.13032,3.6462800000000004,0.85515
464.40601,52.11,0.13366,3.6462800000000004,0.85441
465.439,52.21,0.13187000000000001,3.6673,0.8536799999999999
466.49701,52.31,0.13199,3.6743099999999997,0.8529399999999999
467.526,52.41,0.13172,3.6743099999999997,0.85221
468.57000999999997,52.51,0.13203,3.6743099999999997,0.8514700000000001
469.60900999999996,52.61,0.1348,3.6743099999999997,0.8507399999999999
470.646,52.71,0.13321,3.6743099999999997,0.85001
471.68300999999997,52.81,0.1337,3.6743099999999997,0.8492700000000001
472.73499000000004,52.91,0.1342,3.70234,0.8485299999999999
473.771,53.01,0.1326,3.70234,0.8478
474.80899000000005,53.11,0.13157,3.68132,0.84706
475.85199000000006,53.21,0.13283,3.68132,0.8463200000000001
476.89000999999996,53.31,0.13065,3.6462800000000004,0.84559
477.95499,53.41,0.13249,3.63715,0.84483
478.98801,53.51,0.13088,3.61614,0.8441
480.01500999999996,53.61,0.13195,3.58811,0.8433700000000001
481.043,53.71,0.13091,3.6019099999999997,0.84264
482.09299000000004,53.81,0.13005999999999998,3.58811,0.8418899999999999
483.133,53.91,0.13076,3.5462800000000003,0.84115
484.177,54.01,0.13068,3.53206,0.84041
485.198,54.11,0.13041,3.50425,0.83968
486.24399000000005,54.21,0.13052,3.4762199999999996,0.83894
487.28699000000006,54.31,0.12967,3.4482,0.83819
488.315,54.41,0.1294,3.44841,0.83746
489.35500999999994,54.51,0.12719,3.3993599999999997,0.83672
490.39300999999995,54.61,0.12866,3.37155,0.83598
491.42099,54.71,0.12703,3.3645400000000003,0.83524
492.452,54.81,0.12714,3.3645400000000003,0.8345100000000001
493.48199000000005,54.91,0.12686,3.3365199999999997,0.8337700000000001
494.517,55.01,0.12639,3.3365199999999997,0.8330299999999999
495.55499000000003,55.11,0.12534,3.3365199999999997,0.8322799999999999
496.58300999999994,55.21,0.12623,3.28769,0.83155
497.625,55.31,0.12537,3.28769,0.8308
498.67599,55.41,0.12314000000000001,3.28769,0.83005
499.70099000000005,55.51,0.12442,3.2806800000000003,0.82931
500.71899,55.61,0.12473,3.2806800000000003,0.8285799999999999
501.754,55.71,0.12347000000000001,3.25265,0.8278399999999999
502.77899,55.81,0.12397000000000001,3.2806800000000003,0.8271
503.814,55.91,0.12153,3.29469,0.82636
504.84601,56.01,0.12243,3.2806800000000003,0.82562
505.88,56.11,0.12293,3.25265,0.8248700000000001
506.90601,56.21,0.12165999999999999,3.26667,0.8241299999999999
507.92999000000003,56.31,0.1204,3.26667,0.8234
508.97198,56.41,0.1211,3.26667,0.8226399999999999
509.98199000000005,56.51,0.12199000000000002,3.23885,0.8219200000000001
511.01599000000004,56.61,0.1223,3.26667,0.8211700000000001
512.052,56.71,0.12379000000000001,3.26667,0.82042
513.07898,56.81,0.12232,3.26667,0.81968
514.10498,56.91,0.12322999999999999,3.26667,0.81894
515.11902,57.01,0.12354000000000001,3.27367,0.81821
516.14001,57.11,0.12563,3.2806800000000003,0.81747
517.17297,57.21,0.12535,3.2806800000000003,0.81672
518.1920200000001,57.31,0.12287999999999999,3.3087,0.81598
519.2069700000001,57.41,0.12319000000000001,3.3087,0.81525
520.23999,57.51,0.12270999999999999,3.33673,0.8145
521.26202,57.61,0.12082999999999999,3.29469,0.81376
522.28998,57.71,0.12114000000000001,3.32272,0.81301
523.323,57.81,0.11985,3.32272,0.81226
524.336,57.91,0.11975999999999999,3.33673,0.81153
525.36401,58.01,0.11867,3.3087,0.8107800000000001
526.38501,58.11,0.11938,3.3087,0.81004
527.4119900000001,58.21,0.11689000000000001,3.29469,0.8093
528.4299900000001,58.31,0.117,3.29469,0.8085600000000001
529.45502,58.41,0.11771,3.2598700000000003,0.80781
530.48297,58.51,0.11862,3.23185,0.80706
531.51202,58.61,0.11853,3.23185,0.8063100000000001
532.52301,58.71,0.12045,3.23185,0.80558
533.5499900000001,58.81,0.12075999999999999,3.20382,0.80483
534.586,58.91,0.12228,3.22484,0.80407
535.60101,59.01,0.12460999999999998,3.22484,0.80333
536.6220099999999,59.11,0.12654,3.19703,0.8025899999999999
537.64203,59.21,0.1307,3.19703,0.80184
538.66699,59.31,0.13122999999999999,3.20382,0.80109
539.6829799999999,59.41,0.13135,3.23185,0.80035
540.7069700000001,59.51,0.1333,3.21083,0.7996
541.71503,59.61,0.13666,3.18981,0.79887
542.73901,59.71,0.14146,3.2178299999999997,0.7981199999999999
543.758,59.81,0.14057999999999998,3.18301,0.79737
544.77197,59.91,0.14599,3.18301,0.7966300000000001
545.784,60.01,0.14694000000000002,3.18301,0.79589
546.8049900000001,60.11,0.14953,3.15499,0.79514
547.81799,60.21,0.15028,3.162,0.7944
548.83002,60.31,0.15389,3.169,0.79366
549.8560200000001,60.41,0.15587,3.1760099999999998,0.79291
550.88,60.51,0.1597,3.162,0.79215
551.89301,60.61,0.16005999999999998,3.162,0.7914100000000001
552.9060099999999,60.71,0.1643,3.1341799999999997,0.79067
553.91901,60.81,0.16507,3.15499,0.78992
554.92902,60.91,0.16749,3.15499,0.78918
555.94897,61.01,0.16847,3.1131599999999997,0.78843
556.9450099999999,61.11,0.1715,3.1131599999999997,0.7877
557.9639900000001,61.21,0.17393,3.11996,0.78695
558.97498,61.31,0.1776,3.09193,0.7862
559.97302,61.41,0.17818,3.1059400000000004,0.78547
560.99298,61.51,0.18041,3.08493,0.78472
562.00403,61.61,0.181,3.09193,0.78397
563.01501,61.71,0.18448,3.09915,0.78323
564.02197,61.81,0.18569000000000002,3.07813,0.78249
565.04401,61.91,0.18835,3.1059400000000004,0.78173
566.04797,62.01,0.19080999999999998,3.08514,0.78099
567.05902,62.11,0.19432,3.0573200000000003,0.78025
568.06897,62.21,0.19367,3.08514,0.7795
569.08301,62.31,0.1949,3.10616,0.77875
570.09302,62.41,0.19717,3.10616,0.7780100000000001
571.10199,62.51,0.19819,3.08514,0.7772600000000001
572.112,62.61,0.19859000000000002,3.08514,0.77651
573.12,62.71,0.2015,3.10616,0.77577
574.12402,62.81,0.20085,3.10616,0.77503
575.13397,62.91,0.20439000000000002,3.07813,0.77428
576.138,63.01,0.20417000000000002,3.0573200000000003,0.77354
577.14502,63.11,0.20709,3.07113,0.77279
578.151,63.21,0.20665999999999998,3.07113,0.77204
579.159,63.31,0.20749,3.0573200000000003,0.7713
580.17102,63.41,0.21085,3.0573200000000003,0.77055
581.177,63.51,0.21189000000000002,3.07113,0.7698
582.17603,63.61,0.21378000000000003,3.08514,0.7690600000000001
583.19098,63.71,0.21484,3.07813,0.76831
584.19897,63.81,0.2142,3.0501099999999997,0.76756
585.1970200000001,63.91,0.21483000000000002,3.07813,0.76682
586.1970200000001,64.01,0.21335,3.07813,0.76608
587.20599,64.11,0.21419000000000002,3.0571099999999998,0.7653300000000001
588.20599,64.21,0.21631,3.0571099999999998,0.76458
589.211,64.31,0.21843,3.08514,0.76384
590.20801,64.41,0.21736999999999998,3.08514,0.7631
591.21002,64.51,0.21609,3.11295,0.76235
592.23999,64.61,0.21843,3.1059400000000004,0.76158
593.21802,64.71,0.22013000000000002,3.13397,0.7608600000000001
594.216,64.81,0.22035,3.162,0.7601100000000001
595.21002,64.91,0.2212,3.18981,0.75937
596.20502,65.01,0.22205999999999998,3.18981,0.75863
597.22601,65.11,0.21993000000000001,3.2178299999999997,0.7578699999999999
598.21802,65.21,0.221,3.19002,0.75713
599.22302,65.31,0.22208000000000003,3.19002,0.75638
600.22803,65.41,0.22100999999999998,3.169,0.75563
601.24402,65.51,0.22102,3.18301,0.75488
602.22601,65.61,0.22252,3.18301,0.7541399999999999
603.2189900000001,65.71,0.22253,3.162,0.7534
604.23297,65.81,0.22446999999999998,3.15499,0.75265
605.22699,65.91,0.22728,3.18301,0.7519
606.2189900000001,66.01,0.23051999999999997,3.18301,0.75116
607.22198,66.11,0.2301,3.15499,0.75041
608.2119799999999,66.21,0.22623000000000001,3.15499,0.74967
609.2130099999999,66.31,0.22732,3.13397,0.74893
610.20801,66.41,0.22798000000000002,3.162,0.7481800000000001
611.2069700000001,66.51,0.22971999999999998,3.15499,0.74744
612.203,66.61,0.22496,3.1758,0.74669
613.19897,66.71,0.22866,3.1758,0.74595
614.1950099999999,66.81,0.23085,3.1828,0.7452
615.18701,66.91,0.22955,3.21083,0.74446
616.19598,67.01,0.23044,3.23885,0.7437
617.17902,67.11,0.22696,3.23885,0.74297
618.17297,67.21,0.22893000000000002,3.2084900000000003,0.74222
619.16498,67.31,0.22698000000000002,3.2084900000000003,0.74148
620.15503,67.41,0.22699,3.2155,0.74074
621.15302,67.51,0.23028,3.2084900000000003,0.7399899999999999
622.14099,67.61,0.23139,3.19469,0.73925
623.14099,67.71,0.23206,3.1806799999999997,0.7385
624.13202,67.81,0.23185999999999998,3.2017,0.73775
625.1229900000001,67.91,0.23165,3.22951,0.73701
626.1270099999999,68.01,0.22969,3.1874700000000002,0.73626
627.11499,68.11,0.2297,3.18047,0.73552
628.10101,68.21,0.22618000000000002,3.18047,0.73477
629.09698,68.31,0.22641,3.18047,0.7340300000000001
630.07898,68.41,0.22885,3.18047,0.73329
631.0670200000001,68.51,0.22975,3.15265,0.73255
632.06598,68.61,0.2271,3.16667,0.7318
633.06,68.71,0.22821999999999998,3.15265,0.73105
634.0499900000001,68.81,0.22713000000000003,3.12017,0.73031
635.03998,68.91,0.22536,3.11295,0.72956
636.0360099999999,69.01,0.22648000000000001,3.08493,0.7288100000000001
637.0380200000001,69.11,0.22783,3.0571099999999998,0.72806
638.013,69.21,0.22626999999999997,3.08493,0.72732
639.01202,69.31,0.22651,3.0431,0.7265699999999999
640.0189799999999,69.41,0.22741,3.0501099999999997,0.7258100000000001
640.98901,69.51,0.22943000000000002,3.0222900000000004,0.7250800000000001
641.98199,69.61,0.23079000000000002,3.0222900000000004,0.72434
642.97302,69.71,0.22810999999999998,2.99427,0.72359
643.9619799999999,69.81,0.22812,2.97325,0.72285
644.953,69.91,0.22926,2.97325,0.7221