File: 01_Data/Overstuffed_Chair_Polyester_Fabric/STA/N2/3K_min/Overstuffed_Chair_Polyester_Fabric_STA_N2_3KData_210309_R1.csv
##Temp./Â°C,Time/min,DSC/(mW/mg),Mass/%,Gas Flow(purge1)/(ml/min),Gas Flow(protective)/(ml/min),Sensit./(uV/mW)
49.052,10.01,-0.003746655,99.85051999999999,50.0,20.0,1.0532700000000002
49.06,10.31,-0.002372884,99.8619,50.0,20.0,1.0532700000000002
49.076,10.61,-0.001748444,99.86206999999999,50.0,20.0,1.0532700000000002
49.101,10.91,-0.0003746677,99.86206999999999,50.0,20.0,1.05326
49.192,11.21,0.00224803,99.8619,50.0,20.0,1.05325
49.298,11.51,0.006244611999999999,99.8619,50.0,20.0,1.05324
49.466,11.81,0.00986668,99.86206999999999,50.0,20.0,1.05322
49.711,12.11,0.0143633,99.8619,50.0,20.0,1.05319
49.989,12.41,0.01960968,99.83724000000001,50.0,20.0,1.05315
50.333,12.71,0.02360753,99.88276,50.0,20.0,1.05311
50.731,13.01,0.0277308,99.86017,50.0,20.0,1.05306
51.145,13.31,0.03085518,99.83740999999999,50.0,20.0,1.05301
51.608,13.61,0.03435487,99.83724000000001,50.0,20.0,1.05295
52.109,13.91,0.03673073,99.85448000000001,50.0,20.0,1.05288
52.635,14.21,0.03810747,99.84879000000001,50.0,20.0,1.05281
53.182,14.51,0.03998432,99.8431,50.0,20.0,1.05274
53.756,14.81,0.04486063,99.81466,50.0,20.0,1.05267
54.364,15.11,0.04398928,99.86017,50.0,20.0,1.05259
54.96,15.41,0.04624223,99.84879000000001,50.0,20.0,1.05251
55.605,15.71,0.04962076,99.84293000000001,50.0,20.0,1.0524200000000001
56.259,16.01,0.05124994,99.84879000000001,50.0,20.0,1.05233
56.922,16.31,0.05350456,99.80328,50.0,20.0,1.05224
57.622,16.61,0.05438463,99.82603,50.0,20.0,1.0521399999999999
58.367,16.91,0.05676565,99.85431,50.0,20.0,1.0520399999999999
59.049,17.21,0.05714596,99.83171999999999,50.0,20.0,1.0519399999999999
59.786,17.51,0.05977786,99.82034,50.0,20.0,1.0518399999999999
60.54,17.81,0.06128484,99.80914,50.0,20.0,1.0517299999999998
61.291,18.11,0.06191658,99.82621,50.0,20.0,1.05162
62.061,18.41,0.06329926,99.85448000000001,50.0,20.0,1.05151
62.85,18.71,0.06543313,99.80914,50.0,20.0,1.0514
63.636,19.01,0.06581576,99.80897,50.0,20.0,1.05128
64.425,19.31,0.0682008,99.80897,50.0,20.0,1.05116
65.226,19.61,0.06908473,99.87706999999999,50.0,20.0,1.05104
66.057,19.91,0.07034474,99.80914,50.0,20.0,1.05091
66.885,20.21,0.06985254,99.83171999999999,50.0,20.0,1.05079
67.724,20.51,0.07173919,99.79207,50.0,20.0,1.05066
68.536,20.81,0.07400174,99.83171999999999,50.0,20.0,1.05053
69.383,21.11,0.07513825,99.79759,50.0,20.0,1.05039
70.23,21.41,0.07740237,99.79776,50.0,20.0,1.05026
71.079,21.71,0.07678613,99.775,50.0,20.0,1.0501200000000002
71.931,22.01,0.07804905,99.82034,50.0,20.0,1.04998
72.769,22.31,0.07818457,99.86017,50.0,20.0,1.04985
73.644,22.61,0.07957379,99.8431,50.0,20.0,1.0497
74.506,22.91,0.07933405,99.88845,50.0,20.0,1.04956
75.37,23.21,0.08172665,99.88293,50.0,20.0,1.04941
76.222,23.51,0.08311694,99.88845,50.0,20.0,1.0492700000000001
77.106,23.81,0.08262741,99.8431,50.0,20.0,1.04912
77.964,24.11,0.08452011,99.82034,50.0,20.0,1.0489700000000002
78.889,24.41,0.08553647,99.94516999999999,50.0,20.0,1.04881
79.738,24.71,0.08730479,99.88276,50.0,20.0,1.04866
80.598,25.01,0.08781932,99.8431,50.0,20.0,1.0485
81.495,25.31,0.08783276,99.88845,50.0,20.0,1.04834
82.389,25.61,0.08872474,99.86017,50.0,20.0,1.04818
83.303,25.91,0.08986845,99.88845,50.0,20.0,1.0480200000000002
84.169,26.21,0.08925442,99.87706999999999,50.0,20.0,1.04786
85.047,26.51,0.09127711,99.86586,50.0,20.0,1.04769
85.956,26.81,0.09191975,99.81483,50.0,20.0,1.0475299999999999
86.848,27.11,0.09268803,99.88276,50.0,20.0,1.04736
87.733,27.41,0.09320534,99.86017,50.0,20.0,1.04719
88.631,27.71,0.09410006,99.88276,50.0,20.0,1.04702
89.53,28.01,0.09486956,99.85448000000001,50.0,20.0,1.04684
90.44,28.31,0.09639369,99.90552,50.0,20.0,1.04667
91.335,28.61,0.09816959,99.85259,50.0,20.0,1.04649
92.26,28.91,0.09969535,99.90361999999999,50.0,20.0,1.04631
93.159,29.21,0.1021,99.88086,50.0,20.0,1.04613
94.078,29.51,0.10099,99.90361999999999,50.0,20.0,1.04595
95.002,29.81,0.10264000000000001,99.92621,50.0,20.0,1.04576
95.889,30.11,0.10354000000000001,99.88086,50.0,20.0,1.04558
96.811,30.41,0.10532000000000001,99.88086,50.0,20.0,1.04539
97.702,30.71,0.10520999999999998,99.85828000000001,50.0,20.0,1.04521
98.646,31.01,0.10611,99.86379000000001,50.0,20.0,1.04501
99.56,31.31,0.10764000000000001,99.9169,50.0,20.0,1.04482
100.474,31.61,0.10892,99.86569,50.0,20.0,1.04463
101.386,31.91,0.11234000000000001,99.91121,50.0,20.0,1.04443
102.317,32.21,0.10997,99.91121,50.0,20.0,1.04423
103.257,32.51,0.11377000000000001,99.86569,50.0,20.0,1.04403
104.163,32.81,0.11505,99.91103000000001,50.0,20.0,1.04383
105.108,33.11,0.11609000000000001,99.88845,50.0,20.0,1.04362
106.025,33.41,0.11674000000000001,99.88861999999999,50.0,20.0,1.04342
106.953,33.71,0.11714000000000001,99.93379,50.0,20.0,1.04322
107.924,34.01,0.1183,99.89793,50.0,20.0,1.043
108.813,34.31,0.11744,99.915,50.0,20.0,1.0428
109.76,34.61,0.12087,99.915,50.0,20.0,1.0425799999999998
110.668,34.91,0.12152,99.92052,50.0,20.0,1.04237
111.603,35.21,0.12344000000000001,99.88655,50.0,20.0,1.04216
112.534,35.51,0.12574000000000002,99.91483000000001,50.0,20.0,1.0419399999999999
113.458,35.81,0.12804000000000001,99.88086,50.0,20.0,1.0417299999999998
114.377,36.11,0.12845,99.89224,50.0,20.0,1.04151
115.32,36.41,0.13037,99.90361999999999,50.0,20.0,1.04129
116.265,36.71,0.13242,99.86966,50.0,20.0,1.04106
117.181,37.01,0.13180999999999998,99.88655,50.0,20.0,1.04084
118.133,37.31,0.13335999999999998,99.89224,50.0,20.0,1.04061
119.063,37.61,0.13516,99.90361999999999,50.0,20.0,1.04039
119.988,37.91,0.13658,99.92069000000001,50.0,20.0,1.04016
120.917,38.21,0.13787,99.89793,50.0,20.0,1.03993
121.864,38.51,0.1398,99.915,50.0,20.0,1.0397
122.79,38.81,0.14085,99.93759,50.0,20.0,1.0394700000000001
123.716,39.11,0.14315999999999998,99.90361999999999,50.0,20.0,1.03924
124.654,39.41,0.14445,99.9319,50.0,20.0,1.039
125.608,39.71,0.14664000000000002,99.92638000000001,50.0,20.0,1.0387600000000001
126.538,40.01,0.14945999999999998,99.93207,50.0,20.0,1.03852
127.515,40.31,0.15267,99.90930999999999,50.0,20.0,1.03827
128.409,40.61,0.15485,99.915,50.0,20.0,1.03804
129.355,40.91,0.15413,99.90361999999999,50.0,20.0,1.03779
130.299,41.21,0.15353,99.90914000000001,50.0,20.0,1.03754
131.24001,41.51,0.15306,99.92621,50.0,20.0,1.0373
132.168,41.81,0.15195999999999998,99.90361999999999,50.0,20.0,1.03705
133.12399,42.11,0.1506,99.90361999999999,50.0,20.0,1.0368
134.05499,42.41,0.14962,99.92069000000001,50.0,20.0,1.03655
134.991,42.71,0.14953,99.88103000000001,50.0,20.0,1.03629
135.955,43.01,0.14906,99.89793,50.0,20.0,1.03603
136.905,43.31,0.14973,99.89224,50.0,20.0,1.03577
137.841,43.61,0.15129,99.92052,50.0,20.0,1.03552
138.783,43.91,0.15247,99.92621,50.0,20.0,1.03525
139.713,44.21,0.15315,99.92638000000001,50.0,20.0,1.035
140.679,44.51,0.15319000000000002,99.92069000000001,50.0,20.0,1.03473
141.617,44.81,0.15525999999999998,99.94328,50.0,20.0,1.03446
142.56,45.11,0.15784,99.87517,50.0,20.0,1.0342
143.53101,45.41,0.1598,99.92052,50.0,20.0,1.0339200000000002
144.438,45.71,0.15984,99.94328,50.0,20.0,1.03366
145.40401,46.01,0.16064,99.94328,50.0,20.0,1.03338
146.343,46.31,0.16119,99.97171999999999,50.0,20.0,1.03311
147.31,46.61,0.16175,99.93759,50.0,20.0,1.03283
148.25301000000002,46.91,0.16305999999999998,99.93759,50.0,20.0,1.0325600000000001
149.224,47.21,0.16617,99.93759,50.0,20.0,1.03227
150.15198999999998,47.51,0.16723,99.96016999999999,50.0,20.0,1.032
151.117,47.81,0.16842000000000001,99.93759,50.0,20.0,1.0317100000000001
152.061,48.11,0.16935999999999998,99.93759,50.0,20.0,1.0314299999999998
153.01199,48.41,0.17132,99.915,50.0,20.0,1.03115
153.974,48.71,0.17265,99.93759,50.0,20.0,1.03086
154.933,49.01,0.17397,99.96034,50.0,20.0,1.0305600000000001
155.875,49.31,0.17543,99.91483000000001,50.0,20.0,1.0302799999999999
156.836,49.61,0.1765,99.91483000000001,50.0,20.0,1.02998
157.79401000000001,49.91,0.17795,99.95466,50.0,20.0,1.02969
158.745,50.21,0.1803,99.9319,50.0,20.0,1.02939
159.69,50.51,0.18112,99.9319,50.0,20.0,1.0291
160.651,50.81,0.18284,99.95466,50.0,20.0,1.0288
161.59801000000002,51.11,0.18275999999999998,99.94896999999999,50.0,20.0,1.0285
162.55901,51.41,0.18563,99.94896999999999,50.0,20.0,1.0282
163.51601000000002,51.71,0.18748,99.94345,50.0,20.0,1.02789
164.466,52.01,0.18907000000000002,99.93379,50.0,20.0,1.02759
165.418,52.31,0.19028,99.91121,50.0,20.0,1.02729
166.37801000000002,52.61,0.1911,99.95085999999999,50.0,20.0,1.02698
167.332,52.91,0.19116,99.93759,50.0,20.0,1.02667
168.285,53.21,0.19353,99.9319,50.0,20.0,1.02636
169.24698999999998,53.51,0.1941,99.95466,50.0,20.0,1.02604
170.20399,53.81,0.19647,99.91672,50.0,20.0,1.02573
171.151,54.11,0.19768,99.94707,50.0,20.0,1.02542
172.097,54.41,0.19979,99.93379,50.0,20.0,1.0251
173.05901,54.71,0.20088,99.95655,50.0,20.0,1.02478
174.032,55.01,0.20185,99.93948,50.0,20.0,1.02446
174.98199,55.31,0.20357999999999998,99.96224000000001,50.0,20.0,1.02414
175.94701,55.61,0.20467,99.95276,50.0,20.0,1.02381
176.88901,55.91,0.20640999999999998,99.97551999999999,50.0,20.0,1.02349
177.854,56.21,0.2075,99.93016999999999,50.0,20.0,1.02316
178.802,56.51,0.20820999999999998,99.93,50.0,20.0,1.02284
179.77299,56.81,0.20981999999999998,99.95845,50.0,20.0,1.02251
180.733,57.11,0.21156,99.89603000000001,50.0,20.0,1.02217
181.716,57.41,0.21318,99.89983000000001,50.0,20.0,1.02183
182.64799,57.71,0.21505,99.89414000000001,50.0,20.0,1.0215100000000001
183.603,58.01,0.21563000000000002,99.95655,50.0,20.0,1.0211700000000001
184.567,58.31,0.21686999999999998,99.95655,50.0,20.0,1.02083
185.534,58.61,0.21874000000000002,99.93397,50.0,20.0,1.02049
186.485,58.91,0.21985,99.95085999999999,50.0,20.0,1.02015
187.436,59.21,0.22173,99.92828,50.0,20.0,1.01981
188.407,59.51,0.22205999999999998,99.92828,50.0,20.0,1.01947
189.362,59.81,0.22471999999999998,99.9281,50.0,20.0,1.01912
190.343,60.11,0.22530999999999998,99.91121,50.0,20.0,1.0187700000000002
191.271,60.41,0.22719,99.9281,50.0,20.0,1.01843
192.23199,60.71,0.22999,99.92241,50.0,20.0,1.0180799999999999
193.19701,61.01,0.23239,99.88845,50.0,20.0,1.01773
194.16701,61.31,0.23401999999999998,99.91672,50.0,20.0,1.01737
195.121,61.61,0.23488,99.91672,50.0,20.0,1.01702
196.08,61.91,0.23626,99.91672,50.0,20.0,1.0166600000000001
197.062,62.21,0.23764000000000002,99.91672,50.0,20.0,1.0163
198.017,62.51,0.23836999999999997,99.91672,50.0,20.0,1.01594
198.99899,62.81,0.24065999999999999,99.90552,50.0,20.0,1.01557
199.95,63.11,0.24191,99.91103000000001,50.0,20.0,1.01521
200.89999,63.41,0.24341999999999997,99.9281,50.0,20.0,1.01486
201.86501,63.71,0.24441,99.88861999999999,50.0,20.0,1.01449
202.81798999999998,64.01,0.2471,99.88293,50.0,20.0,1.0141200000000001
203.79201,64.31,0.24835,99.93016999999999,50.0,20.0,1.01375
204.761,64.61,0.25221,99.85069,50.0,20.0,1.01338
205.69901000000002,64.91,0.25190999999999997,99.89034000000001,50.0,20.0,1.01302
206.658,65.21,0.25421,99.845,50.0,20.0,1.01264
207.625,65.51,0.25665,99.85638,50.0,20.0,1.01227
208.595,65.81,0.25843,99.91672,50.0,20.0,1.01189
209.552,66.11,0.26087,99.87155,50.0,20.0,1.0115100000000001
210.505,66.41,0.26266,99.8431,50.0,20.0,1.01114
211.472,66.71,0.26536,99.86586,50.0,20.0,1.01076
212.41499,67.01,0.26559,99.87534000000001,50.0,20.0,1.0103799999999998
213.40401,67.31,0.26895,99.90930999999999,50.0,20.0,1.00999
214.362,67.61,0.27309,99.79207,50.0,20.0,1.0096
215.339,67.91,0.27332,99.90552,50.0,20.0,1.00921
216.276,68.21,0.27564,99.88293,50.0,20.0,1.00883
217.23199,68.51,0.27823000000000003,99.88276,50.0,20.0,1.00845
218.196,68.81,0.2816,99.86017,50.0,20.0,1.00806
219.166,69.11,0.28445,99.86017,50.0,20.0,1.00766
220.134,69.41,0.2873,99.79207,50.0,20.0,1.00726
221.09399,69.71,0.28964,99.79016999999999,50.0,20.0,1.0068700000000002
222.049,70.01,0.29275999999999996,99.86948000000001,50.0,20.0,1.0064799999999998
223.00301000000002,70.31,0.29562,99.86397,50.0,20.0,1.0060799999999999
223.972,70.61,0.29835,99.79569000000001,50.0,20.0,1.00568
224.94,70.91,0.30122,99.7731,50.0,20.0,1.00528
225.89,71.21,0.30435,99.85828000000001,50.0,20.0,1.00488
226.85201,71.51,0.3084,99.79016999999999,50.0,20.0,1.00447
227.821,71.81,0.31311,99.83551999999999,50.0,20.0,1.00407
228.78101,72.11,0.31743000000000005,99.79586,50.0,20.0,1.00366
229.73599,72.41,0.32175,99.83362,50.0,20.0,1.00326
230.69501,72.71,0.32149,99.78828,50.0,20.0,1.00285
231.666,73.01,0.31887,99.81085999999999,50.0,20.0,1.00243
232.633,73.31,0.31795,99.77121,50.0,20.0,1.0020200000000001
233.578,73.61,0.31493000000000004,99.79948,50.0,20.0,1.0016100000000001
234.549,73.91,0.31545,99.82224000000001,50.0,20.0,1.00119
235.515,74.21,0.31677,99.76552,50.0,20.0,1.0007700000000002
236.483,74.51,0.31835,99.74276,50.0,20.0,1.00035
237.465,74.81,0.32099,99.72017,50.0,20.0,0.99992
238.41701,75.11,0.32216999999999996,99.7031,50.0,20.0,0.99951
239.373,75.41,0.32455,99.77121,50.0,20.0,0.9990899999999999
240.36,75.71,0.32785,99.7031,50.0,20.0,0.99865
241.29201,76.01,0.33128,99.71638,50.0,20.0,0.99824
242.259,76.31,0.33485,99.73914,50.0,20.0,0.9978100000000001
243.226,76.61,0.33974,99.64259,50.0,20.0,0.9973799999999999
244.17999,76.91,0.34318000000000004,99.68224000000001,50.0,20.0,0.99695
245.147,77.21,0.34624,99.68224000000001,50.0,20.0,0.9965200000000001
246.117,77.51,0.35299,99.65966,50.0,20.0,0.99608
247.069,77.81,0.35764,99.6369,50.0,20.0,0.99565
248.026,78.11,0.36453,99.59155,50.0,20.0,0.9952200000000001
248.996,78.41,0.37117,99.59724,50.0,20.0,0.9947799999999999
249.96001,78.71,0.37742,99.59155,50.0,20.0,0.99434
250.92,79.01,0.38672,99.58017,50.0,20.0,0.9939
251.879,79.31,0.39974,99.50069,50.0,20.0,0.99346
252.828,79.61,0.42441999999999996,99.55362,50.0,20.0,0.9930200000000001
253.771,79.91,0.47403999999999996,99.5481,50.0,20.0,0.99259
254.728,80.21,0.53033,99.48569,50.0,20.0,0.9921399999999999
255.67,80.51,0.5947600000000001,99.44603000000001,50.0,20.0,0.9917100000000001
256.63,80.81,0.63325,99.46293,50.0,20.0,0.99126
257.58801,81.11,0.62252,99.43448000000001,50.0,20.0,0.9908100000000001
258.53601000000003,81.41,0.5788300000000001,99.43086,50.0,20.0,0.9903700000000001
259.49799,81.71,0.52913,99.39672,50.0,20.0,0.9899100000000001
260.47501,82.01,0.4883,99.34948,50.0,20.0,0.98945
261.436,82.31,0.46179,99.30414,50.0,20.0,0.989
262.39801,82.61,0.44218,99.32672,50.0,20.0,0.98854
263.37299,82.91,0.42708,99.30414,50.0,20.0,0.98808
264.33301,83.21,0.41622,99.33051999999999,50.0,20.0,0.98762
265.30801,83.51,0.40762,99.23983,50.0,20.0,0.98715
266.255,83.81,0.40088,99.22845,50.0,20.0,0.9867
267.22699,84.11,0.39573,99.20017,50.0,20.0,0.9862299999999999
268.19,84.41,0.39152,99.21138,50.0,20.0,0.9857600000000001
269.14401000000004,84.71,0.3885,99.17172,50.0,20.0,0.9853
270.10999,85.01,0.38668,99.19448,50.0,20.0,0.9848299999999999
271.09299,85.31,0.38473,99.115,50.0,20.0,0.98435
272.03601000000003,85.61,0.38478,99.12638000000001,50.0,20.0,0.9838899999999999
272.99701,85.91,0.38416,99.19448,50.0,20.0,0.9834200000000001
273.953,86.21,0.38488,99.12638000000001,50.0,20.0,0.98295
274.89401000000004,86.51,0.38466,99.10361999999999,50.0,20.0,0.9824799999999999
275.897,86.81,0.38378,99.08103,50.0,20.0,0.98198
276.83499,87.11,0.38611,99.03551999999999,50.0,20.0,0.9815200000000001
277.78799,87.41,0.38561999999999996,99.03551999999999,50.0,20.0,0.9810399999999999
278.737,87.71,0.38635,98.96759,50.0,20.0,0.98057
279.70401,88.01,0.38949,98.9731,50.0,20.0,0.98009
280.66901,88.31,0.39049,98.99586,50.0,20.0,0.9796
281.62601,88.61,0.39431,98.905,50.0,20.0,0.9791200000000001
282.591,88.91,0.39289,98.97121,50.0,20.0,0.9786299999999999
283.56201,89.21,0.39524000000000004,98.91828000000001,50.0,20.0,0.97814
284.50699,89.51,0.39638,98.89759000000001,50.0,20.0,0.9776600000000001
285.46398999999997,89.81,0.3994,98.82948,50.0,20.0,0.9771700000000001
286.422,90.11,0.39852,98.87483,50.0,20.0,0.9766799999999999
287.388,90.41,0.40007,98.8181,50.0,20.0,0.97619
288.34299,90.71,0.4027,98.78966,50.0,20.0,0.9757
289.29199,91.01,0.40506,98.7669,50.0,20.0,0.97521
290.254,91.31,0.41026,98.74431,50.0,20.0,0.9747100000000001
291.22198,91.61,0.41331,98.75569,50.0,20.0,0.97421
292.16901,91.91,0.41216,98.72724000000001,50.0,20.0,0.97372
293.13199,92.21,0.41508,98.72740999999999,50.0,20.0,0.9732200000000001
294.08801,92.51,0.41853999999999997,98.63655,50.0,20.0,0.97272
295.03799,92.81,0.42389,98.65914000000001,50.0,20.0,0.9722200000000001
296.0,93.11,0.4252,98.64224,50.0,20.0,0.97172
296.95499,93.41,0.42935,98.61948000000001,50.0,20.0,0.97121
297.92499,93.71,0.43093000000000004,98.57983,50.0,20.0,0.9707
298.879,94.01,0.43115,98.61397,50.0,20.0,0.9702
299.84698,94.31,0.43355,98.56276,50.0,20.0,0.9696799999999999
300.784,94.61,0.43432,98.54,50.0,20.0,0.96919
301.73499,94.91,0.43712,98.4719,50.0,20.0,0.9686799999999999
302.694,95.21,0.43885,98.47207,50.0,20.0,0.9681700000000001
303.66199,95.51,0.43922,98.47207,50.0,20.0,0.96765
304.59201,95.81,0.44135,98.42655,50.0,20.0,0.96715
305.539,96.11,0.44254,98.41534,50.0,20.0,0.9666399999999999
306.49701,96.41,0.44468,98.3869,50.0,20.0,0.9661200000000001
307.44299,96.71,0.44859,98.37,50.0,20.0,0.9656100000000001
308.40302,97.01,0.44924,98.33586,50.0,20.0,0.96509
309.358,97.31,0.45276000000000005,98.3019,50.0,20.0,0.96457
310.32901,97.61,0.45601,98.27914,50.0,20.0,0.96404
311.27301,97.91,0.45788999999999996,98.23948,50.0,20.0,0.96352
312.233,98.21,0.46292,98.14103,50.0,20.0,0.963
313.18201,98.51,0.46603999999999995,98.19776,50.0,20.0,0.96247
314.13501,98.81,0.47478000000000004,98.1581,50.0,20.0,0.96195
315.091,99.11,0.4853,98.09,50.0,20.0,0.96142
316.04501,99.41,0.49282,98.04448000000001,50.0,20.0,0.9608899999999999
317.01401,99.71,0.50022,98.07293,50.0,20.0,0.96036
317.95499,100.01,0.50817,98.01069,50.0,20.0,0.95983
318.90701,100.31,0.51174,97.96517,50.0,20.0,0.9593
319.87,100.61,0.5180600000000001,97.91966,50.0,20.0,0.9587600000000001
320.82501,100.91,0.52535,97.83466,50.0,20.0,0.9582299999999999
321.76801,101.21,0.5340199999999999,97.83466,50.0,20.0,0.9577
322.73199,101.51,0.54175,97.8119,50.0,20.0,0.95715
323.672,101.81,0.55016,97.75914,50.0,20.0,0.95662
324.63199,102.11,0.55735,97.69103,50.0,20.0,0.9560799999999999
325.57999,102.41,0.56565,97.62293000000001,50.0,20.0,0.95554
326.548,102.71,0.5734100000000001,97.57759,50.0,20.0,0.95499
327.48801000000003,103.01,0.57911,97.55483000000001,50.0,20.0,0.9544600000000001
328.44199,103.31,0.58813,97.46414,50.0,20.0,0.95391
329.39401000000004,103.61,0.59385,97.39603000000001,50.0,20.0,0.95337
330.34201,103.91,0.59846,97.35051999999999,50.0,20.0,0.95283
331.28101000000004,104.21,0.60322,97.24845,50.0,20.0,0.95229
332.23999,104.51,0.6070300000000001,97.20293000000001,50.0,20.0,0.95173
333.186,104.81,0.61056,97.12361999999999,50.0,20.0,0.95119
334.125,105.11,0.61354,97.10466,50.0,20.0,0.9506399999999999
335.09698,105.41,0.61625,97.00259,50.0,20.0,0.9500799999999999
336.017,105.71,0.6191,96.97621,50.0,20.0,0.9495399999999999
336.95499,106.01,0.6201399999999999,96.81155,50.0,20.0,0.949
337.90601000000004,106.31,0.62079,96.73397,50.0,20.0,0.94844
338.85001,106.61,0.6199,96.70759,50.0,20.0,0.94789
339.78699,106.91,0.62165,96.63569,50.0,20.0,0.94734
340.73199,107.21,0.6220100000000001,96.5431,50.0,20.0,0.94678
341.664,107.51,0.62154,96.46931,50.0,20.0,0.94624
342.63501,107.81,0.61983,96.34259,50.0,20.0,0.9456600000000001
343.57501,108.11,0.62005,96.24414,50.0,20.0,0.94511
344.49799,108.41,0.61888,96.12328000000001,50.0,20.0,0.9445600000000001
345.44101,108.71,0.61827,95.98517,50.0,20.0,0.944
346.40601000000004,109.01,0.61893,95.89431,50.0,20.0,0.94342
347.31299,109.31,0.6169100000000001,95.86603000000001,50.0,20.0,0.9428799999999999
348.24701,109.61,0.6151800000000001,95.66931,50.0,20.0,0.94232
349.203,109.91,0.6147199999999999,95.57466,50.0,20.0,0.94175
350.13698999999997,110.21,0.61327,95.50103,50.0,20.0,0.94119
351.077,110.51,0.61434,95.33086,50.0,20.0,0.9406200000000001
352.021,110.81,0.61485,95.27965999999999,50.0,20.0,0.94005
352.95599,111.11,0.61592,95.14362,50.0,20.0,0.9394899999999999
353.897,111.41,0.61825,95.03586,50.0,20.0,0.9389200000000001
354.84601000000004,111.71,0.61751,94.84103,50.0,20.0,0.93834
355.77301,112.01,0.61662,94.84483,50.0,20.0,0.93778
356.716,112.31,0.61616,94.69534,50.0,20.0,0.93721
357.66598999999997,112.61,0.61738,94.565,50.0,20.0,0.93663
358.59201,112.91,0.61607,94.46293,50.0,20.0,0.93606
359.55899,113.21,0.61548,94.36448,50.0,20.0,0.93547
360.474,113.51,0.60923,94.27172,50.0,20.0,0.9349
361.405,113.81,0.60778,94.11293,50.0,20.0,0.9343299999999999
362.33701,114.11,0.6059,94.045,50.0,20.0,0.93376
363.29001,114.41,0.60473,93.92017,50.0,20.0,0.93317
364.203,114.71,0.60312,93.83293,50.0,20.0,0.9326
365.14801,115.01,0.6011,93.71759,50.0,20.0,0.9320200000000001
366.08898999999997,115.31,0.59865,93.62879000000001,50.0,20.0,0.93143
367.02398999999997,115.61,0.59705,93.44724000000001,50.0,20.0,0.93085
367.95001,115.91,0.5953,93.3469,50.0,20.0,0.93027
368.88199,116.21,0.591,93.26759,50.0,20.0,0.92969
369.81699,116.51,0.5927899999999999,93.09362,50.0,20.0,0.9291
370.755,116.81,0.5977,92.99328,50.0,20.0,0.9285100000000001
371.70999,117.11,0.60163,92.78345,50.0,20.0,0.92791
372.63101,117.41,0.60555,92.67948,50.0,20.0,0.9273299999999999
373.57401,117.71,0.6102,92.51671999999999,50.0,20.0,0.92674
374.51999,118.01,0.6147100000000001,92.26534000000001,50.0,20.0,0.92614
375.452,118.31,0.61965,92.03466,50.0,20.0,0.92555
376.38901,118.61,0.62375,91.80207,50.0,20.0,0.92495
377.323,118.91,0.6282800000000001,91.52017,50.0,20.0,0.9243600000000001
378.25,119.21,0.6340899999999999,91.2081,50.0,20.0,0.9237700000000001
379.17899,119.51,0.63977,91.02655,50.0,20.0,0.9231799999999999
380.10901,119.81,0.64489,90.66552,50.0,20.0,0.92258
381.039,120.11,0.64887,90.36103,50.0,20.0,0.92199
381.97601000000003,120.41,0.65372,89.99224,50.0,20.0,0.92138
382.90701,120.71,0.6594300000000001,89.64414000000001,50.0,20.0,0.92079
383.84601000000004,121.01,0.6622899999999999,89.23,50.0,20.0,0.9201799999999999
384.76999,121.31,0.66873,88.82345,50.0,20.0,0.91958
385.702,121.61,0.67575,88.40361999999999,50.0,20.0,0.9189799999999999
386.63501,121.91,0.6815,87.95914,50.0,20.0,0.91838
387.55301000000003,122.21,0.69255,87.46741,50.0,20.0,0.9177799999999999
388.49399,122.51,0.69817,86.90016999999999,50.0,20.0,0.91717
389.436,122.81,0.70639,86.34414,50.0,20.0,0.91656
390.367,123.11,0.7149,85.76345,50.0,20.0,0.91595
391.29001,123.41,0.72601,85.13948,50.0,20.0,0.91535
392.23199,123.71,0.73369,84.46051999999999,50.0,20.0,0.9147299999999999
393.14898999999997,124.01,0.7430899999999999,83.78931,50.0,20.0,0.9141299999999999
394.08801,124.31,0.7532399999999999,83.05171999999999,50.0,20.0,0.91351
395.02398999999997,124.61,0.7631100000000001,82.29534,50.0,20.0,0.9129
395.953,124.91,0.77271,81.43483,50.0,20.0,0.91228
396.88501,125.21,0.7813100000000001,80.6631,50.0,20.0,0.9116700000000001
397.80701,125.51,0.79122,79.71948,50.0,20.0,0.91106
398.73199,125.81,0.8073600000000001,78.755,50.0,20.0,0.9104399999999999
399.67801000000003,126.11,0.8134100000000001,77.78671999999999,50.0,20.0,0.9098200000000001
400.59,126.41,0.81699,76.70121,50.0,20.0,0.9092100000000001
401.51999,126.71,0.82739,75.70259,50.0,20.0,0.90859
402.452,127.01,0.8401299999999999,74.44707,50.0,20.0,0.90797
403.366,127.31,0.84895,73.27069,50.0,20.0,0.90736
404.31799,127.61,0.85869,72.04345,50.0,20.0,0.9067200000000001
405.23499,127.91,0.86392,70.77241,50.0,20.0,0.9061100000000001
406.14898999999997,128.21,0.8711899999999999,69.5281,50.0,20.0,0.90549
407.07901,128.51,0.8776,68.08345,50.0,20.0,0.9048700000000001
408.00601,128.81,0.8849,66.6781,50.0,20.0,0.9042399999999999
408.93701,129.11,0.8935200000000001,65.24655,50.0,20.0,0.90361
409.85999,129.41,0.90084,63.735519999999994,50.0,20.0,0.90299
410.79501,129.71,0.9067200000000001,62.177240000000005,50.0,20.0,0.90236
411.72501,130.01,0.91261,60.53379,50.0,20.0,0.9017299999999999
412.664,130.31,0.91763,58.90172,50.0,20.0,0.90109
413.556,130.61,0.92132,57.273619999999994,50.0,20.0,0.90048
414.48999,130.91,0.92548,55.624480000000005,50.0,20.0,0.89984
415.40302,131.21,0.9258299999999999,53.89966,50.0,20.0,0.89922
416.32198999999997,131.51,0.92706,52.15224,50.0,20.0,0.89859
417.258,131.81,0.9262600000000001,50.43517,50.0,20.0,0.89795
418.17899,132.11,0.92486,48.7369,50.0,20.0,0.8973200000000001
419.091,132.41,0.9214,47.1031,50.0,20.0,0.89669
420.026,132.71,0.9169200000000001,45.4519,50.0,20.0,0.89605
420.94199000000003,133.01,0.9089,43.783970000000004,50.0,20.0,0.8954200000000001
421.87600999999995,133.31,0.9014700000000001,42.19931,50.0,20.0,0.8947799999999999
422.82500999999996,133.61,0.89065,40.68448,50.0,20.0,0.89412
423.72699000000006,133.91,0.8805299999999999,39.215,50.0,20.0,0.8935
424.66299000000004,134.21,0.8637799999999999,37.89121,50.0,20.0,0.89285
425.59200999999996,134.51,0.8524700000000001,36.59207,50.0,20.0,0.8922
426.51599000000004,134.81,0.8365600000000001,35.46483,50.0,20.0,0.89156
427.44500999999997,135.11,0.8216600000000001,34.305690000000006,50.0,20.0,0.8909100000000001
428.362,135.41,0.80585,33.2581,50.0,20.0,0.8902700000000001
429.30099,135.71,0.78914,32.346379999999996,50.0,20.0,0.8896200000000001
430.23400999999996,136.01,0.7762600000000001,31.50483,50.0,20.0,0.8889600000000001
431.159,136.31,0.76054,30.784309999999998,50.0,20.0,0.8883200000000001
432.08401,136.61,0.74998,30.08448,50.0,20.0,0.8876700000000001
433.03601,136.91,0.74179,29.50034,50.0,20.0,0.887
433.927,137.21,0.73238,28.93862,50.0,20.0,0.8863700000000001
434.85500999999994,137.51,0.72534,28.397759999999998,50.0,20.0,0.8857200000000001
435.771,137.81,0.71829,27.879659999999998,50.0,20.0,0.88507
436.686,138.11,0.7136100000000001,27.482409999999998,50.0,20.0,0.8844200000000001
437.60699000000005,138.41,0.70818,27.06069,50.0,20.0,0.8837700000000001
438.52700999999996,138.71,0.7045399999999999,26.678620000000002,50.0,20.0,0.8831200000000001
439.452,139.01,0.70104,26.338279999999997,50.0,20.0,0.88246
440.36099,139.31,0.6946899999999999,26.00724,50.0,20.0,0.88182
441.30399000000006,139.61,0.69134,25.76914,50.0,20.0,0.88115
442.19199000000003,139.91,0.6869,25.48724,50.0,20.0,0.88051
443.11499000000003,140.21,0.68338,25.17707,50.0,20.0,0.87985
444.026,140.51,0.6806,24.95017,50.0,20.0,0.8792
444.948,140.81,0.67647,24.7781,50.0,20.0,0.87854
445.86301,141.11,0.67218,24.57379,50.0,20.0,0.87789
446.77399,141.41,0.66923,24.362070000000003,50.0,20.0,0.87723
447.694,141.71,0.6695800000000001,24.14655,50.0,20.0,0.8765700000000001
448.61899000000005,142.01,0.67745,23.99517,50.0,20.0,0.8759100000000001
449.52802,142.31,0.68637,23.83069,50.0,20.0,0.87525
450.448,142.61,0.6899,23.73793,50.0,20.0,0.87459
451.371,142.91,0.69901,23.59603,50.0,20.0,0.87392
452.298,143.21,0.7003,23.441029999999998,50.0,20.0,0.87325
453.211,143.51,0.70128,23.299310000000002,50.0,20.0,0.87259
454.13599000000005,143.81,0.70001,23.18017,50.0,20.0,0.87192
455.07401,144.11,0.69558,23.112070000000003,50.0,20.0,0.87123
455.97699000000006,144.41,0.68583,23.015520000000002,50.0,20.0,0.8705799999999999
456.88199000000003,144.71,0.67455,22.91345,50.0,20.0,0.86992
457.78699000000006,145.01,0.67038,22.84534,50.0,20.0,0.86926
458.69600999999994,145.31,0.66301,22.7319,50.0,20.0,0.86859
459.61099,145.61,0.65974,22.72052,50.0,20.0,0.86792
460.52700999999996,145.91,0.65357,22.61828,50.0,20.0,0.86725
461.43799,146.21,0.64937,22.52759,50.0,20.0,0.8665799999999999
462.353,146.51,0.64395,22.43672,50.0,20.0,0.8659100000000001
463.26599000000004,146.81,0.6403399999999999,22.34621,50.0,20.0,0.86524
464.168,147.11,0.6381,22.32914,50.0,20.0,0.8645799999999999
465.07999,147.41,0.6361600000000001,22.277929999999998,50.0,20.0,0.8639
465.98199000000005,147.71,0.63345,22.23259,50.0,20.0,0.86324
466.89999000000006,148.01,0.63242,22.187070000000002,50.0,20.0,0.86256
467.797,148.31,0.62925,22.1531,50.0,20.0,0.8619
468.71300999999994,148.61,0.6279100000000001,22.0681,50.0,20.0,0.8612200000000001
469.61899000000005,148.91,0.62534,22.005689999999998,50.0,20.0,0.86055
470.51599000000004,149.21,0.62047,22.00552,50.0,20.0,0.85988
471.43399000000005,149.51,0.62005,21.93759,50.0,20.0,0.8592
472.34,149.81,0.61824,21.86948,50.0,20.0,0.8585200000000001
473.23801,150.11,0.61841,21.87517,50.0,20.0,0.85785
474.14800999999994,150.41,0.5975699999999999,21.823970000000003,50.0,20.0,0.8571700000000001
475.05399000000006,150.71,0.61954,21.82414,50.0,20.0,0.8565
475.96200999999996,151.01,0.61665,21.77121,50.0,20.0,0.85582
476.86899000000005,151.31,0.6153,21.77103,50.0,20.0,0.85514
477.78101,151.61,0.61641,21.759829999999997,50.0,20.0,0.85445
478.677,151.91,0.6150399999999999,21.68603,50.0,20.0,0.8537799999999999
479.62201,152.21,0.6149399999999999,21.623620000000003,50.0,20.0,0.8530700000000001
480.50201,152.51,0.61465,21.572589999999998,50.0,20.0,0.85241
481.41599,152.81,0.61561,21.54983,50.0,20.0,0.85172
482.32000999999997,153.11,0.61826,21.55,50.0,20.0,0.85104
483.20599000000004,153.41,0.62153,21.504479999999997,50.0,20.0,0.8503700000000001
484.12399000000005,153.71,0.62359,21.4931,50.0,20.0,0.8496799999999999
485.022,154.01,0.62471,21.44776,50.0,20.0,0.849
485.952,154.31,0.62848,21.46483,50.0,20.0,0.84829
486.84601,154.61,0.63131,21.47034,50.0,20.0,0.8476100000000001
487.73999000000003,154.91,0.6299600000000001,21.43638,50.0,20.0,0.84693
488.64099000000004,155.21,0.6340399999999999,21.44776,50.0,20.0,0.84625
489.556,155.51,0.63581,21.425,50.0,20.0,0.84555
490.466,155.81,0.63649,21.3569,50.0,20.0,0.84486
491.37701,156.11,0.63779,21.31155,50.0,20.0,0.84416
492.272,156.41,0.6414300000000001,21.25483,50.0,20.0,0.8434799999999999
493.17899000000006,156.71,0.6413300000000001,21.203789999999998,50.0,20.0,0.8427899999999999
494.08899,157.01,0.6431100000000001,21.21517,50.0,20.0,0.84209
494.98599,157.31,0.6462899999999999,21.38724,50.0,20.0,0.8414
495.884,157.61,0.64854,21.24914,50.0,20.0,0.8407100000000001
496.784,157.91,0.65158,21.2681,50.0,20.0,0.8400200000000001
497.68300999999997,158.21,0.6551,21.2719,50.0,20.0,0.8393299999999999
498.58099000000004,158.51,0.65627,21.175520000000002,50.0,20.0,0.8386399999999999
499.48900999999995,158.81,0.65713,21.103620000000003,50.0,20.0,0.83794
500.40200999999996,159.11,0.65815,21.07534,50.0,20.0,0.8372299999999999
501.31299,159.41,0.6594899999999999,21.10931,50.0,20.0,0.8365299999999999
502.21300999999994,159.71,0.6624,21.077070000000003,50.0,20.0,0.83583
503.11400999999995,160.01,0.66547,21.099829999999997,50.0,20.0,0.83514
504.009,160.31,0.66682,21.05259,50.0,20.0,0.83444
504.901,160.61,0.6661100000000001,20.984479999999998,50.0,20.0,0.83375
505.798,160.91,0.66919,21.007070000000002,50.0,20.0,0.83306
506.70499,161.21,0.6713399999999999,21.035339999999998,50.0,20.0,0.83235
507.60599,161.51,0.67333,21.02414,50.0,20.0,0.83165
508.505,161.81,0.67801,21.08672,50.0,20.0,0.83095
509.40601,162.11,0.67795,20.99586,50.0,20.0,0.83025
510.30499000000003,162.41,0.68011,20.96741,50.0,20.0,0.82955
511.207,162.71,0.68275,20.96741,50.0,20.0,0.8288399999999999
512.10901,163.01,0.68524,20.99,50.0,20.0,0.82814
513.013,163.31,0.68725,20.96741,50.0,20.0,0.8274299999999999
513.922,163.61,0.68991,20.94466,50.0,20.0,0.8267200000000001
514.81403,163.91,0.69257,20.92759,50.0,20.0,0.8260200000000001
515.711,164.21,0.69603,20.91069,50.0,20.0,0.82531
516.61102,164.51,0.6974199999999999,20.95052,50.0,20.0,0.8246
517.51398,164.81,0.70122,20.95034,50.0,20.0,0.82389
518.41901,165.11,0.70167,20.905,50.0,20.0,0.8231799999999999
519.31201,165.41,0.70578,20.88241,50.0,20.0,0.8224799999999999
520.211,165.71,0.70527,20.8369,50.0,20.0,0.8217700000000001
521.11499,166.01,0.70829,20.84828,50.0,20.0,0.82105
522.00403,166.31,0.71018,20.79724,50.0,20.0,0.82035
522.90698,166.61,0.7125600000000001,20.7631,50.0,20.0,0.8196399999999999
523.80701,166.91,0.7165600000000001,20.76879,50.0,20.0,0.81892
524.70398,167.21,0.7179800000000001,20.76897,50.0,20.0,0.81821
525.59497,167.51,0.72182,20.72914,50.0,20.0,0.8175100000000001
526.47998,167.81,0.72341,20.717760000000002,50.0,20.0,0.8168
527.38702,168.11,0.72614,20.700689999999998,50.0,20.0,0.81608
528.28302,168.41,0.72872,20.655520000000003,50.0,20.0,0.8153699999999999
529.18402,168.71,0.73178,20.700860000000002,50.0,20.0,0.81465
530.0869799999999,169.01,0.73437,20.700860000000002,50.0,20.0,0.81393
530.98401,169.31,0.73469,20.62707,50.0,20.0,0.8132199999999999
531.8770099999999,169.61,0.73792,20.63845,50.0,20.0,0.8125
532.755,169.91,0.74553,20.66121,50.0,20.0,0.8118
533.6610099999999,170.21,0.7483,20.61,50.0,20.0,0.81108
534.54901,170.51,0.75058,20.63276,50.0,20.0,0.8103600000000001
535.43103,170.81,0.75254,20.59293,50.0,20.0,0.80966
536.33002,171.11,0.75646,20.61759,50.0,20.0,0.80894
537.24402,171.41,0.7618699999999999,20.594829999999998,50.0,20.0,0.8082
538.1229900000001,171.71,0.76563,20.54397,50.0,20.0,0.8075
539.02502,172.01,0.76974,20.515520000000002,50.0,20.0,0.80677
539.9279799999999,172.31,0.77305,20.487070000000003,50.0,20.0,0.80604
540.82098,172.61,0.77358,20.481379999999998,50.0,20.0,0.80532
541.71802,172.91,0.77885,20.45879,50.0,20.0,0.8046
542.59698,173.21,0.78363,20.47586,50.0,20.0,0.80389
543.49597,173.51,0.78925,20.551379999999998,50.0,20.0,0.80316
544.39301,173.81,0.7943899999999999,20.51931,50.0,20.0,0.8024399999999999
545.29797,174.11,0.7984,20.45121,50.0,20.0,0.80171
546.17902,174.41,0.80486,20.45103,50.0,20.0,0.80099
547.073,174.71,0.80904,20.38879,50.0,20.0,0.80027
547.9619799999999,175.01,0.81223,20.3831,50.0,20.0,0.79955
548.84198,175.31,0.8144399999999999,20.33776,50.0,20.0,0.79883
549.74597,175.61,0.8178300000000001,20.34328,50.0,20.0,0.7981
550.63599,175.91,0.82055,20.34914,50.0,20.0,0.79737
551.5360099999999,176.21,0.82362,20.36603,50.0,20.0,0.79664
552.41498,176.51,0.82419,20.27534,50.0,20.0,0.79592
553.31097,176.81,0.82545,20.271379999999997,50.0,20.0,0.79519
554.20398,177.11,0.82935,20.226029999999998,50.0,20.0,0.79447
555.0939900000001,177.41,0.83011,20.29983,50.0,20.0,0.79374
555.99103,177.71,0.83237,20.231720000000003,50.0,20.0,0.793
556.86798,178.01,0.83462,20.25069,50.0,20.0,0.7922899999999999
557.763,178.31,0.83739,20.2281,50.0,20.0,0.79155
558.6630200000001,178.61,0.8395,20.22224,50.0,20.0,0.79082
559.5499900000001,178.91,0.8424299999999999,20.18259,50.0,20.0,0.79009
560.4450099999999,179.21,0.84455,20.1769,50.0,20.0,0.7893600000000001
561.3220200000001,179.51,0.84883,20.16,50.0,20.0,0.78864
562.2189900000001,179.81,0.84862,20.11448,50.0,20.0,0.7879
563.11298,180.11,0.85208,20.10879,50.0,20.0,0.7871600000000001
564.0020099999999,180.41,0.85355,20.04655,50.0,20.0,0.7864300000000001
564.88,180.71,0.8590200000000001,20.171210000000002,50.0,20.0,0.78571
565.77301,181.01,0.8608299999999999,20.1031,50.0,20.0,0.78497
566.65503,181.31,0.8634700000000001,20.08034,50.0,20.0,0.7842399999999999
567.53998,181.61,0.86445,20.103279999999998,50.0,20.0,0.78351
568.4619799999999,181.91,0.86546,20.057760000000002,50.0,20.0,0.78275
569.3380099999999,182.21,0.8691200000000001,20.02362,50.0,20.0,0.78203
570.22803,182.51,0.8702700000000001,19.97845,50.0,20.0,0.7812899999999999
571.10498,182.81,0.8746200000000001,19.97845,50.0,20.0,0.78056
571.99402,183.11,0.87849,19.97276,50.0,20.0,0.77983
572.87598,183.41,0.88184,20.05397,50.0,20.0,0.7791
573.77301,183.71,0.8828600000000001,19.940520000000003,50.0,20.0,0.77835
574.64801,184.01,0.88808,19.940520000000003,50.0,20.0,0.77763
575.52399,184.31,0.8916200000000001,19.89517,50.0,20.0,0.7769
576.41602,184.61,0.8912899999999999,19.90655,50.0,20.0,0.7761600000000001
577.31,184.91,0.89469,19.88379,50.0,20.0,0.77541
578.19897,185.21,0.89843,19.88948,50.0,20.0,0.77467
579.0880099999999,185.51,0.9016700000000001,19.855520000000002,50.0,20.0,0.77393
579.96997,185.81,0.90423,19.8781,50.0,20.0,0.7731899999999999
580.85901,186.11,0.90612,19.83276,50.0,20.0,0.77245
581.73602,186.41,0.91038,19.85914,50.0,20.0,0.77172
582.6270099999999,186.71,0.90922,19.83638,50.0,20.0,0.77098
583.513,187.01,0.91761,19.92914,50.0,20.0,0.77023
584.38501,187.31,0.9181299999999999,19.847929999999998,50.0,20.0,0.7695
585.28497,187.61,0.9209200000000001,19.80259,50.0,20.0,0.76875
586.16699,187.91,0.92489,19.762929999999997,50.0,20.0,0.7680100000000001
587.06097,188.21,0.9275,19.75155,50.0,20.0,0.76726
587.93799,188.51,0.92994,19.81569,50.0,20.0,0.76653
588.83398,188.81,0.9315399999999999,19.7931,50.0,20.0,0.76577
589.711,189.11,0.9324399999999999,19.76276,50.0,20.0,0.7650399999999999
590.60101,189.41,0.9355899999999999,19.794829999999997,50.0,20.0,0.7642899999999999
591.47101,189.71,0.9394100000000001,19.78345,50.0,20.0,0.76356
592.36102,190.01,0.94447,19.7269,50.0,20.0,0.76281
593.229,190.31,0.94676,19.74379,50.0,20.0,0.76208
594.1220099999999,190.61,0.94735,19.681379999999997,50.0,20.0,0.76132
595.01501,190.91,0.95088,19.724829999999997,50.0,20.0,0.76057
595.9060099999999,191.21,0.95373,19.68534,50.0,20.0,0.7598199999999999
596.7869900000001,191.51,0.9539700000000001,19.707929999999998,50.0,20.0,0.75907
597.67902,191.81,0.9564799999999999,19.707929999999998,50.0,20.0,0.75832
598.5529799999999,192.11,0.9622700000000001,19.69086,50.0,20.0,0.75758
599.43103,192.41,0.9628700000000001,19.6569,50.0,20.0,0.75684
600.33099,192.71,0.96367,19.679660000000002,50.0,20.0,0.75608
601.1829799999999,193.01,0.9672,19.64552,50.0,20.0,0.75536
602.06299,193.31,0.96973,19.69086,50.0,20.0,0.75461
602.93903,193.61,0.974,19.63414,50.0,20.0,0.7538699999999999
603.8319700000001,193.91,0.97585,19.573620000000002,50.0,20.0,0.7531100000000001
604.711,194.21,0.97944,19.636029999999998,50.0,20.0,0.75236
605.60797,194.51,0.9848100000000001,19.61345,50.0,20.0,0.7516
606.48901,194.81,0.9889399999999999,19.592589999999998,50.0,20.0,0.75085
607.367,195.11,0.98975,19.5869,50.0,20.0,0.75011
608.26202,195.41,0.9909399999999999,19.530170000000002,50.0,20.0,0.74934
609.13898,195.71,0.99544,19.57552,50.0,20.0,0.7486
610.01801,196.01,0.99731,19.54155,50.0,20.0,0.74785
610.90698,196.31,1.00079,19.56414,50.0,20.0,0.7470899999999999
611.77301,196.61,1.00531,19.55845,50.0,20.0,0.74635
612.6680299999999,196.91,1.00775,19.51897,50.0,20.0,0.74559
613.53302,197.21,1.0121,19.501720000000002,50.0,20.0,0.74485
614.4119900000001,197.51,1.01472,19.501720000000002,50.0,20.0,0.7441
615.29602,197.81,1.01787,19.56793,50.0,20.0,0.74334
616.1749900000001,198.11,1.02209,19.501720000000002,50.0,20.0,0.74259
617.0549900000001,198.41,1.0277399999999999,19.54724,50.0,20.0,0.7418399999999999
617.94,198.71,1.0295,19.501720000000002,50.0,20.0,0.7410800000000001
618.8049900000001,199.01,1.03195,19.494139999999998,50.0,20.0,0.74034
619.6779799999999,199.31,1.03655,19.47155,50.0,20.0,0.73959
620.54602,199.61,1.03884,19.44879,50.0,20.0,0.73885
621.427,199.91,1.04365,19.47155,50.0,20.0,0.7380899999999999
622.315,200.21,1.04419,19.426029999999997,50.0,20.0,0.73733
623.1950099999999,200.51,1.0458,19.43759,50.0,20.0,0.73657
624.07599,200.81,1.05313,19.46034,50.0,20.0,0.7358100000000001
624.95203,201.11,1.05815,19.443279999999998,50.0,20.0,0.73506
625.8200099999999,201.41,1.0631700000000002,19.46586,50.0,20.0,0.73431
626.69299,201.71,1.06748,19.4431,50.0,20.0,0.73356
627.58002,202.01,1.0718299999999998,19.42034,50.0,20.0,0.7328
628.45203,202.31,1.07131,19.39776,50.0,20.0,0.73205
629.32599,202.61,1.07637,19.39776,50.0,20.0,0.73129
630.21503,202.91,1.08074,19.42034,50.0,20.0,0.73053
631.09003,203.21,1.0851,19.42052,50.0,20.0,0.72977
631.96997,203.51,1.08786,19.42052,50.0,20.0,0.72901
632.84302,203.81,1.09386,19.40345,50.0,20.0,0.72826
633.716,204.11,1.0951799999999998,19.40345,50.0,20.0,0.7275
634.6060200000001,204.41,1.10122,19.42052,50.0,20.0,0.7267399999999999
635.47498,204.71,1.10417,19.42052,50.0,20.0,0.7259800000000001
636.34802,205.01,1.10859,19.380689999999998,50.0,20.0,0.72523
637.2139900000001,205.31,1.11319,19.39966,50.0,20.0,0.72448
638.09802,205.61,1.11636,19.35431,50.0,20.0,0.7237100000000001
638.961,205.91,1.12025,19.450689999999998,50.0,20.0,0.72297
639.85303,206.21,1.12418,19.369310000000002,50.0,20.0,0.72219
640.72699,206.51,1.12809,19.43552,50.0,20.0,0.72143
641.599,206.81,1.13402,19.344829999999998,50.0,20.0,0.72068
642.474,207.11,1.13796,19.36741,50.0,20.0,0.71992
643.34198,207.41,1.14428,19.375,50.0,20.0,0.71916
644.21997,207.71,1.14897,19.35241,50.0,20.0,0.7184
645.10699,208.01,1.15314,19.34103,50.0,20.0,0.71763
645.97803,208.31,1.1569200000000002,19.35052,50.0,20.0,0.71687
646.85498,208.61,1.16367,19.41672,50.0,20.0,0.71611
647.72198,208.91,1.16655,19.25966,50.0,20.0,0.71536
648.59198,209.21,1.17147,19.35621,50.0,20.0,0.7146
649.47498,209.51,1.1742,19.2881,50.0,20.0,0.71383
650.3369799999999,209.81,1.17544,19.35793,50.0,20.0,0.71308
650.64001,209.91,1.17754,19.34672,50.0,20.0,0.71281