File: 01_Data/Polyester_Batting/STA/N2/3K_min/Polyester_Batting_STA_N2_3KData_210305_R2.csv
##Temp./Â°C,Time/min,DSC/(mW/mg),Mass/%,Sensit./(uV/mW)
48.865,10.01,0.04035596,103.08686,1.05329
48.877,10.31,0.04014906,103.08686,1.05329
48.905,10.61,0.04221874,103.16229,1.05329
48.97,10.91,0.04408167,103.19971,1.05328
49.043,11.21,0.04739337,103.23714,1.0532700000000002
49.176,11.51,0.05236118,103.29371,1.05325
49.347,11.81,0.05815727,103.388,1.0532299999999999
49.576,12.11,0.06498889,103.35,1.0532
49.879,12.41,0.06995871,103.42514,1.0531700000000002
50.215,12.71,0.07555016,103.42543,1.05312
50.603,13.01,0.08155656,103.42857,1.05308
51.04,13.31,0.08652904,103.46943,1.05302
51.502,13.61,0.09129532,103.46914,1.0529600000000001
51.982,13.91,0.09523426,103.57571,1.0529
52.515,14.21,0.09855321,103.54771,1.05283
53.063,14.51,0.10084,103.58514,1.0527600000000001
53.626,14.81,0.10354000000000001,103.58514,1.0526799999999998
54.247,15.11,0.1052,103.56629000000001,1.0526
54.842,15.41,0.10687,103.69485999999999,1.0525200000000001
55.502,15.71,0.11412,103.69485999999999,1.05243
56.152,16.01,0.11517000000000001,103.65714,1.05235
56.809,16.31,0.11890999999999999,103.69485999999999,1.05226
57.499,16.61,0.12327,103.65743,1.05216
58.218,16.91,0.12410999999999998,103.80771,1.05206
58.926,17.21,0.12474,103.77,1.05196
59.684,17.51,0.12849000000000002,103.80771,1.05185
60.407,17.81,0.13078,103.78886,1.05175
61.188,18.11,0.13349,103.87371,1.05164
61.947,18.41,0.13599,103.88314,1.0515299999999999
62.724,18.71,0.13746,103.81085999999999,1.05141
63.5,19.01,0.13892000000000002,103.84829,1.0513
64.308,19.31,0.14184000000000002,103.87657,1.05118
65.119,19.61,0.14476,103.98943,1.05106
65.924,19.91,0.14623,103.87686,1.05093
66.733,20.21,0.1477,103.91429000000001,1.05081
67.577,20.51,0.15,103.886,1.0506799999999998
68.411,20.81,0.1523,103.952,1.05055
69.248,21.11,0.15294000000000002,103.914,1.0504200000000001
70.084,21.41,0.1596,103.89543,1.0502799999999999
70.931,21.71,0.15859,103.97086,1.05015
71.775,22.01,0.16005999999999998,104.04571,1.05001
72.627,22.31,0.15904000000000001,104.08343,1.04987
73.526,22.61,0.15969,104.08343,1.04972
74.343,22.91,0.16096,104.15857,1.04958
75.205,23.21,0.16576,104.19629,1.04944
76.082,23.51,0.1664,104.15857,1.04929
76.947,23.81,0.16726,104.16171,1.04914
77.813,24.11,0.17206,104.04914000000001,1.0489899999999999
78.692,24.41,0.17188,104.25571,1.04884
79.565,24.71,0.17273,104.218,1.04869
80.45,25.01,0.1738,104.12429,1.04853
81.328,25.31,0.17653,104.23686,1.04837
82.202,25.61,0.17947000000000002,104.15257,1.0482200000000002
83.107,25.91,0.18241,104.17429,1.04805
83.996,26.21,0.18119000000000002,104.21171,1.04789
84.86,26.51,0.18683,104.24971,1.0477299999999998
85.75,26.81,0.18561,104.18370999999999,1.04756
86.665,27.11,0.18667999999999998,104.22143,1.04739
87.539,27.41,0.19067,104.22143,1.0472299999999999
88.439,27.71,0.1932,104.25914,1.04705
89.353,28.01,0.19469,104.24029,1.04688
90.304,28.31,0.19722,104.37171,1.04669
91.178,28.61,0.19934000000000002,104.25571,1.0465200000000001
92.08,28.91,0.20040999999999998,104.33114,1.04635
93.006,29.21,0.20357,104.24943,1.04616
93.921,29.51,0.20382,104.28714000000001,1.04598
94.835,29.81,0.2051,104.32457,1.04579
95.758,30.11,0.20847,104.36229,1.04561
96.678,30.41,0.21122,104.32486,1.04542
97.611,30.71,0.21064000000000002,104.32486,1.0452299999999999
98.522,31.01,0.21255,104.29656999999999,1.04504
99.453,31.31,0.21363000000000001,104.38429000000001,1.04484
100.357,31.61,0.21472,104.48770999999999,1.04465
101.291,31.91,0.2206,104.52543,1.04445
102.263,32.21,0.21939,104.49714,1.04424
103.187,32.51,0.22111,104.41257,1.0440399999999999
104.091,32.81,0.22365,104.52514000000001,1.04385
105.018,33.11,0.22495,104.52514000000001,1.04364
105.945,33.41,0.2275,104.43143,1.04344
106.883,33.71,0.22671,104.46571,1.0432299999999999
107.813,34.01,0.22946999999999998,104.51914000000001,1.04302
108.732,34.31,0.22951999999999997,104.56629000000001,1.04282
109.67,34.61,0.23479,104.58485999999999,1.0426
110.601,34.91,0.23421,104.54714,1.04239
111.518,35.21,0.23886,104.51914000000001,1.0421799999999999
112.461,35.51,0.23975,104.63171,1.04196
113.37,35.81,0.24126,104.516,1.04175
114.322,36.11,0.24236,104.58171,1.0415299999999998
115.249,36.41,0.24178000000000002,104.65686,1.04131
116.169,36.71,0.24791,104.54429,1.04109
117.098,37.01,0.24586,104.58171,1.0408600000000001
118.035,37.31,0.24800999999999998,104.61943000000001,1.04064
118.972,37.61,0.25079,104.61943000000001,1.04041
119.893,37.91,0.25315,104.69457,1.04019
120.836,38.21,0.25572,104.64743,1.03995
121.762,38.51,0.25892,104.68514,1.03972
122.698,38.81,0.26045,104.72286,1.03949
123.623,39.11,0.26659,104.704,1.03926
124.555,39.41,0.26749,104.71314,1.03902
125.496,39.71,0.27321999999999996,104.68543000000001,1.0387899999999999
126.427,40.01,0.27454,104.75114,1.03855
127.358,40.31,0.27859,104.71343,1.03831
128.321,40.61,0.27992,104.74143000000001,1.03806
129.23199,40.91,0.27976999999999996,104.77914,1.03782
130.161,41.21,0.28173000000000004,104.77914,1.03758
131.10201,41.51,0.28158,104.78856999999999,1.0373299999999999
132.075,41.81,0.28039000000000003,104.67571,1.0370700000000002
132.98599,42.11,0.27962,104.704,1.03683
133.909,42.41,0.27716,104.73229,1.0365799999999998
134.85898999999998,42.71,0.27681,104.73229,1.03633
135.783,43.01,0.27771999999999997,104.76971,1.03608
136.739,43.31,0.278,104.66657,1.03582
137.689,43.61,0.27975,104.76971,1.03556
138.621,43.91,0.28171999999999997,104.81685999999999,1.0353
139.565,44.21,0.28221,104.77943,1.03504
140.50999,44.51,0.2827,104.88257,1.03477
141.47099,44.81,0.28783000000000003,104.80429000000001,1.0345
142.411,45.11,0.29275,104.69143000000001,1.03424
143.362,45.41,0.29367,104.79486,1.03397
144.299,45.71,0.29649000000000003,104.76657,1.0337
145.24899,46.01,0.29846999999999996,104.84170999999999,1.0334299999999998
146.177,46.31,0.30023,104.89828999999999,1.03316
147.136,46.61,0.30285,104.804,1.03288
148.097,46.91,0.30525,104.84170999999999,1.0326
149.056,47.21,0.30808,104.84170999999999,1.0323200000000001
150.00101,47.51,0.31175,104.87,1.03204
150.94901000000002,47.81,0.31268,104.842,1.03176
151.905,48.11,0.31404,104.83256999999999,1.03148
152.86,48.41,0.31835,104.82314000000001,1.03119
153.81599,48.71,0.3214,104.936,1.0309
154.769,49.01,0.32255,104.92657,1.03061
155.72,49.31,0.32476,104.88886000000001,1.0303200000000001
156.666,49.61,0.32739,104.87943,1.03004
157.634,49.91,0.33108000000000004,104.92657,1.0297399999999999
158.58098999999999,50.21,0.33541,104.88886000000001,1.02944
159.54401000000001,50.51,0.33593,104.91686000000001,1.02915
160.506,50.81,0.3373,104.95456999999999,1.02885
161.45399,51.11,0.33824,104.95456999999999,1.02855
162.41298999999998,51.41,0.34131,104.91686000000001,1.02824
163.36301,51.71,0.34502,104.94543,1.0279399999999999
164.31,52.01,0.34745,104.97657,1.0276399999999999
165.28101,52.31,0.35244000000000003,104.94828999999999,1.0273299999999999
166.229,52.61,0.35169,104.96713999999999,1.0270299999999999
167.19501,52.91,0.35498,104.97343000000001,1.02671
168.14101000000002,53.21,0.35849000000000003,104.94514,1.02641
169.114,53.51,0.3569,105.00171,1.02609
170.05901,53.81,0.36168,104.964,1.02578
171.033,54.11,0.3635,104.964,1.02546
171.959,54.41,0.36551999999999996,104.92629,1.02515
172.927,54.71,0.36712,105.03943000000001,1.02483
173.892,55.01,0.37256,105.03913999999999,1.02451
174.83,55.31,0.37565,105.04886,1.02419
175.78999,55.61,0.37833,105.05171000000001,1.02387
176.752,55.91,0.38292,105.052,1.02354
177.707,56.21,0.38581,105.052,1.02321
178.674,56.51,0.38636,105.04229,1.02288
179.62399,56.81,0.38947,104.99857,1.0225600000000001
180.584,57.11,0.39066,104.97028999999999,1.0222200000000001
181.54601,57.41,0.39484,104.97028999999999,1.02189
182.504,57.71,0.39924,104.91371000000001,1.02156
183.47501,58.01,0.39766,105.06428999999999,1.02122
184.41701,58.31,0.40164,105.102,1.0208899999999999
185.382,58.61,0.40284000000000003,105.06456999999999,1.02054
186.342,58.91,0.40510999999999997,105.06456999999999,1.0202
187.29601,59.21,0.40824,105.08313999999999,1.01986
188.245,59.51,0.41073000000000004,105.12086000000001,1.01952
189.20598999999999,59.81,0.41236000000000006,105.08313999999999,1.01918
190.166,60.11,0.41741999999999996,105.09257,1.01883
191.125,60.41,0.42035,105.05486,1.0184799999999998
192.088,60.71,0.42456000000000005,105.05486,1.01813
193.048,61.01,0.42899,105.07371,1.01778
194.006,61.31,0.4315,105.04543000000001,1.0174299999999998
194.964,61.61,0.43636,105.102,1.01708
195.916,61.91,0.43673,105.13943,1.01672
196.88,62.21,0.44031000000000003,105.13943,1.01637
197.83299,62.51,0.44283,105.13943,1.01601
198.799,62.81,0.4462,105.13943,1.01565
199.757,63.11,0.44658000000000003,105.102,1.01529
200.743,63.41,0.45147,105.13943,1.01491
201.67799,63.71,0.45377,105.11143,1.0145600000000001
202.659,64.01,0.45888,105.13971000000001,1.01419
203.619,64.31,0.46163000000000004,105.218,1.0138200000000002
204.60699,64.61,0.46868999999999994,105.03943000000001,1.01344
205.539,64.91,0.47036000000000006,105.22713999999999,1.01308
206.502,65.21,0.47247,105.07686000000001,1.01271
207.459,65.51,0.4763,105.17086,1.01233
208.41901000000001,65.81,0.4795,105.19286000000001,1.01196
209.38699,66.11,0.48355,105.17428999999998,1.01158
210.347,66.41,0.48568,105.10829,1.0112
211.31798999999998,66.71,0.48802,105.15543000000001,1.01082
212.276,67.01,0.48993000000000003,105.18971,1.01044
213.242,67.31,0.49421000000000004,105.22713999999999,1.01005
214.20598999999999,67.61,0.50217,105.07056999999999,1.00967
215.15601,67.91,0.50474,105.22086000000002,1.00929
216.133,68.21,0.5049399999999999,105.18343,1.00889
217.09399,68.51,0.5068600000000001,105.25856999999999,1.0085
218.05499,68.81,0.51052,105.22113999999999,1.00811
219.01601000000002,69.11,0.51417,105.18343,1.0077200000000002
219.981,69.41,0.5191399999999999,105.07056999999999,1.0073299999999998
220.937,69.71,0.52194,105.10513999999999,1.00694
221.89999,70.01,0.52452,105.27429,1.00654
222.86099,70.31,0.52755,105.26513999999999,1.00614
223.834,70.61,0.53123,105.22713999999999,1.0057399999999999
224.78,70.91,0.53599,105.15229,1.00534
225.741,71.21,0.53946,105.26513999999999,1.00494
226.715,71.51,0.54315,105.23686000000001,1.00453
227.673,71.81,0.54793,105.30256999999999,1.00413
228.63499,72.11,0.5505399999999999,105.27429,1.0037200000000002
229.59599,72.41,0.5566300000000001,105.30856999999999,1.0033100000000001
230.55901,72.71,0.56055,105.30886000000001,1.00291
231.521,73.01,0.56426,105.27113999999999,1.0024899999999999
232.489,73.31,0.56862,105.27113999999999,1.0020799999999999
233.459,73.61,0.57038,105.34629,1.00166
234.416,73.91,0.5743199999999999,105.42171,1.00125
235.373,74.21,0.58,105.29943,1.0008299999999999
236.339,74.51,0.5833,105.26171000000001,1.00041
237.308,74.81,0.5874699999999999,105.28057,0.9999899999999999
238.283,75.11,0.5947,105.31828999999999,0.99956
239.23398999999998,75.41,0.59953,105.35571000000002,0.99915
240.202,75.71,0.60764,105.29943,0.99872
241.174,76.01,0.61533,105.28371000000001,0.99829
242.125,76.31,0.62149,105.406,0.99787
243.12399,76.61,0.62876,105.32113999999999,0.9974200000000001
244.036,76.91,0.63776,105.38713999999999,0.99702
245.009,77.21,0.6432899999999999,105.42456999999999,0.9965799999999999
245.965,77.51,0.6553800000000001,105.45286000000002,0.99615
246.933,77.81,0.66399,105.44657,0.99571
247.87801000000002,78.11,0.67982,105.37143,0.99529
248.832,78.41,0.69392,105.37143,0.99485
249.80901,78.71,0.71309,105.41828999999998,0.99441
250.758,79.01,0.74169,105.37143,0.99397
251.744,79.31,0.77735,105.32428999999999,0.9935200000000001
252.686,79.61,0.81237,105.44971000000001,0.9930899999999999
253.63699,79.91,0.8390799999999999,105.52514,0.99265
254.584,80.21,0.85988,105.43113999999998,0.99221
255.54601,80.51,0.87456,105.40286,0.9917600000000001
256.51901000000004,80.81,0.88089,105.45913999999999,0.99131
257.46701,81.11,0.87051,105.48743,0.99087
258.43399,81.41,0.8383299999999999,105.48114,0.99041
259.39499,81.71,0.7893899999999999,105.44343,0.9899600000000001
260.36499,82.01,0.74063,105.40286,0.98951
261.34398999999996,82.31,0.70792,105.41228999999998,0.9890399999999999
262.30099,82.61,0.68884,105.478,0.98859
263.276,82.91,0.67747,105.478,0.9881200000000001
264.23999,83.21,0.6735899999999999,105.55943,0.98766
265.21799,83.51,0.67325,105.522,0.98719
266.15398999999996,83.81,0.67687,105.50313999999999,0.98674
267.12299,84.11,0.67918,105.428,0.9862799999999999
268.08801,84.41,0.68216,105.46543,0.9858100000000001
269.03799,84.71,0.6869,105.47514,0.98535
270.005,85.01,0.68988,105.54086000000001,0.98488
270.974,85.31,0.6913199999999999,105.46571000000002,0.98441
271.91699,85.61,0.6932,105.522,0.98395
272.88599,85.91,0.69752,105.63486,0.9834700000000001
273.84698,86.21,0.70007,105.58771000000002,0.983
274.81201,86.51,0.70663,105.55028999999999,0.9825200000000001
275.76198999999997,86.81,0.7067399999999999,105.58771000000002,0.98205
276.715,87.11,0.7133,105.48428999999999,0.9815799999999999
277.67899,87.41,0.7149800000000001,105.51257,0.9811
278.634,87.71,0.71778,105.47514,0.98062
279.60001,88.01,0.72035,105.522,0.98014
280.55801,88.31,0.7236,105.55943,0.9796600000000001
281.513,88.61,0.72885,105.48428999999999,0.9791799999999999
282.47501,88.91,0.72921,105.60343,0.97869
283.43399,89.21,0.73292,105.59086,0.9782
284.392,89.51,0.73797,105.50943000000001,0.97772
285.35199,89.81,0.7421300000000001,105.47171000000002,0.9772299999999999
286.32198999999997,90.11,0.74005,105.58457,0.9767299999999999
287.26401,90.41,0.7451,105.54686000000001,0.97625
288.228,90.71,0.74883,105.48114,0.9757600000000001
289.18799,91.01,0.75547,105.51857,0.97526
290.14999,91.31,0.7601,105.50943000000001,0.97477
291.104,91.61,0.76407,105.54713999999998,0.9742700000000001
292.04999,91.91,0.7658,105.5,0.97378
293.01001,92.21,0.76776,105.566,0.9732799999999999
293.96898999999996,92.51,0.77084,105.45313999999999,0.97278
294.92801000000003,92.81,0.77595,105.51886,0.9722799999999999
295.87701,93.11,0.77635,105.51886,0.97178
296.82999,93.41,0.78258,105.51886,0.9712799999999999
297.78699,93.71,0.78523,105.45286000000002,0.97078
298.746,94.01,0.78654,105.472,0.9702700000000001
299.689,94.31,0.78987,105.50943000000001,0.96977
300.64801,94.61,0.79051,105.50943000000001,0.96926
301.59,94.91,0.7972199999999999,105.434,0.9687600000000001
302.54401,95.21,0.79899,105.44343,0.96825
303.50699,95.51,0.80482,105.51886,0.96773
304.46701,95.81,0.80615,105.49056999999999,0.96721
305.422,96.11,0.80703,105.5,0.9667
306.37799,96.41,0.80747,105.48114,0.9661799999999999
307.33301,96.71,0.80993,105.48114,0.96567
308.289,97.01,0.81172,105.55657,0.96515
309.23999,97.31,0.82006,105.42486000000001,0.9646299999999999
310.198,97.61,0.82073,105.42486000000001,0.96411
311.13698999999997,97.91,0.8214,105.47171000000002,0.9636
312.10901,98.21,0.8272799999999999,105.35571000000002,0.96306
313.04901,98.51,0.8266,105.48743,0.96255
314.01099,98.81,0.8286399999999999,105.45,0.9620200000000001
314.953,99.11,0.83385,105.44971000000001,0.9615
315.91101000000003,99.41,0.83567,105.412,0.9609700000000001
316.853,99.71,0.83975,105.46857,0.96044
317.81201,100.01,0.8459,105.45,0.95991
318.755,100.31,0.8461299999999999,105.43113999999998,0.95939
319.707,100.61,0.8509200000000001,105.384,0.95885
320.66598999999997,100.91,0.8566299999999999,105.37456999999999,0.9583200000000001
321.61401,101.21,0.86325,105.42143,0.95778
322.57001,101.51,0.86692,105.43086000000001,0.95725
323.522,101.81,0.8744700000000001,105.40914,0.9567100000000001
324.479,102.11,0.8765700000000001,105.38086000000001,0.9561700000000001
325.42499,102.41,0.8832200000000001,105.37171000000001,0.95563
326.39301,102.71,0.8860100000000001,105.37171000000001,0.9550799999999999
327.36401,103.01,0.88995,105.40914,0.9545299999999999
328.30099,103.31,0.8950100000000001,105.37171000000001,0.95399
329.25101,103.61,0.89735,105.38086000000001,0.95345
330.20599,103.91,0.8994700000000001,105.37143,0.9529
331.15799,104.21,0.90251,105.31513999999999,0.95236
332.09698,104.51,0.90622,105.39029,0.9518200000000001
333.03601000000003,104.81,0.9083399999999999,105.31513999999999,0.9512700000000001
334.01099,105.11,0.90843,105.35886,0.95071
334.93301,105.41,0.9151299999999999,105.28371000000001,0.9501700000000001
335.88698999999997,105.71,0.9204899999999999,105.39029,0.94962
336.83301,106.01,0.92653,105.268,0.9490700000000001
337.77898999999996,106.31,0.9323600000000001,105.21486000000002,0.94852
338.73401,106.61,0.93199,105.28371000000001,0.94796
339.69601,106.91,0.93875,105.28371000000001,0.94739
340.62701,107.21,0.9448200000000001,105.24286000000001,0.94685
341.57999,107.51,0.94976,105.27113999999999,0.9462799999999999
342.52398999999997,107.81,0.95493,105.25228999999999,0.94573
343.479,108.11,0.95873,105.24286000000001,0.94516
344.422,108.41,0.96368,105.19286000000001,0.9446
345.35901,108.71,0.9681700000000001,105.07686000000001,0.94405
346.306,109.01,0.9775299999999999,105.03913999999999,0.9434799999999999
347.24899,109.31,0.9795,105.18971,0.9429200000000001
348.194,109.61,0.98518,104.96113999999999,0.9423600000000001
349.14001,109.91,0.9904,104.96713999999999,0.94179
350.08701,110.21,0.99285,105.06114,0.9412200000000001
351.03601000000003,110.51,0.9994799999999999,104.90143,0.94065
351.987,110.81,1.00426,104.96713999999999,0.9400799999999999
352.93399,111.11,1.00882,104.85457,0.9395
353.88599,111.41,1.01385,104.85457,0.9389299999999999
354.83301,111.71,1.0167899999999999,104.65686,0.93835
355.771,112.01,1.02183,104.76657,0.93778
356.72299,112.31,1.0289700000000002,104.71,0.9372
357.68201,112.61,1.0345,104.56943000000001,0.9366200000000001
358.62,112.91,1.04049,104.55057,0.93604
359.56201,113.21,1.04883,104.43457,0.9354600000000001
360.52499,113.51,1.05275,104.39686,0.9348700000000001
361.45999,113.81,1.0604,104.20886,0.9343
362.40701,114.11,1.0662,104.17143,0.93371
363.36899,114.41,1.07342,104.05856999999999,0.9331200000000001
364.328,114.71,1.08205,103.97371,0.93253
365.26599,115.01,1.0902100000000001,103.82,0.93194
366.229,115.31,1.1009799999999998,103.74829,0.93134
367.15799,115.61,1.1143100000000001,103.48486,0.9307700000000001
368.11801,115.91,1.12604,103.39086,0.93017
369.073,116.21,1.13896,103.25943000000001,0.9295700000000001
370.02301,116.51,1.1629200000000002,103.03343000000001,0.9289700000000001
370.97501,116.81,1.1902,102.95829,0.9283799999999999
371.92401,117.11,1.2064700000000002,102.61057,0.9277799999999999
372.87701,117.41,1.21337,102.53229,0.9271799999999999
373.82999,117.71,1.2221600000000001,102.28143,0.92658
374.80499,118.01,1.22532,101.99314,0.92596
375.724,118.31,1.24423,101.72371,0.92538
376.67401,118.61,1.27239,101.448,0.9247700000000001
377.625,118.91,1.3041200000000002,101.09057,0.92417
378.57101,119.21,1.34746,100.73343,0.9235700000000001
379.513,119.51,1.38116,100.52343,0.92296
380.44901,119.81,1.41916,100.16,0.9223600000000001
381.41699,120.11,1.4608,99.73686,0.92174
382.33898999999997,120.41,1.4996,99.37657,0.92115
383.27701,120.71,1.56831,98.96257,0.92055
384.215,121.01,1.71672,98.43314000000001,0.91994
385.15201,121.31,1.7733299999999999,97.98514,0.9193399999999999
386.09,121.61,1.81152,97.48657,0.9187299999999999
387.03799,121.91,1.85024,96.98829,0.91812
387.97699,122.21,1.88283,96.446,0.91751
388.90799,122.51,1.9114200000000001,95.86343000000001,0.9169
389.83301,122.81,1.9298,95.21457,0.9163
390.75299,123.11,1.93012,94.58771,0.9157
391.686,123.41,1.9185400000000001,93.86086,0.91509
392.58401000000003,123.71,1.89022,93.08343,0.9145
393.51401,124.01,1.8857599999999999,92.39429,0.91389
394.427,124.31,1.8850900000000002,91.56057,0.9132899999999999
395.35199,124.61,1.85601,90.74571,0.9126799999999999
396.23499,124.91,1.81968,89.83371,0.9121
397.14301,125.21,1.77328,89.00943000000001,0.9115
398.03699,125.51,1.71006,88.00343000000001,0.91091
398.94101,125.81,1.6740700000000002,87.032,0.9103100000000001
399.827,126.11,1.6071,85.932,0.9097200000000001
400.65398999999996,126.41,1.4258600000000001,84.69114,0.90917
401.54401,126.71,1.33922,83.61914,0.9085700000000001
402.44101,127.01,1.3350600000000001,82.206,0.9079799999999999
403.34698,127.31,1.33451,80.83629,0.9073700000000001
404.27398999999997,127.61,1.33085,79.46370999999999,0.90675
405.186,127.91,1.3279,78.02514000000001,0.90614
406.108,128.21,1.3252,76.73714,0.9055200000000001
407.03,128.51,1.33189,75.15143,0.9049
407.95999,128.81,1.3304,73.63143000000001,0.90427
408.884,129.11,1.32674,72.074,0.90365
409.815,129.41,1.32621,70.42229,0.90302
410.74799,129.71,1.32473,68.82714,0.9023899999999999
411.67899,130.01,1.32735,67.066,0.90176
412.604,130.31,1.32875,65.34857,0.9011299999999999
413.51901000000004,130.61,1.33064,63.70029,0.90051
414.45801,130.91,1.33571,61.97971,0.8998700000000001
415.37399,131.21,1.33251,60.18371,0.8992399999999999
416.31299,131.51,1.32813,58.338,0.8986
417.229,131.81,1.3251700000000002,56.56429,0.89797
418.15799,132.11,1.3185799999999999,54.76229,0.8973399999999999
419.082,132.41,1.31125,53.06371,0.8967
420.022,132.71,1.3049,51.39343,0.89605
420.94600999999994,133.01,1.2939,49.66029,0.8954200000000001
421.867,133.31,1.28702,48.04029,0.8947799999999999
422.79400999999996,133.61,1.2738,46.507709999999996,0.8941399999999999
423.71300999999994,133.91,1.26544,44.96886,0.89351
424.64401,134.21,1.25048,43.62429,0.89286
425.57401,134.51,1.2425899999999999,42.24857,0.8922100000000001
426.504,134.81,1.22736,41.13943,0.8915700000000001
427.44,135.11,1.21431,39.92657,0.89092
428.36899000000005,135.41,1.1995200000000001,38.77657,0.8902700000000001
429.293,135.71,1.1866700000000001,37.902,0.8896200000000001
430.23199000000005,136.01,1.17602,37.02429,0.88897
431.16599,136.31,1.16683,36.294290000000004,0.88831
432.09601,136.61,1.1630200000000002,35.57971,0.88766
433.01901,136.91,1.171,34.95943,0.8870100000000001
433.95999000000006,137.21,1.1723700000000001,34.46743,0.88635
434.897,137.51,1.19145,33.878,0.88569
435.89000999999996,137.81,1.33649,33.32343,0.8849899999999999
436.84601,138.11,1.42305,32.98514,0.88431
437.77899,138.41,1.4297799999999998,32.530570000000004,0.88365
438.711,138.71,1.4219700000000002,32.179429999999996,0.8829899999999999
439.633,139.01,1.37435,31.81914,0.88233
440.53699000000006,139.31,1.1662,31.47743,0.88169
441.44,139.61,1.07451,31.24571,0.88105
442.341,139.91,1.01216,31.013709999999996,0.88041
443.24899000000005,140.21,0.9474899999999999,30.624859999999998,0.87976
444.13699,140.51,0.82147,30.434,0.8791200000000001
445.02499000000006,140.81,0.71363,30.314859999999996,0.87849
445.92400999999995,141.11,0.68362,30.108,0.87784
446.81600999999995,141.41,0.68486,29.860570000000003,0.8772
447.71300999999994,141.71,0.6945600000000001,29.663140000000002,0.87656
448.61800999999997,142.01,0.70802,29.51257,0.8759100000000001
449.50699000000003,142.31,0.72772,29.36229,0.8752700000000001
450.418,142.61,0.74795,29.24943,0.87461
451.32199,142.91,0.7719600000000001,29.139709999999997,0.87395
452.22299000000004,143.21,0.78776,28.99857,0.8733
453.14000999999996,143.51,0.8076,28.801140000000004,0.87264
454.039,143.81,0.8287,28.650859999999998,0.8719899999999999
454.953,144.11,0.84734,28.660290000000003,0.8713200000000001
455.879,144.41,0.8675299999999999,28.566,0.87065
456.78101,144.71,0.88046,28.43457,0.8699899999999999
457.698,145.01,0.8899100000000001,28.396859999999997,0.8693200000000001
458.60699000000005,145.31,0.90164,28.280859999999997,0.86866
459.51800999999995,145.61,0.9153899999999999,28.299709999999997,0.8679899999999999
460.435,145.91,0.92389,28.168,0.8673200000000001
461.35000999999994,146.21,0.9361700000000001,28.055429999999998,0.86665
462.26099000000005,146.51,0.94394,27.94257,0.86598
463.17599,146.81,0.95299,27.86743,0.86531
464.08700999999996,147.11,0.95978,27.86743,0.86464
464.979,147.41,0.9668200000000001,27.867140000000003,0.86398
465.88901,147.71,0.9733799999999999,27.792,0.86331
466.82401,148.01,0.9761799999999999,27.75429,0.86262
467.71399,148.31,0.9835,27.698,0.8619600000000001
468.64300999999995,148.61,0.9916200000000001,27.63229,0.8612700000000001
469.54400999999996,148.91,0.9959399999999999,27.51,0.8606
470.461,149.21,1.0018,27.566290000000002,0.85992
471.367,149.51,1.00512,27.453709999999997,0.85925
472.28,149.81,1.0130299999999999,27.453709999999997,0.85857
473.189,150.11,1.02196,27.49114,0.8578899999999999
474.08800999999994,150.41,1.0217399999999999,27.346859999999996,0.8572200000000001
475.01500999999996,150.71,1.03096,27.41286,0.8565299999999999
475.914,151.01,1.03636,27.334570000000003,0.85585
476.832,151.31,1.0445799999999998,27.36257,0.8551700000000001
477.73801,151.61,1.04975,27.334290000000003,0.85449
478.64899,151.91,1.05519,27.25943,0.8538
479.54999000000004,152.21,1.0608799999999998,27.15571,0.8531299999999999
480.50201,152.51,1.06459,27.108859999999996,0.85241
481.38699,152.81,1.06875,27.071140000000003,0.8517399999999999
482.30301,153.11,1.07499,27.108859999999996,0.85105
483.22500999999994,153.41,1.08126,27.024,0.85035
484.11499000000003,153.71,1.0887799999999999,26.996,0.8496799999999999
485.02300999999994,154.01,1.09454,26.996,0.8489899999999999
485.939,154.31,1.10109,26.98657,0.8483
486.83300999999994,154.61,1.10609,26.996,0.84762
487.73199000000005,154.91,1.1067200000000001,27.01486,0.8469399999999999
488.64401,155.21,1.1158700000000001,26.996,0.84625
489.54199000000006,155.51,1.12245,26.996,0.8455600000000001
490.45800999999994,155.81,1.1275,26.88314,0.84486
491.37201,156.11,1.13179,26.770290000000003,0.8441700000000001
492.298,156.41,1.14075,26.75143,0.84346
493.181,156.71,1.1468399999999999,26.685709999999997,0.84278
494.08899,157.01,1.15244,26.72343,0.84209
495.00600999999995,157.31,1.16221,26.99914,0.84139
495.939,157.61,1.1728,26.75143,0.84067
496.80399000000006,157.91,1.17814,26.79229,0.84001
497.70999000000006,158.21,1.18561,26.826859999999996,0.83931
498.617,158.51,1.18816,26.638859999999998,0.8386100000000001
499.51599000000004,158.81,1.18654,26.67629,0.8379200000000001
500.43201,159.11,1.1919600000000001,26.58257,0.83721
501.33499000000006,159.41,1.1984299999999999,26.657709999999998,0.8365100000000001
502.23801,159.71,1.2067299999999999,26.594859999999997,0.8358200000000001
503.147,160.01,1.21584,26.594859999999997,0.83511
504.05499000000003,160.31,1.22157,26.58543,0.83441
504.95599000000004,160.61,1.22625,26.472859999999997,0.8337100000000001
505.85999000000004,160.91,1.23357,26.55743,0.83301
506.76901,161.21,1.24011,26.576,0.8323
507.672,161.51,1.24719,26.594859999999997,0.8316
508.556,161.81,1.2595,26.63257,0.83091
509.45099000000005,162.11,1.26319,26.519709999999996,0.83021
510.36400999999995,162.41,1.27163,26.482290000000003,0.8295
511.259,162.71,1.27928,26.482290000000003,0.8288
512.164,163.01,1.28827,26.51029,0.82809
513.08398,163.31,1.2944,26.51029,0.82737
513.99902,163.61,1.30264,26.47257,0.8266600000000001
514.90399,163.91,1.30851,26.444290000000002,0.82595
515.77899,164.21,1.31884,26.482,0.82526
516.672,164.51,1.32235,26.46343,0.8245600000000001
517.58002,164.81,1.33355,26.51029,0.82384
518.487,165.11,1.33894,26.435140000000004,0.8231299999999999
519.38599,165.41,1.34884,26.435140000000004,0.82242
520.29498,165.71,1.3524100000000001,26.359709999999996,0.8217
521.18597,166.01,1.3623299999999998,26.39743,0.821
522.08398,166.31,1.36856,26.331709999999998,0.82029
522.992,166.61,1.3758700000000001,26.284570000000002,0.81957
523.89301,166.91,1.38266,26.284570000000002,0.81886
524.78302,167.21,1.3913200000000001,26.322290000000002,0.81815
525.67902,167.51,1.39866,26.284570000000002,0.8174399999999999
526.5889900000001,167.81,1.4063,26.23743,0.81672
527.49298,168.11,1.41395,26.237709999999996,0.816
528.39001,168.41,1.42134,26.20029,0.81528
529.315,168.71,1.42798,26.25657,0.81455
530.19299,169.01,1.4351,26.237709999999996,0.81385
531.08398,169.31,1.4417200000000001,26.18114,0.81314
531.98901,169.61,1.4489,26.162570000000002,0.8124100000000001
532.88599,169.91,1.45743,26.20029,0.8117
533.784,170.21,1.4611399999999999,26.19057,0.81098
534.6749900000001,170.51,1.46539,26.19086,0.8102600000000001
535.58398,170.81,1.47183,26.162570000000002,0.80953
536.47998,171.11,1.4777200000000001,26.203139999999998,0.80882
537.37598,171.41,1.48901,26.09029,0.8081
538.26599,171.71,1.4930299999999999,26.128,0.80738
539.16998,172.01,1.50357,26.128,0.80665
540.06201,172.31,1.5070700000000001,26.05286,0.80594
540.9569700000001,172.61,1.51356,26.043429999999997,0.80521
541.849,172.91,1.51708,26.043429999999997,0.8044899999999999
542.7520099999999,173.21,1.52633,26.05286,0.80377
543.63501,173.51,1.53447,26.168860000000002,0.80305
544.53003,173.81,1.54101,26.11543,0.80233
545.42902,174.11,1.54785,26.002860000000002,0.8016
546.3220200000001,174.41,1.55524,26.002570000000002,0.80088
547.20599,174.71,1.56371,25.95571,0.80016
548.099,175.01,1.56649,25.99314,0.7994399999999999
548.9979900000001,175.31,1.57066,25.88029,0.79871
549.89502,175.61,1.57837,25.96486,0.79798
550.7869900000001,175.91,1.58692,26.012,0.79725
551.68402,176.21,1.5933,26.04029,0.79652
552.5700099999999,176.51,1.59776,25.880570000000002,0.7958
553.461,176.81,1.60388,25.874,0.7950699999999999
554.35901,177.11,1.61057,25.80829,0.7943399999999999
555.25598,177.41,1.61563,25.89314,0.79361
556.14899,177.71,1.62179,25.81771,0.79288
557.04102,178.01,1.63044,25.89629,0.79215
557.93402,178.31,1.6385599999999998,25.85857,0.7914100000000001
558.8220200000001,178.61,1.64779,25.85829,0.79069
559.71997,178.91,1.6565,25.80229,0.78995
560.60901,179.21,1.66383,25.830289999999998,0.78922
561.5020099999999,179.51,1.6814099999999998,25.764570000000003,0.7884899999999999
562.396,179.81,1.68851,25.68914,0.78775
563.29401,180.11,1.6934200000000001,25.68914,0.78701
564.164,180.41,1.6985700000000001,25.57657,0.7863
565.09003,180.71,1.7107599999999998,25.830289999999998,0.7855300000000001
565.9639900000001,181.01,1.71678,25.726860000000002,0.78481
566.84302,181.31,1.72281,25.71743,0.78409
567.73602,181.61,1.7286099999999998,25.75514,0.78335
568.61603,181.91,1.73272,25.69857,0.78262
569.51202,182.21,1.74217,25.651429999999998,0.78188
570.39899,182.51,1.7477200000000002,25.62343,0.78115
571.2810099999999,182.81,1.7543799999999998,25.61429,0.78042
572.1829799999999,183.11,1.7638900000000002,25.548289999999998,0.77967
573.0819700000001,183.41,1.7672599999999998,25.720570000000002,0.77893
573.98499,183.71,1.7731599999999998,25.57943,0.77818
574.87097,184.01,1.7793299999999999,25.57943,0.7774399999999999
575.75598,184.31,1.7860599999999998,25.541710000000002,0.7767
576.64203,184.61,1.78888,25.55143,0.7759699999999999
577.534,184.91,1.79172,25.51371,0.77522
578.4180299999999,185.21,1.79708,25.51371,0.77449
579.31,185.51,1.80332,25.51371,0.77374
580.19,185.81,1.807,25.53229,0.7730100000000001
581.0670200000001,186.11,1.8166200000000001,25.49486,0.77228
581.97198,186.41,1.8209400000000002,25.53886,0.77152
582.84302,186.71,1.8223799999999999,25.529139999999998,0.77079
583.73297,187.01,1.8332,25.636,0.77005
584.62097,187.31,1.83667,25.49171,0.76931
585.50098,187.61,1.84411,25.426,0.76857
586.38397,187.91,1.8498599999999998,25.407429999999998,0.76783
587.26501,188.21,1.85874,25.36029,0.7670899999999999
588.15198,188.51,1.86169,25.49486,0.76635
589.0380200000001,188.81,1.8672,25.46686,0.7656
589.9329799999999,189.11,1.87074,25.388289999999998,0.76485
590.80603,189.41,1.8773900000000001,25.46971,0.76412
591.68701,189.71,1.8855,25.44143,0.7633800000000001
592.5700099999999,190.01,1.8933400000000002,25.35714,0.76263
593.44098,190.31,1.9026,25.38514,0.7619
594.33301,190.61,1.90648,25.33829,0.76115
595.229,190.91,1.9098099999999998,25.37257,0.76039
596.1279900000001,191.21,1.9177400000000002,25.32571,0.75963
596.99597,191.51,1.9196,25.34457,0.7589
597.8939799999999,191.81,1.92698,25.38229,0.7581399999999999
598.77399,192.11,1.8937599999999999,25.354,0.7574
599.65002,192.41,1.90167,25.30686,0.75665
600.53003,192.71,1.90556,25.33514,0.7559100000000001
601.41699,193.01,1.91179,25.278570000000002,0.75516
602.297,193.31,1.91888,25.35371,0.75441
603.17102,193.61,1.92337,25.241139999999998,0.75367
604.0529799999999,193.91,1.9273099999999999,25.15971,0.75292
604.93701,194.21,1.9335799999999999,25.27257,0.75217
605.82898,194.51,1.9416200000000001,25.23486,0.75141
606.7119799999999,194.81,1.95082,25.238,0.75066
607.60303,195.11,1.95628,25.228289999999998,0.7499
608.49298,195.41,1.9594200000000002,25.162570000000002,0.74915
609.37598,195.71,1.9643099999999998,25.23771,0.74839
610.24597,196.01,1.9677099999999998,25.18143,0.74765
611.1229900000001,196.31,1.9749299999999999,25.21914,0.7469100000000001
611.9810200000001,196.61,1.98038,25.172,0.74617
612.8720099999999,196.91,1.9885400000000002,25.144,0.74541
613.7520099999999,197.21,1.9926,25.15314,0.74466
614.62903,197.51,1.99665,25.11571,0.7439100000000001
615.51703,197.81,2.0028,25.23486,0.74315
616.40503,198.11,2.00661,25.106289999999998,0.74239
617.28198,198.41,2.0127599999999997,25.144,0.74164
618.172,198.71,2.01954,25.12514,0.74088
619.02197,199.01,2.02565,25.07486,0.74015
619.89697,199.31,2.03124,25.07486,0.7394
620.77197,199.61,2.03478,25.07486,0.73865
621.65802,199.91,2.03983,25.03743,0.7378899999999999
622.53998,200.21,2.04399,25.01543,0.7371300000000001
623.4110099999999,200.51,2.0484400000000003,25.05314,0.73639
624.29401,200.81,2.05589,25.09086,0.73563
625.15503,201.11,2.06241,25.02486,0.7348899999999999
626.0369900000001,201.41,2.07285,25.06229,0.7341300000000001
626.9420200000001,201.71,2.0807,25.06229,0.73335
627.81201,202.01,2.0867,25.02486,0.7326
628.6799900000001,202.31,2.08913,24.94971,0.73185
629.56598,202.61,2.0954900000000003,25.006,0.73109
630.44,202.91,2.09795,24.977710000000002,0.73033
631.30603,203.21,2.10607,25.006,0.72959
632.16699,203.51,2.11091,25.006,0.7288399999999999
633.04498,203.81,2.1182,24.96829,0.7280800000000001
633.935,204.11,2.12194,24.977710000000002,0.72732
634.79199,204.41,2.1331,24.99686,0.7265699999999999
635.6799900000001,204.71,2.13836,24.959139999999998,0.7258100000000001
636.56403,205.01,2.14242,24.89314,0.72504
637.43903,205.31,2.14888,24.924570000000003,0.72428
638.34003,205.61,2.15571,24.924570000000003,0.7235
639.1829799999999,205.91,2.16121,25.05629,0.72277
640.05701,206.21,2.1671,24.921429999999997,0.72202
640.93103,206.51,2.1714900000000004,25.040570000000002,0.72126
641.8029799999999,206.81,2.1816400000000002,24.880570000000002,0.7205
642.67902,207.11,2.1884900000000003,24.880570000000002,0.7197399999999999
643.55902,207.41,2.1956700000000002,24.921429999999997,0.7189800000000001
644.427,207.71,2.20192,24.921429999999997,0.71822
645.2999900000001,208.01,2.21002,24.89314,0.71746
646.16998,208.31,2.21691,24.861710000000002,0.7167100000000001
647.04797,208.61,2.22598,24.99057,0.7159399999999999
647.9180299999999,208.91,2.23412,24.739710000000002,0.71519
648.7999900000001,209.21,2.24324,24.92771,0.7144199999999999
649.672,209.51,2.23219,24.768,0.7136600000000001
650.5529799999999,209.81,2.21808,24.85543,0.7128899999999999
650.841,209.91,2.2194700000000003,24.83686,0.7126399999999999