File: 02_Data/MDF/STA/N2/3K_min/MDF_STA_N2_3KData_210317_R3.csv
##Temp./Â°C,Time/min,DSC/(mW/mg),Mass/%,Sensit./(uV/mW)
49.018,10.00917,0.001152376,99.30455,1.0532700000000002
49.03,10.30917,0.0006585014,99.29727,1.0532700000000002
49.042,10.609169999999999,-0.00032925120000000004,99.28976999999999,1.0532700000000002
49.086,10.90917,0.001646264,99.31205,1.0532700000000002
49.159,11.20917,0.00378644,99.25227,1.05326
49.273,11.50917,0.006420579,99.25227,1.05324
49.453,11.80917,0.008725585,99.25227,1.05322
49.675,12.109169999999999,0.01317104,99.25227,1.05319
49.984,12.40917,0.01580582,99.23727,1.05315
50.32,12.70917,0.01926412,99.215,1.05311
50.692,13.00917,0.01926498,99.1925,1.05306
51.136,13.309170000000002,0.02288868,99.1925,1.05301
51.589,13.60917,0.02651281,99.1925,1.05295
52.07,13.909170000000001,0.03030213,99.1625,1.0528899999999999
52.611,14.20917,0.03425687,99.1625,1.05282
53.155,14.509170000000001,0.03524743,99.16273000000001,1.05275
53.714,14.809170000000002,0.03739123,99.1325,1.05267
54.302,15.10917,0.03970024,99.13273000000001,1.0526
54.923,15.409170000000001,0.04184504,99.13273000000001,1.05251
55.569,15.70917,0.04349608,99.10273000000001,1.05243
56.22,16.00917,0.04580653,99.08023,1.05234
56.89,16.30917,0.0461401,99.10273000000001,1.05225
57.594,16.609170000000002,0.04861638,99.07295,1.05215
58.299,16.90917,0.04977463,99.08773000000001,1.05205
59.021,17.20917,0.05126292,99.07295,1.05195
59.738,17.50917,0.05390545,99.04295,1.05185
60.5,17.80917,0.05391104,99.04295,1.05174
61.273,18.109170000000002,0.05391676,99.02045,1.0516299999999998
62.029,18.40917,0.0565608,99.02795,1.05152
62.807,18.70917,0.05640204,99.02045,1.0514
63.608,19.00917,0.05690322,98.99068,1.05128
64.392,19.30917,0.05806426,98.99045,1.0511700000000002
65.219,19.609170000000002,0.05823613,98.99068,1.05104
66.064,19.90917,0.05890325,98.96045,1.05091
66.843,20.20917,0.06171521,98.95318,1.05079
67.67,20.50917,0.06122765,98.93068000000001,1.05066
68.5,20.80917,0.0620605,98.94568000000001,1.05053
69.353,21.109170000000002,0.06091294,98.92318,1.0504
70.169,21.40917,0.06009501,98.90091,1.05027
71.021,21.70917,0.05911215,98.90841,1.05013
71.874,22.00917,0.06027593,98.84864,1.04999
72.743,22.30917,0.0607796,98.89318,1.04985
73.608,22.609170000000002,0.06128343,98.84091,1.0497100000000001
74.465,22.90917,0.06178741,98.85591,1.04956
75.321,23.20917,0.0613002,98.82614000000001,1.04942
76.199,23.50917,0.06015214,98.85591,1.0492700000000001
77.099,23.80917,0.06032626,98.84114,1.04912
77.954,24.109170000000002,0.06099597,98.82614000000001,1.0489700000000002
78.832,24.40917,0.05902097,98.79614000000001,1.04882
79.709,24.70917,0.06150989,98.79614000000001,1.04866
80.588,25.00917,0.05887306,98.78114000000001,1.04851
81.464,25.30917,0.05822026,98.76635999999999,1.04835
82.342,25.609170000000002,0.06004872,98.76635999999999,1.04819
83.231,25.90917,0.05691445,98.76614000000001,1.04803
84.127,26.20917,0.05526863,98.75886,1.04786
85.003,26.50917,0.05577368,98.73635999999999,1.0477
85.894,26.80917,0.055617,98.74364,1.04754
86.801,27.109170000000002,0.05430162,98.73614,1.0473700000000001
87.697,27.40917,0.05596623,98.76635999999999,1.0472
88.603,27.70917,0.05663792,98.73635999999999,1.04702
89.521,28.00917,0.05416295,98.74364,1.04685
90.394,28.30917,0.05533136,98.70636,1.0466799999999998
91.293,28.609170000000002,0.05550635,98.69136,1.0465
92.216,28.90917,0.05452169,98.68409,1.0463200000000001
93.12,29.20917,0.05602279,98.68409,1.04614
94.033,29.50917,0.05603259,98.68409,1.04596
94.947,29.80917,0.05239474,98.69136,1.04577
95.854,30.109170000000002,0.05373067,98.69136,1.04559
96.773,30.40917,0.05324275,98.66909,1.0454
97.68,30.70917,0.05258872,98.66909,1.04521
98.609,31.00917,0.0516029,98.63909,1.04502
99.521,31.30917,0.05310595,98.63909,1.04483
100.447,31.609170000000002,0.051788,98.63909,1.04463
101.377,31.90917,0.05511818,98.62409,1.04443
102.318,32.20917,0.05346833,98.63909,1.04423
103.219,32.509170000000005,0.05630168,98.63886,1.0440399999999999
104.157,32.80917,0.05714327,98.62409,1.04383
105.078,33.10917,0.05615745,98.59409000000001,1.0436299999999998
106.023,33.40917,0.05633485,98.57932,1.04342
106.942,33.70917,0.0551824,98.56432,1.04322
107.858,34.009170000000005,0.05569199,98.57932,1.04301
108.796,34.30917,0.05503817,98.56409000000001,1.0428
109.733,34.60917,0.05288734,98.56432,1.04259
110.651,34.90917,0.0525653,98.56432,1.0423799999999999
111.574,35.20917,0.05490533,98.54932,1.04217
112.516,35.509170000000005,0.05475042,98.54182,1.04195
113.447,35.80917,0.052598,98.55682,1.0417299999999998
114.364,36.10917,0.05227591,98.51955,1.04152
115.319,36.40917,0.05195421,98.51955,1.04129
116.238,36.70917,0.05279791,98.51932,1.0410700000000002
117.168,37.009170000000005,0.05364217,98.52682,1.04085
118.104,37.30917,0.05282068,98.48955,1.04062
119.023,37.60917,0.05299867,98.47455,1.0404
119.962,37.90917,0.05501076,98.50455,1.04017
120.89,38.20917,0.053022,98.49705,1.0399399999999999
121.818,38.509170000000005,0.05470145,98.50455,1.0397100000000001
122.746,38.80917,0.05337914,98.48205,1.03948
123.681,39.10917,0.05455911,98.48931999999999,1.03925
124.647,39.40917,0.05440502,98.48205,1.039
125.554,39.70917,0.05391631,98.44455,1.03877
126.493,40.009170000000005,0.05493053,98.45205,1.03853
127.418,40.30917,0.05460911,98.42205,1.03829
128.366,40.60917,0.05261753,98.42227,1.03805
129.293,40.90917,0.05246268,98.43705,1.0378100000000001
130.272,41.20917,0.05063732,98.43727,1.03755
131.187,41.509170000000005,0.05549668,98.39976999999999,1.03731
132.125,41.80917,0.05450679,98.42976999999999,1.03706
133.07201,42.10917,0.05201147,98.43705,1.03681
134.01601000000002,42.40917,0.05419881,98.40705,1.03656
134.951,42.70917,0.05203683,98.42205,1.0363
135.903,43.009170000000005,0.05104562,98.42205,1.03605
136.839,43.30917,0.05156042,98.42205,1.03579
137.77698999999998,43.60917,0.05006623,98.39227,1.0355299999999998
138.724,43.90917,0.05058134,98.42227,1.0352700000000001
139.66701,44.20917,0.05159931,98.40727,1.03501
140.623,44.509170000000005,0.05211534,98.39976999999999,1.03474
141.55901,44.80917,0.05112288,98.39976999999999,1.0344799999999998
142.508,45.10917,0.05147144,98.39976999999999,1.03421
143.452,45.40917,0.05014318,98.39227,1.0339399999999999
144.401,45.70917,0.05099506,98.37,1.03367
145.377,46.009170000000005,0.05000213,98.36227,1.03339
146.3,46.30917,0.05135772,98.34,1.0331299999999999
147.269,46.60917,0.04986077,98.36227,1.03284
148.216,46.90917,0.05037789,98.33227,1.03257
149.142,47.20917,0.04988725,98.33227,1.0323
150.092,47.509170000000005,0.05124492,98.31727,1.0320200000000002
151.04401000000001,47.80917,0.05025058,98.3025,1.03173
152.041,48.10917,0.04623041,98.3025,1.03144
152.97099,48.40917,0.04708369,98.2725,1.03116
153.92598999999998,48.70917,0.04961989,98.28,1.0308700000000002
154.883,49.009170000000005,0.0487926,98.2425,1.0305799999999998
155.836,49.30917,0.04846975,98.2425,1.03029
156.786,49.60917,0.0479784,98.22773000000001,1.03
157.746,49.90917,0.04866574,98.22773000000001,1.0297
158.69701,50.20917,0.05137472,98.19795,1.02941
159.657,50.509170000000005,0.05037868,98.19795,1.02911
160.605,50.80917,0.04938196,98.22773000000001,1.02881
161.55701000000002,51.10917,0.05091361,98.20545,1.02852
162.50999,51.40917,0.05059124,98.16795,1.02821
163.466,51.70917,0.05246171,98.19773,1.02791
164.42598999999998,52.009170000000005,0.05112744,98.22023,1.0276
165.382,52.30917,0.04962359,98.19023,1.0273
166.33501,52.60917,0.04946958,98.18273,1.02699
167.3,52.909169999999996,0.04847129,98.14545,1.02668
168.24698999999998,53.20916999999999,0.04814796,98.16773,1.02637
169.2,53.50917,0.05069744,98.15295,1.02606
170.157,53.809169999999995,0.04902254,98.18273,1.02575
171.11099,54.10917,0.05039035,98.13068,1.0254299999999998
172.082,54.409169999999996,0.05243595,98.12318,1.02511
173.017,54.70916999999999,0.05312869,98.10068000000001,1.0248
173.998,55.00917,0.05416123,98.08568000000001,1.02447
174.942,55.309169999999995,0.05316218,98.07068000000001,1.02415
175.89301,55.60917,0.05351758,98.08568000000001,1.02383
176.84399,55.909169999999996,0.05353445,98.05568000000001,1.0235100000000001
177.80701000000002,56.20916999999999,0.05490736,98.05568000000001,1.02318
178.78798999999998,56.50917,0.05356921,98.05568000000001,1.02284
179.72,56.809169999999995,0.05511218,98.02568000000001,1.02252
180.67598999999998,57.10917,0.05513,98.02568000000001,1.02219
181.644,57.409169999999996,0.05599656,97.99591,1.02186
182.60001,57.70916999999999,0.0566938,98.00341,1.02152
183.562,58.00917,0.05518433,98.01068000000001,1.02119
184.51199,58.309169999999995,0.05622152,97.97341,1.02085
185.472,58.60917,0.0560703,97.94364,1.02051
186.446,58.909169999999996,0.05608931,97.94364,1.02017
187.40198999999998,59.20916999999999,0.05695818,97.89114000000001,1.01983
188.364,59.50917,0.05595693,97.88364,1.01948
189.328,59.809169999999995,0.05682666,97.85364,1.01914
190.291,60.10917,0.05752685,97.83136,1.0187899999999999
191.23599,60.409169999999996,0.05635444,97.80159,1.01844
192.19501,60.70916999999999,0.0567144,97.79409,1.01809
193.14799,61.00917,0.05656346,97.77136,1.01775
194.11,61.309169999999995,0.05743527,97.73409000000001,1.01739
195.071,61.60917,0.05864873,97.70432,1.01704
196.01801,61.909169999999996,0.05696351,97.71181999999999,1.0166899999999999
197.005,62.20916999999999,0.05749593,97.66682,1.0163200000000001
197.94501,62.50917,0.05819849,97.65182,1.01597
198.89999,62.809169999999995,0.06026779,97.65205,1.0156100000000001
199.88699,63.10917,0.06011907,97.62205,1.01524
200.83,63.409169999999996,0.05996935,97.58455,1.01488
201.786,63.70916999999999,0.06016173,97.53976999999999,1.01452
202.74899,64.00917,0.05984157,97.51727,1.01415
203.698,64.30917,0.06088924,97.49476999999999,1.01379
204.661,64.60916999999999,0.06056929,97.4425,1.01342
205.62801000000002,64.90916999999999,0.05990696,97.4125,1.01304
206.582,65.20917,0.05838781,97.37523,1.0126700000000002
207.53999,65.50917,0.05686771,97.34523,1.0123
208.51801,65.80917,0.05963083,97.32273,1.0119200000000002
209.474,66.10916999999999,0.05845302,97.26295,1.0115399999999999
210.42799,66.40916999999999,0.0596751,97.23295,1.0111700000000001
211.38901,66.70917,0.05901135,97.20318,1.0107899999999999
212.33701000000002,67.00917,0.05748881,97.18068000000001,1.01041
213.293,67.30917,0.05648045,97.09841,1.01003
214.25301000000002,67.60916999999999,0.05633018,97.06090999999999,1.00965
215.23199,67.90916999999999,0.05411865,96.98635999999999,1.00926
216.18401,68.20917,0.05740476,96.92659,1.0088700000000002
217.132,68.50917,0.05622304,96.89659,1.0084899999999999
218.097,68.80917,0.05641689,96.79182,1.0081
219.05499,69.10916999999999,0.05695495,96.78432,1.00771
220.02299,69.40916999999999,0.05801019,96.72431999999999,1.00731
220.972,69.70917,0.05975467,96.66455,1.00692
221.927,70.00917,0.05908895,96.59,1.00653
222.89101000000002,70.30917,0.0592847,96.51523,1.00613
223.842,70.60916999999999,0.05982519,96.45545,1.00573
224.808,70.90916999999999,0.06088399,96.39545,1.0053299999999998
225.76199,71.20917,0.05935526,96.27568000000001,1.0049299999999999
226.72701,71.50917,0.06024225,96.24591,1.00453
227.69501,71.80917,0.05802182,96.17114000000001,1.0041200000000001
228.662,72.10916999999999,0.05787269,96.07386,1.00371
229.618,72.40916999999999,0.05755043,95.98409000000001,1.0033100000000001
230.58299,72.70917,0.05809269,95.89432,1.00289
231.53101,73.00917,0.05638651,95.80455,1.0024899999999999
232.49899,73.30917,0.05606379,95.71477,1.00207
233.452,73.60916999999999,0.05937577,95.61023,1.00166
234.42101,73.90916999999999,0.05662971,95.49818,1.00125
235.383,74.20917,0.05734629,95.40091,1.0008299999999999
236.32899,74.50917,0.0568499,95.29614000000001,1.00042
237.297,74.80917,0.05635371,95.11659,1.0
238.27499,75.10916999999999,0.05707173,95.02682,0.9995700000000001
239.21899,75.40916999999999,0.05726895,94.93727,0.99915
240.18201000000002,75.70917,0.05764052,94.8175,0.9987299999999999
241.146,76.00917,0.05540716,94.69773,0.9983
242.104,76.30917,0.05699464,94.52591,0.9978799999999999
243.065,76.60916999999999,0.05562837,94.39864,0.99745
244.033,76.90916999999999,0.05478293,94.27159,0.99702
244.99001,77.20917,0.05463251,94.10205,0.99659
245.95,77.50917,0.05691902,93.93,0.99616
246.91,77.80917,0.0531127,93.77045,0.99572
247.869,78.10916999999999,0.05278743,93.59841,0.99529
248.834,78.40916999999999,0.05420502,93.40909,0.99485
249.778,78.70917,0.05370533,93.18955,0.9944200000000001
250.755,79.00917,0.05128721,93.0625,0.99398
251.70399,79.30917,0.05026253,92.84568,0.99354
252.66901000000001,79.60916999999999,0.05272941,92.62114,0.9931
253.62399,79.90916999999999,0.05013265,92.46682,0.99266
254.601,80.20917,0.05172832,92.1825,0.9922
255.558,80.50917,0.04930379,91.90590999999999,0.9917600000000001
256.53201,80.80917,0.0496762,91.73886,0.99131
257.48999,81.10916999999999,0.04724871,91.48455,0.9908600000000001
258.45401,81.40916999999999,0.0449943,91.23773,0.99041
259.396,81.70917,0.04606535,90.99840999999999,0.9899600000000001
260.36099,82.00917,0.0443342,90.67205,0.98951
261.31699,82.30917,0.04382854,90.4525,0.98905
262.28101000000004,82.60916999999999,0.04174408,90.21568,0.9886
263.23499,82.90916999999999,0.04088589,89.90409,0.98814
264.19,83.20917,0.04090477,89.585,0.98769
265.15601000000004,83.50917,0.03934319,89.31318,0.9872200000000001
266.104,83.80917,0.03953707,89.04659000000001,0.98677
267.07198999999997,84.10916999999999,0.03639131,88.7225,0.9863
268.03699,84.40916999999999,0.03394611,88.39568,0.9858399999999999
268.983,84.70917,0.03149835,88.09159,0.9853799999999999
269.94698999999997,85.00917,0.03186545,87.7775,0.9849100000000001
270.90398999999996,85.30917,0.03099988,87.46341,0.98444
271.86099,85.60916999999999,0.02995731,87.15432,0.9839700000000001
272.815,85.90916999999999,0.02750332,86.81773000000001,0.98351
273.763,86.20917,0.02628166,86.40159,0.9830399999999999
274.72,86.50917,0.02576487,86.13226999999999,0.98257
275.68201,86.80917,0.02383523,85.75841,0.98209
276.64898999999997,87.10916999999999,0.02490675,85.47681999999999,0.98161
277.60001,87.40916999999999,0.02244456,85.09273,0.98114
278.552,87.70917,0.02422358,84.76114,0.9806600000000001
279.526,88.00917,0.02494324,84.37477,0.9801799999999999
280.48599,88.30917,0.02566347,84.03591,0.97969
281.435,88.60916999999999,0.02425938,83.65432,0.9792200000000001
282.392,88.90916999999999,0.02444852,83.26545,0.9787299999999999
283.341,89.20917,0.02534678,82.91159,0.97825
284.297,89.50917,0.02447267,82.52773,0.97777
285.25,89.80917,0.02661393,82.12386,0.9772799999999999
286.20099,90.10916999999999,0.02485201,81.75976999999999,0.9768
287.16901,90.40916999999999,0.02735109,81.36091,0.9763
288.117,90.70917,0.02967479,80.95455,0.9758100000000001
289.07198999999997,91.00917,0.02968975,80.55068,0.9753200000000001
290.02301,91.30917,0.03006044,80.12205,0.97483
290.98901,91.60916999999999,0.03434699,79.75545,0.9743299999999999
291.94,91.90916999999999,0.03525466,79.32432,0.9738399999999999
292.892,92.20917,0.03616332,78.91318000000001,0.97334
293.84,92.50917,0.03582523,78.48182,0.97285
294.81201,92.80917,0.03958885,78.04318,0.97234
295.76501,93.10916999999999,0.04210709,77.59931999999999,0.9718399999999999
296.716,93.40916999999999,0.04248579,77.18045,0.97134
297.66699,93.70917,0.04482958,76.72431999999999,0.9708399999999999
298.63101,94.00917,0.04753359,76.25818000000001,0.9703299999999999
299.582,94.30917,0.0475583,75.77205,0.9698200000000001
300.53601000000003,94.60916999999999,0.05026643,75.34818,0.9693200000000001
301.491,94.90916999999999,0.05208261,74.88705,0.9688100000000001
302.43201,95.20917,0.05372128,74.40590999999999,0.96831
303.39499,95.50917,0.0564374,73.90977,0.9677899999999999
304.34201,95.80917,0.05754263,73.44386,0.9672799999999999
305.28101000000004,96.10916999999999,0.06080108,72.94023,0.96678
306.245,96.40916999999999,0.06298722,72.40682,0.96626
307.186,96.70917,0.06355906,71.87818,0.96575
308.14001,97.00917,0.06682668,71.36976999999999,0.9652299999999999
309.082,97.30917,0.06614321,70.82614000000001,0.96472
310.035,97.60916999999999,0.06905618,70.285,0.9642
311.00299,97.90916999999999,0.07143321,69.69205,0.96367
311.95099,98.20917,0.0738121,69.10614,0.96315
312.89898999999997,98.50917,0.07313151,68.54773,0.9626299999999999
313.85598999999996,98.80917,0.07695629,67.92205,0.9621
314.81,99.10916999999999,0.07988361,67.32864000000001,0.9615799999999999
315.77301,99.40916999999999,0.08227341,66.70545,0.96104
316.75299,99.70917,0.08448627,66.10455,0.9605
317.68301,100.00917,0.08687988,65.44136,0.9599799999999999
318.642,100.30917,0.09198854,64.79590999999999,0.95945
319.59601000000004,100.60916999999999,0.09330543,64.07045,0.9589200000000001
320.54098999999997,100.90916999999999,0.0982419,63.392269999999996,0.95839
321.491,101.20917,0.10029,62.659319999999994,0.95785
322.45001,101.50917,0.10432999999999999,61.89909,0.95731
323.39301,101.80917,0.10801,61.12386,0.95678
324.35199,102.10916999999999,0.11025,60.338640000000005,0.95624
325.32999,102.40916999999999,0.11302999999999999,59.541140000000006,0.9556899999999999
326.24799,102.70917,0.11527000000000001,58.770680000000006,0.95516
327.194,103.00917,0.11805999999999998,57.89818,0.95463
328.13101,103.30917,0.12104000000000001,57.013180000000006,0.95409
329.077,103.60916999999999,0.12529,56.14318000000001,0.95355
330.01099,103.90916999999999,0.12754000000000001,55.295680000000004,0.9530200000000001
330.97601000000003,104.20917,0.12907000000000002,54.36591,0.9524600000000001
331.91901,104.50917,0.13097,53.458180000000006,0.9519200000000001
332.85699,104.80917,0.13487000000000002,52.53614,0.9513799999999999
333.79401,105.10916999999999,0.1375,51.53886,0.95083
334.74399,105.40916999999999,0.13849,50.57909,0.9502799999999999
335.67899,105.70917,0.13784000000000002,49.60455,0.9497399999999999
336.617,106.00917,0.13902,48.602270000000004,0.94919
337.56699,106.30917,0.13745,47.61273,0.9486399999999999
338.51099,106.60916999999999,0.13863,46.59545,0.94809
339.45901000000003,106.90916999999999,0.13743,45.580909999999996,0.9475299999999999
340.409,107.20917,0.13477,44.583859999999994,0.9469700000000001
341.358,107.50917,0.13265,43.58659,0.94642
342.29999,107.80917,0.12796,42.58955,0.94586
343.24799,108.10916999999999,0.1207,41.61977,0.9453
344.181,108.40916999999999,0.11085999999999999,40.712270000000004,0.94475
345.12399,108.70917,0.10284000000000001,39.82227,0.94419
346.05701,109.00917,0.0931629,38.95727,0.94363
347.0,109.30917,0.0810835,38.16455,0.9430700000000001
347.94501,109.60916999999999,0.06623027,37.456590000000006,0.9425
348.896,109.90916999999999,0.0548571,36.71864,0.9419299999999999
349.82501,110.20917,0.0408909,36.18023,0.9413799999999999
350.776,110.50917,0.02801439,35.58705,0.94081
351.698,110.80917,0.01585961,35.133179999999996,0.94025
352.63101,111.10916999999999,0.005166691,34.749320000000004,0.9396899999999999
353.578,111.40916999999999,-0.005723756,34.40795,0.93911
354.51801,111.70917,-0.0157037,34.12614,0.9385399999999999
355.465,112.00917,-0.02125922,33.89932,0.9379700000000001
356.405,112.30917,-0.02682147,33.6925,0.9374
357.34601000000004,112.60916999999999,-0.0320204,33.47295,0.9368200000000001
358.28799,112.90916999999999,-0.03333651,33.36091,0.93625
359.23599,113.20917,-0.03780483,33.213640000000005,0.93566
360.16199,113.50917,-0.03912582,33.06409,0.9351
361.108,113.80917,-0.04100564,32.96682,0.9345100000000001
362.04401,114.10916999999999,-0.04288758,32.86977,0.93394
362.987,114.40916999999999,-0.04440055,32.7275,0.9333600000000001
363.92499,114.70917,-0.04665888,32.66795,0.9327700000000001
364.85999,115.00917,-0.04650188,32.54818,0.9322
365.802,115.30917,-0.05137033,32.45841,0.93161
366.73801000000003,115.60916999999999,-0.05065751,32.33886,0.9310299999999999
367.68301,115.90916999999999,-0.05404405,32.24909,0.9304399999999999
368.62701,116.20917,-0.05687549,32.17432,0.92985
369.573,116.50917,-0.05915089,32.05455,0.9292600000000001
370.50699,116.80917,-0.05956164,32.00977,0.9286700000000001
371.44501,117.10916999999999,-0.05941264,31.83773,0.9280799999999999
372.38599,117.40916999999999,-0.06132011,31.83023,0.9274899999999999
373.328,117.70917,-0.06135943,31.71045,0.92689
374.245,118.00917,-0.0643929,31.66568,0.9263100000000001
375.17899,118.30917,-0.06462135,31.53091,0.9257200000000001
376.13501,118.60916999999999,-0.06578831,31.501140000000003,0.92512
377.099,118.90916999999999,-0.06864524,31.359090000000002,0.9245
378.01099,119.20917,-0.07206651,31.291590000000003,0.9239200000000001
378.948,119.50917,-0.07286436,31.21705,0.92332
379.88501,119.80917,-0.07516666,31.17205,0.9227299999999999
380.819,120.10916999999999,-0.07502738,31.057270000000003,0.9221299999999999
381.763,120.40916999999999,-0.07695831,31.0125,0.9215200000000001
382.69101,120.70917,-0.07983242,30.88545,0.9209200000000001
383.63501,121.00917,-0.07818948,30.84068,0.92032
384.57901,121.30917,-0.08257752,30.743409999999997,0.91971
385.50601,121.60916999999999,-0.08168807,30.68341,0.91911
386.448,121.90916999999999,-0.08193109,30.61614,0.9185
387.37601,122.20917,-0.08292935,30.526359999999997,0.9179
388.31299,122.50917,-0.08430761,30.466590000000004,0.9172899999999999
389.27701,122.80917,-0.08493281,30.34705,0.91666
390.194,123.10916999999999,-0.08479897,30.28705,0.91606
391.11801,123.40916999999999,-0.08769601,30.24977,0.91546
392.06201,123.70917,-0.08870292,30.13,0.91484
392.983,124.00917,-0.08970981,30.07023,0.9142399999999999
393.92099,124.30917,-0.09166819,30.01795,0.9136200000000001
394.85001,124.60916999999999,-0.09381863,29.928179999999998,0.91301
395.79901,124.90916999999999,-0.09236257,29.875909999999998,0.91238
396.755,125.20917,-0.09280687,29.778640000000003,0.91175
397.681,125.50917,-0.09401108,29.71136,0.91114
398.62299,125.80917,-0.09331377,29.591820000000002,0.9105200000000001
399.54401,126.10916999999999,-0.0920425,29.53182,0.90991
400.483,126.40916999999999,-0.09248708,29.48682,0.90928
401.43399,126.70917,-0.08968912,29.44205,0.90865
402.34201,127.00917,-0.0899399,29.33,0.90804
403.271,127.30917,-0.08656187,29.32227,0.9074200000000001
404.198,127.60916999999999,-0.0854738,29.21773,0.9068
405.13599,127.90916999999999,-0.08228017,29.172729999999998,0.90617
406.05499,128.20917,-0.08654879,29.15045,0.90556
406.98499,128.50916999999998,-0.08488411,29.068179999999998,0.9049299999999999
407.918,128.80917,-0.08590183,29.015909999999998,0.9043
408.85199,129.10917,-0.08327544,28.918409999999998,0.9036700000000001
409.78699,129.40917,-0.08467781,28.828640000000004,0.90304
410.72198,129.70917,-0.08339218,28.784090000000003,0.90241
411.65201,130.00916999999998,-0.08075855,28.75409,0.9017799999999999
412.57501,130.30917,-0.08023748,28.66432,0.90115
413.50101,130.60917,-0.08221912,28.60432,0.9005200000000001
414.423,130.90917,-0.08015698,28.55227,0.89989
415.36301000000003,131.20917,-0.0796357,28.49977,0.89925
416.28299,131.50916999999998,-0.08065622,28.4325,0.8986200000000001
417.21799,131.80917,-0.08283776,28.395,0.8979799999999999
418.138,132.10917,-0.08019077,28.305229999999998,0.89735
419.04901,132.40917,-0.08082681,28.27545,0.8967200000000001
419.97299000000004,132.70917,-0.08107764,28.18068,0.8960899999999999
420.91,133.00916999999998,-0.07958696,28.135679999999997,0.89544
421.82599000000005,133.30917,-0.08022451,28.075909999999997,0.89481
422.75299,133.60917,-0.07970023,28.016140000000004,0.89417
423.68701,133.90917,-0.08208659,27.986140000000002,0.8935200000000001
424.61800999999997,134.20917,-0.0840879,27.866590000000002,0.8928799999999999
425.577,134.50916999999998,-0.0839563,27.866590000000002,0.8922100000000001
426.47699000000006,134.80917,-0.08557107,27.78432,0.89159
427.40799000000004,135.10917,-0.08446561,27.78432,0.89094
428.32401,135.40917,-0.08491574,27.724320000000002,0.8903
429.25,135.70917,-0.08634179,27.67977,0.88965
430.17801,136.00916999999998,-0.08562466,27.64227,0.889
431.09601,136.30917,-0.08373473,27.5525,0.88836
432.02399,136.60917,-0.08477278,27.5375,0.88771
432.94,136.90917,-0.08463882,27.4925,0.88707
433.85999000000004,137.20917,-0.08548309,27.39545,0.8864200000000001
434.78799000000004,137.50916999999998,-0.08378438,27.39545,0.88576
435.711,137.80917,-0.08600096,27.30568,0.8851100000000001
436.625,138.10917,-0.08704399,27.24591,0.8844700000000001
437.556,138.40917,-0.08553936,27.215909999999997,0.88381
438.46799000000004,138.70917,-0.08658364,27.133640000000003,0.8831600000000001
439.39499000000006,139.00916999999998,-0.08605875,27.12636,0.8825
440.32000999999997,139.30917,-0.08651617,27.096359999999997,0.88185
441.25201,139.60917,-0.08874584,27.036590000000004,0.88118
442.198,139.90917,-0.08763225,26.999090000000002,0.88051
443.09698,140.20917,-0.08868152,26.96909,0.87987
444.01800999999995,140.50916999999998,-0.08815628,26.939320000000002,0.87921
444.923,140.80917,-0.08664238,26.88705,0.87856
445.836,141.10917,-0.08710199,26.82705,0.8779100000000001
446.75600999999995,141.40917,-0.08894649,26.79727,0.87725
447.68399000000005,141.70917,-0.09217913,26.70727,0.8765799999999999
448.608,142.00916999999998,-0.08888381,26.7,0.8759100000000001
449.51199,142.30917,-0.09093105,26.64773,0.87526
450.42999000000003,142.60917,-0.09080168,26.58773,0.8746
451.38,142.90917,-0.09067461,26.55045,0.8739100000000001
452.27499000000006,143.20917,-0.09352178,26.52045,0.87326
453.203,143.50916999999998,-0.09538227,26.49045,0.87259
454.10699000000005,143.80917,-0.09664721,26.43068,0.8719399999999999
455.035,144.10917,-0.09612497,26.393179999999997,0.87126
455.94699,144.40917,-0.08942653,26.310909999999996,0.8706
456.858,144.70917,-0.08710292,26.28114,0.86993
457.77700999999996,145.00916999999998,-0.08477642,26.251140000000003,0.86926
458.69299,145.30917,-0.08504135,26.221140000000002,0.86859
459.61301,145.60917,-0.08091187,26.19136,0.86792
460.52399,145.90917,-0.07777514,26.11659,0.86725
461.43300999999997,146.20917,-0.07603417,26.071820000000002,0.86659
462.35900999999996,146.50916999999998,-0.07489239,26.071820000000002,0.8659100000000001
463.26901,146.80917,-0.07575192,25.98955,0.86524
464.17999000000003,147.10917,-0.07561012,26.00432,0.8645700000000001
465.08800999999994,147.40917,-0.07607013,25.92227,0.8639
465.99399000000005,147.70917,-0.07693253,25.862270000000002,0.8632299999999999
466.91199000000006,148.00916999999998,-0.07779714,25.8475,0.86255
467.832,148.30917,-0.08047399,25.8325,0.86187
468.742,148.60917,-0.08033565,25.765,0.8612
469.659,148.90917,-0.07939165,25.71273,0.8605200000000001
470.564,149.20917,-0.08308357,25.70545,0.8598399999999999
471.487,149.50916999999998,-0.08092993,25.64545,0.85916
472.39099000000004,149.80917,-0.07877162,25.61545,0.8584799999999999
473.30499000000003,150.10917,-0.07903633,25.56318,0.8578
474.21300999999994,150.40917,-0.07930112,25.55568,0.85713
475.12799,150.70917,-0.07997181,25.47341,0.85644
476.04099,151.00916999999998,-0.08165662,25.47341,0.8557600000000001
476.94299,151.30917,-0.08151837,25.41364,0.85508
477.85999000000004,151.60917,-0.08036632,25.38364,0.8544
478.77399,151.90917,-0.08124336,25.35364,0.8537100000000001
479.66500999999994,152.20917,-0.08151042,25.33136,0.8530399999999999
480.58300999999994,152.50916999999998,-0.08015247,25.26386,0.85235
481.479,152.80917,-0.08245555,25.23409,0.85167
482.38699,153.10917,-0.08191065,25.17432,0.8509899999999999
483.29501,153.40917,-0.08421986,25.196820000000002,0.8503
484.20800999999994,153.70917,-0.08530874,25.14205,0.8496100000000001
485.112,154.00916999999998,-0.0837435,25.07455,0.84893
486.02300999999994,154.30917,-0.08606027,25.07455,0.84824
486.927,154.60917,-0.08572076,25.04477,0.84755
487.84,154.90917,-0.08456246,25.014770000000002,0.8468600000000001
488.74701,155.20917,-0.08565599,24.985,0.8461700000000001
489.64499000000006,155.50916999999998,-0.08511001,24.925,0.8454799999999999
490.55399000000006,155.80917,-0.08600083,24.895229999999998,0.8447899999999999
491.465,156.10917,-0.08709877,24.895229999999998,0.8441
492.37201,156.40917,-0.0857312,24.83523,0.8434
493.27399,156.70917,-0.08497835,24.81273,0.8427100000000001
494.181,157.00916999999998,-0.08628401,24.77545,0.8420200000000001
495.08899,157.30917,-0.085531,24.73045,0.8413200000000001
495.98999000000003,157.60917,-0.08580762,24.71295,0.8406299999999999
496.89300999999995,157.90917,-0.0864978,24.66068,0.8399399999999999
497.81,158.20917,-0.08698371,24.60841,0.8392299999999999
498.715,158.50916999999998,-0.08788313,24.60841,0.8385299999999999
499.608,158.80917,-0.08774837,24.54841,0.83785
500.51099000000005,159.10917,-0.08802852,24.54114,0.83715
501.418,159.40917,-0.08499276,24.48864,0.83645
502.323,159.70917,-0.08630876,24.473860000000002,0.83575
503.233,160.00916999999998,-0.08700451,24.44386,0.83505
504.12299,160.30917,-0.08873898,24.41386,0.83436
505.034,160.60917,-0.08902219,24.38409,0.83365
505.91599,160.90917,-0.08867905,24.34659,0.83296
506.815,161.20917,-0.08750346,24.25705,0.8322700000000001
507.715,161.50916999999998,-0.08736863,24.286820000000002,0.8315600000000001
508.621,161.80917,-0.08619067,24.22705,0.83086
509.52700999999996,162.10917,-0.0856374,24.182270000000003,0.83015
510.44100999999995,162.40917,-0.08947398,24.167270000000002,0.82944
511.345,162.70917,-0.08955023,24.13727,0.82873
512.26703,163.00916999999998,-0.08962822,24.1075,0.82801
513.17902,163.30917,-0.08970558,24.0775,0.8273
514.08099,163.60917,-0.08684549,24.047729999999998,0.8265899999999999
514.979,163.90917,-0.08712952,24.01773,0.82589
515.883,164.20917,-0.08657408,23.98023,0.8251799999999999
516.77802,164.50916999999998,-0.08391392,23.93545,0.82447
517.67102,164.80917,-0.08356451,23.92795,0.8237700000000001
518.5579799999999,165.10917,-0.08426738,23.87545,0.8230700000000001
519.44598,165.40917,-0.08265233,23.86068,0.82237
520.33301,165.70917,-0.08715438,23.81568,0.8216700000000001
521.23901,166.00916999999998,-0.08532938,23.78591,0.82096
522.1270099999999,166.30917,-0.08709355,23.75591,0.82025
523.03302,166.60917,-0.08886237,23.73341,0.8195399999999999
523.93701,166.90917,-0.08724598,23.70364,0.81882
524.8319700000001,167.20917,-0.08710971,23.67364,0.81811
525.7310200000001,167.50916999999998,-0.08803427,23.643639999999998,0.8174
526.63397,167.80917,-0.08981013,23.598860000000002,0.8166800000000001
527.51599,168.10917,-0.08924983,23.57636,0.81598
528.4180299999999,168.40917,-0.08656349,23.55409,0.81526
529.302,168.70917,-0.08748981,23.51659,0.8145600000000001
530.1970200000001,169.00916999999998,-0.08799264,23.48659,0.81384
531.08398,169.30917,-0.08444411,23.47932,0.81314
531.966,169.60917,-0.08537106,23.419320000000003,0.81243
532.85999,169.90917,-0.08715515,23.38932,0.81172
533.758,170.20917,-0.08744619,23.35955,0.811
534.6779799999999,170.50916999999998,-0.0903077,23.32955,0.8102600000000001
535.57397,170.80917,-0.08567567,23.307270000000003,0.8095399999999999
536.46997,171.10917,-0.08575183,23.26977,0.80882
537.35797,171.40917,-0.08840234,23.24,0.80811
538.2529900000001,171.70917,-0.08826635,23.24,0.8073899999999999
539.13098,172.00916999999998,-0.09049312,23.21,0.8066800000000001
540.0360099999999,172.30917,-0.09014466,23.157729999999997,0.80596
540.92902,172.60917,-0.09087124,23.157729999999997,0.80524
541.8029799999999,172.90917,-0.08987325,23.15,0.80453
542.7130099999999,173.20917,-0.08973968,23.09023,0.8038
543.59497,173.50916999999998,-0.0878761,23.11273,0.80308
544.474,173.80917,-0.09249213,23.05295,0.80237
545.36401,174.10917,-0.08976338,23.05273,0.80165
546.25,174.40917,-0.08984381,23.02295,0.80094
547.15302,174.70917,-0.09360973,22.963179999999998,0.8002
548.0369900000001,175.00916999999998,-0.091308,22.93318,0.7994899999999999
548.91998,175.30917,-0.0920412,22.948179999999997,0.79877
549.82397,175.60917,-0.09190867,22.90341,0.79803
550.72302,175.90917,-0.09329784,22.89568,0.7973
551.612,176.20917,-0.09360028,22.86591,0.7965800000000001
552.51001,176.50916999999998,-0.09281484,22.85841,0.79585
553.40698,176.80917,-0.09246407,22.82841,0.7951199999999999
554.30402,177.10917,-0.0905848,22.835910000000002,0.79438
555.17902,177.40917,-0.08848164,22.80614,0.79367
556.06097,177.70917,-0.08681271,22.78364,0.79295
556.94598,178.00916999999998,-0.08601656,22.776139999999998,0.79222
557.8170200000001,178.30917,0.02891709,22.74614,0.79151
558.69397,178.60917,0.21356999999999998,22.71636,0.79079
559.578,178.90917,0.30001,22.68636,0.7900699999999999
560.466,179.20917,0.30556,22.70886,0.7893399999999999
561.35303,179.50916999999998,0.3109,22.67909,0.78861
562.2470099999999,179.80917,0.31669,22.64909,0.78788
563.12903,180.10917,0.31940999999999997,22.61909,0.78715
563.99298,180.40917,0.32145999999999997,22.61159,0.7864399999999999
564.8939799999999,180.70917,0.28844000000000003,22.58182,0.7857
565.7860099999999,181.00916999999998,0.32825,22.529320000000002,0.78496
566.66998,181.30917,0.33475,22.551820000000003,0.78423
567.55902,181.60917,0.3375,22.52205,0.7835
568.4500099999999,181.90917,0.3037,22.53705,0.78276
569.3319700000001,182.20917,0.3419,22.536820000000002,0.78203
570.21002,182.50916999999998,0.34731999999999996,22.47705,0.7813100000000001
571.099,182.80917,0.34609,22.44727,0.78057
571.992,183.10917,0.34953,22.432270000000003,0.77983
572.8770099999999,183.40917,0.34675,22.417270000000002,0.7791
573.77002,183.70917,0.3522,22.38727,0.77835
574.65302,184.00916999999998,0.35677,22.365,0.77762
575.54102,184.30917,0.35465,22.3275,0.77688
576.43597,184.60917,0.35902,22.334770000000002,0.7761399999999999
577.30603,184.90917,0.36046999999999996,22.31227,0.77541
578.1920200000001,185.20917,0.36417,22.31227,0.77468
579.07898,185.50916999999998,0.36586,22.314770000000003,0.77394
579.9619799999999,185.80917,0.36509,22.285,0.7732
580.85699,186.10917,0.36657,22.285,0.77245
581.73499,186.40917,0.33613000000000004,22.22523,0.77172
582.63202,186.70917,0.31801999999999997,22.21045,0.7709699999999999
583.51599,187.00916999999998,0.29829,22.18795,0.77023
584.40399,187.30917,0.30218,22.18795,0.76949
585.28998,187.60917,0.30518,22.18773,0.76875
586.17401,187.90917,0.31066,22.15795,0.7680100000000001
587.06097,188.20917,0.30803,22.15795,0.76726
587.93597,188.50916999999998,0.33026,22.14295,0.76653
588.80902,188.80917,0.32424000000000003,22.12795,0.7658
589.69098,189.10917,0.32252,22.13545,0.76505
590.57703,189.40917,0.37569,22.12068,0.76431
591.4619799999999,189.70917,0.37628,22.12068,0.76356
592.34601,190.00916999999998,0.3787,22.10545,0.7628199999999999
593.22498,190.30917,0.37679,22.13545,0.76208
594.09998,190.60917,0.37806,22.10545,0.76134
594.9970099999999,190.90917,0.37776,22.10568,0.76059
595.90399,191.20917,0.37951,22.09818,0.7598199999999999
596.77502,191.50916999999998,0.37462,22.053179999999998,0.75908
597.6619900000001,191.80917,0.37865,22.08318,0.75834
598.54602,192.10917,0.38154,22.023410000000002,0.75759
599.4180299999999,192.40917,0.38741,21.99341,0.75685
600.31897,192.70917,0.39055,21.97841,0.7560899999999999
601.18903,193.00916999999998,0.39139,21.97841,0.75535
602.078,193.30917,0.3927,21.94864,0.7546
602.95801,193.60917,0.39746,21.91864,0.75385
603.841,193.90917,0.39993,21.90364,0.7531
604.72699,194.20917,0.40448,21.93364,0.75235
605.61298,194.50916999999998,0.40765,21.95591,0.7516
606.49298,194.80917,0.40875,21.95591,0.75085
607.36902,195.10917,0.41262,21.940910000000002,0.7501
608.258,195.40917,0.41326999999999997,21.91114,0.74935
609.13098,195.70917,0.41577,21.92614,0.7486
609.992,196.00916999999998,0.41686999999999996,21.92614,0.74787
610.8779900000001,196.30917,0.41776,21.92614,0.74711
611.7689799999999,196.60917,0.42468999999999996,21.89636,0.74635
612.65399,196.90917,0.42581,21.86636,0.7456
613.53003,197.20917,0.42904,21.89614,0.74485
614.40802,197.50916999999998,0.43296,21.86636,0.7441
615.28302,197.80917,0.4376,21.89614,0.74335
616.18103,198.10917,0.43922,21.85114,0.74258
617.04102,198.40917,0.43755,21.873639999999998,0.74185
617.90399,198.70917,0.4415,21.84364,0.74111
618.78998,199.00916999999998,0.44288999999999995,21.85136,0.74035
619.66602,199.30917,0.4431,21.84386,0.7396
620.552,199.60917,0.44496,21.86636,0.7388399999999999
621.42902,199.90917,0.44401,21.85886,0.7380899999999999
622.29602,200.20917,0.44869,21.84386,0.73734
623.159,200.50916999999998,0.44748999999999994,21.84364,0.7366
624.03302,200.80917,0.45337,21.85864,0.73585
624.9060099999999,201.10917,0.45407,21.82886,0.7351
625.7810099999999,201.40917,0.45666,21.821360000000002,0.73435
626.659,201.70917,0.45973,21.80636,0.73359
627.54602,202.00916999999998,0.46707,21.80636,0.73283
628.42401,202.30917,0.47466,21.76886,0.73207
629.29102,202.60917,0.47823000000000004,21.79886,0.73132
630.159,202.90917,0.48085,21.76909,0.73058
631.0189799999999,203.20917,0.48063,21.76909,0.72983
631.89203,203.50916999999998,0.48373999999999995,21.754089999999998,0.7290800000000001
632.76703,203.80917,0.49091,21.754089999999998,0.72832
633.6270099999999,204.10917,0.49522,21.761589999999998,0.72758
634.49402,204.40917,0.50003,21.761589999999998,0.72683
635.3729900000001,204.70917,0.5039,21.746589999999998,0.72607
636.23798,205.00916999999998,0.50442,21.716820000000002,0.72532
637.10999,205.30917,0.50279,21.716820000000002,0.7245699999999999
637.98798,205.60917,0.5069100000000001,21.704320000000003,0.7238100000000001
638.8560200000001,205.90917,0.51103,21.67432,0.72306
639.72198,206.20917,0.51805,21.704320000000003,0.72231
640.62097,206.50916999999998,0.51981,21.689320000000002,0.72153
641.48901,206.80917,0.52179,21.681820000000002,0.72077
642.36298,207.10917,0.52812,21.65205,0.72001
643.23901,207.40917,0.53109,21.681820000000002,0.71925
644.104,207.70917,0.5340600000000001,21.66682,0.7185
644.99298,208.00916999999998,0.5385,21.67432,0.71773
645.85797,208.30917,0.53786,21.65182,0.7169800000000001
646.73901,208.60917,0.54013,21.65182,0.71621
647.6060200000001,208.90917,0.54579,21.62955,0.71546
648.487,209.20917,0.55147,21.62955,0.7146899999999999
649.34497,209.50916999999998,0.5535,21.62955,0.71394
650.21002,209.80917000000002,0.5582199999999999,21.63705,0.71319
650.5,209.90917000000002,0.5596300000000001,21.63705,0.71294