File: 02_Data/MDF/STA/N2/3K_min/MDF_STA_N2_3KData_210311_R2.csv
##Temp./Â°C,Time/min,DSC/(mW/mg),Mass/%,Sensit./(uV/mW)
48.864,10.00917,0.0237388,100.64979,1.05329
48.891,10.30917,0.02389105,100.6292,1.05329
48.944,10.609169999999999,0.02434772,100.65671999999999,1.05328
48.996,10.90917,0.027087,100.65671999999999,1.05328
49.083,11.20917,0.02952209,100.65671999999999,1.0532700000000002
49.209,11.50917,0.03469658,100.68445,1.05325
49.424,11.80917,0.03971946,100.70525,1.05322
49.662,12.109169999999999,0.04611239,100.69811,1.05319
49.952,12.40917,0.05220164,100.71197,1.05316
50.323,12.70917,0.05798748,100.71218,1.05311
50.705,13.00917,0.06255628,100.71218,1.05306
51.146,13.309170000000002,0.06864814,100.71197,1.05301
51.594,13.60917,0.07291408,100.71197,1.05295
52.122,13.909170000000001,0.07824688,100.75336,1.05288
52.633,14.20917,0.08038318,100.76744000000001,1.05281
53.21,14.509170000000001,0.08602225,100.73971,1.05274
53.771,14.809170000000002,0.08724638,100.76029,1.05267
54.379,15.10917,0.09151674,100.79517,1.05259
54.997,15.409170000000001,0.09274221,100.76723,1.0525
55.64,15.70917,0.09594811,100.7605,1.0524200000000001
56.307,16.00917,0.10037,100.77436999999999,1.05233
56.995,16.30917,0.1016,100.77416,1.05223
57.687,16.609170000000002,0.1039,100.7605,1.0521399999999999
58.384,16.90917,0.1068,100.7605,1.0520399999999999
59.122,17.20917,0.10772000000000001,100.73277,1.05193
59.862,17.50917,0.11048,100.78803,1.0518299999999998
60.599,17.80917,0.11155999999999999,100.7605,1.05172
61.387,18.109170000000002,0.11416,100.73277,1.05161
62.157,18.40917,0.116,100.73277,1.0515
62.938,18.70917,0.11769,100.7605,1.05138
63.717,19.00917,0.11999000000000001,100.76029,1.0512700000000001
64.532,19.30917,0.12153,100.78803,1.05114
65.358,19.609170000000002,0.12245999999999999,100.7605,1.05102
66.165,19.90917,0.12369000000000001,100.76029,1.0509
66.992,20.20917,0.12539,100.78803,1.05077
67.808,20.50917,0.12647,100.7605,1.05064
68.639,20.80917,0.12725,100.76029,1.05051
69.474,21.109170000000002,0.12909,100.7605,1.0503799999999999
70.329,21.40917,0.12942,100.7605,1.05024
71.158,21.70917,0.13126,100.76744000000001,1.05011
72.008,22.00917,0.13204000000000002,100.73971,1.04997
72.846,22.30917,0.13205999999999998,100.76723,1.0498299999999998
73.702,22.609170000000002,0.13284,100.76744000000001,1.04969
74.585,22.90917,0.1321,100.79517,1.04954
75.429,23.20917,0.13242,100.75336,1.0494
76.301,23.50917,0.13305,100.76723,1.04925
77.179,23.80917,0.13292,100.76744000000001,1.0491
78.036,24.109170000000002,0.13492,100.76723,1.0489600000000001
78.922,24.40917,0.13372,100.77416,1.0488
79.783,24.70917,0.13634000000000002,100.74664,1.04865
80.674,25.00917,0.13575,100.74664,1.04849
81.572,25.30917,0.13790999999999998,100.74664,1.04833
82.429,25.609170000000002,0.13716,100.73971,1.04818
83.323,25.90917,0.13902,100.7605,1.04801
84.205,26.20917,0.13751,100.76723,1.04785
85.098,26.50917,0.13692000000000001,100.76744000000001,1.04769
85.991,26.80917,0.13725,100.77436999999999,1.04752
86.874,27.109170000000002,0.13727,100.73971,1.04735
87.786,27.40917,0.13714,100.73971,1.04718
88.687,27.70917,0.13854,100.75357,1.04701
89.57,28.00917,0.13688,100.78109,1.04684
90.493,28.30917,0.13767000000000001,100.76723,1.0466600000000001
91.39,28.609170000000002,0.13815,100.80189,1.0464799999999999
92.3,28.90917,0.13985999999999998,100.75357,1.0463
93.211,29.20917,0.13835,100.74664,1.0461200000000002
94.114,29.50917,0.14006,100.74664,1.0459399999999999
95.046,29.80917,0.14039000000000001,100.77436999999999,1.04575
95.944,30.109170000000002,0.14165,100.77416,1.04557
96.857,30.40917,0.1409,100.80189,1.04538
97.768,30.70917,0.142,100.77416,1.04519
98.7,31.00917,0.14234000000000002,100.78803,1.045
99.604,31.30917,0.14236,100.81576,1.04481
100.528,31.609170000000002,0.14469,100.82269000000001,1.04461
101.439,31.90917,0.14625,100.82269000000001,1.0444200000000001
102.366,32.20917,0.14858,100.77436999999999,1.0442200000000001
103.281,32.509170000000005,0.14999,100.8021,1.0440200000000002
104.203,32.80917,0.15125,100.81576,1.04382
105.121,33.10917,0.15066,100.81576,1.04362
106.049,33.40917,0.15145999999999998,100.83655,1.04342
106.974,33.70917,0.14965,100.82961999999999,1.04321
107.895,34.009170000000005,0.15152000000000002,100.80189,1.043
108.825,34.30917,0.15078,100.82961999999999,1.0427899999999999
109.76,34.60917,0.1522,100.80882,1.0425799999999998
110.683,34.90917,0.15192,100.83634,1.04237
111.61,35.20917,0.15149,100.83634,1.04216
112.539,35.509170000000005,0.15106,100.81576,1.0419399999999999
113.474,35.80917,0.15278,100.84349,1.04172
114.405,36.10917,0.15297,100.84349,1.04151
115.333,36.40917,0.15377000000000002,100.83634,1.04129
116.26,36.70917,0.1535,100.84349,1.0410700000000002
117.187,37.009170000000005,0.15507,100.81576,1.04084
118.114,37.30917,0.15403,100.86429,1.04062
119.073,37.60917,0.15375,100.87101,1.04039
119.981,37.90917,0.15502,100.89180999999999,1.04016
120.923,38.20917,0.1569,100.86408,1.03993
121.841,38.509170000000005,0.15447,100.87122,1.0397100000000001
122.767,38.80917,0.15389,100.87122,1.0394700000000001
123.705,39.10917,0.15531,100.87101,1.03924
124.628,39.40917,0.1555,100.87101,1.03901
125.579,39.70917,0.15615,100.89874,1.0387600000000001
126.513,40.009170000000005,0.1568,100.87101,1.03853
127.447,40.30917,0.15684,100.89874,1.03829
128.37801000000002,40.60917,0.15811,100.89874,1.03805
129.313,40.90917,0.15753,100.90567,1.0378
130.24698999999998,41.20917,0.15803,100.9334,1.03756
131.17101,41.509170000000005,0.15869,100.93319,1.03731
132.123,41.80917,0.15934,100.93319,1.03706
133.056,42.10917,0.15861,100.90545999999999,1.03681
133.991,42.40917,0.16035,100.96092,1.03656
134.93401,42.70917,0.15915,100.95399,1.03631
135.871,43.009170000000005,0.16074000000000002,100.98151,1.03605
136.817,43.30917,0.16155,100.96786,1.0358
137.76199,43.60917,0.16237000000000001,100.95399,1.03554
138.69901000000002,43.90917,0.16008,100.95399,1.03528
139.64799,44.20917,0.15980999999999998,100.98151,1.03501
140.589,44.509170000000005,0.16063,100.98151,1.03475
141.534,44.80917,0.16021,100.98845,1.03449
142.474,45.10917,0.1618,100.98172,1.0342200000000001
143.43201000000002,45.40917,0.16199000000000002,101.03004,1.03395
144.367,45.70917,0.16343,101.01618,1.03368
145.327,46.009170000000005,0.16379000000000002,100.98845,1.03341
146.27499,46.30917,0.16398,101.00231,1.0331299999999999
147.23599,46.60917,0.1631,101.01618,1.03285
148.17,46.90917,0.1633,101.01639,1.0325799999999998
149.123,47.20917,0.16427,101.00924,1.0323
150.077,47.509170000000005,0.16416,101.03697,1.0320200000000002
151.069,47.80917,0.16421,101.03004,1.03173
151.98199,48.10917,0.16472,100.99538000000001,1.03145
152.94501,48.40917,0.1629,101.01618,1.0311700000000001
153.896,48.70917,0.16403,101.03004,1.03088
154.842,49.009170000000005,0.16454000000000002,100.98866,1.03059
155.783,49.30917,0.16505999999999998,101.01618,1.03031
156.743,49.60917,0.16526,101.05084000000001,1.03001
157.7,49.90917,0.16733,101.03697,1.02972
158.647,50.20917,0.16831,101.05776999999999,1.02942
159.62,50.509170000000005,0.16727,101.06470999999999,1.02912
160.569,50.80917,0.1681,101.09223,1.02883
161.5,51.10917,0.16860999999999998,101.10609000000001,1.02853
162.45598999999999,51.40917,0.16757,101.08529,1.02823
163.41298999999998,51.70917,0.16871,101.08529,1.02793
164.371,52.009170000000005,0.16798,101.13382,1.02762
165.336,52.30917,0.16990999999999998,101.07164,1.02731
166.291,52.60917,0.16902,101.09223,1.02701
167.241,52.909169999999996,0.17079,101.12689,1.0267
168.189,53.20916999999999,0.171,101.09916,1.02639
169.14799,53.50917,0.17245,101.11303000000001,1.0260799999999999
170.103,53.809169999999995,0.17063,101.08529,1.02576
171.069,54.10917,0.17412,101.11303000000001,1.02544
172.024,54.409169999999996,0.17152,101.11303000000001,1.0251299999999999
172.99001,54.70916999999999,0.17314000000000002,101.13361,1.02481
173.94298999999998,55.00917,0.17365999999999998,101.11303000000001,1.02449
174.914,55.309169999999995,0.17372,101.11303000000001,1.02416
175.873,55.60917,0.17565,101.14076,1.0238399999999999
176.814,55.909169999999996,0.17414000000000002,101.12689,1.02352
177.789,56.20916999999999,0.17465999999999998,101.12689,1.02319
178.739,56.50917,0.17456,101.09916,1.02286
179.70598999999999,56.809169999999995,0.17321,101.12668000000001,1.02253
180.66701,57.10917,0.17515,101.11975,1.0222
181.62,57.409169999999996,0.17332,101.09916,1.02187
182.567,57.70916999999999,0.17542,101.09223,1.02154
183.533,58.00917,0.17406,101.09916,1.0212
184.481,58.309169999999995,0.17443,101.10609000000001,1.02086
185.444,58.60917,0.17432999999999998,101.10609000000001,1.02052
186.40601,58.909169999999996,0.17644,101.11303000000001,1.0201799999999999
187.383,59.20916999999999,0.17665,101.09223,1.01983
188.332,59.50917,0.17451,101.09223,1.01949
189.29201,59.809169999999995,0.17551,101.09223,1.01915
190.242,60.10917,0.17683,101.08529,1.0188
191.2,60.409169999999996,0.17705,101.07143,1.0184600000000001
192.16701,60.70916999999999,0.179,101.05063,1.01811
193.12801000000002,61.00917,0.17859,101.02311,1.01775
194.08501,61.309169999999995,0.17723,101.05084000000001,1.0174
195.052,61.60917,0.17698,101.0437,1.01704
196.01199,61.909169999999996,0.17925,101.03697,1.0166899999999999
196.981,62.20916999999999,0.17805,101.01618,1.01633
197.942,62.50917,0.17827,101.00251999999999,1.01597
198.909,62.809169999999995,0.17833,100.94706,1.0156100000000001
199.879,63.10917,0.17665999999999998,100.96092,1.01524
200.839,63.409169999999996,0.1772,100.91933,1.01488
201.799,63.70916999999999,0.17774,100.87122,1.01451
202.77901,64.00917,0.17812,100.87794,1.01414
203.729,64.30917,0.17770999999999998,100.87794,1.01378
204.694,64.60916999999999,0.17951,100.85735,1.0134
205.64799,64.90916999999999,0.17879,100.82961999999999,1.01304
206.608,65.20917,0.17964000000000002,100.8021,1.0126600000000001
207.58299,65.50917,0.1794,100.77436999999999,1.0122799999999998
208.55098999999998,65.80917,0.17915,100.77436999999999,1.01191
209.50301000000002,66.10916999999999,0.18016,100.73277,1.0115299999999998
210.48398999999998,66.40916999999999,0.1796,100.67752,1.01115
211.455,66.70917,0.17967,100.66366,1.01076
212.409,67.00917,0.17926,100.62899,1.0103799999999998
213.37198999999998,67.30917,0.17948,100.58067,1.01
214.319,67.60916999999999,0.18003,100.58067,1.00962
215.285,67.90916999999999,0.18025,100.53235,1.0092299999999998
216.241,68.20917,0.17874,100.49076,1.00885
217.22,68.50917,0.17881,100.4563,1.00845
218.17999,68.80917,0.17808,100.40084,1.00806
219.142,69.10916999999999,0.17672000000000002,100.34559,1.00767
220.106,69.40916999999999,0.17567,100.31806999999999,1.00728
221.078,69.70917,0.17511,100.24181,1.00688
222.037,70.00917,0.17549,100.15881999999999,1.0064799999999998
222.99698999999998,70.30917,0.17715999999999998,100.10356999999999,1.0060799999999999
223.96001,70.60916999999999,0.17515,100.03466,1.00568
224.92999,70.90916999999999,0.17602,99.99306999999999,1.00528
225.886,71.20917,0.17609,99.93088,1.00488
226.843,71.50917,0.17473,99.87563,1.0044799999999998
227.81599,71.80917,0.17415999999999998,99.76491999999999,1.00407
228.786,72.10916999999999,0.17551,99.7166,1.00366
229.73199,72.40916999999999,0.1759,99.65441,1.00326
230.696,72.70917,0.17549,99.57143,1.00285
231.66,73.00917,0.17684,99.48151,1.00243
232.617,73.30917,0.17675,99.39874,1.0020200000000001
233.576,73.60916999999999,0.17539000000000002,99.31555,1.0016100000000001
234.52299,73.90916999999999,0.17418,99.20504,1.0012
235.485,74.20917,0.17409000000000002,99.14979,1.00079
236.442,74.50917,0.1756,99.05063,1.00037
237.39799,74.80917,0.17359000000000002,98.90545999999999,0.99995
238.356,75.10916999999999,0.17463,98.82248,0.9995299999999999
239.31599,75.40916999999999,0.17438,98.71176,0.99911
240.27299,75.70917,0.17622000000000002,98.58067,0.99869
241.23,76.00917,0.17806,98.44937,0.9982700000000001
242.19901000000002,76.30917,0.1775,98.33866,0.99784
243.146,76.60916999999999,0.1787,98.17269,0.99741
244.12198999999998,76.90916999999999,0.18006,98.03214,0.99698
245.075,77.20917,0.18158,97.89390999999999,0.99655
246.03999,77.50917,0.18424000000000001,97.75567,0.9961200000000001
247.002,77.80917,0.1877,97.58971,0.9956799999999999
247.95598999999999,78.10916999999999,0.18859,97.41681,0.99525
248.91901000000001,78.40916999999999,0.19510999999999998,97.24853,0.9948100000000001
249.88,78.70917,0.20035999999999998,97.06891,0.9943799999999999
250.849,79.00917,0.20109000000000002,96.90294,0.99393
251.81,79.30917,0.1986,96.70714,0.99349
252.771,79.60916999999999,0.2003,96.52038,0.99305
253.72501,79.90916999999999,0.20055,96.31996,0.99261
254.688,80.20917,0.20064,96.05735,0.99216
255.65401,80.50917,0.20040999999999998,95.84769,0.9917100000000001
256.608,80.80917,0.20131,95.61723,0.9912700000000001
257.57401,81.10916999999999,0.20205,95.37059,0.99082
258.53201,81.40916999999999,0.20214000000000001,95.10798,0.9903700000000001
259.49701,81.70917,0.20207,94.87521,0.9899100000000001
260.46301,82.00917,0.19941,94.61239,0.98946
261.42401,82.30917,0.19869,94.34286,0.989
262.37799,82.60916999999999,0.20008,94.0916,0.98855
263.32901,82.90916999999999,0.20033,93.79685,0.9881
264.29501,83.20917,0.20237,93.51555,0.98764
265.263,83.50917,0.20328,93.28298000000001,0.9871700000000001
266.245,83.80917,0.20663,92.91408,0.9867
267.17099,84.10916999999999,0.20623000000000002,92.63067,0.98625
268.13599,84.40916999999999,0.20893,92.32185,0.9857899999999999
269.10199,84.70917,0.20919000000000001,92.02017,0.9853200000000001
270.052,85.00917,0.21141,91.71134,0.9848600000000001
271.02301,85.30917,0.2159,91.40252,0.9843799999999999
271.98001,85.60916999999999,0.22057,91.06618,0.9839200000000001
272.944,85.90916999999999,0.2241,90.7458,0.98344
273.892,86.20917,0.22746999999999998,90.41408,0.98298
274.867,86.50917,0.23035,90.04517,0.98249
275.832,86.80917,0.23306999999999997,89.69958000000001,0.9820200000000001
276.78201,87.10916999999999,0.23498000000000002,89.38866,0.98155
277.745,87.40916999999999,0.23901999999999998,89.02668,0.9810700000000001
278.685,87.70917,0.24028000000000002,88.65126,0.9806
279.65601000000004,88.00917,0.24416,88.28466,0.98011
280.62299,88.30917,0.24722,87.95063,0.97962
281.58499,88.60916999999999,0.24833000000000002,87.54055,0.97914
282.55399,88.90916999999999,0.25058,87.19937,0.97865
283.51198999999997,89.20917,0.25497,86.80756,0.9781700000000001
284.46799,89.50917,0.25575,86.44349,0.9776799999999999
285.427,89.80917,0.2562,86.04496,0.97719
286.379,90.10916999999999,0.26175,85.66029,0.9767
287.33801,90.40916999999999,0.26073,85.25231,0.97621
288.298,90.70917,0.26266999999999996,84.85146999999999,0.97572
289.25699,91.00917,0.26379,84.47794,0.9752299999999999
290.215,91.30917,0.26721,84.08381999999999,0.9747299999999999
291.17499,91.60916999999999,0.268,83.65987,0.97424
292.12601,91.90916999999999,0.27242,83.28193,0.9737399999999999
293.07599,92.20917,0.27255999999999997,82.83277,0.97325
294.03699,92.50917,0.27599,82.43655,0.97275
294.991,92.80917,0.27795,81.99853,0.97225
295.94,93.10916999999999,0.27892,81.57226999999999,0.97175
296.897,93.40916999999999,0.28319,81.13214,0.97124
297.85001,93.70917,0.28548,80.68276999999999,0.9707399999999999
298.80099,94.00917,0.28695,80.21282,0.97024
299.74399,94.30917,0.28925,79.79328000000001,0.9697399999999999
300.68701,94.60916999999999,0.29369,79.27731,0.96924
301.64401000000004,94.90916999999999,0.29683000000000004,78.85084,0.96873
302.599,95.20917,0.30112,78.34391,0.9682200000000001
303.54501,95.50917,0.30161,77.86933,0.9677100000000001
304.495,95.80917,0.30326,77.37836,0.9672
305.47198,96.10916999999999,0.30706999999999995,76.8645,0.96667
306.396,96.40916999999999,0.30956,76.34832,0.9661700000000001
307.33499,96.70917,0.31171,75.80672,0.96567
308.29098999999997,97.00917,0.3152,75.29769,0.96515
309.22699,97.30917,0.31869000000000003,74.75147,0.9646399999999999
310.17599,97.60916999999999,0.32318,74.22143,0.9641200000000001
311.12399,97.90916999999999,0.32652,73.62689,0.9636
312.08499,98.20917,0.32936,73.05546,0.9630799999999999
313.04199,98.50917,0.3327,72.46555,0.96255
313.995,98.80917,0.33555,71.89180999999999,0.9620299999999999
314.939,99.10916999999999,0.3389,71.25336,0.9615
315.89001,99.40916999999999,0.34375,70.67059,0.96098
316.836,99.70917,0.34310999999999997,70.04139,0.96045
317.78101000000004,100.00917,0.34947,69.38235,0.95993
318.737,100.30917,0.3515,68.68403,0.9594
319.67899,100.60916999999999,0.35420999999999997,68.00441,0.9588700000000001
320.617,100.90916999999999,0.35808,67.29916,0.95834
321.564,101.20917,0.36246,66.57101,0.95781
322.51001,101.50917,0.36517,65.85441,0.9572799999999999
323.47501,101.80917,0.37041,65.09622,0.9567399999999999
324.42099,102.10916999999999,0.37313,64.33361,0.9562
325.36401,102.40916999999999,0.37787,63.53634,0.95567
326.32401,102.70917,0.38077,62.71597,0.9551200000000001
327.259,103.00917,0.38434,61.881719999999994,0.9545899999999999
328.20401,103.30917,0.38606999999999997,61.01996,0.95405
329.147,103.60916999999999,0.39049,60.16029,0.9535100000000001
330.09,103.90916999999999,0.39323,59.2687,0.9529700000000001
331.03799,104.20917,0.3943,58.38381999999999,0.9524299999999999
331.97501,104.50917,0.39654,57.45966,0.95189
332.914,104.80917,0.40266,56.54265,0.95134
333.86401,105.10916999999999,0.40543,55.560919999999996,0.9507899999999999
334.798,105.40916999999999,0.40667,54.581509999999994,0.95025
335.73999,105.70917,0.40589000000000003,53.606930000000006,0.94971
336.685,106.00917,0.40646,52.625209999999996,0.94915
337.638,106.30917,0.40552,51.625209999999996,0.9486
338.58099,106.60916999999999,0.40457,50.638870000000004,0.94805
339.521,106.90916999999999,0.4021,49.638870000000004,0.9475
340.45401,107.20917,0.39844,48.65252,0.94695
341.39999,107.50917,0.39241,47.650209999999994,0.94639
342.35901,107.80917,0.38519000000000003,46.67773,0.94583
343.28601000000003,108.10916999999999,0.37863,45.73298,0.9452799999999999
344.22699,108.40916999999999,0.36613,44.81597,0.9447200000000001
345.16501,108.70917,0.35836,43.9334,0.94416
346.103,109.00917,0.34567,43.0645,0.9436
347.05701,109.30917,0.33177,42.21891,0.94304
347.98999,109.60916999999999,0.31785,41.5021,0.9424799999999999
348.923,109.90916999999999,0.30255,40.829409999999996,0.9419200000000001
349.88,110.20917,0.28758,40.18424,0.94134
350.819,110.50917,0.2714,39.64748,0.94078
351.75201,110.80917,0.25435,39.17038,0.9402200000000001
352.68799,111.10916999999999,0.23949,38.762609999999995,0.93965
353.61499,111.40916999999999,0.22426999999999997,38.40756,0.93909
354.55899,111.70917,0.21381999999999998,38.11954,0.93852
355.5,112.00917,0.20404,37.88697,0.93795
356.423,112.30917,0.19219,37.66345,0.9373799999999999
357.35699,112.60916999999999,0.18461,37.50441,0.93681
358.29199,112.90916999999999,0.17685,37.33613,0.93624
359.22101000000004,113.20917,0.16976,37.17248,0.9356700000000001
360.155,113.50917,0.16215,37.02962,0.9351
361.08898999999997,113.80917,0.15693,36.91891,0.93453
362.01999,114.10916999999999,0.15222,36.83613,0.93395
362.94601,114.40916999999999,0.1451,36.71155,0.9333799999999999
363.879,114.70917,0.1409,36.62878,0.9328
364.81601,115.00917,0.13652,36.51807,0.93222
365.74301,115.30917,0.1292,36.40735,0.93165
366.677,115.60916999999999,0.12498,36.303779999999996,0.9310700000000001
367.60199,115.90916999999999,0.12195999999999999,36.19307,0.9304899999999999
368.526,116.20917,0.11927,36.110079999999996,0.92991
369.453,116.50917,0.11710999999999999,35.99937,0.9293299999999999
370.397,116.80917,0.10942,35.95798,0.92874
371.32101,117.10916999999999,0.10740999999999999,35.81975,0.92816
372.25699,117.40916999999999,0.10558,35.73676,0.9275700000000001
373.177,117.70917,0.1015,35.626259999999995,0.92699
374.117,118.00917,0.09896533,35.543279999999996,0.9264
375.04401,118.30917,0.09296866,35.46723,0.92581
375.97,118.60916999999999,0.09077561,35.363659999999996,0.92522
376.90302,118.90916999999999,0.08771357,35.25294,0.92463
377.832,119.20917,0.08325981,35.19769,0.92404
378.75101,119.50917,0.08070914,35.09391,0.92345
379.69101,119.80917,0.07485652,35.01113,0.92285
380.617,120.10916999999999,0.07247154,34.94874,0.9222600000000001
381.539,120.40916999999999,0.06990948,34.83824,0.9216700000000001
382.46701,120.70917,0.0664744,34.76218,0.92107
383.41901,121.00917,0.06529973,34.672270000000005,0.9204600000000001
384.34398999999996,121.30917,0.06116018,34.589290000000005,0.91986
385.276,121.60916999999999,0.05614382,34.54097,0.9192600000000001
386.21799,121.90916999999999,0.05513422,34.43718,0.91865
387.14001,122.20917,0.05202753,34.375,0.91805
388.061,122.50917,0.05048913,34.29895,0.91745
388.99301,122.80917,0.04685134,34.20903,0.91685
389.93399,123.10916999999999,0.04513335,34.139920000000004,0.9162299999999999
390.86301000000003,123.40916999999999,0.04148717,34.04307,0.9156299999999999
391.78299,123.70917,0.04203996,33.953359999999996,0.9150200000000001
392.70901000000003,124.00917,0.03803635,33.9187,0.9144200000000001
393.64099,124.30917,0.03630782,33.79433,0.91381
394.57001,124.60916999999999,0.03440142,33.73908,0.91319
395.50201,124.90916999999999,0.0321413,33.649159999999995,0.91258
396.43799,125.20917,0.03146005,33.57311,0.91196
397.367,125.50917,0.03042601,33.50399,0.91135
398.29999,125.80917,0.02604685,33.44853,0.9107299999999999
399.224,126.10916999999999,0.02236604,33.365759999999995,0.91012
400.155,126.40916999999999,0.02255748,33.26891,0.9095
401.08499,126.70917,0.02080934,33.24811,0.9088799999999999
402.01599,127.00917,0.01817649,33.158190000000005,0.9082600000000001
402.94501,127.30917,0.01589323,33.06155,0.90764
403.875,127.60916999999999,0.014137,33.02689,0.90702
404.80399,127.90916999999999,0.0120247,32.93025,0.9064
405.733,128.20917,0.01026342,32.875,0.9057700000000001
406.65302,128.50916999999998,0.008676747,32.80588,0.90515
407.59,128.80917,0.007973999,32.75042,0.9045200000000001
408.509,129.10917,0.006915538000000001,32.70903,0.9039
409.44901,129.40917,0.005855722,32.62605,0.90327
410.38101,129.70917,0.003196262,32.58466,0.90264
411.31299,130.00916999999998,0.0021323329999999997,32.50861,0.9020100000000001
412.23801000000003,130.30917,0.001066909,32.4395,0.90138
413.16299,130.60917,-0.0005338271,32.37017,0.90075
414.08301,130.90917,-0.0005341987000000001,32.30105,0.90012
415.01401,131.20917,-0.0012473439999999998,32.23193,0.89949
415.95099,131.50916999999998,-0.004992928,32.17668,0.89885
416.875,131.80917,-0.008743774000000001,32.135290000000005,0.89822
417.81,132.10917,-0.008928588000000001,32.07983,0.8975700000000001
418.73499,132.40917,-0.01054319,32.02458,0.89694
419.655,132.70917,-0.01269652,31.96933,0.89631
420.582,133.00916999999998,-0.01270557,31.893279999999997,0.8956700000000001
421.51599000000004,133.30917,-0.01593816,31.83088,0.89502
422.45099000000005,133.60917,-0.01612888,31.810290000000002,0.89438
423.36499000000003,133.90917,-0.01847167,31.76197,0.89375
424.28799000000004,134.20917,-0.01722864,31.706509999999998,0.8931100000000001
425.26099000000005,134.50916999999998,-0.02083369,31.637390000000003,0.89243
426.146,134.80917,-0.02156695,31.609659999999998,0.8918200000000001
427.078,135.10917,-0.02194236,31.554409999999997,0.89117
428.00699000000003,135.40917,-0.02393817,31.499159999999996,0.8905200000000001
428.939,135.70917,-0.02485626,31.43004,0.88987
429.87799,136.00916999999998,-0.02811912,31.353990000000003,0.8892100000000001
430.79400999999996,136.30917,-0.02813942,31.34013,0.8885700000000001
431.71700999999996,136.60917,-0.03267274,31.26408,0.88792
432.638,136.90917,-0.03197399,31.26408,0.88728
433.54400999999996,137.20917,-0.03398548,31.188240000000004,0.88664
434.46200999999996,137.50916999999998,-0.03563843,31.13277,0.8859899999999999
435.38500999999997,137.80917,-0.0378371,31.125840000000004,0.88534
436.31799,138.10917,-0.04076407,31.08445,0.8846799999999999
437.24899000000005,138.40917,-0.04478325,31.03613,0.88403
438.173,138.70917,-0.04427208,30.97395,0.8833700000000001
439.08499000000006,139.00916999999998,-0.04321508,30.94622,0.8827200000000001
440.009,139.30917,-0.04433751,30.890970000000003,0.88207
440.92801,139.60917,-0.04837103,30.83571,0.88141
441.84399,139.90917,-0.04895282,30.80798,0.88076
442.76099000000005,140.20917,-0.05172095,30.76639,0.8801100000000001
443.69100999999995,140.50916999999998,-0.05358256,30.7042,0.87944
444.61899000000005,140.80917,-0.05398783,30.66975,0.8787799999999999
445.52700999999996,141.10917,-0.05439288,30.64895,0.87813
446.45000999999996,141.40917,-0.05644324,30.5937,0.8774700000000001
447.37201,141.70917,-0.05995913,30.56597,0.8768
448.28299000000004,142.00916999999998,-0.0596381,30.52458,0.87615
449.203,142.30917,-0.06316173,30.45525,0.8754799999999999
450.125,142.60917,-0.06412583,30.4416,0.87482
451.05499000000003,142.90917,-0.06545862,30.38634,0.87415
451.96300999999994,143.20917,-0.06514086,30.35861,0.87349
452.88100999999995,143.50916999999998,-0.06574139,30.33782,0.8728299999999999
453.797,143.80917,-0.0685481,30.26176,0.87216
454.715,144.10917,-0.07025579,30.24097,0.87149
455.62600999999995,144.40917,-0.07325413,30.19265,0.8708299999999999
456.543,144.70917,-0.07459973,30.137390000000003,0.87016
457.457,145.00916999999998,-0.07502559,30.12353,0.8695
458.38,145.30917,-0.07619068,30.08193,0.86882
459.29099,145.60917,-0.07717224,30.005879999999998,0.86816
460.207,145.90917,-0.07834049,29.99202,0.86749
461.146,146.20917,-0.08191603,29.97836,0.8668
462.05499000000003,146.50916999999998,-0.08382968,29.9229,0.86613
462.966,146.80917,-0.08778369,29.89538,0.86546
463.88100999999995,147.10917,-0.08748135,29.860709999999997,0.86479
464.79199000000006,147.40917,-0.08977514,29.81239,0.8641200000000001
465.70800999999994,147.70917,-0.09337239,29.7916,0.86344
466.62,148.00916999999998,-0.09400263,29.736340000000002,0.86277
467.54099,148.30917,-0.09946867,29.729409999999998,0.8620899999999999
468.44,148.60917,-0.10066,29.688029999999998,0.8614200000000001
469.35500999999994,148.90917,-0.10390999999999999,29.68109,0.86074
470.26901,149.20917,-0.10455,29.59811,0.86006
471.18300999999997,149.50916999999998,-0.10612,29.577309999999997,0.8593799999999999
472.09698,149.80917,-0.10901,29.542859999999997,0.8587
473.008,150.10917,-0.10984000000000001,29.508190000000003,0.8580200000000001
473.922,150.40917,-0.11217,29.508190000000003,0.85734
474.82000999999997,150.70917,-0.11394000000000001,29.43908,0.85667
475.73801,151.00916999999998,-0.11402999999999999,29.41828,0.8559899999999999
476.65799000000004,151.30917,-0.11619000000000002,29.390759999999997,0.8553
477.57199,151.60917,-0.12097000000000001,29.376890000000003,0.8546100000000001
478.48999000000003,151.90917,-0.12125,29.30084,0.8539200000000001
479.39300999999995,152.20917,-0.12304000000000001,29.280040000000003,0.85324
480.30499000000003,152.50916999999998,-0.12502,29.252309999999998,0.85256
481.21899,152.80917,-0.1255,29.217859999999998,0.8518700000000001
482.11499000000003,153.10917,-0.12729000000000001,29.19013,0.85119
483.05301,153.40917,-0.13022999999999998,29.162609999999997,0.8504799999999999
483.94,153.70917,-0.13203,29.134870000000003,0.8498100000000001
484.85699000000005,154.00916999999998,-0.13232,29.093490000000003,0.8491200000000001
485.77802,154.30917,-0.13355999999999998,29.07269,0.8484200000000001
486.67400999999995,154.60917,-0.13348,29.044959999999996,0.8477399999999999
487.59,154.90917,-0.13775,28.98971,0.84705
488.48900999999995,155.20917,-0.14032999999999998,28.98971,0.84636
489.392,155.50916999999998,-0.14215,28.982979999999998,0.8456799999999999
490.298,155.80917,-0.14359,28.92752,0.84499
491.20999000000006,156.10917,-0.14352,28.92752,0.84429
492.108,156.40917,-0.14497000000000002,28.87227,0.8436
493.01901,156.70917,-0.14604,28.844540000000002,0.84291
493.936,157.00916999999998,-0.14806,28.83067,0.84221
494.83401,157.30917,-0.15085,28.77542,0.84152
495.737,157.60917,-0.15192999999999998,28.76176,0.8408200000000001
496.642,157.90917,-0.15282,28.706509999999998,0.8401299999999999
497.54599,158.20917,-0.15332,28.67185,0.8394299999999999
498.45499,158.50916999999998,-0.1546,28.671640000000004,0.8387399999999999
499.362,158.80917,-0.15721,28.6166,0.83804
500.28200999999996,159.10917,-0.16097999999999998,28.616390000000003,0.8373299999999999
501.17099,159.40917,-0.16188,28.56134,0.8366399999999999
502.077,159.70917,-0.16355,28.56134,0.83594
502.98099,160.00916999999998,-0.16657,28.505879999999998,0.83524
503.88901,160.30917,-0.16997,28.49895,0.83454
504.79199000000006,160.60917,-0.1705,28.4645,0.8338399999999999
505.70800999999994,160.90917,-0.17103,28.41597,0.8331299999999999
506.617,161.20917,-0.17137,28.41597,0.83242
507.504,161.50916999999998,-0.17536,28.38845,0.83173
508.40799000000004,161.80917,-0.17686,28.3813,0.8310299999999999
509.31699000000003,162.10917,-0.17759,28.35378,0.8303200000000001
510.233,162.40917,-0.1791,28.32605,0.8296
511.117,162.70917,-0.17809,28.29832,0.82891
512.021,163.00916999999998,-0.18192,28.26408,0.8282
512.9329799999999,163.30917,-0.18227000000000002,28.236340000000002,0.82749
513.83398,163.60917,-0.18494000000000002,28.236340000000002,0.82678
514.73401,163.90917,-0.18433,28.18109,0.8260799999999999
515.63098,164.20917,-0.18759,28.15336,0.82537
516.53198,164.50916999999998,-0.19008,28.14643,0.8246700000000001
517.43799,164.80917,-0.19044,28.118909999999996,0.82395
518.3369799999999,165.10917,-0.1943,28.091179999999998,0.82325
519.23401,165.40917,-0.19389,28.04265,0.8225399999999999
520.11902,165.70917,-0.19755999999999999,28.022059999999996,0.82184
521.02502,166.00916999999998,-0.19832,28.00126,0.8211299999999999
521.92102,166.30917,-0.20084000000000002,27.980459999999997,0.82042
522.828,166.60917,-0.20473,27.994329999999998,0.8197
523.72601,166.90917,-0.20686,27.95294,0.81899
524.62598,167.20917,-0.20978000000000002,27.925209999999996,0.81828
525.52197,167.50916999999998,-0.21114000000000002,27.89769,0.8175600000000001
526.422,167.80917,-0.21349,27.86996,0.81685
527.31799,168.10917,-0.21269000000000002,27.86996,0.81614
528.21997,168.40917,-0.2115,27.828359999999996,0.81542
529.11902,168.70917,-0.217,27.80084,0.8147
530.01501,169.00916999999998,-0.21936,27.800629999999998,0.81399
530.9279799999999,169.30917,-0.22171999999999997,27.77311,0.81326
531.81097,169.60917,-0.22152,27.717859999999998,0.8125600000000001
532.6950099999999,169.90917,-0.22448,27.69013,0.81185
533.61902,170.20917,-0.22705,27.69013,0.81111
534.49597,170.50916999999998,-0.22784000000000001,27.683190000000003,0.8104100000000001
535.38501,170.80917,-0.22883,27.65567,0.8096899999999999
536.289,171.10917,-0.23023000000000002,27.627940000000002,0.80897
537.1779799999999,171.40917,-0.23121999999999998,27.62101,0.8082600000000001
538.086,171.70917,-0.23381,27.60714,0.80753
538.98999,172.00916999999998,-0.23542,27.57269,0.8068
539.87598,172.30917,-0.23820999999999998,27.544959999999996,0.80609
540.77698,172.60917,-0.24181,27.544959999999996,0.8053600000000001
541.67102,172.90917,-0.24063,27.544959999999996,0.8046399999999999
542.56,173.20917,-0.24065,27.50357,0.80392
543.45801,173.50916999999998,-0.24306,27.482770000000002,0.80319
544.349,173.80917,-0.24506999999999998,27.46197,0.80247
545.23999,174.10917,-0.24609,27.42752,0.80175
546.138,174.40917,-0.24511999999999998,27.42752,0.80103
547.0310099999999,174.70917,-0.25075,27.40672,0.8003
547.914,175.00916999999998,-0.25017,27.37899,0.7995899999999999
548.8170200000001,175.30917,-0.2518,27.365340000000003,0.79885
549.703,175.60917,-0.25364000000000003,27.344540000000002,0.79813
550.5939900000001,175.90917,-0.25347,27.302940000000003,0.7974100000000001
551.48999,176.20917,-0.25571,27.358190000000004,0.79668
552.383,176.50916999999998,-0.25655,27.30315,0.79595
553.26202,176.80917,-0.25556999999999996,27.26155,0.79523
554.172,177.10917,-0.26004,27.23382,0.7944899999999999
555.06799,177.40917,-0.25988,27.219959999999997,0.79376
555.95203,177.70917,-0.25991,27.206090000000003,0.79304
556.82703,178.00916999999998,-0.26035,27.17857,0.79232
557.716,178.30917,-0.2616,27.12332,0.79159
558.61499,178.60917,-0.26327,27.09559,0.79086
559.49298,178.90917,-0.26026,27.102729999999998,0.79014
560.39001,179.20917,-0.26375,27.0958,0.7894
561.2880200000001,179.50916999999998,-0.26237,27.068070000000002,0.78866
562.17603,179.80917,-0.26566999999999996,27.04727,0.78793
563.0670200000001,180.10917,-0.26591,27.04727,0.7872
563.9470200000001,180.40917,-0.26575,27.0334,0.7864800000000001
564.85303,180.70917,-0.26723,27.0334,0.78573
565.74402,181.00916999999998,-0.2685,27.005670000000002,0.785
566.633,181.30917,-0.27038,26.977940000000004,0.7842600000000001
567.51398,181.60917,-0.26593,26.977940000000004,0.7835300000000001
568.40399,181.90917,-0.26946,26.95042,0.7828
569.28998,182.20917,-0.26621999999999996,26.9021,0.7820699999999999
570.19397,182.50916999999998,-0.26750999999999997,26.92962,0.78132
571.07098,182.80917,-0.26878,26.909029999999998,0.78059
571.9689900000001,183.10917,-0.26800999999999997,26.89517,0.77985
572.862,183.40917,-0.26868000000000003,26.874370000000003,0.7791100000000001
573.755,183.70917,-0.26873,26.867440000000002,0.77837
574.63599,184.00916999999998,-0.26795,26.81912,0.77764
575.53003,184.30917,-0.27109,26.860709999999997,0.77689
576.42102,184.60917,-0.26991,26.812179999999998,0.77615
577.29797,184.90917,-0.26727,26.812179999999998,0.77542
578.19098,185.20917,-0.26607,26.812179999999998,0.77468
579.06403,185.50916999999998,-0.26695,26.79832,0.77395
579.95898,185.80917,-0.26534,26.7708,0.7732
580.8439900000001,186.10917,-0.26684,26.74307,0.77246
581.73499,186.40917,-0.26647,26.74307,0.77172
582.62097,186.70917,-0.26652,26.70168,0.77098
583.513,187.00916999999998,-0.2647,26.722479999999997,0.77023
584.42102,187.30917,-0.26746,26.69475,0.76947
585.2810099999999,187.60917,-0.26875,26.69475,0.76875
586.164,187.90917,-0.27089,26.68088,0.7680100000000001
587.0369900000001,188.20917,-0.2678,26.65336,0.7672800000000001
587.9180299999999,188.50916999999998,-0.27057,26.625629999999997,0.76654
588.81201,188.80917,-0.26895,26.611759999999997,0.76579
589.69,189.10917,-0.26628,26.61849,0.76505
590.586,189.40917,-0.26591,26.57038,0.7643
591.466,189.70917,-0.26323,26.57017,0.76356
592.35101,190.00916999999998,-0.26538,26.54265,0.7628199999999999
593.23401,190.30917,-0.26711,26.54265,0.76207
594.11102,190.60917,-0.26505,26.51492,0.7613300000000001
595.01801,190.90917,-0.26848,26.48718,0.76057
595.87598,191.20917,-0.26789,26.50105,0.75984
596.76202,191.50916999999998,-0.26605,26.48739,0.7591
597.64801,191.80917,-0.26758000000000004,26.459659999999996,0.75835
598.5189799999999,192.10917,-0.26826,26.459659999999996,0.75761
599.40802,192.40917,-0.26874000000000003,26.431929999999998,0.7568600000000001
600.29401,192.70917,-0.26858000000000004,26.41807,0.7561100000000001
601.18201,193.00916999999998,-0.26821,26.411340000000003,0.75536
602.06,193.30917,-0.26869,26.39055,0.75461
602.93597,193.60917,-0.26661999999999997,26.397270000000002,0.7538699999999999
603.79797,193.90917,-0.26581,26.36975,0.7531399999999999
604.6829799999999,194.20917,-0.26416,26.36975,0.75239
605.56598,194.50916999999998,-0.27146,26.34895,0.75164
606.44598,194.80917,-0.26703000000000005,26.335079999999998,0.75089
607.328,195.10917,-0.26666,26.335079999999998,0.7501399999999999
608.198,195.40917,-0.26821,26.32815,0.7494
609.07397,195.70917,-0.26761999999999997,26.342229999999997,0.74865
609.93597,196.00916999999998,-0.26788,26.300629999999998,0.74792
610.81403,196.30917,-0.26686,26.300629999999998,0.74717
611.685,196.60917,-0.26755999999999996,26.300629999999998,0.74643
612.573,196.90917,-0.26804,26.2729,0.7456699999999999
613.41998,197.20917,-0.2668,26.259240000000002,0.7449399999999999
614.33002,197.50916999999998,-0.26104,26.27983,0.74417
615.18799,197.80917,-0.26066,26.26618,0.74343
616.0720200000001,198.10917,-0.25509,26.259240000000002,0.74268
616.94397,198.40917,-0.26118,26.231509999999997,0.74193
617.8380099999999,198.70917,-0.26361999999999997,26.22458,0.74117
618.7139900000001,199.00916999999998,-0.26345,26.231509999999997,0.74042
619.58099,199.30917,-0.26198,26.21071,0.7396699999999999
620.466,199.60917,-0.26116999999999996,26.21071,0.7389100000000001
621.34302,199.90917,-0.26121,26.15546,0.73816
622.21802,200.20917,-0.2617,26.17626,0.73741
623.09198,200.50916999999998,-0.26175,26.148529999999997,0.73666
623.96698,200.80917,-0.26332,26.09307,0.7359100000000001
624.84302,201.10917,-0.26272,26.1208,0.73515
625.72803,201.40917,-0.26081,26.09328,0.73439
626.6060200000001,201.70917,-0.26150999999999996,26.07248,0.73364
627.48499,202.00916999999998,-0.262,26.07248,0.73288
628.35699,202.30917,-0.26468,26.04475,0.7321300000000001
629.21802,202.60917,-0.26406999999999997,26.05189,0.73139
630.09497,202.90917,-0.2661,26.00336,0.73063
630.96802,203.20917,-0.26659,25.97563,0.72988
631.84802,203.50916999999998,-0.26863000000000004,25.96197,0.72912
632.72101,203.80917,-0.26913000000000004,25.96197,0.72836
633.59198,204.10917,-0.26478,25.94118,0.7276100000000001
634.45801,204.40917,-0.26505,25.94118,0.7268600000000001
635.3319700000001,204.70917,-0.26069000000000003,25.927310000000002,0.72611
636.211,205.00916999999998,-0.2581,25.87206,0.72535
637.073,205.30917,-0.25792,25.87206,0.7246
637.9470200000001,205.60917,-0.25797,25.865129999999997,0.7238399999999999
638.82599,205.90917,-0.25756999999999997,25.85126,0.7230800000000001
639.69598,206.20917,-0.25916999999999996,25.80987,0.72233
640.55402,206.50916999999998,-0.255,25.81681,0.72158
641.4119900000001,206.80917,-0.25482,25.80294,0.7208399999999999
642.29102,207.10917,-0.25196999999999997,25.78908,0.72008
643.16498,207.40917,-0.24756,25.77521,0.71932
644.0380200000001,207.70917,-0.24135,25.768279999999997,0.7185600000000001
644.90399,208.00916999999998,-0.24070999999999998,25.74076,0.7178100000000001
645.77502,208.30917,-0.24140999999999999,25.76155,0.71705
646.64801,208.60917,-0.23786,25.71996,0.71629
647.52002,208.90917,-0.23834,25.71996,0.71553
648.3779900000001,209.20917,-0.23567,25.692439999999998,0.7147899999999999
649.24402,209.50916999999998,-0.23256,25.692439999999998,0.71403
650.10498,209.80917000000002,-0.23235,25.66471,0.71328
650.39502,209.90917000000002,-0.23288000000000003,25.66471,0.71303