File: 02_Data/MDF/STA/N2/3K_min/MDF_STA_N2_3KData_210302_R1.csv
##Temp./Â°C,Time/min,DSC/(mW/mg),Mass/%,Sensit./(uV/mW)
49.099,10.01,0.02383728,99.61658,1.05326
49.115,10.31,0.02439168,99.61658,1.05326
49.118,10.61,0.02586997,99.58315999999999,1.05326
49.153,10.91,0.02623965,99.58291,1.05326
49.233,11.21,0.03012045,99.54923000000001,1.05325
49.357,11.51,0.03289275,99.54949,1.0532299999999999
49.541,11.81,0.03769813,99.58315999999999,1.05321
49.77,12.11,0.04157995,99.57449,1.05318
50.058,12.41,0.04786478,99.51301,1.05314
50.398,12.71,0.05396558,99.57194,1.0531
50.79,13.01,0.05932797,99.51301,1.05305
51.224,13.31,0.06099457,99.51326999999999,1.053
51.668,13.61,0.06580376,99.49616999999999,1.05294
52.159,13.91,0.0709836,99.50459000000001,1.05288
52.691,14.21,0.0733915,99.54668000000001,1.05281
53.245,14.51,0.07506045,99.47934000000001,1.05273
53.809,14.81,0.08172182,99.44592,1.05266
54.393,15.11,0.08154293,99.48801,1.0525799999999998
55.019,15.41,0.08413828,99.46276,1.0525
55.662,15.71,0.08858364,99.44592,1.05241
56.322,16.01,0.08896109,99.42908,1.0523200000000001
57.001,16.31,0.09211338,99.36199,1.05223
57.673,16.61,0.09619115,99.36199,1.0521399999999999
58.394,16.91,0.09620033,99.39541,1.0520399999999999
59.109,17.21,0.09787469,99.36199,1.0519399999999999
59.839,17.51,0.10103,99.36199,1.0518299999999998
60.598,17.81,0.10086,99.30332,1.05172
61.361,18.11,0.10216,99.32857,1.05161
62.129,18.41,0.10328,99.37040999999999,1.0515
62.92,18.71,0.10515,99.26964,1.05139
63.701,19.01,0.10405,99.24439,1.0512700000000001
64.511,19.31,0.10647000000000001,99.26964,1.05115
65.315,19.61,0.10665999999999999,99.33673,1.05103
66.128,19.91,0.10555999999999999,99.22780999999999,1.0509
66.946,20.21,0.10465,99.23597,1.0507799999999998
67.779,20.51,0.10595999999999998,99.21096999999999,1.05065
68.606,20.81,0.10857,99.16888,1.0505200000000001
69.433,21.11,0.10820999999999999,99.15204,1.05039
70.289,21.41,0.11008,99.13546,1.05025
71.144,21.71,0.10768,99.10179000000001,1.05011
71.998,22.01,0.10844000000000001,99.16888,1.04997
72.826,22.31,0.1079,99.20255,1.0498399999999999
73.699,22.61,0.10790999999999999,99.16888,1.04969
74.547,22.91,0.10496,99.22755,1.04955
75.404,23.21,0.10627,99.19413,1.04941
76.285,23.51,0.10925,99.16888,1.04926
77.138,23.81,0.10686,99.1102,1.04911
78.007,24.11,0.10817,99.05969,1.0489600000000001
78.879,24.41,0.10745,99.21070999999999,1.04881
79.771,24.71,0.10672000000000001,99.10153000000001,1.04865
80.651,25.01,0.10580999999999999,99.03469,1.04849
81.52,25.31,0.10507999999999999,99.10179000000001,1.04834
82.422,25.61,0.10435,99.05995,1.04818
83.281,25.91,0.10547999999999999,99.06811,1.0480200000000002
84.179,26.21,0.10439000000000001,99.03444,1.04786
85.083,26.51,0.10662999999999999,99.03469,1.04769
85.973,26.81,0.10515999999999999,98.97577,1.04752
86.882,27.11,0.10462,99.04286,1.04735
87.778,27.41,0.10445,99.00102,1.04718
88.673,27.71,0.10520999999999998,99.00102,1.04701
89.578,28.01,0.10542,98.9676,1.04684
90.47,28.31,0.10505999999999999,99.06811,1.0466600000000001
91.432,28.61,0.10564000000000001,98.99821,1.04647
92.322,28.91,0.10417,99.02346999999999,1.0463
93.211,29.21,0.10642,98.99821,1.0461200000000002
94.128,29.51,0.10532000000000001,98.99821,1.0459399999999999
95.046,29.81,0.10553,99.03163,1.04575
95.97,30.11,0.10685,98.96454,1.04556
96.883,30.41,0.10649000000000002,98.97296,1.04538
97.806,30.71,0.10614000000000001,98.93954000000001,1.04519
98.719,31.01,0.10522999999999999,98.90587,1.045
99.641,31.31,0.10375999999999999,98.98444,1.0448
100.562,31.61,0.10303,98.90867,1.04461
101.489,31.91,0.10472999999999999,98.97577,1.04441
102.404,32.21,0.10307000000000001,99.03469,1.04421
103.328,32.51,0.1057,98.93393,1.04401
104.26,32.81,0.10777,99.00102,1.0438100000000001
105.173,33.11,0.1091,98.96735,1.04361
106.118,33.41,0.11099,98.93393,1.0434
107.049,33.71,0.1097,98.98418000000001,1.04319
107.958,34.01,0.10916,98.9648,1.0429899999999999
108.89,34.31,0.10639000000000001,98.9648,1.0427799999999998
109.833,34.61,0.10828,98.96454,1.04257
110.75,34.91,0.104,98.97296,1.04236
111.677,35.21,0.1044,98.93111999999999,1.04214
112.613,35.51,0.10461,98.99821,1.04193
113.541,35.81,0.10388,98.94796,1.0417100000000001
114.473,36.11,0.10353,98.93111999999999,1.04149
115.398,36.41,0.10167999999999999,98.93111999999999,1.0412700000000001
116.375,36.71,0.10375999999999999,98.93111999999999,1.04104
117.269,37.01,0.10191,98.95638000000001,1.04082
118.205,37.31,0.10081,98.9648,1.0406
119.149,37.61,0.10082999999999999,98.9648,1.04037
120.078,37.91,0.10048,98.9648,1.04014
121.021,38.21,0.10107000000000001,98.96454,1.0399100000000001
121.962,38.51,0.09959055,98.99821,1.03968
122.869,38.81,0.09848877,98.99821,1.03945
123.793,39.11,0.09907259,98.98163000000001,1.03922
124.722,39.41,0.09853298,99.02320999999999,1.03898
125.67,39.71,0.09855583,99.03189,1.03874
126.605,40.01,0.09764146,99.04030999999999,1.0385
127.55,40.31,0.09841414,99.00663,1.03826
128.47501,40.61,0.09937433,99.01505,1.0380200000000002
129.411,40.91,0.09845995,99.02346999999999,1.03778
130.356,41.21,0.0979207,99.02883,1.0375299999999998
131.291,41.51,0.09756869,99.02883,1.03728
132.23,41.81,0.09796747,98.98699,1.03703
133.177,42.11,0.09855451,98.96173,1.03678
134.117,42.41,0.09876625,98.98418000000001,1.03653
135.07899,42.71,0.09822755,98.95076999999999,1.03627
135.99001,43.01,0.09787528,98.98418000000001,1.0360200000000002
136.95598999999999,43.31,0.09752437,98.95918,1.03576
137.866,43.61,0.09886358,99.0176,1.03551
138.83098999999999,43.91,0.09851303,99.05969,1.03524
139.76401,44.21,0.09646916,99.02628,1.03498
140.72501,44.51,0.0955537,99.01786,1.03471
141.65198999999998,44.81,0.09670663,99.01786,1.03445
142.60699,45.11,0.09899019,98.98418000000001,1.0341799999999999
143.548,45.41,0.09713336,99.05128,1.0339200000000002
144.511,45.71,0.09715922,99.04286,1.03364
145.44501,46.01,0.09643108,99.04286,1.0333700000000001
146.408,46.31,0.09325437,99.09337,1.03309
147.351,46.61,0.09290222,99.07653,1.03282
148.304,46.91,0.09311576,99.06811,1.03254
149.282,47.21,0.09351876,99.06811,1.03226
150.215,47.51,0.09184634,99.10995,1.03198
151.179,47.81,0.09130587,99.07653,1.03169
152.121,48.11,0.09057596,99.07653,1.03141
153.086,48.41,0.08852511,99.06811,1.03112
154.04401000000001,48.71,0.09043798,99.07653,1.03083
154.993,49.01,0.09027437,99.10179000000001,1.03055
155.96001,49.31,0.08841108,99.08495,1.03025
156.92799,49.61,0.08957034,99.09337,1.02995
157.881,49.91,0.08921782,99.12704000000001,1.02966
158.854,50.21,0.08943303,99.09337,1.02936
159.79401000000001,50.51,0.08908019,99.08495,1.0290700000000002
160.746,50.81,0.08740331,99.11861999999999,1.02877
161.705,51.11,0.08477957,99.10995,1.02847
162.65198999999998,51.41,0.08707578,99.10995,1.02817
163.619,51.71,0.08501892,99.06837,1.02786
164.588,52.01,0.08542333,99.11276,1.02755
165.536,52.31,0.086017,99.07934,1.02725
166.502,52.61,0.08395833,99.07934,1.02694
167.452,52.91,0.08436265,99.05128,1.02663
168.41,53.21,0.08533646,99.04286,1.0263200000000001
169.37601,53.51,0.08175853,99.10179000000001,1.026
170.33501,53.81,0.08235291,99.06811,1.02569
171.299,54.11,0.08332754,99.10179000000001,1.0253700000000001
172.248,54.41,0.08335313,99.06811,1.02505
173.213,54.71,0.08148,99.1102,1.02473
174.17999,55.01,0.08245571,99.09337,1.02441
175.13,55.31,0.08248145,99.1102,1.02409
176.09801000000002,55.61,0.08250781,99.07092,1.02376
177.06,55.91,0.0815833,99.10459,1.0234299999999998
177.998,56.21,0.08179902,99.0375,1.02311
178.995,56.51,0.08106518,99.0625,1.0227700000000002
179.922,56.81,0.08109049,99.07934,1.02245
180.88699,57.11,0.08054576,98.98699,1.0221200000000001
181.85201,57.41,0.0788579,98.97856999999999,1.02178
182.81,57.71,0.08040804,98.93648,1.02145
183.79401000000001,58.01,0.07967279,99.02041,1.02111
184.72301000000002,58.31,0.08007966,99.01224,1.02078
185.69298999999998,58.61,0.08163243,98.95357,1.02043
186.65401,58.91,0.07937023,98.95357,1.02009
187.621,59.21,0.07901538,98.95357,1.01975
188.58098999999999,59.51,0.07789652,98.94515,1.0194
189.541,59.81,0.07734998,98.89464,1.01906
190.507,60.11,0.07986019,98.87781,1.01871
191.47701,60.41,0.07931446,98.85280999999999,1.01836
192.459,60.71,0.07857762,98.86097,1.018
193.396,61.01,0.07975166,98.81071,1.01766
194.36,61.31,0.07958814,98.78546,1.0173
195.342,61.61,0.07980792,98.78546,1.01694
196.28798999999998,61.91,0.07792096,98.75204000000001,1.0165899999999999
197.25301000000002,62.21,0.07775697,98.75204000000001,1.01623
198.213,62.51,0.07548542,98.71837,1.01587
199.181,62.81,0.0757041,98.67628,1.0155
200.142,63.11,0.07611459,98.65969,1.01514
201.10001,63.41,0.07422387,98.65969,1.01478
202.067,63.71,0.07463451,98.60101999999999,1.01441
203.036,64.01,0.07638913,98.55893,1.01404
204.004,64.31,0.07468908,98.59541,1.01367
204.95598999999999,64.61,0.07548438,98.49464,1.0133
205.931,64.91,0.07359103,98.52806,1.0129299999999999
206.896,65.21,0.07477154,98.41071,1.01255
207.85001,65.51,0.07614499,98.41071,1.0121799999999999
208.80701000000002,65.81,0.07521135,98.43290999999999,1.01181
209.771,66.11,0.0738925,98.36607,1.0114299999999998
210.742,66.41,0.07488298,98.29030999999999,1.01104
211.694,66.71,0.07568119,98.25689,1.0106700000000002
212.657,67.01,0.07359075,98.22883,1.01029
213.619,67.31,0.07284783,98.25383000000001,1.0099
214.584,67.61,0.07615319,98.05536,1.00952
215.53798999999998,67.91,0.07463919,98.13903,1.0091299999999999
216.511,68.21,0.07428236,98.05536,1.00874
217.47301000000002,68.51,0.07315296,98.02168,1.00835
218.44099,68.81,0.07472625,97.92092,1.00796
219.39101000000002,69.11,0.07533449,97.8875,1.00757
220.36099,69.41,0.07517097,97.71964,1.0071700000000001
221.317,69.71,0.07616689,97.64949,1.00678
222.27499,70.01,0.07542324,97.70815999999999,1.0063799999999998
223.237,70.31,0.0748727,97.62449000000001,1.00599
224.185,70.61,0.07393431,97.52346999999999,1.00559
225.155,70.91,0.07396407,97.42296,1.00519
226.116,71.21,0.07244408,97.45663,1.00478
227.067,71.51,0.07344179,97.32219,1.0043799999999998
228.02499,71.81,0.07502218,97.28878,1.0039799999999999
229.022,72.11,0.07485985,97.19617,1.00356
229.957,72.41,0.07430744,97.12628000000001,1.00316
230.92,72.71,0.07394967,97.02551,1.00275
231.87801000000002,73.01,0.07300904,96.95815999999999,1.00234
232.85001,73.31,0.07381645,96.82423,1.0019200000000001
233.811,73.61,0.07034895,96.75689,1.0015100000000001
234.78,73.91,0.07173929,96.6898,1.00109
235.748,74.21,0.0715749,96.52194,1.0006700000000002
236.69901000000002,74.51,0.07160452,96.35383,1.00026
237.66901000000001,74.81,0.0724135,96.27015,0.9998299999999999
238.62601,75.11,0.07049647,96.16096999999999,0.99941
239.59,75.41,0.0689678,96.0852,0.9989899999999999
240.564,75.71,0.06802294,95.90918,0.99856
241.492,76.01,0.06512606,95.79439,0.99815
242.468,76.31,0.0633987,95.69082,0.99772
243.41701,76.61,0.06479168,95.44745,0.99729
244.381,76.91,0.06306254,95.3523,0.9968600000000001
245.34599,77.21,0.06191799,95.18418,0.9964299999999999
246.313,77.51,0.06311752,95.02474000000001,0.9959899999999999
247.27,77.81,0.06040799,94.84005,0.99556
248.231,78.11,0.06102117,94.63878000000001,0.99513
249.19099,78.41,0.05967828,94.4625,0.99469
250.14,78.71,0.05931276,94.26097,0.99426
251.103,79.01,0.05933906,94.09311,0.99382
252.058,79.31,0.05897339,93.81607,0.9933799999999999
253.02,79.61,0.05782363,93.68163,0.99293
253.978,79.91,0.05706502,93.47474,0.99249
254.94298999999998,80.21,0.05493268,93.18111999999999,0.9920399999999999
255.91298999999998,80.51,0.05770554,92.93469,0.99159
256.875,80.81,0.05910623,92.71913,0.99115
257.83898999999997,81.11,0.05736504,92.46173,0.99069
258.81299,81.41,0.05640879,92.21276,0.99024
259.78299,81.71,0.05820456,91.9301,0.9897799999999999
260.745,82.01,0.06196911,91.58315999999999,0.9893299999999999
261.68701,82.31,0.06376842,91.28929000000001,0.98888
262.65398999999996,82.61,0.06517642,91.06837,0.9884200000000001
263.60598999999996,82.91,0.06225139,90.79413000000001,0.9879700000000001
264.56699,83.21,0.06247744,90.57857,0.98751
265.53101000000004,83.51,0.06211234,90.20638000000001,0.9870399999999999
266.49399,83.81,0.06352243,89.87908,0.9865799999999999
267.452,84.11,0.062368,89.52398000000001,0.9861200000000001
268.409,84.41,0.06279222,89.20485,0.9856600000000001
269.37799,84.71,0.06578551,88.88597,0.98519
270.33898999999997,85.01,0.06403794,88.60893,0.98472
271.28601000000003,85.31,0.06742968,88.19184,0.98426
272.24301,85.61,0.06983582,87.90357,0.9837899999999999
273.19901,85.91,0.07006709,87.65179,0.9833200000000001
274.147,86.21,0.07386283,87.24337,0.98285
275.116,86.51,0.07488942,86.89643000000001,0.9823700000000001
276.07198999999997,86.81,0.07552019,86.55790999999999,0.9819
277.03,87.11,0.0803163,86.12959000000001,0.9814200000000001
277.99301,87.41,0.08194286,85.80790999999999,0.9809399999999999
278.94698999999997,87.71,0.08297523,85.34643,0.9804700000000001
279.90302,88.01,0.08678924,85.02168,0.9799899999999999
280.85999,88.31,0.08881885,84.725,0.97951
281.81601,88.61,0.0936337,84.19337,0.9790200000000001
282.78,88.91,0.09288474,83.91351999999999,0.97854
283.75601,89.21,0.09591667,83.45485,0.9780399999999999
284.69601,89.51,0.09695902,83.05459,0.97756
285.64301,89.81,0.10079,82.61531,0.97708
286.60598999999996,90.11,0.09964661,82.2824,0.97659
287.56799,90.41,0.10249000000000001,81.83469000000001,0.9761
288.534,90.71,0.10394,81.37832,0.9756
289.48401,91.01,0.10618,80.96148000000001,0.97511
290.42999,91.31,0.11023,80.53903000000001,0.97462
291.396,91.61,0.11049,80.15841999999999,0.9741200000000001
292.34299,91.91,0.11134000000000001,79.73597,0.9736299999999999
293.29401,92.21,0.115,79.29106999999999,0.9731299999999999
294.23901,92.51,0.11846,78.73444,0.97264
295.19501,92.81,0.11852,78.35944,0.97214
296.155,93.11,0.12059,77.90893,0.97164
297.099,93.41,0.12525999999999998,77.45841999999999,0.97114
298.06601,93.71,0.12753,76.96582,0.9706299999999999
299.01901000000004,94.01,0.1278,76.57143,0.9701200000000001
299.98001,94.31,0.13168,76.02577,0.9696100000000001
300.93301,94.61,0.13114,75.53596999999999,0.96911
301.884,94.91,0.13744,75.00995,0.9686
302.832,95.21,0.13852,74.5176,0.96809
303.78299,95.51,0.1396,74.05306,0.9675799999999999
304.72699,95.81,0.1441,73.51301,0.9670799999999999
305.686,96.11,0.14377,72.96735,0.9665600000000001
306.638,96.41,0.14687,72.48061,0.96604
307.59799,96.71,0.14897,71.90689,0.96552
308.548,97.01,0.15066,71.34184,0.96501
309.492,97.31,0.15599000000000002,70.72883,0.96449
310.45599,97.61,0.16071,70.16378,0.9639700000000001
311.401,97.91,0.16282,69.57321,0.96345
312.35199,98.21,0.16857,68.87092,0.96293
313.302,98.51,0.16967000000000002,68.40357,0.96241
314.25101,98.81,0.17057,67.74056,0.96188
315.194,99.11,0.17694000000000001,67.05204,0.96136
316.155,99.41,0.18028,66.32449,0.96083
317.10001,99.71,0.18382,65.73138,0.96031
318.04401,100.01,0.18899000000000002,65.02653000000001,0.95978
318.98999,100.31,0.19174000000000002,64.30179,0.95925
319.94299,100.61,0.19428,63.56556,0.9587200000000001
320.89801,100.91,0.19967000000000001,62.8074,0.95819
321.836,101.21,0.20465999999999998,62.04056,0.9576600000000001
322.79199,101.51,0.20823000000000003,61.26837,0.9571200000000001
323.745,101.81,0.21079,60.45995,0.9565799999999999
324.67499,102.11,0.2109,59.634440000000005,0.95606
325.63698999999997,102.41,0.21652,58.800509999999996,0.9555100000000001
326.58099,102.71,0.22113000000000002,57.944390000000006,0.9549700000000001
327.522,103.01,0.22329000000000002,57.096430000000005,0.95444
328.47,103.31,0.22954000000000002,56.18724,0.9539
329.422,103.61,0.2313,55.289030000000004,0.95335
330.35598999999996,103.91,0.23285999999999998,54.37934,0.9528200000000001
331.30801,104.21,0.23565,53.38061,0.9522700000000001
332.26501,104.51,0.23804,52.44311,0.9517200000000001
333.20401,104.81,0.23879,51.42194,0.9511799999999999
334.16,105.11,0.23831,50.54056,0.95062
335.103,105.41,0.2407,49.48827,0.9500799999999999
336.07501,105.71,0.24085,48.593109999999996,0.9495100000000001
336.996,106.01,0.24015999999999998,47.45128,0.9489700000000001
337.948,106.31,0.23825,46.40485,0.94842
338.88,106.61,0.23079000000000002,45.52628,0.9478700000000001
339.82001,106.91,0.23093000000000002,44.5301,0.94732
340.767,107.21,0.22386999999999999,43.51148,0.94676
341.716,107.51,0.21803000000000003,42.58265,0.9462
342.67001,107.81,0.20951999999999998,41.60893,0.9456399999999999
343.60598999999996,108.11,0.20038,40.74974,0.94509
344.54999,108.41,0.19143,39.787240000000004,0.94453
345.505,108.71,0.17979,38.87806,0.94396
346.44199,109.01,0.17123,38.12806,0.9434
347.36801,109.31,0.15461,37.4648,0.94285
348.32198999999997,109.61,0.14169,36.64796,0.9422799999999999
349.259,109.91,0.12607000000000002,36.07985,0.9417200000000001
350.23801000000003,110.21,0.10857,35.62372,0.9411299999999999
351.151,110.51,0.09849535,34.99158,0.94058
352.091,110.81,0.08219793,34.739540000000005,0.94001
353.04401,111.11,0.07292547,34.29745,0.9394399999999999
353.991,111.41,0.06115385,34.0176,0.93886
354.92499,111.71,0.05310117,33.659440000000004,0.9383
355.866,112.01,0.045039,33.58112,0.9377200000000001
356.81699,112.31,0.04132859,33.39643,0.93714
357.76198999999997,112.61,0.03886035,33.20357,0.9365700000000001
358.70001,112.91,0.03784449,33.04388,0.93599
359.646,113.21,0.03495504,32.909690000000005,0.9354100000000001
360.58301,113.51,0.03227005,32.83393,0.93484
361.521,113.81,0.03208167,32.64107,0.9342600000000001
362.46701,114.11,0.02960029,32.57398,0.93368
363.39499,114.41,0.02648977,32.43954,0.9331
364.345,114.71,0.02504549,32.36378,0.9325100000000001
365.28,115.01,0.0246434,32.24643,0.9319299999999999
366.23999,115.31,0.0246592,32.16531,0.93134
367.146,115.61,0.02446505,31.96378,0.9307700000000001
368.08898999999997,115.91,0.02280664,31.94694,0.9301799999999999
369.02301,116.21,0.02386781,31.888270000000002,0.9296
369.97101000000004,116.51,0.02241656,31.762240000000002,0.92901
370.88599,116.81,0.02431711,31.762240000000002,0.92843
371.836,117.11,0.02202535,31.59439,0.9278299999999999
372.76198999999997,117.41,0.02098972,31.59158,0.92725
373.70599,117.71,0.02058316,31.535709999999998,0.92665
374.634,118.01,0.01954538,31.359440000000003,0.9260700000000001
375.573,118.31,0.01934765,31.29235,0.9254700000000001
376.509,118.61,0.01999139,31.2,0.9248799999999999
377.43701,118.91,0.01684561,31.088009999999997,0.92429
378.37601,119.21,0.01496016,30.961990000000004,0.92369
379.31699,119.51,0.0115964,31.01505,0.92309
380.254,119.81,0.01054903,30.908929999999998,0.9224899999999999
381.19,120.11,0.009922545,30.825,0.92189
382.13901,120.41,0.006548986,30.73265,0.9212799999999999
383.07501,120.71,0.008244435,30.66811,0.9206799999999999
383.99899,121.01,0.004865249,30.533929999999998,0.9200799999999999
384.93301,121.31,0.005715125,30.50051,0.91948
385.87,121.61,0.002965353,30.39133,0.9188700000000001
386.811,121.91,0.002543419,30.35765,0.9182600000000001
387.72198,122.21,0.001696705,30.27372,0.9176700000000001
388.664,122.51,0.0023345279999999998,30.173209999999997,0.91706
389.58898999999997,122.81,0.0019113239999999998,30.07245,0.91646
390.53799,123.11,0.002550155,30.038520000000002,0.91584
391.46398999999997,123.41,0.000850614,29.92959,0.9152299999999999
392.397,123.71,0.001063978,29.80357,0.9146200000000001
393.32901,124.01,0.00021293790000000002,29.77577,0.91401
394.267,124.31,0.0014915710000000001,29.70867,0.9133899999999999
395.19601,124.61,0.005543834,29.607909999999997,0.9127799999999999
396.14401000000004,124.91,0.007041228,29.507140000000003,0.9121600000000001
397.04199,125.21,0.007259319,29.54337,0.91156
397.98199,125.51,0.007264276,29.4426,0.91094
398.89898999999997,125.81,0.006200137,29.34184,0.91033
399.841,126.11,0.004920730999999999,29.30842,0.90971
400.767,126.41,0.005138155,29.171429999999997,0.90909
401.69901,126.71,0.005141667,29.20485,0.9084700000000001
402.61499,127.01,0.008360834000000001,28.99515,0.90786
403.54098999999997,127.31,0.006221272,28.961479999999998,0.9072399999999999
404.46799,127.61,0.009016287,28.89439,0.9066200000000001
405.39001,127.91,0.00622978,28.7852,0.906
406.34698,128.21,0.006019231999999999,28.871679999999998,0.90536
407.254,128.51,0.007529115,28.6676,0.90475
408.18701,128.81,0.006458016,28.63393,0.90412
409.10901,129.11,0.007324127,28.592090000000002,0.9035
410.03601000000003,129.41,0.008407038,28.52474,0.9028700000000001
410.96301,129.71,0.003667156,28.491329999999998,0.9022399999999999
411.88501,130.01,0.005612483000000001,28.365309999999997,0.9016200000000001
412.811,130.31,0.0043203090000000005,28.272959999999998,0.90099
413.73599,130.61,0.005620329,28.30663,0.90036
414.67401,130.91,0.007354885,28.272959999999998,0.8997200000000001
415.60501,131.21,0.006277719,28.18903,0.8990799999999999
416.522,131.51,0.008015094,28.071679999999997,0.89846
417.45099,131.81,0.008454329,27.97092,0.8978200000000001
418.367,132.11,0.009978757,27.87015,0.8971899999999999
419.28299,132.41,0.007163699,27.87015,0.89656
420.23199000000005,132.71,0.00825512,27.8449,0.89591
421.13699,133.01,0.007826089,27.74413,0.8952899999999999
422.06,133.31,0.01065976,27.71071,0.89465
422.98599,133.61,0.009578885,27.643620000000002,0.8940100000000001
423.909,133.91,0.008932165,27.57628,0.8933700000000001
424.84698,134.21,0.005886443000000001,27.57628,0.8927200000000001
425.78799000000004,134.51,0.00676346,27.509179999999997,0.89207
426.68701,134.81,0.004803242,27.61556,0.89144
427.60199000000006,135.11,0.006554562,27.4477,0.8908
428.521,135.41,0.005684712,27.346940000000004,0.8901600000000001
429.45401,135.71,0.004157257,27.299229999999998,0.88951
430.37799,136.01,0.006568864000000001,27.21531,0.88886
431.302,136.31,0.004601557,27.19872,0.8882200000000001
432.22,136.61,0.003727774,27.13138,0.8875700000000001
433.14800999999994,136.91,0.003949958,27.097959999999997,0.88692
434.08800999999994,137.21,0.001976453,27.097959999999997,0.88626
434.98400999999996,137.51,0.0017581,26.997190000000003,0.8856299999999999
435.892,137.81,0.001759374,26.86301,0.8849799999999999
436.79900999999995,138.11,0.00374138,26.91327,0.88434
437.70499,138.41,0.00726795,26.8125,0.8837
438.61800999999997,138.71,0.005950863000000001,26.77883,0.8830600000000001
439.539,139.01,0.008822626,26.72015,0.8824
440.453,139.31,0.006842574000000001,26.63622,0.88175
441.36301,139.61,0.0061849340000000004,26.653059999999996,0.8811
442.297,139.91,0.004863267,26.619390000000003,0.88044
443.20800999999994,140.21,0.0048668620000000004,26.48495,0.87979
444.134,140.51,0.001106938,26.48495,0.87913
445.05800999999997,140.81,-0.002215543,26.48495,0.87846
445.98099,141.11,-0.0028823779999999997,26.46837,0.8778
446.89999000000006,141.41,-0.004437763,26.38444,0.8771399999999999
447.814,141.71,-0.004885199000000001,26.31735,0.8764799999999999
448.73000999999994,142.01,-0.008222204,26.27526,0.8758299999999999
449.65302,142.31,-0.007783674,26.24158,0.87516
450.55899000000005,142.61,-0.008679724,26.27526,0.87451
451.479,142.91,-0.007572698,26.21097,0.87384
452.40399,143.21,-0.01359673,26.118370000000002,0.8731700000000001
453.33099000000004,143.51,-0.01338413,26.043110000000002,0.8725
454.237,143.81,-0.01428718,26.009439999999998,0.87184
455.14899,144.11,-0.01496827,26.009439999999998,0.87118
456.078,144.41,-0.01363841,25.96735,0.8705
456.996,144.71,-0.01521517,25.95051,0.8698299999999999
457.91101,145.01,-0.0165704,25.917089999999998,0.8691700000000001
458.84601,145.31,-0.01747984,25.84974,0.8684799999999999
459.75201,145.61,-0.01480193,25.92551,0.86782
460.67099,145.91,-0.01548676,25.816329999999997,0.86715
461.577,146.21,-0.01392631,25.749229999999997,0.8664799999999999
462.49701,146.51,-0.01348759,25.64847,0.8658100000000001
463.40200999999996,146.81,-0.01417287,25.58138,0.8651399999999999
464.32000999999997,147.11,-0.01530966,25.6148,0.86446
465.228,147.41,-0.01712406,25.6148,0.8638
466.147,147.71,-0.01713752,25.5727,0.8631200000000001
467.04999000000004,148.01,-0.0198588,25.53087,0.86245
467.97601,148.31,-0.01693857,25.49719,0.8617600000000001
468.87399000000005,148.61,-0.01672564,25.45536,0.8611
469.785,148.91,-0.01832218,25.36301,0.8604200000000001
470.70499,149.21,-0.0210533,25.39643,0.85974
471.616,149.51,-0.01971055,25.32959,0.85906
472.534,149.81,-0.01972625,25.26224,0.8583799999999999
473.448,150.11,-0.01792658,25.32934,0.8577
474.35101,150.41,-0.0242994,25.22857,0.8570200000000001
475.26999000000006,150.71,-0.02386433,25.295920000000002,0.85634
476.16599,151.01,-0.02411049,25.200770000000002,0.85567
477.082,151.31,-0.0261786,25.21735,0.85498
478.00600999999995,151.61,-0.02255465,25.19235,0.85429
478.905,151.91,-0.02553655,25.12526,0.8536100000000001
479.81699000000003,152.21,-0.02829534,25.03265,0.8529200000000001
480.73199000000005,152.51,-0.03014519,24.990820000000003,0.85224
481.646,152.81,-0.03016958,24.95714,0.85155
482.54400999999996,153.11,-0.02813495,24.96582,0.8508700000000001
483.448,153.41,-0.02632617,24.89005,0.85019
484.35699000000005,153.71,-0.02382728,24.89005,0.8495
485.27899,154.01,-0.02728633,24.85663,0.8488
486.18201,154.31,-0.02616095,24.84821,0.8481200000000001
487.104,154.61,-0.02870894,24.856379999999998,0.8474200000000001
488.004,154.91,-0.0278127,24.87321,0.84673
488.91199000000006,155.21,-0.025765,24.822960000000002,0.84604
489.811,155.51,-0.0267068,24.822960000000002,0.84536
490.72,155.81,-0.02972417,24.75587,0.8446600000000001
491.617,156.11,-0.02974828,24.64668,0.84398
492.52700999999996,156.41,-0.02861883,24.59617,0.8432799999999999
493.436,156.71,-0.03095232,24.52092,0.84259
494.34799000000004,157.01,-0.02959093,24.5375,0.8418899999999999
495.259,157.31,-0.0279959,24.81735,0.84119
496.172,157.61,-0.02431422,24.571170000000002,0.84049
497.07000999999997,157.91,-0.02549297,24.624229999999997,0.8398
497.98000999999994,158.21,-0.02458644,24.638270000000002,0.8391
498.88699,158.51,-0.02599977,24.42857,0.8384
499.77700999999996,158.81,-0.02393009,24.46199,0.83772
500.703,159.11,-0.02534569,24.38648,0.837
501.60599,159.41,-0.02862496,24.453570000000003,0.8363
502.50699000000003,159.71,-0.02934758,24.40612,0.8356100000000001
503.41500999999994,160.01,-0.02517625,24.38087,0.8349
504.306,160.31,-0.02589701,24.3977,0.83421
505.22101,160.61,-0.02755361,24.29694,0.8335
506.12701,160.91,-0.02851184,24.355610000000002,0.8328
507.02700999999996,161.21,-0.02502719,24.33036,0.8321
507.927,161.51,-0.0259848,24.313779999999998,0.8314
508.81799,161.81,-0.02132068,24.381120000000003,0.8307100000000001
509.72299000000004,162.11,-0.02438719,24.246679999999998,0.83
510.629,162.41,-0.02605083,24.20459,0.82929
511.521,162.71,-0.02607275,24.17117,0.8286
512.414,163.01,-0.02444914,24.20459,0.8279
513.3200099999999,163.31,-0.02282309,24.20459,0.82719
514.22803,163.61,-0.02095882,24.13724,0.8264799999999999
515.125,163.91,-0.02003392,24.10383,0.8257700000000001
516.02301,164.21,-0.02028694,24.11224,0.8250700000000001
516.93903,164.51,-0.02242955,24.12066,0.82435
517.84302,164.81,-0.01961329,24.12066,0.8236399999999999
518.74902,165.11,-0.0196303,24.05357,0.8229200000000001
519.63,165.41,-0.01656968,24.02832,0.8222299999999999
520.526,165.71,-0.01539939,23.95281,0.82152
521.4249900000001,166.01,-0.01517545,23.98648,0.82081
522.3220200000001,166.31,-0.01352733,23.91913,0.8201
523.2139900000001,166.61,-0.01330146,23.885460000000002,0.81939
524.11102,166.91,-0.01117341,23.82679,0.81868
525.0029900000001,167.21,-0.01023132,23.86046,0.81798
525.90198,167.51,-0.00904953,23.793110000000002,0.81726
526.79602,167.81,-0.007865639,23.74286,0.81655
527.70801,168.11,-0.005486986,23.74286,0.81583
528.62402,168.41,-0.005730673,23.6926,0.8151
529.51001,168.71,-0.00334579,23.6926,0.81439
530.40698,169.01,-0.0023919510000000002,23.67577,0.8136800000000001
531.29797,169.31,-0.0033516609999999997,23.591839999999998,0.81297
532.185,169.61,-0.0002396133,23.58342,0.81226
533.08398,169.91,0.004077034,23.58342,0.8115399999999999
533.97699,170.21,0.006000924,23.524739999999998,0.81082
534.86603,170.51,0.005285456,23.55,0.81011
535.7520099999999,170.81,0.003606883,23.49107,0.8094
536.65198,171.11,0.005776167,23.5023,0.8086800000000001
537.54797,171.41,0.006985752,23.4352,0.80796
538.4470200000001,171.71,0.008197526,23.4352,0.80724
539.3380099999999,172.01,0.007239542,23.37653,0.80652
540.237,172.31,0.009419861,23.309179999999998,0.80579
541.13397,172.61,0.008703066,23.30077,0.80507
542.034,172.91,0.009194863000000001,23.27577,0.8043399999999999
542.92102,173.21,0.01235147,23.27577,0.8036300000000001
543.81097,173.51,0.01430176,23.337239999999998,0.80291
544.70203,173.81,0.01746868,23.306379999999997,0.80219
545.58502,174.11,0.01821277,23.20587,0.80147
546.5,174.41,0.01944494,23.20561,0.80073
547.36798,174.71,0.02262463,23.13852,0.80003
548.2689799999999,175.01,0.02167133,23.13852,0.7993
549.17297,175.31,0.02290987,23.037760000000002,0.79856
550.047,175.61,0.02634542,23.06276,0.79785
550.948,175.91,0.0300321,23.11352,0.7971199999999999
551.82898,176.21,0.03005916,23.13852,0.7964
552.724,176.51,0.03106514,23.00434,0.79567
553.591,176.81,0.03305138,22.98189,0.79497
554.47699,177.11,0.03553195,22.90638,0.79424
555.36102,177.41,0.03654537,23.01556,0.79352
556.258,177.71,0.0336332,22.8977,0.79279
557.1610099999999,178.01,0.03685903,22.95102,0.79205
558.05603,178.31,0.0415663,22.9176,0.7913100000000001
558.94098,178.61,0.04406623,22.908929999999998,0.79059
559.8250099999999,178.91,0.04755637,22.85051,0.78986
560.73199,179.21,0.05179409,22.875510000000002,0.7891199999999999
561.61102,179.51,0.05505077,22.81684,0.7884
562.50098,179.81,0.05386643,22.75791,0.78767
563.39099,180.11,0.05737908,22.716070000000002,0.78693
564.28497,180.41,0.05421459,22.648979999999998,0.7862
565.17401,180.71,0.05996423,22.841839999999998,0.78547
566.078,181.01,0.06349349,22.741329999999998,0.78472
566.974,181.31,0.06727736,22.70765,0.78398
567.84802,181.61,0.06783633,22.741329999999998,0.7832600000000001
568.724,181.91,0.07212723,22.6824,0.7825300000000001
569.61298,182.21,0.07792086,22.64031,0.7818
570.4970099999999,182.51,0.07923976,22.59872,0.7810699999999999
571.39099,182.81,0.08555039,22.56505,0.78033
572.27399,183.11,0.09237131,22.53138,0.7796
573.15399,183.41,0.09495674,22.65179,0.77887
574.0369900000001,183.71,0.09804763,22.52577,0.77813
574.9299900000001,184.01,0.10265,22.50893,0.7773899999999999
575.81897,184.31,0.10876,22.475260000000002,0.77665
576.7130099999999,184.61,0.11087000000000001,22.466839999999998,0.77591
577.59003,184.91,0.11474000000000001,22.425,0.77518
578.48901,185.21,0.11938,22.425,0.7744300000000001
579.367,185.51,0.12628,22.408160000000002,0.7737
580.23401,185.81,0.12791,22.408160000000002,0.7729699999999999
581.12402,186.11,0.13282,22.341070000000002,0.77223
582.01202,186.41,0.13699,22.41378,0.77149
582.896,186.71,0.13787,22.346429999999998,0.77075
583.7930299999999,187.01,0.14534,22.45026,0.77
584.66901,187.31,0.147,22.27959,0.76927
585.55603,187.61,0.15423,22.19566,0.76852
586.44397,187.91,0.15818,22.204079999999998,0.76778
587.3220200000001,188.21,0.16417,22.153570000000002,0.7670399999999999
588.20398,188.51,0.16585,22.248720000000002,0.7663
589.0700099999999,188.81,0.16855,22.215310000000002,0.76558
589.95599,189.11,0.16897,22.14515,0.76483
590.84698,189.41,0.16888,22.21786,0.76408
591.73199,189.71,0.17567,22.1676,0.76334
592.60699,190.01,0.18222,22.08367,0.7626
593.48499,190.31,0.18598,22.15077,0.76186
594.38202,190.61,0.18539,22.07526,0.7611
595.26501,190.91,0.19044,22.10306,0.76036
596.15399,191.21,0.1937,22.07806,0.75961
597.013,191.51,0.19389,22.07806,0.75888
597.90198,191.81,0.19639,22.07806,0.75813
598.78198,192.11,0.20198,22.07806,0.75739
599.6610099999999,192.41,0.19909000000000002,22.00255,0.75664
600.54102,192.71,0.20032,22.03622,0.7559
601.42297,193.01,0.20155,21.98571,0.75515
602.29498,193.31,0.20794,22.01913,0.75441
603.1799900000001,193.61,0.21124,21.91862,0.75366
604.065,193.91,0.21041999999999997,21.84592,0.7529100000000001
604.94397,194.21,0.21425,21.91301,0.75216
605.841,194.51,0.21939,21.90459,0.7514
606.724,194.81,0.22271999999999997,21.873720000000002,0.75065
607.59698,195.11,0.22371999999999997,21.86531,0.7499100000000001
608.47803,195.41,0.2229,21.80663,0.74916
609.3560200000001,195.71,0.22313000000000002,21.86531,0.74841
610.22803,196.01,0.22751,21.79821,0.74767
611.0939900000001,196.31,0.23139,21.831889999999998,0.74693
611.9810200000001,196.61,0.2311,21.82347,0.74617
612.867,196.91,0.2329,21.7648,0.74542
613.73401,197.21,0.23836,21.756120000000003,0.74468
614.60999,197.51,0.23911999999999997,21.72245,0.74393
615.4970099999999,197.81,0.23884,21.803829999999998,0.74317
616.37,198.11,0.24301,21.70587,0.74242
617.23901,198.41,0.24824000000000002,21.70587,0.74168
618.1229900000001,198.71,0.24770999999999999,21.69745,0.74092
619.01001,199.01,0.24691,21.686220000000002,0.74016
619.89203,199.31,0.25006,21.652810000000002,0.73941
620.7810099999999,199.61,0.25374,21.644389999999998,0.73864
621.65302,199.91,0.25664000000000003,21.644389999999998,0.7379
622.52899,200.21,0.25795999999999997,21.59388,0.73714
623.38898,200.51,0.25848000000000004,21.62755,0.7364
624.24902,200.81,0.26535,21.62755,0.7356699999999999
625.1229900000001,201.11,0.27171999999999996,21.56888,0.7349100000000001
626.0,201.41,0.27783,21.6023,0.73416
626.8779900000001,201.71,0.2813,21.61071,0.7334
627.76801,202.01,0.28292,21.57704,0.73264
628.65503,202.31,0.28189000000000003,21.5352,0.73187
629.53198,202.61,0.28536999999999996,21.55179,0.73112
630.414,202.91,0.29153,21.5352,0.73036
631.2810099999999,203.21,0.2985,21.54362,0.7296100000000001
632.14697,203.51,0.29854,21.56046,0.7288600000000001
633.0189799999999,203.81,0.30713,21.5352,0.72811
633.89001,204.11,0.30638000000000004,21.52679,0.72735
634.7930299999999,204.41,0.31475,21.52679,0.7265699999999999
635.64899,204.71,0.31963,21.493370000000002,0.72583
636.52301,205.01,0.32318,21.42602,0.7250800000000001
637.38702,205.31,0.32781,21.4625,0.72433
638.2689799999999,205.61,0.33515,21.42908,0.7235699999999999
639.13202,205.91,0.33819,21.563270000000003,0.72282
640.00098,206.21,0.33936,21.44286,0.72206
640.8729900000001,206.51,0.34376,21.5324,0.72131
641.73901,206.81,0.35033000000000003,21.381120000000003,0.7205600000000001
642.617,207.11,0.35394000000000003,21.381120000000003,0.7197899999999999
643.4979900000001,207.41,0.35865,21.4176,0.7190300000000001
644.36902,207.71,0.36499000000000004,21.384179999999997,0.71827
645.23401,208.01,0.37243000000000004,21.36735,0.7175199999999999
646.09198,208.31,0.37716,21.33087,0.71677
646.96002,208.61,0.38326,21.428829999999998,0.71602
647.8389900000001,208.91,0.38666999999999996,21.25536,0.71525
648.7069700000001,209.21,0.39252,21.3898,0.7145
649.60101,209.51,0.39377,21.22194,0.71372
650.479,209.81,0.39283,21.32526,0.71296
650.76398,209.91,0.39405999999999997,21.308670000000003,0.7127100000000001