File: 01_Data/OSB/STA/N2/3K_min/OSB_STA_N2_3KData_210303_R1.csv
##Temp./Â°C,Time/min,DSC/(mW/mg),Mass/%,Sensit./(uV/mW)
49.177,10.00917,0.0037338429999999997,99.35540999999999,1.05325
49.177,10.30917,0.004293918,99.35540999999999,1.05325
49.172,10.609169999999999,0.00485399,99.33015,1.05325
49.21,10.90917,0.005974167,99.3299,1.05325
49.298,11.20917,0.006721006999999999,99.3299,1.05324
49.403,11.50917,0.01026833,99.3299,1.0532299999999999
49.59,11.80917,0.01138876,99.33015,1.0532
49.814,12.109169999999999,0.01717695,99.3299,1.0531700000000002
50.099,12.40917,0.02109848,99.29304,1.05314
50.429,12.70917,0.02371339,99.32732,1.0531
50.832,13.00917,0.02856948,99.2933,1.05305
51.248,13.309170000000002,0.0304383,99.2933,1.0529899999999999
51.706,13.60917,0.03268098,99.28454,1.05293
52.18,13.909170000000001,0.03548427,99.28479,1.05287
52.713,14.20917,0.03735432,99.26778,1.0528
53.239,14.509170000000001,0.03903781,99.25928,1.05274
53.825,14.809170000000002,0.04128224,99.22525999999999,1.05266
54.411,15.10917,0.04203253,99.3018,1.0525799999999998
55.016,15.409170000000001,0.04390402,99.3018,1.0525
55.649,15.70917,0.04708387,99.27603,1.05241
56.312,16.00917,0.04933018,99.24226999999999,1.0523200000000001
56.98,16.30917,0.05082945,99.14046,1.05223
57.667,16.609170000000002,0.05644074,99.17448,1.0521399999999999
58.388,16.90917,0.05551159,99.11495,1.0520399999999999
59.11,17.20917,0.05626465,99.14896999999999,1.0519399999999999
59.844,17.50917,0.05757883,99.21985,1.0518299999999998
60.598,17.80917,0.06001527,99.11804000000001,1.05172
61.365,18.109170000000002,0.05796478,99.11804000000001,1.05161
62.124,18.40917,0.0594669,99.25954,1.0515
62.909,18.70917,0.0600345,99.31314,1.05139
63.7,19.00917,0.05948007,99.1433,1.0512700000000001
64.517,19.30917,0.06173179,99.1518,1.05115
65.318,19.609170000000002,0.05949386,99.18581999999999,1.05103
66.165,19.90917,0.06099806,99.07576999999999,1.0509
66.965,20.20917,0.05894676,99.07552,1.05077
67.786,20.50917,0.05914108,99.01624,1.05065
68.633,20.80917,0.06120752,99.05875999999999,1.05051
69.47,21.109170000000002,0.05934322,99.00747,1.0503799999999999
70.294,21.40917,0.06047402,98.95696,1.05025
71.18,21.70917,0.05673721,98.92294,1.05011
72.019,22.00917,0.05693187,98.96521,1.04997
72.862,22.30917,0.05450446,98.99923000000001,1.0498299999999998
73.72,22.609170000000002,0.05544847,98.96546,1.04969
74.575,22.90917,0.05208369,98.99923000000001,1.04955
75.456,23.20917,0.05452697,98.96546,1.0494
76.308,23.50917,0.05490931,98.96521,1.04925
77.188,23.80917,0.05154346,98.89742,1.0491
78.042,24.109170000000002,0.05342529,98.82964,1.04895
78.927,24.40917,0.05249573,99.05,1.0488
79.815,24.70917,0.05344112,98.93119,1.04864
80.669,25.00917,0.05269869,98.82964,1.04849
81.565,25.30917,0.05120621,98.8634,1.04833
82.459,25.609170000000002,0.0508389,98.85515,1.04817
83.338,25.90917,0.04953328,98.89742,1.04801
84.23,26.20917,0.04635088,98.83789,1.04785
85.113,26.50917,0.04842265,98.82964,1.04768
86.008,26.80917,0.04692864,98.73634,1.04752
86.949,27.109170000000002,0.04505912,98.78711,1.04734
87.815,27.40917,0.04487841,98.75335,1.0471700000000002
88.716,27.70917,0.0448858,98.75335,1.047
89.608,28.00917,0.0445175,98.71959,1.04683
90.52,28.30917,0.04377356,98.80412,1.04665
91.428,28.609170000000002,0.043781,98.69948000000001,1.04647
92.339,28.90917,0.0441644,98.75052,1.04629
93.24,29.20917,0.04435994,98.68247,1.0461200000000002
94.15,29.50917,0.04399168,98.71649000000001,1.04593
95.059,29.80917,0.04343532,98.75026,1.04575
95.977,30.109170000000002,0.04419534,98.68247,1.04556
96.893,30.40917,0.04382709,98.68247,1.0453700000000001
97.823,30.70917,0.04233009,98.60644,1.04518
98.756,31.00917,0.0421498,98.61469,1.0449899999999999
99.683,31.30917,0.04121663,98.69407,1.0447899999999999
100.59,31.609170000000002,0.04310658,98.60051999999999,1.0446
101.517,31.90917,0.04367956,98.66856,1.0444
102.434,32.20917,0.04142808,98.69381,1.04421
103.372,32.509170000000005,0.04444967,98.60051999999999,1.044
104.304,32.80917,0.04558861,98.68531,1.0438
105.224,33.10917,0.04371323,98.63454,1.0436
106.141,33.40917,0.04334481,98.60077,1.0434
107.085,33.70917,0.04278806,98.68531,1.04319
108.034,34.009170000000005,0.04392798,98.6317,1.0429700000000002
108.929,34.30917,0.04110796,98.65722,1.04277
109.861,34.60917,0.04469985,98.64871,1.04256
110.775,34.90917,0.04301102,98.60619,1.04235
111.728,35.20917,0.04490693,98.59794000000001,1.04213
112.654,35.509170000000005,0.04416129,98.66546,1.0419200000000002
113.586,35.80917,0.04511434,98.61469,1.0417
114.533,36.10917,0.04399117,98.59768000000001,1.04148
115.46,36.40917,0.04343391,98.59768000000001,1.04126
116.368,36.70917,0.04608728,98.55541,1.04104
117.32,37.009170000000005,0.04345246,98.55541,1.04081
118.234,37.30917,0.04516237,98.56392,1.04059
119.178,37.60917,0.04498332,98.56392,1.04036
120.105,37.90917,0.0468836,98.59794000000001,1.04013
121.048,38.20917,0.04651589,98.5384,1.0399
121.969,38.509170000000005,0.04501306,98.5384,1.03967
122.919,38.80917,0.04615836,98.57242,1.03944
123.845,39.10917,0.04825006,98.52165,1.0392
124.781,39.40917,0.04636845,98.56366,1.0389700000000002
125.702,39.70917,0.04600029,98.56392,1.03873
126.65,40.009170000000005,0.04563234,98.55541,1.03849
127.588,40.30917,0.04753685,98.5299,1.03825
128.528,40.60917,0.04887403,98.52139,1.03801
129.47,40.90917,0.04736975,98.55541,1.03776
130.41,41.20917,0.04908673,98.5299,1.03751
131.35898999999998,41.509170000000005,0.05004642,98.56366,1.03726
132.32401000000002,41.80917,0.04873146,98.5299,1.03701
133.24001,42.10917,0.05007057,98.49588,1.0367600000000001
134.173,42.40917,0.05273857,98.54691,1.03651
135.127,42.70917,0.05199266,98.48763000000001,1.03626
136.05901,43.009170000000005,0.05162576,98.49588,1.036
137.002,43.30917,0.05277769,98.50464000000001,1.03575
137.935,43.60917,0.05146147,98.5299,1.03549
138.89101000000002,43.90917,0.05185449,98.5384,1.0352299999999999
139.826,44.20917,0.05224749,98.50464000000001,1.0349700000000002
140.77299,44.509170000000005,0.05188077,98.51314,1.0347
141.74001,44.80917,0.05455566,98.51314,1.03443
142.681,45.10917,0.05666121,98.4451,1.03416
143.62601,45.40917,0.05534462,98.48763000000001,1.03389
144.584,45.70917,0.05707142,98.52139,1.03362
145.52698999999998,46.009170000000005,0.05347092,98.52139,1.03335
146.481,46.30917,0.0525335,98.54691,1.0330700000000002
147.427,46.60917,0.05368982,98.47036,1.0328
148.38901,46.90917,0.05465662,98.47036,1.03252
149.33701000000002,47.20917,0.05524285,98.50438,1.03224
150.28999,47.509170000000005,0.05449574,98.50438,1.03196
151.255,47.80917,0.05565446,98.47062,1.03167
152.216,48.10917,0.05547929,98.48763000000001,1.03138
153.14999,48.40917,0.05625719,98.47912,1.0311
154.112,48.70917,0.05570076,98.49613000000001,1.03081
155.069,49.009170000000005,0.05533483,98.49613000000001,1.03052
156.011,49.30917,0.05611371,98.42809,1.03024
156.976,49.60917,0.05670258,98.42809,1.0299399999999999
157.914,49.90917,0.05614558,98.46211,1.02965
158.867,50.20917,0.05883607,98.42809,1.02936
159.81798999999998,50.509170000000005,0.05866191,98.41108,1.02906
160.78798999999998,50.80917,0.06001717,98.4451,1.0287600000000001
161.748,51.10917,0.05774047,98.41108,1.02845
162.69298999999998,51.40917,0.05947848,98.41108,1.02816
163.64799,51.70917,0.06140908,98.40284,1.02785
164.612,52.009170000000005,0.06161883,98.42241999999999,1.02755
165.56798999999998,52.30917,0.0624029,98.35464,1.02724
166.526,52.60917,0.06088985,98.40567,1.02693
167.479,52.909169999999996,0.06378118,98.3518,1.02662
168.436,53.20916999999999,0.06380054,98.3518,1.02631
169.39301,53.50917,0.06017862,98.38582,1.026
170.354,53.809169999999995,0.0628811,98.31778,1.02568
171.31,54.10917,0.06366754,98.36881,1.0253700000000001
172.263,54.409169999999996,0.06407083,98.31778,1.02505
173.228,54.70916999999999,0.06409095,98.33505,1.02473
174.177,55.00917,0.06507055,98.30103000000001,1.02441
175.14,55.309169999999995,0.06681922,98.33505,1.02409
176.13901,55.60917,0.0658809,98.30386999999999,1.02375
177.058,55.909169999999996,0.06859084,98.32088,1.02344
178.009,56.20916999999999,0.06745944,98.25309,1.02311
178.972,56.50917,0.06901925,98.29536,1.02278
179.935,56.809169999999995,0.06788773,98.27835,1.02245
180.908,57.10917,0.07021868,98.18505,1.02211
181.85699,57.409169999999996,0.06947158,98.15954,1.02178
182.815,57.70916999999999,0.07315192,98.12552,1.02145
183.769,58.00917,0.06932452,98.19355999999999,1.02111
184.74001,58.309169999999995,0.07050354,98.19355999999999,1.0207700000000002
185.7,58.60917,0.07283937,98.12576999999999,1.02043
186.653,58.909169999999996,0.07093594,98.12576999999999,1.02009
187.604,59.20916999999999,0.07038108,98.08325,1.01975
188.576,59.50917,0.07059803,98.08325,1.01941
189.561,59.809169999999995,0.0719733,98.01546,1.01905
190.47701,60.10917,0.07180368,97.98144,1.01872
191.459,60.409169999999996,0.07318044,97.98144,1.01836
192.399,60.70916999999999,0.07494347,97.91366,1.0180200000000001
193.401,61.00917,0.07825531,97.87964000000001,1.01765
194.33098999999999,61.309169999999995,0.07808834,97.82887,1.01731
195.308,61.60917,0.07888948,97.82887,1.01695
196.24899,61.909169999999996,0.07659546,97.78634,1.0166
197.222,62.20916999999999,0.07778373,97.78634,1.01624
198.175,62.50917,0.07781103,97.71856,1.01588
199.144,62.809169999999995,0.07919432,97.71005,1.01552
200.11301,63.10917,0.07961023,97.65928000000001,1.01515
201.067,63.409169999999996,0.08080117,97.63376,1.0147899999999999
202.035,63.70916999999999,0.08102433,97.54923000000001,1.01442
202.995,64.00917,0.0829927,97.53222,1.01406
203.955,64.30917,0.08302283,97.53479,1.01369
204.916,64.60916999999999,0.08479958,97.39923,1.01332
205.871,64.90916999999999,0.0830834,97.43299,1.01295
206.845,65.20917,0.08447375,97.33144,1.01257
207.806,65.50917,0.08508779,97.28041,1.0122
208.76601000000002,65.80917,0.08395334,97.30309,1.0118200000000002
209.726,66.10916999999999,0.08573427,97.23531,1.01145
210.69,66.40916999999999,0.08732235,97.125,1.0110700000000001
211.64301,66.70917,0.08735493,97.125,1.0106899999999999
212.604,67.00917,0.08738793,97.06289,1.01031
213.57401000000002,67.30917,0.08800551,97.02887,1.0099200000000002
214.545,67.60916999999999,0.08959761,96.81959,1.0095299999999998
215.509,67.90916999999999,0.0888526,96.88736999999999,1.00914
216.45598999999999,68.20917,0.08966595,96.81985,1.00876
217.42999,68.50917,0.09145604,96.78556999999999,1.00837
218.386,68.80917,0.09207652,96.68401999999999,1.0079799999999999
219.347,69.10916999999999,0.09386873,96.61624,1.00759
220.31,69.40916999999999,0.09566254,96.44665,1.00719
221.27299,69.70917,0.09745791,96.37576999999999,1.0068
222.231,70.00917,0.09632388,96.42655,1.0064
223.202,70.30917,0.09714422,96.35051999999999,1.006
224.16499,70.60916999999999,0.09992043,96.21469,1.0056
225.132,70.90916999999999,0.09996052,96.11289000000001,1.0052
226.089,71.20917,0.09921759,96.11289000000001,1.0048
227.052,71.50917,0.10122,96.01108,1.00439
228.02,71.80917,0.10165,95.9433,1.0039799999999999
228.97501,72.10916999999999,0.1013,95.85,1.00358
229.938,72.40916999999999,0.10389000000000001,95.81314,1.0031700000000001
230.896,72.70917,0.10413,95.7116,1.00276
231.85898999999998,73.00917,0.10338,95.64356,1.00235
232.814,73.30917,0.10303,95.50799,1.00194
233.783,73.60916999999999,0.10228999999999999,95.43995,1.00152
234.743,73.90916999999999,0.10350999999999999,95.40619000000001,1.00111
235.705,74.20917,0.10709,95.2366,1.0006899999999999
236.66499,74.50917,0.10733,95.10077,1.00027
237.634,74.80917,0.1062,95.01598,0.99985
238.599,75.10916999999999,0.10683,94.92268,0.9994299999999999
239.558,75.40916999999999,0.10805999999999999,94.88866,0.999
240.524,75.70917,0.10968,94.71933,0.9985799999999999
241.49001,76.00917,0.11110999999999999,94.60335,0.99815
242.44701,76.30917,0.11115,94.56081999999999,0.9977299999999999
243.41499,76.60916999999999,0.11435999999999999,94.34046,0.99729
244.36301,76.90916999999999,0.11283,94.26392,0.99687
245.339,77.20917,0.11268,94.16211,0.9964299999999999
246.31599,77.50917,0.11549000000000001,94.02655,0.9959899999999999
247.261,77.80917,0.11515,93.85696,0.9955700000000001
248.217,78.10916999999999,0.11796,93.70438,0.99513
249.17598999999998,78.40916999999999,0.11762,93.58556999999999,0.9947
250.13499,78.70917,0.11807000000000001,93.44691,0.99426
251.106,79.00917,0.1205,93.24072,0.9938100000000001
252.06,79.30917,0.12134,93.02861,0.9933799999999999
253.015,79.60916999999999,0.1212,92.93814,0.9929399999999999
253.985,79.90916999999999,0.12185,92.82809,0.99249
254.94,80.20917,0.11853,92.60746999999999,0.99205
255.89799,80.50917,0.12037,92.37294,0.9916
256.862,80.80917,0.1232,92.26263,0.99115
257.82901,81.10916999999999,0.12245999999999999,92.08144,0.9907
258.797,81.40916999999999,0.12172000000000001,91.90361,0.99024
259.74799,81.70917,0.12218,91.67732,0.9898
260.741,82.00917,0.12522,91.40309,0.9893299999999999
261.66598999999997,82.30917,0.12547,91.1799,0.9888899999999999
262.62201,82.60916999999999,0.12692,91.02139,0.98844
263.58701,82.90916999999999,0.12718,90.81237,0.98798
264.543,83.20917,0.12724000000000002,90.63119,0.9875200000000001
265.505,83.50917,0.1273,90.31753,0.98706
266.46898999999996,83.80917,0.12955,90.0518,0.98659
267.42599,84.10916999999999,0.12980999999999998,89.78918,0.98613
268.39301,84.40916999999999,0.13147,89.53737,0.9856600000000001
269.354,84.70917,0.13472,89.24356,0.9852
270.314,85.00917,0.13598,89.02577,0.9847299999999999
271.26501,85.30917,0.13665,88.63557,0.9842700000000001
272.22198,85.60916999999999,0.13671,88.42629000000001,0.9838
273.202,85.90916999999999,0.13698,88.23969,0.9833200000000001
274.133,86.20917,0.14024,87.86959,0.9828600000000001
275.09799,86.50917,0.14151,87.53325,0.9823799999999999
276.048,86.80917,0.14038,87.23634,0.9819100000000001
277.00699,87.10916999999999,0.14385,86.89124,0.9814299999999999
277.961,87.40916999999999,0.14573,86.59459,0.98096
278.918,87.70917,0.1464,86.17912,0.9804799999999999
279.883,88.00917,0.14728,85.87371,0.98
280.83801,88.30917,0.14835,85.59380999999999,0.9795200000000001
281.797,88.60916999999999,0.15144000000000002,85.14407,0.97903
282.76401,88.90916999999999,0.15111,84.85025999999999,0.97854
283.728,89.20917,0.1538,84.4518,0.97806
284.67499,89.50917,0.15589,84.03325,0.97757
285.63698999999997,89.80917,0.15959,83.57809,0.97708
286.58701,90.10916999999999,0.15805999999999998,83.2701,0.9766
287.552,90.40916999999999,0.16055,82.80644000000001,0.9761
288.505,90.70917,0.16063,82.37938,0.9756100000000001
289.457,91.00917,0.16233,81.97525999999999,0.9751200000000001
290.42099,91.30917,0.16604000000000002,81.55386999999999,0.9746299999999999
291.37299,91.60916999999999,0.16774,81.10746999999999,0.9741299999999999
292.332,91.90916999999999,0.16621,80.66906999999999,0.9736299999999999
293.28799,92.20917,0.16913,80.22551999999999,0.97314
294.245,92.50917,0.17285,79.6317,0.97264
295.19698999999997,92.80917,0.17456,79.24149,0.97214
296.16598999999997,93.10916999999999,0.17586,78.78093,0.9716299999999999
297.104,93.40916999999999,0.17859,78.31443,0.97114
298.056,93.70917,0.18131,77.76289,0.9706299999999999
299.01401,94.00917,0.18525999999999998,77.29381,0.9701299999999999
299.96398999999997,94.30917,0.18738,76.77938,0.96962
300.922,94.60916999999999,0.1891,76.26186,0.96911
301.87701,94.90916999999999,0.19347,75.65979,0.9686
302.82401,95.20917,0.19336,75.18763,0.9681
303.78299,95.50917,0.19469,74.67036,0.9675799999999999
304.73001,95.80917,0.19601,74.08247,0.9670700000000001
305.68399,96.10916999999999,0.19794,73.54253,0.9665600000000001
306.64401000000004,96.40916999999999,0.2007,72.97423,0.96604
307.58801,96.70917,0.20121,72.39485,0.9655299999999999
308.54401,97.00917,0.20356,71.82938,0.96501
309.49799,97.30917,0.20795,71.21030999999999,0.96449
310.45401,97.60916999999999,0.21031,70.58273,0.9639700000000001
311.41101000000003,97.90916999999999,0.21266999999999997,69.98040999999999,0.96345
312.36099,98.20917,0.21605,69.25103,0.96293
313.314,98.50917,0.21821,68.77603,0.9624
314.255,98.80917,0.21894,68.12886999999999,0.96188
315.21398999999997,99.10916999999999,0.22416999999999998,67.43351,0.96135
316.16,99.40916999999999,0.2243,66.76907,0.96083
317.116,99.70917,0.22830999999999999,66.18943,0.9603
318.06,100.00917,0.23008,65.48299,0.9597700000000001
319.01401,100.30917,0.23246,64.76778,0.95924
319.96301,100.60916999999999,0.23443000000000003,64.1116,0.9587100000000001
320.94,100.90916999999999,0.23826,63.35696,0.95816
321.871,101.20917,0.24044000000000001,62.6982,0.9576399999999999
322.832,101.50917,0.24325,61.98299,0.9571
323.78699,101.80917,0.2477,61.21134,0.9565600000000001
324.741,102.10916999999999,0.24764,60.476290000000006,0.9560200000000001
325.69501,102.40916999999999,0.24984,59.71031,0.9554799999999999
326.63901,102.70917,0.25368,58.95825,0.95494
327.57901,103.00917,0.2563,58.217530000000004,0.9544100000000001
328.522,103.30917,0.26221,57.39485,0.9538700000000001
329.47299,103.60916999999999,0.26484,56.606190000000005,0.9533200000000001
330.41901,103.90916999999999,0.26334,55.8683,0.95278
331.36801,104.20917,0.26452,55.000519999999995,0.95224
332.32001,104.50917,0.26674000000000003,54.194590000000005,0.9516899999999999
333.26401,104.80917,0.26938,53.33531,0.95114
334.20901000000003,105.10916999999999,0.26766999999999996,52.55515,0.9505899999999999
335.151,105.40916999999999,0.27051,51.69562,0.95005
336.10101000000003,105.70917,0.26943,50.90412,0.9495
337.052,106.00917,0.27061999999999997,49.94304,0.94894
337.991,106.30917,0.26891,49.075,0.94839
338.94199,106.60916999999999,0.26409,48.334540000000004,0.94784
339.88698999999997,106.90916999999999,0.26487,47.506190000000004,0.9472799999999999
340.828,107.20917,0.26274000000000003,46.62397,0.94673
341.78299,107.50917,0.26082,45.78454,0.9461700000000001
342.73199,107.80917,0.25723,44.93067,0.9456
343.67401,108.10916999999999,0.25093000000000004,44.164429999999996,0.94505
344.617,108.40916999999999,0.24670999999999998,43.29407,0.9444899999999999
345.565,108.70917,0.24206,42.4884,0.9439200000000001
346.51599,109.00917,0.23575,41.71366,0.9433600000000001
347.45999,109.30917,0.22671,41.094590000000004,0.94279
348.40302,109.60916999999999,0.21933000000000002,40.24098,0.9422299999999999
349.35598999999996,109.90916999999999,0.20756,39.61598,0.94166
350.289,110.20917,0.1964,39.05335,0.9411
351.23599,110.50917,0.18795,38.3384,0.94053
352.16598999999997,110.80917,0.17551,37.90567,0.9399700000000001
353.12201,111.10916999999999,0.16641,37.30928,0.93939
354.05801,111.40916999999999,0.15227000000000002,36.83428,0.9388200000000001
355.01501,111.70917,0.14126,36.30567,0.93824
355.944,112.00917,0.12939,36.0768,0.93768
356.89301,112.30917,0.12022999999999999,35.70335,0.9371
357.83301,112.60916999999999,0.11295999999999999,35.38995,0.93652
358.776,112.90916999999999,0.10336,35.12706,0.93595
359.72101000000004,113.20917,0.09691191,34.883759999999995,0.93537
360.664,113.50917,0.08750617,34.70851,0.93479
361.61099,113.80917,0.08524548,34.43428,0.9342
362.55701,114.10916999999999,0.0812971,34.29871,0.9336200000000001
363.48499,114.40916999999999,0.07692147,34.162890000000004,0.93305
364.44501,114.70917,0.07380735,34.01856,0.93245
365.37201,115.00917,0.07427494,33.91675,0.9318799999999999
366.319,115.30917,0.07558875,33.81804,0.93129
367.254,115.60916999999999,0.0754248,33.61443,0.93071
368.18799,115.90916999999999,0.07631771,33.56057,0.9301200000000001
369.13599,116.20917,0.07467406,33.48454,0.92953
370.10001,116.50917,0.07641606,33.34021,0.9289299999999999
371.00699,116.80917,0.07519209,33.30619,0.9283600000000001
371.94698999999997,117.10916999999999,0.0741803,33.1366,0.92776
372.892,117.40916999999999,0.07253132,33.16778,0.92717
373.828,117.70917,0.07109209,33.06881,0.92658
374.76801,118.00917,0.06943894,32.899229999999996,0.9259799999999999
375.70401,118.30917,0.06990844,32.79742,0.9253899999999999
376.638,118.60916999999999,0.06889017,32.70412,0.9248
377.573,118.90916999999999,0.06723243,32.55722,0.9242
378.51401,119.20917,0.06514711,32.39613,0.9236
379.448,119.50917,0.06092848,32.46675,0.923
380.41699,119.80917,0.06075626,32.34253,0.92238
381.34,120.10916999999999,0.05823546,32.23222,0.92179
382.254,120.40916999999999,0.05720531,32.13041,0.9212100000000001
383.17599,120.70917,0.05766935,32.09923,0.92061
384.117,121.00917,0.05172291,31.929640000000003,0.92001
385.04599,121.30917,0.05132891,31.861859999999997,0.9194100000000001
385.978,121.60916999999999,0.05007853,31.78557,0.9188
386.91699,121.90916999999999,0.04904096,31.7683,0.91819
387.836,122.20917,0.04735851,31.666490000000003,0.9176
388.78101000000004,122.50917,0.04567477,31.531190000000002,0.9169799999999999
389.71799,122.80917,0.04420315,31.463140000000003,0.91637
390.65701,123.10916999999999,0.04466218,31.3951,0.91576
391.60699,123.40916999999999,0.04082488,31.259790000000002,0.91514
392.51999,123.70917,0.04321667,31.12397,0.9145399999999999
393.45499,124.00917,0.04044869,31.09562,0.9139299999999999
394.40302,124.30917,0.04198339,31.02784,0.9133
395.30099,124.60916999999999,0.04222603,30.9232,0.91271
396.233,124.90916999999999,0.04354799,30.78763,0.9121
397.16199,125.20917,0.03990992,30.82423,0.91148
398.09799,125.50917,0.04166407,30.69691,0.91086
399.026,125.80917,0.0403961,30.620620000000002,0.91025
399.98098999999996,126.10916999999999,0.04042427,30.586859999999998,0.9096200000000001
400.89898999999997,126.40916999999999,0.04088406,30.41443,0.909
401.828,126.70917,0.03961314,30.414179999999998,0.9083899999999999
402.767,127.00917,0.04072356,30.20232,0.90776
403.68799,127.30917,0.03945064,30.12603,0.90714
404.61499,127.60916999999999,0.04273131,29.99897,0.9065200000000001
405.556,127.90916999999999,0.04167578,29.89691,0.90589
406.46898999999996,128.20917,0.04517936,29.959020000000002,0.90528
407.39499,128.50916999999998,0.04868821,29.76985,0.90465
408.32501,128.80917,0.04741693,29.73582,0.9040299999999999
409.24799,129.10917,0.04897325,29.71057,0.9034
410.20099,129.40917,0.05031511,29.591490000000004,0.90276
411.09799,129.70917,0.04882327,29.55773,0.90215
412.03299,130.00916999999998,0.05103878,29.421909999999997,0.9015200000000001
412.965,130.30917,0.0515112,29.30309,0.9008799999999999
413.88501,130.60917,0.05460491,29.30335,0.9002600000000001
414.814,130.90917,0.05857768,29.26933,0.8996200000000001
415.75299,131.20917,0.05861947,29.184540000000002,0.8989799999999999
416.677,131.50916999999998,0.05887959,29.031959999999998,0.89835
417.60699,131.80917,0.06220696,28.96418,0.89771
418.52802,132.10917,0.06729222,28.82835,0.8970799999999999
419.461,132.40917,0.06602425,28.82835,0.89644
420.37201,132.70917,0.06870451,28.79433,0.89581
421.30099,133.00916999999998,0.06985196,28.667270000000002,0.89517
422.224,133.30917,0.07297916,28.625,0.89454
423.14300999999995,133.60917,0.07457086,28.5317,0.8939
424.06699000000003,133.90917,0.07418402,28.4299,0.89326
424.995,134.20917,0.07269549,28.429640000000003,0.8926200000000001
425.91,134.50916999999998,0.07627443,28.35335,0.8919799999999999
426.83700999999996,134.80917,0.07434417,28.40155,0.8913399999999999
427.76500999999996,135.10917,0.07682657,28.26598,0.89069
428.67599,135.40917,0.07533497,28.13015,0.89005
429.59200999999996,135.70917,0.07561028,28.08196,0.88941
430.52499000000006,136.00916999999998,0.0769933,27.997159999999997,0.88876
431.44100999999995,136.30917,0.07727037,27.997159999999997,0.88812
432.38100999999995,136.60917,0.07998666,27.87835,0.88746
433.29501,136.90917,0.08204019,27.87861,0.88682
434.21200999999996,137.20917,0.08010293,27.84485,0.8861700000000001
435.133,137.50916999999998,0.08038373,27.74278,0.8855200000000001
436.04199000000006,137.80917,0.08177532,27.641240000000003,0.8848799999999999
436.96799000000004,138.10917,0.08250302,27.65799,0.8842200000000001
437.884,138.40917,0.0836763,27.55619,0.8835799999999999
438.83499000000006,138.70917,0.08240394,27.4884,0.8829
439.724,139.00916999999998,0.08491451,27.46289,0.8822700000000001
440.646,139.30917,0.0852007,27.378090000000004,0.88161
441.57000999999997,139.60917,0.08660358,27.403609999999997,0.8809600000000001
442.49799,139.90917,0.08912579,27.3951,0.88029
443.40700999999996,140.20917,0.08986218,27.19149,0.87965
444.32401,140.50916999999998,0.08992923,27.157729999999997,0.8789899999999999
445.242,140.80917,0.08842944,27.22552,0.8783299999999999
446.15799000000004,141.10917,0.08625524,27.17448,0.8776700000000001
447.09200999999996,141.40917,0.08475173,27.08995,0.877
447.99899000000005,141.70917,0.08301979,27.013659999999998,0.87635
448.91199000000006,142.00916999999998,0.07993848,26.979640000000003,0.87569
449.84200999999996,142.30917,0.08044919,26.911859999999997,0.87502
450.755,142.60917,0.07736142,26.94562,0.87436
451.66,142.90917,0.07899476,26.897679999999998,0.87371
452.57999,143.20917,0.07432524,26.82113,0.8730399999999999
453.48999000000003,143.50916999999998,0.07641004,26.7451,0.8723799999999999
454.435,143.80917,0.07759806,26.71108,0.8717
455.31600999999995,144.10917,0.07652641,26.71108,0.8710600000000001
456.23801,144.40917,0.077715,26.66856,0.87039
457.14499000000006,144.70917,0.07573929,26.583759999999998,0.86972
458.069,145.00916999999998,0.07602432,26.583759999999998,0.86905
458.98000999999994,145.30917,0.07630905,26.51598,0.8683799999999999
459.888,145.60917,0.07999324,26.60077,0.86772
460.797,145.90917,0.07778685,26.51572,0.86705
461.71799000000004,146.20917,0.08102496,26.414179999999998,0.8663799999999999
462.62701,146.50916999999998,0.07995178,26.34613,0.8657100000000001
463.54501,146.80917,0.078423,26.278609999999997,0.8650399999999999
464.46200999999996,147.10917,0.07734683,26.278609999999997,0.86436
465.383,147.40917,0.07740765,26.29536,0.8636799999999999
466.289,147.70917,0.07723981,26.244329999999998,0.86301
467.216,148.00916999999998,0.07798528,26.19356,0.8623299999999999
468.12299,148.30917,0.07895886,26.17655,0.86166
469.03299000000004,148.60917,0.08107617,26.11753,0.86098
469.936,148.90917,0.0806822,26.040979999999998,0.86031
470.84299000000004,149.20917,0.08005922,26.07474,0.85964
471.754,149.50916999999998,0.08080915,26.023970000000002,0.8589600000000001
472.659,149.80917,0.08224723,25.96469,0.85829
473.565,150.10917,0.08460484,25.96469,0.85761
474.47500999999994,150.40917,0.07962373,25.930670000000003,0.85693
475.38,150.70917,0.08129415,25.96469,0.85625
476.276,151.00916999999998,0.08273682,25.894070000000003,0.8555799999999999
477.19199000000003,151.30917,0.0816532,25.893810000000002,0.8549
478.09799000000004,151.60917,0.08263894,25.86005,0.8542200000000001
479.009,151.90917,0.08316595,25.792270000000002,0.8535299999999999
479.91101,152.20917,0.08300154,25.698710000000002,0.85285
480.819,152.50916999999998,0.08122216,25.65644,0.8521700000000001
481.71799000000004,152.80917,0.0845198,25.64794,0.85149
482.62399000000005,153.10917,0.08458773,25.68196,0.8508100000000001
483.53,153.40917,0.08766274,25.58015,0.8501200000000001
484.444,153.70917,0.08727111,25.546129999999998,0.8494299999999999
485.366,154.00916999999998,0.08942802,25.51237,0.8487299999999999
486.26401,154.30917,0.08926795,25.51237,0.84805
487.18399000000005,154.60917,0.08771713,25.51237,0.84736
488.08800999999994,154.90917,0.08639484,25.49536,0.84667
488.995,155.20917,0.08948695,25.48686,0.84598
489.89899,155.50916999999998,0.0881641,25.444589999999998,0.84529
490.80899000000005,155.80917,0.08870217,25.43582,0.8446
491.70800999999994,156.10917,0.0885413,25.30876,0.84391
492.62201,156.40917,0.091413,25.28325,0.84321
493.52802,156.70917,0.09032127,25.198710000000002,0.84252
494.43201,157.00916999999998,0.09296494,25.19845,0.84183
495.33401,157.30917,0.09304139,25.44742,0.8411299999999999
496.23900999999995,157.60917,0.09686174,25.24948,0.84044
497.13699,157.90917,0.09858044,25.27758,0.83975
498.02899,158.20917,0.10077,25.28325,0.83906
498.93799,158.50916999999998,0.09733618,25.10541,0.83836
499.85101,158.80917,0.1,25.10515,0.8376600000000001
500.75,159.10917,0.0998481,25.029120000000002,0.8369700000000001
501.651,159.40917,0.10111,25.09691,0.8362700000000001
502.55099,159.70917,0.1026,25.00619,0.83557
503.46200999999996,160.00916999999998,0.10457000000000001,25.00619,0.8348700000000001
504.37399000000005,160.30917,0.10608,24.97242,0.83416
505.26999000000006,160.60917,0.10263,24.870620000000002,0.83347
506.18399000000005,160.90917,0.10413,24.9299,0.8327600000000001
507.07000999999997,161.20917,0.10822999999999999,24.9384,0.8320700000000001
507.97299000000004,161.50916999999998,0.11022,24.95541,0.83136
508.86499000000003,161.80917,0.11315,24.98943,0.83067
509.76901,162.10917,0.11254000000000002,24.85387,0.82996
510.668,162.40917,0.11263,24.81985,0.82926
511.57199,162.70917,0.11485999999999999,24.811339999999998,0.8285600000000001
512.47198,163.00916999999998,0.11757000000000001,24.80258,0.82785
513.38,163.30917,0.11839000000000001,24.811339999999998,0.82714
514.263,163.60917,0.12182,24.7433,0.82645
515.1799900000001,163.90917,0.12478,24.70928,0.82573
516.06598,164.20917,0.12894,24.72629,0.8250299999999999
516.9810200000001,164.50916999999998,0.12905,24.70103,0.82431
517.867,164.80917,0.13203,24.73479,0.82362
518.7689799999999,165.10917,0.13118,24.675520000000002,0.82291
519.6610099999999,165.40917,0.1356,24.62474,0.8222
520.56799,165.70917,0.13668,24.5567,0.8214899999999999
521.47101,166.00916999999998,0.14087,24.55696,0.8207700000000001
522.367,166.30917,0.14195,24.52294,0.82006
523.26099,166.60917,0.14399,24.48892,0.8193600000000001
524.1560099999999,166.90917,0.14964,24.4549,0.81865
525.0380200000001,167.20917,0.15145,24.45515,0.81795
525.93903,167.50916999999998,0.15350999999999998,24.404120000000002,0.81723
526.83398,167.80917,0.15846,24.33634,0.81652
527.73999,168.10917,0.1586,24.35335,0.8158
528.62598,168.40917,0.16355999999999998,24.28557,0.8151
529.54102,168.70917,0.16902,24.319329999999997,0.8143699999999999
530.4299900000001,169.00916999999998,0.17085999999999998,24.32784,0.81366
531.32599,169.30917,0.17149,24.24304,0.81294
532.22198,169.60917,0.17479,24.226029999999998,0.81223
533.125,169.90917,0.17955,24.26005,0.8115
534.02301,170.20917,0.1831,24.19227,0.81079
534.92102,170.50916999999998,0.18497,24.22629,0.81007
535.80902,170.80917,0.1878,24.16675,0.80935
536.7119799999999,171.10917,0.19332,24.22036,0.8086300000000001
537.59497,171.40917,0.20152,24.13557,0.80792
538.48798,171.70917,0.20194,24.135820000000002,0.8072
539.39001,172.00916999999998,0.20578000000000002,24.11881,0.80648
540.2880200000001,172.30917,0.20621,24.05077,0.80575
541.21002,172.60917,0.21153000000000002,24.042270000000002,0.80501
542.078,172.90917,0.21366999999999997,24.00851,0.8043100000000001
542.96802,173.20917,0.21704,24.01701,0.8035899999999999
543.8560200000001,173.50916999999998,0.21993000000000001,24.07912,0.80287
544.75702,173.80917,0.22551999999999997,24.03119,0.80214
545.633,174.10917,0.22695,23.92938,0.80143
546.5360099999999,174.40917,0.23403000000000002,23.954639999999998,0.8007
547.427,174.70917,0.23744,23.878610000000002,0.79998
548.315,175.00916999999998,0.24356,23.87835,0.7992600000000001
549.20898,175.30917,0.24403000000000002,23.80206,0.7985300000000001
550.09998,175.60917,0.25115,23.81881,0.79781
550.99597,175.90917,0.25804,23.8701,0.79708
551.888,176.20917,0.25976,23.92088,0.79635
552.78302,176.50916999999998,0.26074,23.75129,0.79562
553.7000099999999,176.80917,0.2642,23.78789,0.79488
554.5819700000001,177.10917,0.26914,23.7116,0.7941600000000001
555.46698,177.40917,0.2736,23.78789,0.79343
556.35901,177.70917,0.27584000000000003,23.68608,0.7927
557.2529900000001,178.00916999999998,0.28528000000000003,23.75696,0.79197
558.13501,178.30917,0.28753,23.722939999999998,0.79125
559.0310099999999,178.60917,0.29277,23.71443,0.79052
559.922,178.90917,0.29827,23.68918,0.78978
560.80701,179.20917,0.30477,23.680410000000002,0.78906
561.6970200000001,179.50916999999998,0.3083,23.621129999999997,0.78833
562.59198,179.80917,0.31033,23.55335,0.78759
563.47699,180.10917,0.31511999999999996,23.56186,0.78686
564.36902,180.40917,0.31966999999999995,23.46856,0.78613
565.255,180.70917,0.32472,23.6549,0.7854
566.14801,181.00916999999998,0.32728,23.60412,0.78466
567.039,181.30917,0.32884,23.51933,0.78393
567.91699,181.60917,0.33216,23.58737,0.7832
568.81897,181.90917,0.33221999999999996,23.50232,0.78246
569.7119799999999,182.20917,0.33908,23.459789999999998,0.78172
570.59802,182.50916999999998,0.34393,23.41778,0.78098
571.5,182.80917,0.35056,23.39227,0.7802399999999999
572.35303,183.10917,0.35819,23.39227,0.7795300000000001
573.237,183.40917,0.35929,23.51366,0.7788
574.13501,183.70917,0.35761,23.40335,0.77805
575.02502,184.00916999999998,0.36401999999999995,23.3951,0.7773100000000001
575.90802,184.30917,0.36816,23.32706,0.77658
576.8049900000001,184.60917,0.36928,23.344070000000002,0.77583
577.68701,184.90917,0.37343000000000004,23.32706,0.7751
578.5700099999999,185.20917,0.37836,23.32706,0.77436
579.461,185.50916999999998,0.38406,23.3018,0.77362
580.3319700000001,185.80917,0.38695999999999997,23.30155,0.77289
581.21802,186.10917,0.38961999999999997,23.26778,0.77215
582.10498,186.40917,0.39229,23.32423,0.77141
582.99298,186.70917,0.39165,23.2732,0.77067
583.87402,187.00916999999998,0.39866999999999997,23.37809,0.76993
584.76703,187.30917,0.40084000000000003,23.23943,0.76918
585.63898,187.60917,0.4066,23.188660000000002,0.76845
586.526,187.90917,0.40699,23.17165,0.76771
587.4130200000001,188.20917,0.41123000000000004,23.13789,0.7669699999999999
588.3079799999999,188.50916999999998,0.41163,23.26778,0.76622
589.19598,188.80917,0.41152,23.2,0.76547
590.06598,189.10917,0.41526,23.16314,0.76474
590.95599,189.40917,0.41644,23.21959,0.76399
591.8380099999999,189.70917,0.42431,23.185570000000002,0.76325
592.72302,190.00916999999998,0.42705,23.12629,0.7625
593.61298,190.30917,0.4316,23.12629,0.76175
594.47803,190.60917,0.43433999999999995,23.03325,0.76102
595.36401,190.90917,0.43528,23.13196,0.7602800000000001
596.22198,191.20917,0.43828999999999996,23.07294,0.75955
597.112,191.50916999999998,0.43301999999999996,23.07268,0.7588
597.99597,191.80917,0.43604,23.1067,0.75805
598.88397,192.10917,0.44088999999999995,23.1067,0.7573
599.76703,192.40917,0.44314,23.04716,0.75655
600.65002,192.70917,0.44383999999999996,23.04716,0.75581
601.5499900000001,193.00916999999998,0.44688999999999995,23.03015,0.7550399999999999
602.41998,193.30917,0.4515,23.06418,0.75431
603.29199,193.60917,0.45455,22.996389999999998,0.75357
604.1779799999999,193.90917,0.45736000000000004,22.888920000000002,0.7528199999999999
605.047,194.20917,0.46042,22.99072,0.75208
605.91901,194.50916999999998,0.46323000000000003,22.99072,0.75134
606.81598,194.80917,0.46763000000000005,22.98505,0.75057
607.69299,195.10917,0.46783,22.97655,0.74983
608.5750099999999,195.40917,0.46935,22.88325,0.74908
609.461,195.70917,0.4693,22.95103,0.74832
610.36102,196.00916999999998,0.47189,22.90026,0.74756
611.20599,196.30917,0.47523999999999994,22.95103,0.74683
612.086,196.60917,0.47703,22.942529999999998,0.74608
612.97198,196.90917,0.47725,22.88351,0.74533
613.85101,197.20917,0.48063999999999996,22.85773,0.74458
614.74402,197.50916999999998,0.48034,22.84072,0.7438100000000001
615.60999,197.80917,0.48346999999999996,22.92268,0.74307
616.4810200000001,198.10917,0.48528000000000004,22.78995,0.74233
617.35901,198.40917,0.49213,22.823970000000003,0.74158
618.2310200000001,198.70917,0.4913,22.823970000000003,0.74083
619.09601,199.00916999999998,0.49206000000000005,22.77861,0.7400899999999999
619.98499,199.30917,0.4931,22.77861,0.73933
620.85303,199.60917,0.49518999999999996,22.77861,0.73858
621.71997,199.90917,0.49541999999999997,22.74485,0.7378399999999999
622.59302,200.20917,0.49538999999999994,22.72784,0.7370899999999999
623.48901,200.50916999999998,0.49431,22.73634,0.73632
624.36798,200.80917,0.50016,22.77036,0.73556
625.24298,201.10917,0.50389,22.74485,0.7348100000000001
626.11401,201.40917,0.51137,22.736079999999998,0.73406
626.995,201.70917,0.51377,22.736079999999998,0.7333
627.86499,202.00916999999998,0.51752,22.70232,0.73255
628.737,202.30917,0.51698,22.66856,0.7318
629.63501,202.60917,0.5183300000000001,22.70232,0.7310300000000001
630.49402,202.90917,0.51993,22.70232,0.73029
631.35901,203.20917,0.52181,22.71933,0.72954
632.23999,203.50916999999998,0.52236,22.70232,0.72878
633.11603,203.80917,0.52722,22.69381,0.72802
634.005,204.10917,0.52805,22.70232,0.72725
634.87903,204.40917,0.53482,22.70232,0.7265
635.77802,204.70917,0.5354,22.67706,0.72572
636.64099,205.00916999999998,0.54164,22.64304,0.72497
637.52301,205.30917,0.54357,22.67139,0.72421
638.38599,205.60917,0.5512,22.63737,0.72346
639.263,205.90917,0.55505,22.77294,0.7227
640.13501,206.20917,0.56135,22.65129,0.72195
640.99402,206.50916999999998,0.56383,22.73351,0.7212
641.86603,206.80917,0.56934,22.58918,0.72045
642.737,207.10917,0.57267,22.58918,0.7196899999999999
643.62097,207.40917,0.57602,22.592010000000002,0.71892
644.49103,207.70917,0.57744,22.592010000000002,0.71817
645.36401,208.00916999999998,0.58436,22.575,0.71741
646.23297,208.30917,0.5896399999999999,22.57216,0.71665
647.09198,208.60917,0.5974,22.67139,0.7159
647.97302,208.90917,0.5988600000000001,22.46211,0.71514
648.85199,209.20917,0.6017100000000001,22.6317,0.71437
649.72699,209.50916999999998,0.60648,22.47062,0.7136100000000001
650.60199,209.80917000000002,0.60575,22.54124,0.71285
650.8939799999999,209.90917000000002,0.60845,22.52448,0.71259