File: 01_Data/Overstuffed_Chair_Polyester_Fabric/STA/N2/10K_min/Deprecated/Overstuffed_Chair_Polyester_Fabric_STA_N2_10KData_210222_R1.csv
##Temp./Â°C,Time/min,DSC/(mW/mg),Mass/%,Gas Flow(purge1)/(ml/min),Gas Flow(protective)/(ml/min),Sensit./(uV/mW)
47.544,10.01,0.01426355,98.98,50.0,20.0,1.08959
47.563,10.11,0.01452298,98.93148000000001,50.0,20.0,1.08958
47.565,10.21,0.01400431,98.80963,50.0,20.0,1.08958
47.575,10.31,0.01633842,98.80963,50.0,20.0,1.08958
47.584,10.41,0.01711649,98.82185,50.0,20.0,1.0895700000000001
47.594,10.51,0.01530115,98.89480999999999,50.0,20.0,1.0895700000000001
47.641,10.61,0.01711681,98.80963,50.0,20.0,1.08955
47.654,10.71,0.02100708,98.72444,50.0,20.0,1.08955
47.693,10.81,0.02204476,98.71185,50.0,20.0,1.0895299999999999
47.759,10.91,0.0223046,98.67556,50.0,20.0,1.08951
47.811,11.01,0.02437986,98.73666999999999,50.0,20.0,1.08949
47.905,11.11,0.02775242,98.76111,50.0,20.0,1.08946
48.014,11.21,0.0293097,98.80963,50.0,20.0,1.08942
48.133,11.31,0.03034842,98.76889,50.0,20.0,1.0893700000000002
48.265,11.41,0.03424074,98.64296,50.0,20.0,1.08932
48.448,11.51,0.03787465,98.59852,50.0,20.0,1.0892600000000001
48.621,11.61,0.03787684,98.52111,50.0,20.0,1.0892
48.849,11.71,0.04332818,98.56593000000001,50.0,20.0,1.08911
49.109,11.81,0.04462931,98.66333,50.0,20.0,1.08902
49.374,11.91,0.04722823,98.65519,50.0,20.0,1.08892
49.662,12.01,0.05034704,98.5863,50.0,20.0,1.0888200000000001
49.977,12.11,0.05242875,98.58593,50.0,20.0,1.0887
50.328,12.21,0.05191578,98.63926,50.0,20.0,1.08857
50.697,12.31,0.05529718,98.63110999999999,50.0,20.0,1.08844
51.079,12.41,0.05738145,98.54963000000001,50.0,20.0,1.0883
51.49,12.51,0.05816846,98.5537,50.0,20.0,1.08815
51.913,12.61,0.05687819,98.45222,50.0,20.0,1.08799
52.371,12.71,0.05740654,98.44815,50.0,20.0,1.08782
52.844,12.81,0.05767555,98.46,50.0,20.0,1.08765
53.328,12.91,0.05924411,98.44815,50.0,20.0,1.0874700000000002
53.835,13.01,0.05925434,98.50074000000001,50.0,20.0,1.08728
54.363,13.11,0.05874515,98.59815,50.0,20.0,1.0870799999999998
54.903,13.21,0.05927595,98.52519000000001,50.0,20.0,1.0868799999999998
55.443,13.31,0.05668662,98.49667,50.0,20.0,1.0866799999999999
56.014,13.41,0.05591749,98.45222,50.0,20.0,1.08647
56.602,13.51,0.05566868,98.44,50.0,20.0,1.08625
57.194,13.61,0.05359855,98.39926,50.0,20.0,1.0860299999999998
57.807,13.71,0.05621233,98.39926,50.0,20.0,1.0858
58.421,13.81,0.0551831,98.44815,50.0,20.0,1.0855700000000001
59.066,13.91,0.05467475,98.38741,50.0,20.0,1.08532
59.705,14.01,0.05338484,98.38296,50.0,20.0,1.0850799999999998
60.332,14.11,0.05209417,98.48037,50.0,20.0,1.08484
60.995,14.21,0.05106412,98.44,50.0,20.0,1.08459
61.677,14.31,0.05081574,98.37889,50.0,20.0,1.08433
62.37,14.41,0.04874287,98.27333,50.0,20.0,1.08407
63.064,14.51,0.0477119,98.27333,50.0,20.0,1.0838
63.76,14.61,0.04589814,98.27333,50.0,20.0,1.08354
64.483,14.71,0.04564905,98.31,50.0,20.0,1.0832600000000001
65.205,14.81,0.04331248,98.34666999999999,50.0,20.0,1.0829799999999998
65.934,14.91,0.04123584,98.35444,50.0,20.0,1.0827
66.672,15.01,0.04202987,98.30593,50.0,20.0,1.0824200000000002
67.444,15.11,0.03943021,98.33,50.0,20.0,1.08212
68.2,15.21,0.03735132,98.30593,50.0,20.0,1.08182
68.978,15.31,0.03657796,98.30593,50.0,20.0,1.08152
69.751,15.41,0.03763354,98.30593,50.0,20.0,1.08122
70.548,15.51,0.03555304,98.30593,50.0,20.0,1.08091
71.335,15.61,0.03660917,98.24481,50.0,20.0,1.0806
72.134,15.71,0.03478883,98.24481,50.0,20.0,1.08028
72.972,15.81,0.03296792,98.2937,50.0,20.0,1.07995
73.782,15.91,0.03219251,98.26111,50.0,20.0,1.0796299999999999
74.607,16.01,0.03141684,98.28556,50.0,20.0,1.07931
75.446,16.11,0.02906955,98.23259,50.0,20.0,1.07897
76.286,16.21,0.02986447,98.12704000000001,50.0,20.0,1.07864
77.141,16.31,0.02882572,98.05815,50.0,20.0,1.0783
78.004,16.41,0.03066991,98.12741,50.0,20.0,1.07795
78.869,16.51,0.03199089,98.17593000000001,50.0,20.0,1.07761
79.742,16.61,0.02806673,98.07444,50.0,20.0,1.07725
80.614,16.71,0.02781351,98.01741,50.0,20.0,1.0769
81.501,16.81,0.02861022,98.62666999999999,50.0,20.0,1.07654
82.407,16.91,0.02835742,98.01333000000001,50.0,20.0,1.07618
83.303,17.01,0.02784171,98.07444,50.0,20.0,1.07581
84.217,17.11,0.02417288,98.12295999999999,50.0,20.0,1.07544
85.113,17.21,0.02654667,98.17148,50.0,20.0,1.07507
86.032,17.31,0.02445253,98.22036999999999,50.0,20.0,1.0747
86.974,17.41,0.02525041,98.17185,50.0,20.0,1.07431
87.911,17.51,0.02499637,98.12333000000001,50.0,20.0,1.07392
88.845,17.61,0.02421571,98.02556,50.0,20.0,1.07354
89.808,17.71,0.02501466,98.14741,50.0,20.0,1.07314
90.751,17.81,0.0252872,98.12295999999999,50.0,20.0,1.07275
91.703,17.91,0.02239799,98.17148,50.0,20.0,1.07235
92.668,18.01,0.0266241,98.12295999999999,50.0,20.0,1.07195
93.633,18.11,0.02478821,98.11480999999999,50.0,20.0,1.07154
94.603,18.21,0.02611666,98.11519,50.0,20.0,1.07113
95.58,18.31,0.02955748,98.0663,50.0,20.0,1.0707200000000001
96.567,18.41,0.02745691,98.0663,50.0,20.0,1.07031
97.552,18.51,0.03090107,98.06593000000001,50.0,20.0,1.06989
98.542,18.61,0.03091322,98.06593000000001,50.0,20.0,1.0694700000000001
99.531,18.71,0.03753339,98.0663,50.0,20.0,1.06905
100.52,18.81,0.03675495,98.0663,50.0,20.0,1.0686200000000001
101.52,18.91,0.03624062,98.01741,50.0,20.0,1.0682
102.532,19.01,0.0420774,97.96889,50.0,20.0,1.06776
103.532,19.11,0.04182962,98.01741,50.0,20.0,1.06733
104.541,19.21,0.04211155,98.05407,50.0,20.0,1.0669
105.548,19.31,0.04583821,98.06593000000001,50.0,20.0,1.06646
106.571,19.41,0.04532716,97.83037,50.0,20.0,1.06602
107.588,19.51,0.0525059,98.11889000000001,50.0,20.0,1.0655700000000001
108.592,19.61,0.05544568,98.07037,50.0,20.0,1.06514
109.626,19.71,0.05706166,98.11926,50.0,20.0,1.0646799999999998
110.64,19.81,0.06186475,98.11926,50.0,20.0,1.0642399999999999
111.672,19.91,0.06375054,97.98481,50.0,20.0,1.06378
112.703,20.01,0.06298057,97.92,50.0,20.0,1.0633299999999999
113.728,20.11,0.0677928,97.93222,50.0,20.0,1.0628799999999998
114.762,20.21,0.07367336,98.06593000000001,50.0,20.0,1.0624200000000001
115.799,20.31,0.07450359,97.87926,50.0,20.0,1.06196
116.832,20.41,0.07906129,97.94,50.0,20.0,1.0615
117.867,20.51,0.08122627,98.09889,50.0,20.0,1.06104
118.899,20.61,0.08445885,97.91593,50.0,20.0,1.06057
119.945,20.71,0.08396318,97.94037,50.0,20.0,1.0601
120.999,20.81,0.08533413,97.96481,50.0,20.0,1.0596299999999998
122.05,20.91,0.08830705,97.91556,50.0,20.0,1.05915
123.1,21.01,0.09048195,97.81407,50.0,20.0,1.0586799999999998
124.15,21.11,0.09586326,97.91185,50.0,20.0,1.0582
125.201,21.21,0.09777664,97.91185,50.0,20.0,1.05772
126.276,21.31,0.10023,97.94852,50.0,20.0,1.05723
127.329,21.41,0.10240999999999999,97.89148,50.0,20.0,1.05675
128.397,21.51,0.10887999999999999,97.89148,50.0,20.0,1.05626
129.466,21.61,0.10759,97.9037,50.0,20.0,1.05577
130.536,21.71,0.11245999999999999,97.9037,50.0,20.0,1.05528
131.61501,21.81,0.11573,98.00111,50.0,20.0,1.0547799999999998
132.679,21.91,0.119,97.94444,50.0,20.0,1.05429
133.754,22.01,0.11959000000000002,97.89556,50.0,20.0,1.05379
134.828,22.11,0.12046,97.93222,50.0,20.0,1.05329
135.916,22.21,0.12803,97.98111,50.0,20.0,1.0527799999999998
137.009,22.31,0.12702,97.8837,50.0,20.0,1.05227
138.086,22.41,0.13057,97.93222,50.0,20.0,1.05176
139.17598999999998,22.51,0.13198,97.93222,50.0,20.0,1.05125
140.255,22.61,0.13581,97.93222,50.0,20.0,1.05074
141.35699,22.71,0.13964000000000001,97.87111,50.0,20.0,1.0502200000000002
142.46001,22.81,0.13783,97.89556,50.0,20.0,1.0497
143.541,22.91,0.14274,97.89556,50.0,20.0,1.04919
144.646,23.01,0.14793,97.89556,50.0,20.0,1.04866
145.74899,23.11,0.15043,97.79815,50.0,20.0,1.04814
146.89301,23.21,0.15213,97.84704,50.0,20.0,1.04759
147.95799,23.31,0.15436,97.85925999999999,50.0,20.0,1.04708
149.05901,23.41,0.15984,97.83481,50.0,20.0,1.04655
150.16701,23.51,0.16072999999999998,97.87111,50.0,20.0,1.04601
151.27299,23.61,0.1619,97.87111,50.0,20.0,1.04548
152.38499,23.71,0.16414,97.87111,50.0,20.0,1.04494
153.476,23.81,0.16504000000000002,97.90778,50.0,20.0,1.04441
154.58,23.91,0.16918,97.85889,50.0,20.0,1.04388
155.69099,24.01,0.16954,97.76148,50.0,20.0,1.04334
156.80701000000002,24.11,0.17315,97.76148,50.0,20.0,1.0427899999999999
157.90198999999998,24.21,0.17514000000000002,97.76148,50.0,20.0,1.04225
159.02499,24.31,0.1812,97.7737,50.0,20.0,1.0417
160.13,24.41,0.18211,97.81,50.0,20.0,1.04116
161.239,24.51,0.18545999999999999,97.85889,50.0,20.0,1.04061
162.351,24.61,0.18583,97.85889,50.0,20.0,1.04006
163.459,24.71,0.18783,97.88333,50.0,20.0,1.03951
164.575,24.81,0.19147,97.81036999999999,50.0,20.0,1.03896
165.674,24.91,0.19455999999999998,97.81036999999999,50.0,20.0,1.03841
166.8,25.01,0.19685,97.73704000000001,50.0,20.0,1.03785
167.901,25.11,0.20104,97.71296,50.0,20.0,1.0373
169.03101,25.21,0.20142000000000002,97.81851999999999,50.0,20.0,1.03673
170.134,25.31,0.20344,97.94815,50.0,20.0,1.0361799999999999
171.252,25.41,0.209,97.85074,50.0,20.0,1.03562
172.35699,25.51,0.20775,97.77778,50.0,20.0,1.03506
173.48199,25.61,0.21031999999999998,97.77778,50.0,20.0,1.03449
174.591,25.71,0.21208000000000002,97.72889,50.0,20.0,1.03393
175.72301000000002,25.81,0.21274,97.72889,50.0,20.0,1.03336
176.83701000000002,25.91,0.21778000000000003,97.77778,50.0,20.0,1.0327899999999999
177.95,26.01,0.22255999999999998,97.76556,50.0,20.0,1.0322200000000001
179.071,26.11,0.2235,97.76963,50.0,20.0,1.03165
180.196,26.21,0.22445,97.85110999999999,50.0,20.0,1.0310700000000002
181.314,26.31,0.22649,97.80221999999999,50.0,20.0,1.0305
182.439,26.41,0.23184000000000002,97.86296,50.0,20.0,1.0299200000000002
183.56599,26.51,0.23031999999999997,97.86296,50.0,20.0,1.02934
184.674,26.61,0.23346999999999998,97.78556,50.0,20.0,1.02877
185.80098999999998,26.71,0.23333,97.65593,50.0,20.0,1.02819
186.927,26.81,0.23758,97.71259,50.0,20.0,1.0276
188.047,26.91,0.24322,97.8263,50.0,20.0,1.02702
189.172,27.01,0.24639,97.75333,50.0,20.0,1.02643
190.29201,27.11,0.24763000000000002,97.6437,50.0,20.0,1.02585
191.43201000000002,27.21,0.2497,97.74110999999999,50.0,20.0,1.02525
192.565,27.31,0.25454,97.72889,50.0,20.0,1.0246600000000001
193.69099,27.41,0.25661,97.83037,50.0,20.0,1.02407
194.811,27.51,0.26145,97.82667,50.0,20.0,1.02348
195.948,27.61,0.2605,97.76148,50.0,20.0,1.02288
197.077,27.71,0.26397,97.76148,50.0,20.0,1.02229
198.21001,27.81,0.26938,97.71259,50.0,20.0,1.02169
199.338,27.91,0.26871,97.82222,50.0,20.0,1.02109
200.467,28.01,0.27413000000000004,97.72074,50.0,20.0,1.02049
201.60201,28.11,0.27928000000000003,97.61926,50.0,20.0,1.01988
202.739,28.21,0.28138,97.72074,50.0,20.0,1.01928
203.86301,28.31,0.2846,97.76963,50.0,20.0,1.01868
204.998,28.41,0.28865999999999997,97.70852,50.0,20.0,1.01807
206.12,28.51,0.29216,97.68406999999999,50.0,20.0,1.01747
207.263,28.61,0.29595,97.74519000000001,50.0,20.0,1.01685
208.383,28.71,0.30141,97.69667,50.0,20.0,1.01625
209.519,28.81,0.30159,97.69667,50.0,20.0,1.0156399999999999
210.645,28.91,0.30595,97.64778000000001,50.0,20.0,1.0150299999999999
211.783,29.01,0.31003000000000003,97.62333000000001,50.0,20.0,1.01441
212.92101,29.11,0.3144,97.63556,50.0,20.0,1.01379
214.052,29.21,0.31766,97.68444000000001,50.0,20.0,1.01318
215.174,29.31,0.31981,97.68444000000001,50.0,20.0,1.01257
216.314,29.41,0.32726,97.68444000000001,50.0,20.0,1.01195
217.429,29.51,0.33333,97.63556,50.0,20.0,1.01134
218.56,29.61,0.34052,97.63556,50.0,20.0,1.01072
219.696,29.71,0.34353,97.53815,50.0,20.0,1.01009
220.83701000000002,29.81,0.35326,97.53815,50.0,20.0,1.00947
221.955,29.91,0.3602,97.58667,50.0,20.0,1.00885
223.08098999999999,30.01,0.36939,97.55,50.0,20.0,1.00823
224.214,30.11,0.37971,97.50148,50.0,20.0,1.0076100000000001
225.342,30.21,0.38865,97.55037,50.0,20.0,1.00698
226.457,30.31,0.40096,97.50148,50.0,20.0,1.0063600000000001
227.592,30.41,0.39896,97.50148,50.0,20.0,1.00573
228.72301000000002,30.51,0.39443,97.55037,50.0,20.0,1.0051
229.854,30.61,0.38624,97.59889,50.0,20.0,1.00447
230.98199,30.71,0.37888,97.57481,50.0,20.0,1.00384
232.103,30.81,0.38194,97.5137,50.0,20.0,1.00321
233.271,30.91,0.3788,97.45296,50.0,20.0,1.0025600000000001
234.36501,31.01,0.3827,97.42851999999999,50.0,20.0,1.00195
235.496,31.11,0.3869,97.47740999999999,50.0,20.0,1.0013100000000001
236.629,31.21,0.38997,97.47740999999999,50.0,20.0,1.0006700000000002
237.76199,31.31,0.39304,97.47740999999999,50.0,20.0,1.00003
238.88901,31.41,0.40149,97.52593,50.0,20.0,0.9994
240.00999,31.51,0.41391000000000006,97.37556,50.0,20.0,0.99876
241.14799,31.61,0.42041000000000006,97.32667,50.0,20.0,0.9981200000000001
242.26601000000002,31.71,0.43371000000000004,97.48926,50.0,20.0,0.9974799999999999
243.39799,31.81,0.44561000000000006,97.47704,50.0,20.0,0.99684
244.521,31.91,0.45951000000000003,97.39185,50.0,20.0,0.9962
245.661,32.01,0.47626999999999997,97.57037,50.0,20.0,0.99555
246.77698999999998,32.11,0.49788000000000004,97.18852,50.0,20.0,0.9949100000000001
247.92999,32.21,0.5252100000000001,97.24148000000001,50.0,20.0,0.99425
249.02,32.31,0.581,97.31036999999999,50.0,20.0,0.9936200000000001
250.159,32.41,0.6846800000000001,97.35925999999999,50.0,20.0,0.99297
251.26601000000002,32.51,0.8004399999999999,97.35925999999999,50.0,20.0,0.9923299999999999
252.392,32.61,0.93175,97.2537,50.0,20.0,0.9916799999999999
253.52,32.71,1.06695,97.20519,50.0,20.0,0.99103
254.618,32.81,1.16549,97.13593,50.0,20.0,0.9904
255.73801,32.91,1.1745299999999999,97.17667,50.0,20.0,0.98975
256.866,33.01,1.09132,97.2337,50.0,20.0,0.9890899999999999
257.98401,33.11,0.9668200000000001,97.18481,50.0,20.0,0.98845
259.11401,33.21,0.8513299999999999,97.18481,50.0,20.0,0.98779
260.229,33.31,0.77059,97.18481,50.0,20.0,0.98714
261.37701,33.41,0.70323,97.13593,50.0,20.0,0.9864700000000001
262.50101,33.51,0.65067,97.13593,50.0,20.0,0.9858100000000001
263.63501,33.61,0.61324,97.13593,50.0,20.0,0.98515
264.758,33.71,0.58122,97.08704,50.0,20.0,0.98449
265.88599,33.81,0.55748,97.03444,50.0,20.0,0.98383
267.017,33.91,0.53918,96.93296,50.0,20.0,0.98316
268.151,34.01,0.52632,97.05444,50.0,20.0,0.98249
269.272,34.11,0.51746,97.07889,50.0,20.0,0.98183
270.39301,34.21,0.51579,97.03036999999999,50.0,20.0,0.9811700000000001
271.51999,34.31,0.5100899999999999,96.98148,50.0,20.0,0.98051
272.64898999999997,34.41,0.50785,96.93259,50.0,20.0,0.9798399999999999
273.77898999999996,34.51,0.50964,96.8963,50.0,20.0,0.9791700000000001
274.909,34.61,0.5079600000000001,96.92074000000001,50.0,20.0,0.97849
276.02701,34.71,0.5112,96.97333,50.0,20.0,0.97783
277.15398999999996,34.81,0.51473,96.87185,50.0,20.0,0.97716
278.26599,34.91,0.51913,96.57925999999999,50.0,20.0,0.9765
279.38599,35.01,0.5160100000000001,96.72148,50.0,20.0,0.97583
280.51401,35.11,0.5155,96.97740999999999,50.0,20.0,0.97515
281.63,35.21,0.51847,96.81481,50.0,20.0,0.9744799999999999
282.755,35.31,0.5220199999999999,96.81481,50.0,20.0,0.9738100000000001
283.88101,35.41,0.52441,96.69296,50.0,20.0,0.9731299999999999
284.98901,35.51,0.5250600000000001,96.64444,50.0,20.0,0.97246
286.11801,35.61,0.5260100000000001,96.62,50.0,20.0,0.97178
287.237,35.71,0.5287,96.67667,50.0,20.0,0.97111
288.35999,35.81,0.5261600000000001,96.62778,50.0,20.0,0.9704299999999999
289.47299,35.91,0.5309,96.62778,50.0,20.0,0.9697600000000001
290.578,36.01,0.5303899999999999,96.57925999999999,50.0,20.0,0.96909
291.71301,36.11,0.5290199999999999,96.57925999999999,50.0,20.0,0.9684
292.81601,36.21,0.53172,96.53036999999999,50.0,20.0,0.96773
293.927,36.31,0.5312100000000001,96.38444,50.0,20.0,0.96705
295.05099,36.41,0.53393,96.33148,50.0,20.0,0.9663700000000001
296.17801000000003,36.51,0.5343100000000001,96.33148,50.0,20.0,0.9656799999999999
297.285,36.61,0.5323399999999999,96.28296,50.0,20.0,0.96501
298.401,36.71,0.53213,96.23406999999999,50.0,20.0,0.9643200000000001
299.51501,36.81,0.53104,96.23406999999999,50.0,20.0,0.9636399999999999
300.63,36.91,0.5290699999999999,96.18519,50.0,20.0,0.96296
301.74701,37.01,0.52915,96.18519,50.0,20.0,0.9622700000000001
302.87399,37.11,0.5280699999999999,96.08778000000001,50.0,20.0,0.9615799999999999
303.983,37.21,0.52609,96.03889000000001,50.0,20.0,0.9609
305.10999,37.31,0.52382,95.99,50.0,20.0,0.9602
306.19501,37.41,0.5274300000000001,95.99,50.0,20.0,0.9595299999999999
307.32198999999997,37.51,0.52545,95.94148,50.0,20.0,0.9588399999999999
308.44601,37.61,0.52465,95.89259,50.0,20.0,0.95814
309.53699,37.71,0.52355,95.84407,50.0,20.0,0.95747
310.64301,37.81,0.52363,95.84407,50.0,20.0,0.95678
311.76901000000004,37.91,0.52667,95.79519,50.0,20.0,0.9560799999999999
312.86899,38.01,0.52705,95.84407,50.0,20.0,0.9554
313.96898999999996,38.11,0.53127,95.71,50.0,20.0,0.9547200000000001
315.09299,38.21,0.5310699999999999,95.64926,50.0,20.0,0.9540200000000001
316.20401,38.31,0.53027,95.63704,50.0,20.0,0.9533200000000001
317.30301000000003,38.41,0.53065,95.70593000000001,50.0,20.0,0.9526399999999999
318.41299,38.51,0.53045,95.62037,50.0,20.0,0.95194
319.52499,38.61,0.53351,95.42556,50.0,20.0,0.95125
320.62799,38.71,0.5371600000000001,95.40111,50.0,20.0,0.95055
321.74701,38.81,0.53042,95.63259000000001,50.0,20.0,0.94985
322.849,38.91,0.53051,95.55963,50.0,20.0,0.94916
323.957,39.01,0.53358,95.40963,50.0,20.0,0.9484600000000001
325.05899,39.11,0.53606,95.36074,50.0,20.0,0.9477700000000001
326.16699,39.21,0.53646,95.3363,50.0,20.0,0.9470700000000001
327.271,39.31,0.53595,95.23852,50.0,20.0,0.94637
328.36899,39.41,0.53963,95.27148000000001,50.0,20.0,0.94568
329.48199,39.51,0.54004,95.25889000000001,50.0,20.0,0.9449799999999999
330.60001,39.61,0.5422399999999999,95.19815,50.0,20.0,0.94427
331.689,39.71,0.53964,95.22259,50.0,20.0,0.94358
332.798,39.81,0.53495,95.29556,50.0,20.0,0.9428700000000001
333.88501,39.91,0.5392399999999999,95.12519,50.0,20.0,0.9421799999999999
334.98001,40.01,0.5435399999999999,94.97480999999999,50.0,20.0,0.9414899999999999
336.08701,40.11,0.54365,94.92593000000001,50.0,20.0,0.94078
337.194,40.21,0.5473600000000001,94.87704000000001,50.0,20.0,0.9400799999999999
338.28799,40.31,0.54867,94.82444,50.0,20.0,0.9393799999999999
339.39001,40.41,0.54878,94.78778,50.0,20.0,0.9386700000000001
340.49799,40.51,0.5552199999999999,94.77556,50.0,20.0,0.93796
341.61301000000003,40.61,0.55052,94.6537,50.0,20.0,0.93725
342.677,40.71,0.55333,94.71481,50.0,20.0,0.9365700000000001
343.78201,40.81,0.5513399999999999,94.66593,50.0,20.0,0.93586
344.879,40.91,0.55508,94.49519000000001,50.0,20.0,0.93515
345.97,41.01,0.557,94.44667,50.0,20.0,0.93445
347.06799,41.11,0.5534899999999999,94.39778000000001,50.0,20.0,0.93375
348.16,41.21,0.55845,94.30037,50.0,20.0,0.93304
349.26599,41.31,0.55433,94.30815,50.0,20.0,0.9323299999999999
350.353,41.41,0.55081,94.30852,50.0,20.0,0.93163
351.45801,41.51,0.5485,94.19852,50.0,20.0,0.93091
352.55301000000003,41.61,0.54892,94.05259000000001,50.0,20.0,0.9302
353.64499,41.71,0.55116,93.95519,50.0,20.0,0.9295
354.742,41.81,0.55219,93.85333,50.0,20.0,0.9287799999999999
355.82599,41.91,0.5513899999999999,93.85333,50.0,20.0,0.9280799999999999
356.952,42.01,0.55243,93.68704,50.0,20.0,0.92735
358.02701,42.11,0.5504100000000001,93.69889,50.0,20.0,0.92665
359.117,42.21,0.54687,93.59333000000001,50.0,20.0,0.92594
360.203,42.31,0.55003,93.45926,50.0,20.0,0.9252299999999999
361.30899,42.41,0.54832,93.34963,50.0,20.0,0.92451
362.38698999999997,42.51,0.54966,93.30074,50.0,20.0,0.92381
363.479,42.61,0.5454899999999999,93.19519,50.0,20.0,0.92309
364.56799,42.71,0.54377,93.03704,50.0,20.0,0.92238
365.66,42.81,0.5448,92.89036999999999,50.0,20.0,0.9216700000000001
366.75201,42.91,0.54983,92.74,50.0,20.0,0.92095
367.849,43.01,0.54873,92.63444,50.0,20.0,0.9202299999999999
368.918,43.11,0.54914,92.48852,50.0,20.0,0.91953
370.035,43.21,0.54374,92.48444,50.0,20.0,0.91879
371.10598999999996,43.31,0.53677,92.46,50.0,20.0,0.91809
372.18301,43.41,0.53257,92.3463,50.0,20.0,0.91738
373.27898999999996,43.51,0.53083,92.09852,50.0,20.0,0.91666
374.35598999999996,43.61,0.5321600000000001,91.89111,50.0,20.0,0.91595
375.44601,43.71,0.52703,91.82222,50.0,20.0,0.9152299999999999
376.51901000000004,43.81,0.52156,91.71259,50.0,20.0,0.9145200000000001
377.608,43.91,0.5142399999999999,91.54593,50.0,20.0,0.9138
378.69299,44.01,0.51186,91.44037,50.0,20.0,0.9130799999999999
379.784,44.11,0.50267,91.23704000000001,50.0,20.0,0.91235
380.862,44.21,0.49965,91.07852,50.0,20.0,0.91164
381.94,44.31,0.49228999999999995,91.03,50.0,20.0,0.9109200000000001
383.02701,44.41,0.48616000000000004,90.85963000000001,50.0,20.0,0.9102
384.09799,44.51,0.48218999999999995,90.66852,50.0,20.0,0.9094899999999999
385.17801000000003,44.61,0.47511000000000003,90.59148,50.0,20.0,0.9087700000000001
386.25699,44.71,0.47207,90.44926,50.0,20.0,0.90805
387.32599,44.81,0.47181000000000006,90.23778,50.0,20.0,0.90733
388.39898999999997,44.91,0.47063,90.08333,50.0,20.0,0.9066200000000001
389.47501,45.01,0.47318999999999994,89.98185,50.0,20.0,0.9059
390.55301000000003,45.11,0.47762,89.76259,50.0,20.0,0.9051799999999999
391.62701,45.21,0.48268999999999995,89.49444,50.0,20.0,0.90446
392.69698999999997,45.31,0.48682,89.40926,50.0,20.0,0.90374
393.78699,45.41,0.49285,89.30333,50.0,20.0,0.9030100000000001
394.85101000000003,45.51,0.49293000000000003,89.04741,50.0,20.0,0.9023
395.92801000000003,45.61,0.49959,88.71,50.0,20.0,0.9015700000000001
397.00699,45.71,0.5050100000000001,88.45444,50.0,20.0,0.90085
398.08301,45.81,0.5060399999999999,88.15778,50.0,20.0,0.90012
399.16901,45.91,0.5099100000000001,87.83296,50.0,20.0,0.8993899999999999
400.25299,46.01,0.5109600000000001,87.48741,50.0,20.0,0.89866
401.315,46.11,0.5151399999999999,87.09333000000001,50.0,20.0,0.89795
402.383,46.21,0.52154,86.69963,50.0,20.0,0.89722
403.45401,46.31,0.5352,86.3337,50.0,20.0,0.8965
404.54098999999997,46.41,0.5381600000000001,85.92741,50.0,20.0,0.8957700000000001
405.60501,46.51,0.55248,85.41556,50.0,20.0,0.89505
406.672,46.61,0.58863,84.79,50.0,20.0,0.8943200000000001
407.73499,46.71,0.59891,84.26593000000001,50.0,20.0,0.8936
408.815,46.81,0.60953,83.66481,50.0,20.0,0.89287
409.87701,46.91,0.62237,83.03519,50.0,20.0,0.89215
410.94901,47.01,0.63556,82.45444,50.0,20.0,0.8914200000000001
412.009,47.11,0.6544800000000001,81.73074,50.0,20.0,0.8907
413.08801,47.21,0.67502,80.8863,50.0,20.0,0.8899600000000001
414.14001,47.31,0.6933600000000001,80.07741,50.0,20.0,0.88925
415.20099,47.41,0.71459,79.25704,50.0,20.0,0.8885299999999999
416.276,47.51,0.72855,78.54185,50.0,20.0,0.88779
417.33898999999997,47.61,0.75941,77.61593,50.0,20.0,0.88707
418.39801,47.71,0.78171,76.45407,50.0,20.0,0.88634
419.45901,47.81,0.80787,75.22704,50.0,20.0,0.8856200000000001
420.51401,47.91,0.82642,74.04074,50.0,20.0,0.8849
421.57599000000005,48.01,0.8472299999999999,72.72036999999999,50.0,20.0,0.8841700000000001
422.651,48.11,0.86585,71.52221999999999,50.0,20.0,0.8834299999999999
423.70901,48.21,0.87936,70.25851999999999,50.0,20.0,0.88271
424.758,48.31,0.88969,68.88148000000001,50.0,20.0,0.8819899999999999
425.828,48.41,0.9023,67.43519,50.0,20.0,0.88125
426.88901,48.51,0.91043,65.89148,50.0,20.0,0.8805200000000001
427.93701,48.61,0.91695,64.36,50.0,20.0,0.8798
429.00100999999995,48.71,0.93315,62.72667,50.0,20.0,0.87907
430.05899000000005,48.81,0.9439,60.8663,50.0,20.0,0.87834
431.11800999999997,48.91,0.9511200000000001,59.44444,50.0,20.0,0.87761
432.185,49.01,0.95965,57.60406999999999,50.0,20.0,0.87687
433.245,49.11,0.9656100000000001,55.79221999999999,50.0,20.0,0.8761399999999999
434.31799,49.21,0.9657899999999999,53.805930000000004,50.0,20.0,0.8754
435.349,49.31,0.9604299999999999,51.90037,50.0,20.0,0.87469
436.41101,49.41,0.9528399999999999,50.14148,50.0,20.0,0.87395
437.46200999999996,49.51,0.9355100000000001,48.325559999999996,50.0,20.0,0.87323
438.526,49.61,0.92011,46.37148,50.0,20.0,0.87249
439.577,49.71,0.89981,44.6163,50.0,20.0,0.8717600000000001
440.64099000000004,49.81,0.8713700000000001,42.66667,50.0,20.0,0.8710200000000001
441.70099000000005,49.91,0.83996,40.80185,50.0,20.0,0.87029
442.75299,50.01,0.79842,39.02667,50.0,20.0,0.86956
443.80301,50.11,0.74478,37.24333,50.0,20.0,0.8688299999999999
444.862,50.21,0.68682,35.58593,50.0,20.0,0.8680899999999999
445.92099,50.31,0.6232300000000001,33.96481,50.0,20.0,0.86735
446.97299000000004,50.41,0.55887,32.502590000000005,50.0,20.0,0.8666200000000001
448.02399,50.51,0.48983000000000004,31.18185,50.0,20.0,0.8658899999999999
449.07999,50.61,0.42558,29.9063,50.0,20.0,0.86515
450.13901,50.71,0.35991,28.675559999999997,50.0,20.0,0.86441
451.198,50.81,0.30002,27.7937,50.0,20.0,0.86367
452.25,50.91,0.24559,26.774070000000002,50.0,20.0,0.8629399999999999
453.32100999999994,51.01,0.195,25.87667,50.0,20.0,0.86219
454.37399000000005,51.11,0.14925,25.088520000000003,50.0,20.0,0.86145
455.423,51.21,0.1149,24.44259,50.0,20.0,0.86072
456.48099,51.31,0.07721607,23.95111,50.0,20.0,0.85998
457.52802,51.41,0.04834238,23.27222,50.0,20.0,0.85924
458.586,51.51,0.02402751,22.74,50.0,20.0,0.8585
459.646,51.61,-0.002306007,22.30556,50.0,20.0,0.8577600000000001
460.69100999999995,51.71,-0.02736607,21.84667,50.0,20.0,0.8570200000000001
461.754,51.81,-0.05213989,21.45259,50.0,20.0,0.8562799999999999
462.80899000000005,51.91,-0.07233252,21.13963,50.0,20.0,0.8555299999999999
463.84601,52.01,-0.0975174,20.85926,50.0,20.0,0.8548
464.89300999999995,52.11,-0.11810999999999999,20.56259,50.0,20.0,0.8540700000000001
465.939,52.21,-0.14206,20.19333,50.0,20.0,0.8533299999999999
466.979,52.31,-0.16571,19.93741,50.0,20.0,0.8526
468.04599,52.41,-0.17879,19.65704,50.0,20.0,0.8518399999999999
469.08700999999996,52.51,-0.19952999999999999,19.48222,50.0,20.0,0.85111
470.13100999999995,52.61,-0.21631999999999998,19.34,50.0,20.0,0.8503700000000001
471.17400999999995,52.71,-0.23414000000000001,19.16926,50.0,20.0,0.8496299999999999
472.21899,52.81,-0.24899000000000002,18.95,50.0,20.0,0.8489
473.28,52.91,-0.25987,18.8037,50.0,20.0,0.84814
474.323,53.01,-0.27743,18.767039999999998,50.0,20.0,0.84741
475.35699000000005,53.11,-0.29202,18.580370000000002,50.0,20.0,0.84667
476.405,53.21,-0.30264,18.23111,50.0,20.0,0.84593
477.45000999999996,53.31,-0.31059000000000003,18.17407,50.0,20.0,0.84519
478.48599,53.41,-0.32056,18.1863,50.0,20.0,0.84445
479.521,53.51,-0.35333000000000003,18.06444,50.0,20.0,0.84372
480.56299,53.61,-0.5799,17.905929999999998,50.0,20.0,0.84298
481.62399000000005,53.71,-0.62068,17.74333,50.0,20.0,0.8422299999999999
482.64999000000006,53.81,-0.6417,17.87741,50.0,20.0,0.8415
483.70000999999996,53.91,-0.65572,17.897779999999997,50.0,20.0,0.84075
484.73900999999995,54.01,-0.66538,17.71889,50.0,20.0,0.84001
485.78299000000004,54.11,-0.67371,17.52,50.0,20.0,0.8392700000000001
486.819,54.21,-0.68374,17.3737,50.0,20.0,0.8385299999999999
487.86301,54.31,-0.69109,17.2763,50.0,20.0,0.83778
488.89999000000006,54.41,-0.69744,17.2763,50.0,20.0,0.83704
489.95000999999996,54.51,-0.70618,17.26407,50.0,20.0,0.83629
490.992,54.61,-0.71425,17.13407,50.0,20.0,0.83555
492.02802,54.71,-0.72165,17.10963,50.0,20.0,0.83481
493.06201,54.81,-0.73144,17.10963,50.0,20.0,0.8340700000000001
494.103,54.91,-0.73955,17.06074,50.0,20.0,0.8333200000000001
495.146,55.01,-0.75074,17.04852,50.0,20.0,0.8325799999999999
496.181,55.11,-0.75616,16.987779999999997,50.0,20.0,0.8318399999999999
497.22,55.21,-0.7653399999999999,16.93926,50.0,20.0,0.83109
498.25201,55.31,-0.77112,16.89037,50.0,20.0,0.83035
499.297,55.41,-0.77455,16.84185,50.0,20.0,0.8296
500.32401,55.51,-0.78103,16.829629999999998,50.0,20.0,0.8288700000000001
501.36301,55.61,-0.7841199999999999,16.82926,50.0,20.0,0.8281200000000001
502.396,55.71,-0.79166,16.73185,50.0,20.0,0.8273799999999999
503.42001,55.81,-0.79851,16.73185,50.0,20.0,0.8266399999999999
504.44901,55.91,-0.80162,16.73185,50.0,20.0,0.8259
505.48000999999994,56.01,-0.80782,16.658520000000003,50.0,20.0,0.82516
506.513,56.11,-0.8102699999999999,16.63407,50.0,20.0,0.82442
507.53200999999996,56.21,-0.8151,16.61,50.0,20.0,0.82368
508.56600999999995,56.31,-0.8185899999999999,16.58556,50.0,20.0,0.82294
509.58300999999994,56.41,-0.82001,16.61,50.0,20.0,0.8222
510.625,56.51,-0.8334799999999999,16.69519,50.0,20.0,0.82145
511.646,56.61,-0.8387100000000001,16.57741,50.0,20.0,0.8207200000000001
512.677,56.71,-0.83878,16.51667,50.0,20.0,0.8199700000000001
513.703,56.81,-0.84851,16.44333,50.0,20.0,0.8192299999999999
514.72998,56.91,-0.8523799999999999,16.39444,50.0,20.0,0.8184899999999999
515.76801,57.01,-0.8548899999999999,16.512220000000003,50.0,20.0,0.8177399999999999
516.79498,57.11,-0.8601700000000001,16.45148,50.0,20.0,0.81699
517.82098,57.21,-0.8640700000000001,16.39852,50.0,20.0,0.81625
518.85101,57.31,-0.86867,16.459629999999997,50.0,20.0,0.8155100000000001
519.86902,57.41,-0.8760399999999999,16.40296,50.0,20.0,0.81477
520.896,57.51,-0.87823,16.439629999999998,50.0,20.0,0.81403
521.91699,57.61,-0.8793799999999999,16.35407,50.0,20.0,0.81328
522.94,57.71,-0.88331,16.455560000000002,50.0,20.0,0.8125399999999999
523.9630099999999,57.81,-0.88969,16.39852,50.0,20.0,0.8118
524.98499,57.91,-0.89433,16.24444,50.0,20.0,0.81106
526.01001,58.01,-0.8993399999999999,16.24444,50.0,20.0,0.8103100000000001
527.0360099999999,58.11,-0.9005200000000001,16.19556,50.0,20.0,0.80957
528.05603,58.21,-0.9100799999999999,16.183329999999998,50.0,20.0,0.80883
529.091,58.31,-0.9158200000000001,16.19556,50.0,20.0,0.80807
530.12097,58.41,-0.9187700000000001,16.19963,50.0,20.0,0.80733
531.159,58.51,-0.92419,16.2,50.0,20.0,0.80657
532.16901,58.61,-0.92819,16.15111,50.0,20.0,0.80583
533.18903,58.71,-0.93396,16.15074,50.0,20.0,0.80509
534.22601,58.81,-0.9394,16.102220000000003,50.0,20.0,0.8043399999999999
535.245,58.91,-0.9409700000000001,16.05333,50.0,20.0,0.8035899999999999
536.26801,59.01,-0.94466,15.9563,50.0,20.0,0.80285
537.284,59.11,-0.95152,15.85852,50.0,20.0,0.8021
538.31097,59.21,-0.95947,15.78519,50.0,20.0,0.80135
539.349,59.31,-0.96073,15.82185,50.0,20.0,0.8006
540.354,59.41,-0.96444,15.919260000000001,50.0,20.0,0.79986
541.3720099999999,59.51,-0.96993,16.00444,50.0,20.0,0.7991199999999999
542.39301,59.61,-0.9740200000000001,15.90741,50.0,20.0,0.79837
543.40399,59.71,-0.9816600000000001,15.80556,50.0,20.0,0.7976300000000001
544.42902,59.81,-0.9864799999999999,15.70815,50.0,20.0,0.79688
545.45502,59.91,-0.99274,15.76074,50.0,20.0,0.79613
546.47998,60.01,-0.9933200000000001,15.671479999999999,50.0,20.0,0.79538
547.49402,60.11,-0.9995799999999999,15.772960000000001,50.0,20.0,0.79464
548.50403,60.21,-1.00301,15.797410000000001,50.0,20.0,0.7939
549.5310099999999,60.31,-1.0050299999999999,15.74889,50.0,20.0,0.79314
550.552,60.41,-1.01668,15.74889,50.0,20.0,0.7923899999999999
551.578,60.51,-1.02121,15.7,50.0,20.0,0.79164
552.586,60.61,-1.02288,15.651110000000001,50.0,20.0,0.7909
553.61603,60.71,-1.02672,15.67556,50.0,20.0,0.79015
554.61902,60.81,-1.0326899999999999,15.724070000000001,50.0,20.0,0.7894100000000001
555.64801,60.91,-1.04085,15.647039999999999,50.0,20.0,0.78865
556.6610099999999,61.01,-1.04434,15.647039999999999,50.0,20.0,0.78791
557.66699,61.11,-1.0460399999999999,15.647039999999999,50.0,20.0,0.78717
558.6829799999999,61.21,-1.0499100000000001,15.70815,50.0,20.0,0.78642
559.6950099999999,61.31,-1.05378,15.65926,50.0,20.0,0.78567
560.70502,61.41,-1.0573,15.610370000000001,50.0,20.0,0.78493
561.71997,61.51,-1.05831,15.72444,50.0,20.0,0.78418
562.729,61.61,-1.06148,15.67556,50.0,20.0,0.7834399999999999
563.73999,61.71,-1.06429,15.651110000000001,50.0,20.0,0.78269
564.742,61.81,-1.0707200000000001,15.62704,50.0,20.0,0.78196
565.75598,61.91,-1.07826,15.57815,50.0,20.0,0.7812100000000001
566.76501,62.01,-1.08435,15.468520000000002,50.0,20.0,0.78046
567.7810099999999,62.11,-1.08866,15.37074,50.0,20.0,0.77971
568.79401,62.21,-1.09152,15.407779999999999,50.0,20.0,0.7789699999999999
569.79901,62.31,-1.0958299999999999,15.383329999999999,50.0,20.0,0.77822
570.83002,62.41,-1.09981,15.322220000000002,50.0,20.0,0.77746
571.83398,62.51,-1.1041299999999998,15.346670000000001,50.0,20.0,0.77672
572.85101,62.61,-1.11394,15.33815,50.0,20.0,0.7759699999999999
573.86798,62.71,-1.11284,15.3263,50.0,20.0,0.77522
574.87097,62.81,-1.12047,15.27741,50.0,20.0,0.77447
575.89099,62.91,-1.1233899999999999,15.265189999999999,50.0,20.0,0.77372
576.89099,63.01,-1.12629,15.228520000000001,50.0,20.0,0.77298
577.89697,63.11,-1.1325,15.19222,50.0,20.0,0.77223
578.9180299999999,63.21,-1.13618,15.131110000000001,50.0,20.0,0.77148
579.91998,63.31,-1.14204,15.082220000000001,50.0,20.0,0.77073
580.92297,63.41,-1.14754,15.131110000000001,50.0,20.0,0.76999
581.927,63.51,-1.1490200000000002,15.082220000000001,50.0,20.0,0.76925
582.93597,63.61,-1.15529,15.082220000000001,50.0,20.0,0.7685
583.93597,63.71,-1.16082,15.0337,50.0,20.0,0.76775
584.9470200000001,63.81,-1.16306,15.0337,50.0,20.0,0.767
585.94299,63.91,-1.16787,15.05815,50.0,20.0,0.76626
586.9470200000001,64.01,-1.16975,15.045929999999998,50.0,20.0,0.76552
587.9470200000001,64.11,-1.1727299999999998,15.08259,50.0,20.0,0.76478
588.9500099999999,64.21,-1.17277,15.13556,50.0,20.0,0.76403
589.9470200000001,64.31,-1.18131,15.03815,50.0,20.0,0.7632899999999999
590.95599,64.41,-1.19174,14.940370000000001,50.0,20.0,0.76254
591.95398,64.51,-1.19735,14.89148,50.0,20.0,0.7618
592.953,64.61,-1.1974,14.9563,50.0,20.0,0.76105
593.95898,64.71,-1.19933,15.017779999999998,50.0,20.0,0.7603
594.97699,64.81,-1.2072200000000002,14.96889,50.0,20.0,0.75955
595.97198,64.91,-1.2125,14.895929999999998,50.0,20.0,0.75881
596.96997,65.01,-1.2177799999999999,14.717039999999999,50.0,20.0,0.7580600000000001
597.98297,65.11,-1.2219799999999998,14.66815,50.0,20.0,0.75731
598.97803,65.21,-1.2254200000000002,14.570739999999999,50.0,20.0,0.75657
599.992,65.31,-1.23076,14.66815,50.0,20.0,0.75581
600.987,65.41,-1.23122,14.92407,50.0,20.0,0.75507
601.98499,65.51,-1.23843,14.721110000000001,50.0,20.0,0.75432
602.992,65.61,-1.24416,14.66815,50.0,20.0,0.75357
603.98901,65.71,-1.2487700000000002,14.57037,50.0,20.0,0.75283
605.0,65.81,-1.25378,14.57037,50.0,20.0,0.75207
605.99402,65.91,-1.26104,14.570739999999999,50.0,20.0,0.75133
607.00702,66.01,-1.26231,14.570739999999999,50.0,20.0,0.75057
608.02197,66.11,-1.2666,14.61926,50.0,20.0,0.7498199999999999
609.0,66.21,-1.2704799999999998,14.61926,50.0,20.0,0.7490899999999999
610.0020099999999,66.31,-1.2747700000000002,14.61926,50.0,20.0,0.74834
610.9970099999999,66.41,-1.27642,14.619629999999999,50.0,20.0,0.74759
611.99402,66.51,-1.2765600000000001,14.66815,50.0,20.0,0.74685
612.99298,66.61,-1.28427,14.619629999999999,50.0,20.0,0.7461
613.97498,66.71,-1.2859200000000002,14.52185,50.0,20.0,0.74536
614.9810200000001,66.81,-1.29064,14.473329999999999,50.0,20.0,0.74461
615.96997,66.91,-1.29952,14.57889,50.0,20.0,0.74387
616.9689900000001,67.01,-1.30006,14.574810000000001,50.0,20.0,0.74312
617.961,67.11,-1.30365,14.48926,50.0,20.0,0.74238
618.95898,67.21,-1.3080100000000001,14.53815,50.0,20.0,0.74163
619.948,67.31,-1.31161,14.59481,50.0,20.0,0.7408899999999999
620.93597,67.41,-1.31254,14.59481,50.0,20.0,0.74015
621.9299900000001,67.51,-1.31577,14.5463,50.0,20.0,0.73941
622.92603,67.61,-1.31825,14.48519,50.0,20.0,0.73866
623.90802,67.71,-1.3207200000000001,14.424439999999999,50.0,20.0,0.73792
624.90302,67.81,-1.32244,14.53815,50.0,20.0,0.7371800000000001
625.896,67.91,-1.32493,14.57444,50.0,20.0,0.73643
626.88898,68.01,-1.3301100000000001,14.62333,50.0,20.0,0.73568
627.88599,68.11,-1.32954,14.574810000000001,50.0,20.0,0.7349399999999999
628.87402,68.21,-1.33473,14.525929999999999,50.0,20.0,0.73419
629.86298,68.31,-1.3387799999999999,14.477039999999999,50.0,20.0,0.73345
630.86499,68.41,-1.34826,14.440370000000001,50.0,20.0,0.7327
631.85797,68.51,-1.34616,14.379629999999999,50.0,20.0,0.73195
632.85797,68.61,-1.35102,14.32704,50.0,20.0,0.7312
633.85797,68.71,-1.3450600000000001,14.27815,50.0,20.0,0.73045
634.85999,68.81,-1.34954,14.176670000000001,50.0,20.0,0.7297
635.84003,68.91,-1.35401,14.257779999999999,50.0,20.0,0.72896
636.84198,69.01,-1.3589,14.135929999999998,50.0,20.0,0.72821
637.8170200000001,69.11,-1.36338,14.135929999999998,50.0,20.0,0.72747
638.815,69.21,-1.36635,14.18481,50.0,20.0,0.72672
639.8250099999999,69.31,-1.36894,14.135929999999998,50.0,20.0,0.72596
640.789,69.41,-1.3675899999999999,14.135929999999998,50.0,20.0,0.72524
641.77802,69.51,-1.37133,14.2337,50.0,20.0,0.72449
642.75098,69.61,-1.3723299999999998,14.2337,50.0,20.0,0.7237600000000001
643.74103,69.71,-1.38,14.18481,50.0,20.0,0.72301
644.72803,69.81,-1.38533,14.18481,50.0,20.0,0.72227
645.71802,69.91,-1.38951,14.233329999999999,50.0,20.0,0.7215199999999999