File: 02_Data/OSB/STA/N2/3K_min/OSB_STA_N2_3KData_210312_R2.csv
##Temp./Â°C,Time/min,DSC/(mW/mg),Mass/%,Sensit./(uV/mW)
48.981,10.01,0.009273053,101.42536,1.05328
49.006,10.31,0.009448043,101.41739,1.05328
49.019,10.61,0.009448058,101.44928,1.0532700000000002
49.094,10.91,0.010148,101.44928,1.05326
49.159,11.21,0.01207272,101.44903000000001,1.05326
49.282,11.51,0.01469743,101.5128,1.05324
49.465,11.81,0.01557262,101.49686,1.05322
49.695,12.11,0.02204723,101.5128,1.05319
50.001,12.41,0.02729756,101.54444000000001,1.05315
50.345,12.71,0.03184846,101.54469,1.05311
50.736,13.01,0.03517494,101.57656999999999,1.05306
51.172,13.31,0.03780193,101.62391,1.053
51.631,13.61,0.04095438,101.63986,1.05294
52.117,13.91,0.04428236,101.60797,1.05288
52.633,14.21,0.04761094,101.70362,1.05281
53.169,14.51,0.05146525,101.64783,1.05274
53.738,14.81,0.05164397,101.68744000000001,1.05267
54.332,15.11,0.05619984,101.67174,1.05259
54.964,15.41,0.05742999,101.6715,1.05251
55.596,15.71,0.0593608,101.69565,1.0524200000000001
56.245,16.01,0.06234281,101.64806999999999,1.05233
56.906,16.31,0.06409953,101.69565,1.05224
57.614,16.61,0.06463094,101.6558,1.05215
58.331,16.91,0.06743976,101.6558,1.05205
59.065,17.21,0.06937342,101.62415,1.0519399999999999
59.784,17.51,0.06938014,101.68768,1.0518399999999999
60.567,17.81,0.07254151,101.6558,1.0517299999999998
61.289,18.11,0.07342489,101.68768,1.05162
62.073,18.41,0.07483493,101.59203000000001,1.05151
62.83,18.71,0.07729671,101.59227,1.0514
63.629,19.01,0.0781819,101.6558,1.05128
64.427,19.31,0.08029458,101.68768,1.05116
65.218,19.61,0.08153105,101.60821,1.05104
66.045,19.91,0.08399583,101.63986,1.05092
66.857,20.21,0.08225204,101.67174,1.05079
67.687,20.51,0.08313912,101.59227,1.05066
68.515,20.81,0.08244771,101.62391,1.05053
69.372,21.11,0.08245835,101.5843,1.0504
70.197,21.41,0.0854516,101.59227,1.05026
71.055,21.71,0.08528735,101.59227,1.05013
71.902,22.01,0.08529853,101.5843,1.04999
72.752,22.31,0.08548539,101.59227,1.04985
73.614,22.61,0.08303918,101.57633,1.0497100000000001
74.479,22.91,0.0841041,101.60024,1.04956
75.331,23.21,0.08306196,101.60797,1.04942
76.193,23.51,0.08201976,101.53913,1.0492700000000001
77.074,23.81,0.080275,101.57101,1.04912
77.94,24.11,0.07835396,101.53913,1.0489700000000002
78.812,24.41,0.08064951,101.54975999999999,1.04882
79.69,24.71,0.08083712,101.55,1.04867
80.579,25.01,0.07997048,101.54975999999999,1.04851
81.447,25.31,0.08033389,101.51812,1.04835
82.335,25.61,0.07858805,101.49155,1.04819
83.224,25.91,0.08123776,101.50749,1.04803
84.106,26.21,0.07808471,101.53913,1.04787
84.99,26.51,0.07651384,101.47585,1.0477100000000001
85.886,26.81,0.07635012,101.48357,1.04754
86.784,27.11,0.07618648,101.44372,1.0473700000000001
87.685,27.41,0.07514302,101.4756,1.0472
88.583,27.71,0.07673941,101.45966,1.04703
89.481,28.01,0.07516775,101.42801999999999,1.04685
90.373,28.31,0.07447592,101.4756,1.0466799999999998
91.315,28.61,0.07448904,101.48357,1.0465
92.214,28.91,0.07397329,101.44396,1.0463200000000001
93.108,29.21,0.07310507,101.44372,1.04614
94.012,29.51,0.07258916,101.44396,1.04596
94.926,29.81,0.07172088,101.47585,1.04578
95.845,30.11,0.0724387,101.43599,1.04559
96.76,30.41,0.07298054,101.43599,1.0454
97.669,30.71,0.07281734,101.44372,1.04521
98.596,31.01,0.07230175,101.4756,1.04502
99.515,31.31,0.07019854,101.47585,1.04483
100.448,31.61,0.07056461,101.4756,1.04463
101.36,31.91,0.07022484,101.49155,1.04444
102.288,32.21,0.07217948,101.43599,1.04424
103.218,32.51,0.07060476,101.40435,1.0440399999999999
104.139,32.81,0.07220722,101.49951999999999,1.0438399999999999
105.051,33.11,0.07151473,101.43599,1.04364
105.981,33.41,0.07082234,101.45966,1.0434299999999999
106.923,33.71,0.06907006,101.4756,1.04322
107.846,34.01,0.07014385,101.42801999999999,1.04302
108.769,34.31,0.06980441,101.43599,1.04281
109.69,34.61,0.06805085,101.41208,1.0426
110.621,34.91,0.06841833,101.43599,1.04239
111.564,35.21,0.06754844,101.46763,1.04217
112.485,35.51,0.06738541,101.41208,1.04195
113.404,35.81,0.06757618,101.41208,1.0417399999999999
114.376,36.11,0.06741406,101.41208,1.04151
115.277,36.41,0.06778181,101.38019,1.0413
116.207,36.71,0.06655713,101.41208,1.04108
117.139,37.01,0.06674846,101.40411,1.04085
118.062,37.31,0.06587729,101.35651999999999,1.04063
119.003,37.61,0.06518325,101.42005,1.0404
119.923,37.91,0.06555166,101.45193,1.0401799999999999
120.854,38.21,0.06503448,101.38816,1.03995
121.787,38.51,0.06451718,101.36449,1.03972
122.721,38.81,0.06204964,101.38841,1.03949
123.656,39.11,0.06348223,101.38816,1.03925
124.592,39.41,0.06243247,101.38816,1.03902
125.53,39.71,0.06120494,101.38816,1.03878
126.461,40.01,0.0610415,101.38816,1.03854
127.387,40.31,0.06141047,101.38019,1.0383
128.325,40.61,0.06124729,101.35651999999999,1.03806
129.261,40.91,0.0603738,101.36449,1.03782
130.194,41.21,0.0602104,101.39638000000001,1.03757
131.125,41.51,0.06040228,101.40411,1.0373299999999999
132.07401000000002,41.81,0.06095002,101.37246,1.03708
133.015,42.11,0.0602538,101.34058,1.03682
133.951,42.41,0.05920168,101.37222,1.03657
134.88901,42.71,0.0590383,101.40411,1.0363200000000001
135.842,43.01,0.05745219,101.43599,1.03606
136.771,43.31,0.05764416,101.37246,1.0358100000000001
137.726,43.61,0.05819262,101.3087,1.03555
138.658,43.91,0.05642705,101.35918000000001,1.03529
139.60699,44.21,0.05608531,101.33527,1.03503
140.556,44.51,0.05645585,101.32729,1.0347600000000001
141.505,44.81,0.05593596,101.35096999999999,1.03449
142.448,45.11,0.05612854,101.31135,1.03423
143.394,45.41,0.0548955,101.343,1.03396
144.347,45.71,0.0561579,101.31135,1.03369
145.295,46.01,0.05545938,101.2558,1.03342
146.245,46.31,0.05476061,101.2558,1.03314
147.192,46.61,0.05299097,101.2558,1.0328700000000002
148.144,46.91,0.05336216,101.22415,1.03259
149.09,47.21,0.05319799,101.23188,1.03231
150.039,47.51,0.0517839,101.21618000000001,1.03203
150.983,47.81,0.05161934,101.22391,1.03175
151.94,48.11,0.05091896,101.18406,1.03147
152.89301,48.41,0.04968208,101.22391,1.03118
153.856,48.71,0.04969606,101.14444,1.0308899999999999
154.80098999999998,49.01,0.05042511,101.14444,1.0306
155.759,49.31,0.05043939,101.16039,1.03031
156.70598999999999,49.61,0.04884336,101.1843,1.0300200000000002
157.647,49.91,0.05118363,101.15241999999999,1.02973
158.60898999999998,50.21,0.0499453,101.15241999999999,1.02944
159.569,50.51,0.04906445,101.15241999999999,1.02914
160.522,50.81,0.04907864,101.15241999999999,1.02884
161.463,51.11,0.04712187,101.16039,1.02854
162.439,51.41,0.04641908,101.16835999999999,1.02824
163.373,51.71,0.04589463,101.11256,1.0279399999999999
164.339,52.01,0.04537039,101.13646999999999,1.0276299999999998
165.299,52.31,0.04430767,101.06498,1.0273299999999999
166.252,52.61,0.04306485,101.09685999999999,1.02702
167.209,52.91,0.04415478,101.03333,1.02671
168.151,53.21,0.04219296,101.03309,1.0264
169.11301,53.51,0.04148749,101.01739,1.02609
170.067,53.81,0.04401532,101.01715,1.02578
171.02499,54.11,0.04205207,100.98550999999999,1.02546
171.97501,54.41,0.04098639,100.95362,1.02514
172.93201000000002,54.71,0.0408193,100.98550999999999,1.02483
173.88699,55.01,0.04029239,100.92995,1.02451
174.847,55.31,0.04138468,100.92995,1.0241799999999999
175.83,55.61,0.04229806,100.89806999999999,1.02385
176.75301000000002,55.91,0.04087062,100.88213,1.02354
177.711,56.21,0.03980304,100.85845,1.02321
178.66499,56.51,0.04125704,100.8186,1.0228899999999999
179.625,56.81,0.03640442,100.78671,1.0225600000000001
180.57401000000002,57.11,0.03749776,100.84227,1.02223
181.543,57.41,0.03300166,100.75506999999999,1.02189
182.5,57.71,0.034636,100.71546,1.02156
183.48,58.01,0.0335649,100.6756,1.02122
184.40601,58.31,0.03285355,100.67536,1.0208899999999999
185.377,58.61,0.03322574,100.6756,1.02055
186.34,58.91,0.03305624,100.58816,1.0202
187.28999,59.21,0.0332479,100.54831,1.01987
188.23599,59.51,0.02964384,100.57222,1.0195299999999998
189.19501,59.81,0.03055795,100.57222,1.01918
190.14101000000002,60.11,0.0282168,100.51666999999999,1.01884
191.106,60.41,0.02858837,100.49275,1.01849
192.067,60.71,0.02787419,100.4529,1.01814
193.039,61.01,0.02571115,100.40531,1.01779
193.987,61.31,0.02173517,100.3814,1.01744
194.961,61.61,0.02355475,100.34952,1.01708
195.89999,61.91,0.02265655,100.2942,1.01673
196.86,62.21,0.02230187,100.27826,1.01637
197.83098999999999,62.51,0.02122155,100.22246,1.01601
198.79201,62.81,0.02213633,100.15894,1.01565
199.74899,63.11,0.01960306,100.15097,1.01529
200.709,63.41,0.01670488,100.12705,1.0149299999999999
201.658,63.71,0.01816392,100.06353,1.01457
202.633,64.01,0.015445,100.02367,1.0142
203.58299,64.31,0.01781355,99.99203,1.01383
204.552,64.61,0.01563802,99.90459,1.01346
205.51401,64.91,0.01546185,99.87295,1.01309
206.472,65.21,0.0149216,99.80918,1.01272
207.43201000000002,65.51,0.01274265,99.80918,1.01234
208.395,65.81,0.01056212,99.74034,1.01197
209.356,66.11,0.01111257,99.66086999999999,1.01159
210.314,66.41,0.01075223,99.61304,1.01121
211.267,66.71,0.009297765999999999,99.5814,1.01084
212.23599,67.01,0.008024653,99.50966,1.01045
213.226,67.31,0.007845336,99.45411,1.01006
214.153,67.61,0.007118148,99.42246,1.00969
215.116,67.91,0.007120873000000001,99.33478000000001,1.0093
216.082,68.21,0.006210335,99.31908,1.00891
217.034,68.51,0.006395431,99.24734000000001,1.00853
218.004,68.81,0.007311918000000001,99.15217,1.00813
218.959,69.11,0.005120318,99.12029,1.00775
219.918,69.41,0.005671130999999999,99.05676,1.00735
220.87601,69.71,0.007686467,98.93744000000001,1.00696
221.839,70.01,0.006957163000000001,98.87391,1.0065600000000001
222.81599,70.31,0.01208834,98.7785,1.00616
223.80098999999998,70.61,0.01209326,98.66739,1.00575
224.735,70.91,0.01264784,98.59589,1.00536
225.69099,71.21,0.01283625,98.54807,1.00496
226.675,71.51,0.01302497,98.51111,1.00455
227.616,71.81,0.01229602,98.40773,1.00415
228.60201,72.11,0.01175036,98.32826,1.0037399999999999
229.558,72.41,0.01157143,98.22488,1.0033299999999998
230.505,72.71,0.0135973,98.13744,1.0029299999999999
231.45799,73.01,0.013419,98.03406,1.00252
232.42598999999998,73.31,0.01452794,97.96256,1.00211
233.37801000000002,73.61,0.01324604,97.83527,1.0017
234.364,73.91,0.01343572,97.77174000000001,1.00127
235.308,74.21,0.0127047,97.67633000000001,1.00086
236.272,74.51,0.01363104,97.58889,1.00044
237.24698999999998,74.81,0.01124117,97.46184000000001,1.0000200000000001
238.20799,75.11,0.01345821,97.36643000000001,0.9996
239.173,75.41,0.01106623,97.27101,0.9991700000000001
240.14,75.71,0.01180902,97.12801999999999,0.99875
241.10699,76.01,0.01015272,97.00097,0.9983200000000001
242.071,76.31,0.00775631,96.90556,0.9978899999999999
243.036,76.61,0.009237679,96.75435,0.99746
243.998,76.91,0.007947828,96.61932,0.99703
244.957,77.21,0.005177561,96.49203,0.9966
245.924,77.51,0.005734802,96.3942,0.9961700000000001
246.89301,77.81,0.0014805979999999999,96.26691,0.9957299999999999
247.864,78.11,-0.01407192,96.10531,0.99529
248.827,78.41,-0.02408093,95.87198000000001,0.9948600000000001
249.79201,78.71,-0.03428416,95.88019,0.9944200000000001
250.74899,79.01,-0.04023209,95.64952,0.99398
251.718,79.31,-0.047113,95.39517,0.9935299999999999
252.672,79.61,-0.05214411,95.30773,0.9931
253.646,79.91,-0.05773722,95.15675999999999,0.99265
254.61099,80.21,-0.06537831,94.98188,0.9922
255.58501,80.51,-0.07284087,94.79106,0.99175
256.54001,80.81,-0.08012374,94.61643000000001,0.9913
257.51501,81.11,-0.08369436,94.40966,0.99085
258.483,81.41,-0.08708202,94.20555999999999,0.99039
259.453,81.71,-0.09233459,93.96715,0.9899399999999999
260.448,82.01,-0.09740706,93.7657,0.9894700000000001
261.39499,82.31,-0.10285,93.58841,0.9890200000000001
262.35199,82.61,-0.10662999999999999,93.37366999999999,0.98856
263.32501,82.91,-0.11022,93.11135,0.9881
264.28799,83.21,-0.11400999999999999,92.86763,0.98764
265.255,83.51,-0.11835,92.67174,0.98718
266.22,83.81,-0.12102,92.36159,0.9867100000000001
267.19698999999997,84.11,-0.12594,92.06232,0.98624
268.16199,84.41,-0.1275,91.83164000000001,0.9857799999999999
269.13199,84.71,-0.13298,91.55894,0.98531
270.09,85.01,-0.1366,91.32295,0.9848399999999999
271.05099,85.31,-0.1406,91.02367,0.9843700000000001
272.02802,85.61,-0.14254,90.74275,0.9838899999999999
272.99899,85.91,-0.14392,90.41159,0.9834200000000001
273.96398999999997,86.21,-0.14736,90.13091999999999,0.9829399999999999
274.92001,86.51,-0.14987,89.80216999999999,0.9824700000000001
275.883,86.81,-0.15445,89.4128,0.9819899999999999
276.86099,87.11,-0.15847,89.14517,0.98151
277.828,87.41,-0.16099000000000002,88.78478,0.9810200000000001
278.798,87.71,-0.16483,88.3558,0.98054
279.763,88.01,-0.16641,88.06159,0.98006
280.729,88.31,-0.16894,87.74106,0.97957
281.70099,88.61,-0.17315999999999998,87.31715,0.97908
282.67499,88.91,-0.17664000000000002,86.94082,0.97859
283.62299,89.21,-0.17842,86.55145,0.97811
284.59,89.51,-0.17945999999999998,86.12222,0.97762
285.55701,89.81,-0.1852,85.74324,0.9771200000000001
286.52499,90.11,-0.18605,85.34879000000001,0.9766299999999999
287.51501,90.41,-0.19257,84.94348000000001,0.9761200000000001
288.452,90.71,-0.19474,84.50362,0.97564
289.422,91.01,-0.19768,84.11908000000001,0.97514
290.38101,91.31,-0.20156,83.68213,0.97465
291.345,91.61,-0.20374,83.22899,0.97415
292.311,91.91,-0.20365999999999998,82.74686,0.97365
293.27701,92.21,-0.20736,82.27005,0.97314
294.24799,92.51,-0.20861,81.80121,0.9726299999999999
295.20901000000003,92.81,-0.21213,81.37174,0.9721299999999999
296.17401,93.11,-0.21508000000000002,80.83646999999999,0.9716299999999999
297.13599,93.41,-0.21841999999999998,80.33309,0.9711200000000001
298.116,93.71,-0.22233000000000003,79.82198000000001,0.9706
299.06799,94.01,-0.22625,79.34517,0.9701
300.02802,94.31,-0.23074,78.80435,0.96959
301.00101,94.61,-0.23276,78.28260999999999,0.9690700000000001
302.00101,94.91,-0.23556,77.73696,0.96854
302.935,95.21,-0.23776999999999998,77.15918,0.96804
303.89001,95.51,-0.24285,76.61353000000001,0.96752
304.84698,95.81,-0.24755,76.04661999999999,0.96701
305.80099,96.11,-0.24825999999999998,75.48478,0.9665
306.755,96.41,-0.25392,74.92319,0.96598
307.729,96.71,-0.25578,74.29517,0.96545
308.677,97.01,-0.26088,73.77874,0.9649399999999999
309.63698999999997,97.31,-0.26006999999999997,73.13478,0.96442
310.60598999999996,97.61,-0.26193,72.55725,0.9638899999999999
311.55801,97.91,-0.26494,71.90266,0.9633700000000001
312.52398999999997,98.21,-0.26853,71.27488000000001,0.9628399999999999
313.47101000000004,98.51,-0.27097,70.62585,0.96231
314.44,98.81,-0.27247,70.01377,0.96178
315.40799,99.11,-0.27128,69.40435,0.96125
316.35699,99.41,-0.27392,68.6971,0.96072
317.311,99.71,-0.27560999999999997,68.07705,0.96019
318.285,100.01,-0.27365,67.41739,0.95965
319.23401,100.31,-0.27342,66.72053000000001,0.9591200000000001
320.19901,100.61,-0.2628,66.02633,0.9585799999999999
321.159,100.91,-0.25429,65.32681,0.95804
322.12201,101.21,-0.24405,64.66715,0.9575
323.08401000000003,101.51,-0.23629,63.92802,0.95696
324.04199,101.81,-0.22968000000000002,63.202169999999995,0.95642
325.01198999999997,102.11,-0.22673000000000001,62.52656999999999,0.9558700000000001
325.96701,102.41,-0.21894,61.726330000000004,0.9553200000000001
326.927,102.71,-0.21386,60.981880000000004,0.95478
327.89401000000004,103.01,-0.20876999999999998,60.25314,0.9542299999999999
328.86301000000003,103.31,-0.20773000000000003,59.46643,0.95367
329.82198999999997,103.61,-0.20456,58.70338,0.9531200000000001
330.78101000000004,103.91,-0.20159000000000002,57.92705,0.95257
331.73401,104.21,-0.20035,57.12947,0.9520200000000001
332.69,104.51,-0.19543,56.31618,0.95147
333.65799,104.81,-0.18992,55.49227,0.95091
334.612,105.11,-0.18868,54.67343,0.95036
335.57101,105.41,-0.18762,53.83091999999999,0.9498
336.52802,105.71,-0.18773,53.107730000000004,0.94925
337.487,106.01,-0.18900999999999998,52.19638,0.9486899999999999
338.42999,106.31,-0.19009,51.37512,0.94814
339.38599,106.61,-0.19351,50.51135,0.94758
340.31699,106.91,-0.19634000000000001,49.626329999999996,0.9470299999999999
341.26999,107.21,-0.20483,48.78913,0.94647
342.20801,107.51,-0.20788,48.00242,0.94591
343.14801,107.81,-0.21735,47.1599,0.9453600000000001
344.08499,108.11,-0.22801,46.35966,0.9448
345.00699,108.41,-0.23888,45.51981,0.94426
345.961,108.71,-0.24800999999999998,44.76208,0.9436899999999999
346.854,109.01,-0.25792,44.02029,0.94316
347.79098999999997,109.31,-0.27,43.30749,0.9426
348.69901,109.61,-0.28678000000000003,42.6186,0.94205
349.638,109.91,-0.3169,41.958940000000005,0.9414899999999999
350.548,110.21,-0.35038,41.304829999999995,0.94094
351.47299,110.51,-0.37998000000000004,40.72971,0.94039
352.379,110.81,-0.4104,40.18671,0.93984
353.28299,111.11,-0.44006999999999996,39.672709999999995,0.93929
354.185,111.41,-0.47684,39.23285,0.93875
355.073,111.71,-0.51541,38.88309,0.93821
355.97101000000004,112.01,-0.55993,38.48575,0.93766
356.85699,112.31,-0.60234,38.17053,0.9371200000000001
357.758,112.61,-0.6391,37.900240000000004,0.9365700000000001
358.65398999999996,112.91,-0.67451,37.65918,0.9360200000000001
359.55099,113.21,-0.7084,37.39928,0.93547
360.45801,113.51,-0.81566,37.24034,0.93491
361.362,113.81,-0.8408,37.04976,0.9343600000000001
362.258,114.11,-0.84741,36.88816,0.93381
363.172,114.41,-0.85425,36.77681,0.93324
364.09299,114.71,-0.8597100000000001,36.6471,0.9326700000000001
365.00699,115.01,-0.8598299999999999,36.49589,0.9321
365.94601,115.31,-0.86413,36.41643,0.9315200000000001
366.85101000000003,115.61,-0.86703,36.33696,0.93096
367.793,115.91,-0.8675799999999999,36.20966,0.93037
368.728,116.21,-0.8681200000000001,36.082609999999995,0.92979
369.64898999999997,116.51,-0.8658899999999999,36.04275,0.9292100000000001
370.56699,116.81,-0.8648399999999999,35.96329,0.92863
371.495,117.11,-0.8665700000000001,35.86787,0.92805
372.436,117.41,-0.8651399999999999,35.772459999999995,0.9274600000000001
373.37,117.71,-0.8658899999999999,35.67729,0.9268700000000001
374.30099,118.01,-0.8676299999999999,35.58188,0.9262799999999999
375.23199,118.31,-0.8713700000000001,35.50217,0.92569
376.16101000000003,118.61,-0.8707299999999999,35.407,0.9251
377.09601000000004,118.91,-0.8752700000000001,35.34348,0.92451
378.02701,119.21,-0.8776299999999999,35.27995,0.92391
378.95499,119.51,-0.8791899999999999,35.184540000000005,0.92332
379.88698999999997,119.81,-0.88256,35.08913,0.9227200000000001
380.82401,120.11,-0.8875299999999999,35.0256,0.92212
381.75699,120.41,-0.8869,34.96208,0.92153
382.694,120.71,-0.8912899999999999,34.88237,0.9209200000000001
383.62,121.01,-0.89226,34.8029,0.92033
384.548,121.31,-0.89465,34.7314,0.9197299999999999
385.487,121.61,-0.89945,34.683820000000004,0.91912
386.40701,121.91,-0.89943,34.620290000000004,0.91853
387.34201,122.21,-0.90002,34.493,0.9179200000000001
388.28201,122.51,-0.90123,34.445409999999995,0.9173100000000001
389.19901,122.81,-0.90664,34.3657,0.91671
390.12701,123.11,-0.90965,34.31812,0.9161100000000001
391.06,123.41,-0.9102600000000001,34.26232,0.9155
391.98401,123.71,-0.91066,34.18285,0.91489
392.909,124.01,-0.91166,34.12729,0.9142899999999999
393.853,124.31,-0.9139,34.04783,0.9136700000000001
394.78601000000003,124.61,-0.91269,33.9843,0.91305
395.70999,124.91,-0.9141100000000001,33.90483,0.9124399999999999
396.64301,125.21,-0.91715,33.857,0.9118299999999999
397.578,125.51,-0.91737,33.77754,0.9112100000000001
398.51198999999997,125.81,-0.9192100000000001,33.74565,0.91059
399.43799,126.11,-0.92064,33.65048,0.9099799999999999
400.35598999999996,126.41,-0.9214600000000001,33.57077,0.9093700000000001
401.306,126.71,-0.92251,33.57101,0.9087299999999999
402.22101000000004,127.01,-0.9213,33.46763,0.90812
403.14401000000004,127.31,-0.92375,33.332609999999995,0.90751
404.06799,127.61,-0.92194,33.3244,0.90689
405.008,127.91,-0.92381,33.27705,0.9062600000000001
405.93201,128.21,-0.92261,33.20556,0.90564
406.849,128.51,-0.92181,33.10217,0.90502
407.767,128.81,-0.9202,33.04638,0.9044
408.70901000000003,129.11,-0.9198299999999999,32.996140000000004,0.9037700000000001
409.62399,129.41,-0.92025,32.956520000000005,0.90315
410.55399,129.71,-0.91946,32.88478,0.9025200000000001
411.47101000000004,130.01,-0.91765,32.797340000000005,0.9019
412.40601000000004,130.31,-0.9152299999999999,32.749759999999995,0.9012600000000001
413.319,130.61,-0.9164700000000001,32.685990000000004,0.90064
414.228,130.91,-0.9158700000000001,32.59082,0.90002
415.15799,131.21,-0.9134399999999999,32.519079999999995,0.8993899999999999
416.08701,131.51,-0.91471,32.47947,0.89875
416.98901,131.81,-0.91615,32.46353,0.8981399999999999
417.91598999999997,132.11,-0.9141299999999999,32.4,0.8975
418.85001,132.41,-0.91314,32.33647,0.89686
419.758,132.71,-0.9115200000000001,32.296620000000004,0.8962399999999999
420.69100999999995,133.01,-0.9074399999999999,32.201209999999996,0.89559
421.616,133.31,-0.9122,32.16135,0.8949600000000001
422.54900999999995,133.61,-0.90853,32.11377,0.89431
423.46700999999996,133.91,-0.90959,32.04227,0.8936799999999999
424.427,134.21,-0.90841,31.99444,0.8930100000000001
425.31600999999995,134.51,-0.9076,31.946859999999997,0.89239
426.241,134.81,-0.90722,31.883329999999997,0.89175
427.16500999999994,135.11,-0.9027,31.85145,0.8911100000000001
428.086,135.41,-0.90004,31.83551,0.8904700000000001
429.01599000000004,135.71,-0.8982100000000001,31.7401,0.88982
429.92499000000004,136.01,-0.8980299999999999,31.67657,0.88918
430.84,136.31,-0.89681,31.636709999999997,0.88854
431.77300999999994,136.61,-0.8991299999999999,31.573190000000004,0.88789
432.69100999999995,136.91,-0.8968700000000001,31.5413,0.8872399999999999
433.60999000000004,137.21,-0.89607,31.48599,0.88659
434.552,137.51,-0.8950799999999999,31.454109999999996,0.8859299999999999
435.44299,137.81,-0.8932200000000001,31.390340000000002,0.8853
436.37399000000005,138.11,-0.8968,31.343,0.88464
437.27802,138.41,-0.89828,31.31111,0.884
438.198,138.71,-0.89707,31.207729999999998,0.88335
439.125,139.01,-0.8987799999999999,31.207729999999998,0.8827
440.03101,139.31,-0.9009,31.17585,0.88205
440.944,139.61,-0.90323,31.11232,0.8814
441.854,139.91,-0.90348,31.048790000000004,0.88075
442.77700999999996,140.21,-0.90499,31.000970000000002,0.8801
443.71300999999994,140.51,-0.90841,30.993,0.8794299999999999
444.63100999999995,140.81,-0.90845,30.95338,0.87877
445.54000999999994,141.11,-0.91102,30.929709999999996,0.8781200000000001
446.46300999999994,141.41,-0.9115,30.865940000000002,0.87746
447.384,141.71,-0.91407,30.8343,0.87679
448.30499000000003,142.01,-0.9139200000000001,30.78647,0.87613
449.216,142.31,-0.91966,30.707,0.8754799999999999
450.12399000000005,142.61,-0.92014,30.691059999999997,0.87482
451.02802,142.91,-0.9223,30.69903,0.8741700000000001
451.953,143.21,-0.92343,30.57198,0.8735
452.871,143.51,-0.9249799999999999,30.51618,0.8728299999999999
453.78699000000006,143.81,-0.9322299999999999,30.49227,0.8721700000000001
454.70901,144.11,-0.9350700000000001,30.476570000000002,0.8715
455.617,144.41,-0.93599,30.42077,0.87084
456.535,144.71,-0.93861,30.36522,0.8701700000000001
457.461,145.01,-0.9391299999999999,30.3413,0.86949
458.366,145.31,-0.9426,30.28575,0.8688299999999999
459.26599000000004,145.61,-0.9469200000000001,30.237920000000003,0.86818
460.186,145.91,-0.9476600000000001,30.237920000000003,0.8675
461.08800999999994,146.21,-0.9498700000000001,30.22198,0.8668399999999999
462.01000999999997,146.51,-0.95316,30.094929999999998,0.86616
462.92001,146.81,-0.95624,30.094929999999998,0.8655
463.84399,147.11,-0.9591299999999999,30.05507,0.86482
464.74701,147.41,-0.96285,29.99952,0.86415
465.66500999999994,147.71,-0.9648899999999999,29.943720000000003,0.8634700000000001
466.577,148.01,-0.9671299999999999,29.943720000000003,0.8628
467.47601,148.31,-0.97044,29.935990000000004,0.86213
468.38,148.61,-0.9699200000000001,29.88816,0.86146
469.29400999999996,148.91,-0.9741,29.84855,0.8607899999999999
470.19901,149.21,-0.9737899999999999,29.753140000000002,0.8601200000000001
471.11099,149.51,-0.9784200000000001,29.753140000000002,0.85944
472.01999000000006,149.81,-0.9828399999999999,29.721259999999997,0.8587600000000001
472.931,150.11,-0.98426,29.68937,0.85808
473.84299000000004,150.41,-0.98805,29.68164,0.8574
474.75299,150.71,-0.9892700000000001,29.62585,0.85672
475.68201,151.01,-0.98985,29.578259999999997,0.85603
476.573,151.31,-0.9938600000000001,29.55435,0.85536
477.48400999999996,151.61,-0.9989600000000001,29.48285,0.8546799999999999
478.39999000000006,151.91,-1.0034399999999999,29.42705,0.8539899999999999
479.31,152.21,-1.00726,29.40338,0.85331
480.22,152.51,-1.0100200000000001,29.339859999999998,0.85262
481.12701,152.81,-1.01126,29.30797,0.8519399999999999
482.03799000000004,153.11,-1.01424,29.26812,0.85125
482.96200999999996,153.41,-1.0165899999999999,29.23647,0.85055
483.884,153.71,-1.01873,29.212559999999996,0.8498600000000001
484.75699000000003,154.01,-1.02169,29.14903,0.8492
485.689,154.31,-1.0242799999999999,29.125120000000003,0.84849
486.57599000000005,154.61,-1.02661,29.10145,0.84782
487.487,154.91,-1.03006,29.061590000000002,0.8471299999999999
488.388,155.21,-1.03351,28.998070000000002,0.84644
489.302,155.51,-1.0385,28.9901,0.8457399999999999
490.215,155.81,-1.04131,28.9343,0.84505
491.11499000000003,156.11,-1.0447799999999998,28.9186,0.84436
492.017,156.41,-1.0441,28.8628,0.84367
492.92099,156.71,-1.0478,28.81522,0.84298
493.82599000000005,157.01,-1.0519399999999999,28.74372,0.84229
494.73999000000003,157.31,-1.0539100000000001,28.70386,0.84159
495.63599000000005,157.61,-1.0582799999999999,28.65652,0.8409
496.534,157.91,-1.06156,28.632609999999996,0.84021
497.435,158.21,-1.06398,28.58478,0.83952
498.354,158.51,-1.06817,28.5529,0.8388100000000001
499.25201,158.81,-1.06971,28.48937,0.8381200000000001
500.14800999999994,159.11,-1.0776299999999999,28.457490000000004,0.8374299999999999
501.04501,159.41,-1.07831,28.43382,0.8367399999999999
501.95800999999994,159.71,-1.0829600000000001,28.36232,0.8360299999999999
502.85599,160.01,-1.08607,28.338409999999996,0.83534
503.75299,160.31,-1.08808,28.322459999999996,0.8346399999999999
504.66199000000006,160.61,-1.09143,28.2087,0.83394
505.565,160.91,-1.09412,28.158209999999997,0.83324
506.45000999999996,161.21,-1.09635,28.221740000000004,0.83255
507.35699000000005,161.51,-1.10259,28.1901,0.8318399999999999
508.24899000000005,161.81,-1.1024100000000001,28.150240000000004,0.83115
509.16500999999994,162.11,-1.10225,28.086470000000002,0.83044
510.07000999999997,162.41,-1.10407,28.07077,0.82973
510.96399,162.71,-1.107,28.219079999999998,0.8290299999999999
511.87,163.01,-1.1104,28.084059999999997,0.8283200000000001
512.77197,163.31,-1.10889,27.98865,0.82762
513.67603,163.61,-1.10984,27.957,0.82691
514.58301,163.91,-1.1168200000000001,27.92512,0.8262
515.50897,164.21,-1.1213799999999998,27.861590000000003,0.82547
516.388,164.51,-1.12477,27.821740000000002,0.82478
517.30103,164.81,-1.12978,27.7901,0.82406
518.203,165.11,-1.13344,27.75821,0.82335
519.09497,165.41,-1.13127,27.70242,0.82265
519.99597,165.71,-1.14055,27.646859999999997,0.82194
520.88202,166.01,-1.14039,27.61522,0.82124
521.77502,166.31,-1.14654,27.61522,0.82053
522.67297,166.61,-1.14709,27.583090000000002,0.8198200000000001
523.5720200000001,166.91,-1.1528100000000001,27.53575,0.81911
524.47803,167.21,-1.15562,27.46425,0.81839
525.3720099999999,167.51,-1.1564,27.40845,0.8176800000000001
526.263,167.81,-1.16371,27.40845,0.81698
527.15997,168.11,-1.1651799999999999,27.37681,0.81626
528.05902,168.41,-1.1644,27.2971,0.81555
528.96002,168.71,-1.17062,27.273429999999998,0.81483
529.84302,169.01,-1.17254,27.265220000000003,0.81413
530.755,169.31,-1.17518,27.17802,0.8134
531.65399,169.61,-1.17803,27.13816,0.8126800000000001
532.5360099999999,169.91,-1.1799600000000001,27.10652,0.81198
533.43402,170.21,-1.18555,27.074640000000002,0.81126
534.3319700000001,170.51,-1.1863700000000001,27.01908,0.8105399999999999
535.23297,170.81,-1.1885700000000001,26.979229999999998,0.80982
536.12903,171.11,-1.19076,26.92367,0.8091
537.02002,171.41,-1.19159,26.907729999999997,0.80838
537.90302,171.71,-1.19834,26.8442,0.80767
538.79797,172.01,-1.20512,26.78043,0.80695
539.69397,172.31,-1.2100799999999998,26.748790000000003,0.80623
540.5939900000001,172.61,-1.21094,26.73285,0.8055100000000001
541.48798,172.91,-1.21317,26.669320000000003,0.80479
542.37598,173.21,-1.21425,26.63744,0.80407
543.27399,173.51,-1.21833,26.597579999999997,0.8033399999999999
544.172,173.81,-1.2233399999999999,26.573909999999998,0.80262
545.06097,174.11,-1.22466,26.50242,0.8019
545.9630099999999,174.41,-1.22279,26.48647,0.8011699999999999
546.84998,174.71,-1.22987,26.407,0.80045
547.7310200000001,175.01,-1.23074,26.35121,0.79973
548.6270099999999,175.31,-1.23463,26.319570000000002,0.79901
549.52197,175.61,-1.23876,26.27174,0.79828
550.41602,175.91,-1.24243,26.232129999999998,0.79755
551.29102,176.21,-1.24261,26.26377,0.79684
552.1749900000001,176.51,-1.2462799999999998,26.17657,0.7961199999999999
553.06799,176.81,-1.24719,26.08889,0.7953899999999999
553.961,177.11,-1.25181,26.057,0.79466
554.86102,177.41,-1.25529,26.03333,0.79393
555.74402,177.71,-1.2571299999999999,25.97778,0.7932100000000001
556.633,178.01,-1.26108,25.97778,0.7924800000000001
557.5369900000001,178.31,-1.26528,25.850479999999997,0.79174
558.42102,178.61,-1.2683,25.818839999999998,0.79102
559.30603,178.91,-1.27017,25.818839999999998,0.7902899999999999
560.1950099999999,179.21,-1.27601,25.77899,0.78956
561.0889900000001,179.51,-1.27603,25.71546,0.78883
561.979,179.81,-1.28119,25.69179,0.7881
562.86798,180.11,-1.28659,25.6599,0.7873600000000001
563.7470099999999,180.41,-1.28918,25.643720000000002,0.78664
564.633,180.71,-1.29272,25.580189999999998,0.78591
565.52802,181.01,-1.29863,25.54831,0.78517
566.4130200000001,181.31,-1.3036,25.532610000000002,0.7844399999999999
567.29401,181.61,-1.30692,25.484779999999997,0.78372
568.18799,181.91,-1.3060399999999999,25.453139999999998,0.78298
569.08301,182.21,-1.30444,25.35773,0.7822399999999999
569.97198,182.51,-1.3106200000000001,25.32585,0.7815
570.85797,182.81,-1.31752,25.3099,0.78077
571.73297,183.11,-1.32512,25.2942,0.78004
572.6279900000001,183.41,-1.32851,25.24638,0.7793
573.51001,183.71,-1.33166,25.21473,0.77857
574.40399,184.01,-1.33198,25.15097,0.77783
575.30103,184.31,-1.34037,25.15121,0.77708
576.19397,184.61,-1.34142,25.11135,0.7763399999999999
577.08099,184.91,-1.34388,25.06377,0.7756
577.96997,185.21,-1.3473,25.047829999999998,0.77486
578.86401,185.51,-1.3500299999999998,25.0,0.77412
579.73602,185.81,-1.3496299999999999,24.96836,0.7733899999999999
580.638,186.11,-1.35548,24.92053,0.77264
581.52698,186.41,-1.3579700000000001,24.90483,0.77189
582.396,186.71,-1.36236,24.90483,0.77117
583.31403,187.01,-1.36563,24.89686,0.7704
584.16901,187.31,-1.37145,24.8413,0.76969
585.05701,187.61,-1.37493,24.81739,0.76894
585.9329799999999,187.91,-1.38008,24.77754,0.7682100000000001
586.828,188.21,-1.3816700000000002,24.75386,0.76746
587.7069700000001,188.51,-1.38565,24.714010000000002,0.76672
588.5880099999999,188.81,-1.38819,24.69807,0.76598
589.48602,189.11,-1.38835,24.67415,0.76523
590.36499,189.41,-1.39283,24.58696,0.76449
591.255,189.71,-1.39371,24.65024,0.76374
592.13599,190.01,-1.39796,24.52319,0.763
593.02502,190.31,-1.40441,24.52319,0.76225
593.90997,190.61,-1.40845,24.52319,0.7615
594.7999900000001,190.91,-1.41541,24.46763,0.76075
595.6749900000001,191.21,-1.42067,24.4756,0.7600100000000001
596.55603,191.51,-1.42036,24.45966,0.75927
597.44598,191.81,-1.42395,24.411839999999998,0.75852
598.32098,192.11,-1.42899,24.36425,0.75778
599.20599,192.41,-1.4316200000000001,24.356279999999998,0.75703
600.08099,192.71,-1.43692,24.3087,0.75629
600.96503,193.01,-1.43981,24.26884,0.75554
601.84198,193.31,-1.4417200000000001,24.26884,0.7548
602.71503,193.61,-1.44582,24.2529,0.7540600000000001
603.59802,193.91,-1.45264,24.22101,0.75331
604.474,194.21,-1.45579,24.1814,0.75256
605.38599,194.51,-1.46366,24.17343,0.75179
606.23999,194.81,-1.46066,24.1099,0.7510600000000001
607.13,195.11,-1.46336,24.08599,0.75031
608.01099,195.41,-1.46679,24.04614,0.74956
608.89001,195.71,-1.4685,24.078020000000002,0.7488100000000001
609.76801,196.01,-1.47071,24.03043,0.7480600000000001
610.63599,196.31,-1.4709299999999998,24.01449,0.74732
611.5189799999999,196.61,-1.46995,23.98261,0.74657
612.39697,196.91,-1.4771100000000001,23.95894,0.7458199999999999
613.27197,197.21,-1.47933,23.93502,0.74507
614.1630200000001,197.51,-1.4749,23.93502,0.74431
615.0380200000001,197.81,-1.4788700000000001,23.895410000000002,0.74356
615.914,198.11,-1.4811,23.831879999999998,0.7428100000000001
616.79199,198.41,-1.4893100000000001,23.85556,0.74206
617.65802,198.71,-1.49825,23.82367,0.74132
618.534,199.01,-1.50201,23.80773,0.74057
619.41602,199.31,-1.5023,23.80773,0.7398100000000001
620.2880200000001,199.61,-1.50831,23.7442,0.73907
621.17603,199.91,-1.51461,23.696379999999998,0.7383
622.05902,200.21,-1.51716,23.72029,0.73755
622.9249900000001,200.51,-1.5212,23.71256,0.7368
623.81299,200.81,-1.52377,23.648789999999998,0.7360399999999999
624.685,201.11,-1.5273299999999999,23.648789999999998,0.73529
625.54797,201.41,-1.5303799999999999,23.61715,0.73455
626.4279799999999,201.71,-1.53472,23.53744,0.7337899999999999
627.3029799999999,202.01,-1.53806,23.56932,0.7330399999999999
628.18201,202.31,-1.54443,23.54541,0.73228
629.06897,202.61,-1.5495700000000001,23.537679999999998,0.73152
629.93799,202.91,-1.55293,23.51377,0.73077
630.80902,203.21,-1.5560399999999999,23.48188,0.73002
631.68701,203.51,-1.56246,23.466179999999998,0.72926
632.57397,203.81,-1.56891,23.466179999999998,0.72849
633.4249900000001,204.11,-1.56644,23.4343,0.7277600000000001
634.29901,204.41,-1.5739,23.402420000000003,0.727
635.19,204.71,-1.5755700000000001,23.37077,0.72623
636.0720200000001,205.01,-1.58027,23.33889,0.72547
636.953,205.31,-1.58346,23.307,0.7247
637.823,205.61,-1.58867,23.29928,0.72395
638.6950099999999,205.91,-1.59263,23.2913,0.7232
639.56799,206.21,-1.5994,23.22754,0.72244
640.4500099999999,206.51,-1.6044100000000001,23.20386,0.72167
641.32599,206.81,-1.60968,23.21981,0.72091
642.2069700000001,207.11,-1.61344,23.187920000000002,0.72015
643.09698,207.41,-1.6185,23.15604,0.71938
643.96698,207.71,-1.62225,23.1244,0.71862
644.841,208.01,-1.62551,23.10845,0.71786
645.70502,208.31,-1.63646,23.116429999999998,0.71711
646.573,208.61,-1.6425599999999998,23.05266,0.71636
647.44397,208.91,-1.6473900000000001,23.0529,0.7156
648.33099,209.21,-1.6540700000000002,23.068839999999998,0.71483
649.2069700000001,209.51,-1.6550599999999998,23.03696,0.71406
650.0750099999999,209.81,-1.66198,23.00507,0.71331
650.36798,209.91,-1.66232,23.00507,0.71305