File: 02_Data/OSB/STA/N2/3K_min/OSB_STA_N2_3KData_210316_R3.csv
##Temp./Â°C,Time/min,DSC/(mW/mg),Mass/%,Sensit./(uV/mW)
49.069,10.00917,0.003052837,99.19943,1.0532700000000002
49.078,10.30917,0.004856796,99.17433,1.0532700000000002
49.092,10.609169999999999,0.003607913,99.18065,1.05326
49.127,10.90917,0.005273123,99.18046,1.05326
49.203,11.20917,0.007909751999999999,99.14904,1.05325
49.319,11.50917,0.01248925,99.12395,1.05324
49.51,11.80917,0.01470989,99.12375,1.05321
49.722,12.109169999999999,0.02012253,99.09866,1.05319
50.01,12.40917,0.0238703,99.08601999999999,1.05315
50.353,12.70917,0.02734094,99.07337,1.05311
50.744,13.00917,0.03039567,99.07337,1.05306
51.177,13.309170000000002,0.03192406,99.0546,1.053
51.626,13.60917,0.035396,99.02931,1.05294
52.111,13.909170000000001,0.03775797,99.02931,1.05288
52.674,14.20917,0.04178654,99.00402,1.05281
53.185,14.509170000000001,0.04387171,98.97893,1.05274
53.757,14.809170000000002,0.04637404,98.95364000000001,1.05267
54.346,15.10917,0.04943229,98.95364000000001,1.05259
55.014,15.409170000000001,0.05138061,98.95364000000001,1.0525
55.613,15.70917,0.05346771,98.90939,1.0524200000000001
56.299,16.00917,0.05722245,98.88429000000001,1.05233
56.926,16.30917,0.05736602,98.87796999999999,1.05224
57.603,16.609170000000002,0.06056612,98.87796999999999,1.05215
58.316,16.90917,0.06098862,98.86533,1.05205
59.035,17.20917,0.06474584,98.83391,1.05195
59.789,17.50917,0.06503033,98.80249,1.0518399999999999
60.533,17.80917,0.06670453,98.82759,1.0517299999999998
61.277,18.109170000000002,0.06796217,98.8023,1.0516299999999998
62.064,18.40917,0.06880357,98.78985,1.05151
62.848,18.70917,0.07020123,98.77701,1.0514
63.635,19.00917,0.0725725,98.75192,1.05128
64.476,19.30917,0.07313737,98.72663,1.05115
65.233,19.609170000000002,0.07397969,98.72681999999999,1.05104
66.041,19.90917,0.07524005,98.67625,1.05092
66.868,20.20917,0.07664008,98.65115,1.05079
67.702,20.50917,0.07734508,98.65096,1.05066
68.52,20.80917,0.07693714,98.63831,1.05053
69.362,21.109170000000002,0.07875577,98.60056999999999,1.0504
70.205,21.40917,0.07890502,98.57548,1.05026
71.047,21.70917,0.07835849,98.56284000000001,1.05013
71.933,22.00917,0.08017883,98.53774,1.04998
72.738,22.30917,0.08032813,98.54387,1.04985
73.62,22.609170000000002,0.08047853,98.51858,1.0497100000000001
74.472,22.90917,0.08104645,98.51226,1.04956
75.337,23.20917,0.08063988,98.48716,1.04942
76.211,23.50917,0.0803727,98.48716,1.0492700000000001
77.074,23.80917,0.08052334,98.47452,1.04912
77.948,24.109170000000002,0.08109227,98.46188000000001,1.0489700000000002
78.825,24.40917,0.07971056,98.45555999999999,1.04882
79.7,24.70917,0.0805585,98.43046,1.04866
80.581,25.00917,0.0807099,98.41149,1.04851
81.488,25.30917,0.08016473,98.3864,1.04834
82.335,25.609170000000002,0.08101303,98.39904,1.04819
83.232,25.90917,0.07963106,98.37375,1.04803
84.122,26.20917,0.0793645,98.34234000000001,1.04787
85.008,26.50917,0.0788189,98.32337,1.0477
85.899,26.80917,0.07924998,98.33161,1.04754
86.795,27.109170000000002,0.07982091,98.32529,1.0473700000000001
87.7,27.40917,0.08109012,98.32548,1.0472
88.606,27.70917,0.08124312,98.31284000000001,1.04702
89.502,28.00917,0.07874342,98.30632,1.04685
90.419,28.30917,0.0790361,98.2749,1.04667
91.317,28.609170000000002,0.07960802,98.26226,1.0465
92.238,28.90917,0.07948216,98.24981,1.04631
93.149,29.20917,0.08019448,98.23716,1.04613
94.052,29.50917,0.078811,98.25613,1.04595
94.977,29.80917,0.07714795,98.23084,1.04577
95.887,30.109170000000002,0.07758097,98.23084,1.04558
96.81,30.40917,0.07717558,98.20575,1.04539
97.736,30.70917,0.07844824,98.23084,1.0452
98.643,31.00917,0.07832256,98.20555999999999,1.04501
99.562,31.30917,0.0784769,98.23065,1.04482
100.494,31.609170000000002,0.07919126,98.23084,1.04462
101.399,31.90917,0.07934581,98.19291,1.04443
102.339,32.20917,0.07922117,98.21188000000001,1.04423
103.241,32.509170000000005,0.078256,98.19291,1.04403
104.163,32.80917,0.08023133,98.16781999999999,1.04383
105.097,33.10917,0.08038711,98.19291,1.0436299999999998
106.032,33.40917,0.08138354,98.16781999999999,1.04342
106.944,33.70917,0.08083895,98.14253000000001,1.04322
107.91,34.009170000000005,0.08071559,98.14253000000001,1.043
108.807,34.30917,0.0815722,98.14253000000001,1.0428
109.717,34.60917,0.08060706,98.12375,1.04259
110.629,34.90917,0.08048297,98.12375,1.0423799999999999
111.557,35.20917,0.08274335,98.09846999999999,1.04217
112.49,35.509170000000005,0.08360216,98.08582,1.04195
113.412,35.80917,0.08446123,98.11092,1.0417399999999999
114.351,36.10917,0.08377746,98.07318000000001,1.04152
115.262,36.40917,0.08435623,98.0795,1.0413
116.193,36.70917,0.08381263,98.07318000000001,1.04108
117.121,37.009170000000005,0.08663894,98.09846999999999,1.0408600000000001
118.062,37.30917,0.08497243,98.05441,1.04063
118.971,37.60917,0.08541189,98.05421,1.04041
119.904,37.90917,0.08739776,98.0795,1.0401799999999999
120.846,38.20917,0.08460639,98.06054,1.03995
121.762,38.509170000000005,0.08617113,98.09215,1.03972
122.702,38.80917,0.08576873,98.06685999999999,1.03949
123.634,39.10917,0.087335,98.06685999999999,1.03926
124.575,39.40917,0.08707361,98.04808,1.03902
125.536,39.70917,0.08526494,98.03544000000001,1.03878
126.444,40.009170000000005,0.08725424,98.03544000000001,1.03854
127.386,40.30917,0.08811917,98.01015,1.0383
128.31,40.60917,0.08560509,97.99138,1.03806
129.25999,40.90917,0.08647046,98.02893,1.03782
130.21201000000002,41.20917,0.08620949,98.00383000000001,1.03757
131.11501,41.509170000000005,0.0889063,98.00383000000001,1.0373299999999999
132.06798999999998,41.80917,0.08822328,98.00383000000001,1.03708
133.008,42.10917,0.08838555,98.01648,1.03683
133.94901000000002,42.40917,0.09052206,97.99119,1.03657
134.895,42.70917,0.08927502,98.00383000000001,1.0363200000000001
135.83098999999999,43.009170000000005,0.08760406,98.01648,1.03607
136.797,43.30917,0.0888963,97.99750999999999,1.0358
137.728,43.60917,0.08821252,97.97452,1.03555
138.675,43.90917,0.08922302,97.97452,1.03528
139.63,44.20917,0.08924587,97.99962,1.03502
140.563,44.509170000000005,0.08983332,97.96188000000001,1.0347600000000001
141.511,44.80917,0.08943257,97.96188000000001,1.03449
142.461,45.10917,0.08987972,97.97433000000001,1.03423
143.409,45.40917,0.08863091,97.94923,1.03396
144.349,45.70917,0.08964368,97.96188000000001,1.03369
145.30098999999998,46.009170000000005,0.08952595,97.94923,1.03341
146.258,46.30917,0.08926695,97.94923,1.03314
147.209,46.60917,0.08971532,97.94923,1.0328600000000001
148.16,46.90917,0.09030561,97.93027,1.0325799999999998
149.105,47.20917,0.08948037,97.94291,1.03231
150.062,47.509170000000005,0.09177079,97.93659,1.03203
150.99698999999998,47.80917,0.08995388,97.92414000000001,1.03175
151.952,48.10917,0.08955361,97.94291,1.03146
152.923,48.40917,0.08972063,97.89253000000001,1.0311700000000001
153.851,48.70917,0.09144629,97.93659,1.0308899999999999
154.79401000000001,49.009170000000005,0.09090437,97.90498000000001,1.03061
155.767,49.30917,0.09093051,97.92395,1.03031
156.716,49.60917,0.08953717,97.89885,1.0300200000000002
157.67,49.90917,0.09084013,97.92414000000001,1.02973
158.60898999999998,50.20917,0.0918596,97.92414000000001,1.02944
159.56599,50.509170000000005,0.09245422,97.90517,1.02914
160.51199,50.80917,0.09347521,97.90517,1.02884
161.48,51.10917,0.09307652,97.93659,1.02854
162.44298999999998,51.40917,0.09296189,97.88620999999999,1.02824
163.386,51.70917,0.09469515,97.88620999999999,1.0279399999999999
164.32401000000002,52.009170000000005,0.09386934,97.91781999999999,1.0276399999999999
165.293,52.30917,0.09304408,97.87356,1.0273299999999999
166.25301000000002,52.60917,0.09236051,97.87356,1.02702
167.217,52.909169999999996,0.0919615,97.82318000000001,1.02671
168.164,53.20916999999999,0.09227387,97.8546,1.0264
169.125,53.50917,0.09344163,97.82318000000001,1.0260799999999999
170.078,53.809169999999995,0.09404006,97.84195,1.02577
171.03101,54.10917,0.09535165,97.82318000000001,1.02546
171.987,54.409169999999996,0.09523853,97.81685999999999,1.02514
172.961,54.70916999999999,0.09669484,97.79789,1.02482
173.903,55.00917,0.09729523,97.79789,1.0245
174.875,55.309169999999995,0.0961846,97.76015,1.02417
175.81599,55.60917,0.09649995,97.75383000000001,1.02386
176.769,55.909169999999996,0.09581645,97.74750999999999,1.0235299999999998
177.73398999999998,56.20916999999999,0.09627577,97.75383000000001,1.0232
178.69099,56.50917,0.09544927,97.75383000000001,1.02288
179.64799,56.809169999999995,0.0967664,97.72854,1.02255
180.605,57.10917,0.0967977,97.72854,1.0222200000000001
181.56599,57.409169999999996,0.09854561,97.68448000000001,1.02188
182.52299,57.70916999999999,0.09943624,97.68448000000001,1.02155
183.481,58.00917,0.09832394,97.67184,1.02121
184.429,58.309169999999995,0.09706755,97.64041999999999,1.02088
185.40401,58.60917,0.09795959,97.64041999999999,1.02054
186.35201,58.909169999999996,0.09856495,97.59617,1.0202
187.313,59.20916999999999,0.09802481,97.57088,1.01986
188.265,59.50917,0.09734078,97.53945999999999,1.01952
189.226,59.809169999999995,0.097804,97.51207,1.0191700000000001
190.187,60.10917,0.09783732,97.50575,1.01882
191.151,60.409169999999996,0.09772739,97.4682,1.0184799999999998
192.121,60.70916999999999,0.09819197,97.44291,1.0181200000000001
193.075,61.00917,0.09750762,97.44904,1.01777
194.033,61.309169999999995,0.09811596,97.39865999999999,1.01742
195.006,61.60917,0.09915652,97.37989,1.01706
195.957,61.909169999999996,0.09832838,97.36092,1.01671
196.933,62.20916999999999,0.09807589,97.32318000000001,1.01635
197.886,62.50917,0.0999804,97.28525,1.01599
198.85699,62.809169999999995,0.09972843,97.28525,1.01563
199.83701000000002,63.10917,0.10005,97.23487,1.01526
200.778,63.409169999999996,0.09979968,97.19693000000001,1.0149
201.74001,63.70916999999999,0.10056,97.1592,1.01454
202.71201000000002,64.00917,0.10146000000000001,97.12146,1.01417
203.672,64.30917,0.10164,97.09617,1.0138
204.631,64.60916999999999,0.10095,97.05192,1.0134299999999998
205.597,64.90916999999999,0.10114,97.00153,1.01306
206.562,65.20917,0.10074,96.94483000000001,1.01268
207.519,65.50917,0.10078,96.91954,1.01231
208.487,65.80917,0.10096000000000001,96.85019,1.01193
209.442,66.10916999999999,0.10142999999999999,96.82299,1.01156
210.39999,66.40916999999999,0.10234,96.77241,1.01118
211.362,66.70917,0.10122,96.70326,1.0108
212.323,67.00917,0.10299000000000001,96.69693000000001,1.01042
213.285,67.30917,0.10086,96.58123,1.01004
214.255,67.60916999999999,0.10206,96.52452,1.00965
215.218,67.90916999999999,0.10181,96.46169,1.00926
216.18401,68.20917,0.10372999999999999,96.41111,1.0088700000000002
217.15601,68.50917,0.10377,96.36073,1.0084799999999998
218.12198999999998,68.80917,0.10192000000000001,96.26609,1.00809
219.06798999999998,69.10916999999999,0.10312,96.26609,1.0077
220.035,69.40916999999999,0.10403,96.13582,1.00731
220.993,69.70917,0.10465999999999999,96.11054,1.00691
221.96201000000002,70.00917,0.10615,96.00976999999999,1.00651
222.923,70.30917,0.10488,95.94041999999999,1.0061200000000001
223.87399,70.60916999999999,0.10493,95.87739,1.0057200000000002
224.842,70.90916999999999,0.10613,95.80805,1.00532
225.806,71.20917,0.10645999999999999,95.70709000000001,1.00491
226.758,71.50917,0.10622000000000001,95.62529,1.00451
227.714,71.80917,0.10509,95.56858000000001,1.00411
228.673,72.10916999999999,0.10514000000000001,95.48659,1.00371
229.62399,72.40916999999999,0.10561,95.38563,1.0033
230.597,72.70917,0.10755,95.291,1.00289
231.569,73.00917,0.10715999999999999,95.209,1.00247
232.53101,73.30917,0.10852,95.10824000000001,1.00206
233.48801,73.60916999999999,0.10855999999999999,95.02011,1.00165
234.448,73.90916999999999,0.10772999999999999,94.94444,1.0012299999999998
235.41499,74.20917,0.10762999999999999,94.84368,1.00082
236.373,74.50917,0.10899,94.73008,1.0004
237.33098999999999,74.80917,0.10772000000000001,94.60401999999999,0.99998
238.299,75.10916999999999,0.10879000000000001,94.52835,0.99956
239.256,75.40916999999999,0.1081,94.42759000000001,0.9991399999999999
240.216,75.70917,0.11034000000000001,94.32663000000001,0.99871
241.187,76.00917,0.10849,94.19425,0.99828
242.151,76.30917,0.10853,94.08716,0.9978600000000001
243.112,76.60916999999999,0.10887000000000001,93.959,0.9974299999999999
244.07401000000002,76.90916999999999,0.10819000000000001,93.85805,0.997
245.03798999999998,77.20917,0.10882,93.73831,0.9965700000000001
246.009,77.50917,0.10930999999999999,93.62893000000001,0.99613
246.968,77.80917,0.10877,93.49042,0.9957
247.95,78.10916999999999,0.10808,93.35172,0.99525
248.896,78.40916999999999,0.11004000000000001,93.22355999999999,0.99482
249.854,78.70917,0.1095,93.04904,0.99439
250.825,79.00917,0.10910999999999998,92.9567,0.9939399999999999
251.79401000000001,79.30917,0.10857,92.75479,0.9935
252.754,79.60916999999999,0.10847000000000001,92.5931,0.99306
253.724,79.90916999999999,0.10822999999999999,92.4523,0.99261
254.686,80.20917,0.1096,92.27797,0.99216
255.655,80.50917,0.11083,92.06992,0.9917100000000001
256.61099,80.80917,0.11117,91.89962,0.9912700000000001
257.57401,81.10916999999999,0.1099,91.72318,0.99082
258.556,81.40916999999999,0.11039000000000002,91.52778,0.99036
259.50699,81.70917,0.11044000000000001,91.32395,0.9899100000000001
260.47299,82.00917,0.11108,91.08659,0.98945
261.42401,82.30917,0.10965,90.90785,0.989
262.401,82.60916999999999,0.11133,90.71034,0.98854
263.35901,82.90916999999999,0.10916,90.46455999999999,0.98808
264.32401,83.20917,0.11084000000000001,90.22931,0.98762
265.29999,83.50917,0.10955999999999999,90.02739,0.98716
266.24301,83.80917,0.11020999999999999,89.78372,0.9867
267.21799,84.10916999999999,0.10980999999999999,89.55038,0.9862299999999999
268.173,84.40916999999999,0.10853,89.26245,0.98577
269.13,84.70917,0.10903,88.97893,0.98531
270.09799,85.00917,0.10952,88.68889,0.9848399999999999
271.06201,85.30917,0.10869000000000001,88.4136,0.98436
272.01501,85.60916999999999,0.10933,88.14674000000001,0.9839
272.96898999999996,85.90916999999999,0.1082,87.84215,0.9834299999999999
273.92499,86.20917,0.10765,87.48487,0.9829600000000001
274.91299,86.50917,0.10845,87.23697,0.9824700000000001
275.853,86.80917,0.10790999999999999,86.91341,0.98201
276.797,87.10916999999999,0.11094000000000001,86.65709,0.98154
277.754,87.40916999999999,0.1101,86.28084,0.98106
278.70999,87.70917,0.11238,85.96781999999999,0.9805799999999999
279.66501,88.00917,0.11244000000000001,85.61054,0.98011
280.60901,88.30917,0.11384000000000001,85.28487,0.9796299999999999
281.57999,88.60916999999999,0.11404,84.94023,0.97914
282.53201,88.90916999999999,0.11514,84.56839000000001,0.9786600000000001
283.48599,89.20917,0.11445,84.19636,0.9781799999999999
284.43701,89.50917,0.11600999999999999,83.81418000000001,0.9777
285.397,89.80917,0.11590999999999999,83.42107,0.97721
286.35199,90.10916999999999,0.11777,83.04904,0.97672
287.30701,90.40916999999999,0.11947,82.64981,0.9762299999999999
288.255,90.70917,0.12057999999999999,82.25268,0.9757399999999999
289.211,91.00917,0.12094,81.80516999999999,0.97525
290.16299,91.30917,0.1234,81.35345,0.9747600000000001
291.12799,91.60916999999999,0.12467,80.95211,0.97426
292.07198999999997,91.90916999999999,0.12668,80.5023,0.97377
293.02898999999996,92.20917,0.12945,80.04023000000001,0.9732700000000001
293.99301,92.50917,0.12830999999999998,79.57375,0.97277
294.94601,92.80917,0.13093,79.11149,0.9722700000000001
295.88501,93.10916999999999,0.13341,78.66188000000001,0.97178
296.85001,93.40916999999999,0.13543,78.16169000000001,0.9712700000000001
297.79999,93.70917,0.13641,77.67625,0.97077
298.76099,94.00917,0.13844,77.16149,0.97026
299.69901,94.30917,0.13926,76.63602,0.9697600000000001
300.659,94.60916999999999,0.14205,76.1613,0.96925
301.608,94.90916999999999,0.14257,75.64865999999999,0.96875
302.56601,95.20917,0.14356,75.13351999999999,0.9682299999999999
303.50299,95.50917,0.14484,74.54119,0.96773
304.491,95.80917,0.14598,74.02221999999999,0.9672
305.45401,96.10916999999999,0.14908,73.45057,0.9666799999999999
306.37701,96.40916999999999,0.15112,72.89175999999999,0.96619
307.33099,96.70917,0.15195999999999998,72.32011,0.96567
308.27398999999997,97.00917,0.15295,71.75498,0.96516
309.23599,97.30917,0.15409,71.16034,0.9646299999999999
310.177,97.60916999999999,0.1569,70.55287,0.9641200000000001
311.15302,97.90916999999999,0.15805,69.92893000000001,0.96359
312.07101,98.20917,0.16025999999999999,69.31954,0.9630799999999999
313.02499,98.50917,0.16141,68.67874,0.9625600000000001
313.99899,98.80917,0.16393,68.09023,0.9620200000000001
314.931,99.10916999999999,0.16675,67.45153,0.9615100000000001
315.89301,99.40916999999999,0.16715,66.78966,0.96098
316.81601,99.70917,0.16937,66.16322,0.96047
317.75299,100.00917,0.1722,65.45728000000001,0.95994
318.73801000000003,100.30917,0.17443,64.81015,0.9594
319.66101000000003,100.60916999999999,0.17651,64.09980999999999,0.95888
320.61099,100.90916999999999,0.18027,63.41073000000001,0.95835
321.56799,101.20917,0.18342,62.702490000000004,0.95781
322.51198999999997,101.50917,0.18596,62.002869999999994,0.9572799999999999
323.45901000000003,101.80917,0.18850999999999998,61.2569,0.9567399999999999
324.405,102.10916999999999,0.19137,60.53811999999999,0.95621
325.38199,102.40916999999999,0.19194,59.77146,0.9556600000000001
326.31201,102.70917,0.1951,59.01705,0.9551299999999999
327.258,103.00917,0.19705,58.258430000000004,0.9545899999999999
328.20001,103.30917,0.20038,57.42835,0.95405
329.17401,103.60916999999999,0.20372,56.65728000000001,0.95349
330.108,103.90916999999999,0.20581999999999998,55.87989,0.95296
331.03799,104.20917,0.20886,55.05613,0.9524299999999999
331.98599,104.50917,0.21005,54.2659,0.95188
332.94199,104.80917,0.21494000000000002,53.42969,0.9513299999999999
333.88501,105.10916999999999,0.21721,52.60191999999999,0.95078
334.82501,105.40916999999999,0.2201,51.73621,0.95024
335.76901000000004,105.70917,0.21961999999999998,50.872609999999995,0.9496899999999999
336.703,106.00917,0.21850999999999998,50.02778,0.94914
337.67001,106.30917,0.22049000000000002,49.16418,0.94858
338.60699,106.60916999999999,0.222,48.27107,0.9480299999999999
339.54098999999997,106.90916999999999,0.22059,47.42011,0.9474799999999999
340.49301,107.20917,0.21918,46.56705,0.9469200000000001
341.42999,107.50917,0.21915,45.70134,0.94637
342.388,107.80917,0.21681,44.81456,0.94581
343.315,108.10916999999999,0.2143,43.94885,0.94526
344.24701,108.40916999999999,0.20901999999999998,43.12088,0.94471
345.20499,108.70917,0.20589000000000002,42.34349,0.94414
346.147,109.00917,0.20121,41.48812,0.94358
347.08701,109.30917,0.19467,40.75057,0.9430200000000001
348.035,109.60916999999999,0.18656,40.00057,0.94245
348.965,109.90916999999999,0.17937999999999998,39.26916,0.94189
349.93201,110.20917,0.1725,38.607279999999996,0.9413100000000001
350.86099,110.50917,0.16499,37.95805,0.94075
351.802,110.80917,0.15483,37.35498,0.94019
352.76001,111.10916999999999,0.14684,36.84636,0.9396100000000001
353.72,111.40916999999999,0.1351,36.33372,0.9390299999999999
354.65302,111.70917,0.12786,35.84195,0.9384600000000001
355.59,112.00917,0.12046,35.45134,0.93789
356.52898999999996,112.30917,0.10993,35.08563,0.93732
357.47501,112.60916999999999,0.10189,34.73046,0.93674
358.422,112.90916999999999,0.09351789,34.43851,0.93616
359.349,113.20917,0.08826325,34.173559999999995,0.9356
360.314,113.50917,0.08237913,33.9341,0.935
361.24301,113.80917,0.07836279,33.73238,0.9344299999999999
362.18201,114.10916999999999,0.07449863,33.58525,0.93385
363.11301000000003,114.40916999999999,0.06968974,33.3751,0.9332799999999999
364.05099,114.70917,0.06800938,33.270109999999995,0.9327
364.99301,115.00917,0.06664078,33.144059999999996,0.93211
365.918,115.30917,0.06495602,32.99061,0.9315399999999999
366.85199,115.60916999999999,0.06515358,32.86456,0.93096
367.79999,115.90916999999999,0.06189597,32.76169,0.93037
368.73199,116.20917,0.0603628,32.62299,0.9297799999999999
369.668,116.50917,0.05867065,32.52835,0.9292
370.60501,116.80917,0.05980954,32.42337,0.92861
371.556,117.10916999999999,0.06000557,32.27835,0.92801
372.492,117.40916999999999,0.05988612,32.24674,0.92742
373.43701,117.70917,0.05724381,32.14598,0.9268200000000001
374.366,118.00917,0.05712231,32.05977,0.92624
375.30701,118.30917,0.0570012,31.91897,0.92564
376.23499,118.60916999999999,0.0564055,31.855940000000004,0.92505
377.17401,118.90916999999999,0.05596762,31.72989,0.9244600000000001
378.116,119.20917,0.05442194,31.62893,0.92386
379.043,119.50917,0.05556495,31.536590000000004,0.9232600000000001
379.978,119.80917,0.05259121,31.44828,0.9226700000000001
380.923,120.10916999999999,0.0548449,31.347509999999996,0.92206
381.85999,120.40916999999999,0.05329454,31.2613,0.9214600000000001
382.79199,120.70917,0.05396409,31.179309999999997,0.92086
383.72699,121.00917,0.0539994,31.10172,0.9202600000000001
384.659,121.30917,0.05165083,30.9818,0.91966
385.59601000000004,121.60916999999999,0.05327518,30.931420000000003,0.91905
386.522,121.90916999999999,0.05235516,30.79904,0.91845
387.444,122.20917,0.05095613,30.69598,0.91785
388.38101,122.50917,0.04987456,30.6205,0.9172399999999999
389.32001,122.80917,0.04783497,30.513409999999997,0.91663
390.25101,123.10916999999999,0.0481858,30.41667,0.9160299999999999
391.185,123.40916999999999,0.04614231,30.334670000000003,0.9154200000000001
392.14001,123.70917,0.04457613,30.23372,0.91479
393.05301000000003,124.00917,0.04348619,30.13295,0.91419
393.98098999999996,124.30917,0.04351521,30.03831,0.91358
394.914,124.60916999999999,0.04354447,29.962640000000004,0.9129700000000001
395.836,124.90916999999999,0.04325308,29.83659,0.9123600000000001
396.78601000000003,125.20917,0.04360345,29.758809999999997,0.9117299999999999
397.71898999999996,125.50917,0.0428309,29.67701,0.91112
398.64999,125.80917,0.04189678,29.55728,0.9105
399.58401000000003,126.10916999999999,0.04256785,29.450190000000003,0.9098799999999999
400.505,126.40916999999999,0.04147133,29.384870000000003,0.90927
401.43201,126.70917,0.04342971,29.271459999999998,0.90865
402.35101000000003,127.00917,0.04313711,29.21475,0.90804
403.27898999999996,127.30917,0.04348872,29.12854,0.9074200000000001
404.23001,127.60916999999999,0.04319688,29.040229999999998,0.9067799999999999
405.15799,127.90916999999999,0.04435559,28.95192,0.9061600000000001
406.095,128.20917,0.04212674,28.88908,0.90553
407.022,128.50916999999998,0.04457851,28.80077,0.90491
407.94601,128.80917,0.04266967,28.718770000000003,0.90428
408.879,129.10917,0.04577246,28.611490000000003,0.90365
409.793,129.40917,0.04612748,28.51073,0.90304
410.72501,129.70917,0.04664562,28.41628,0.9024
411.64898999999997,130.00916999999998,0.04716426,28.365709999999996,0.9017799999999999
412.57501,130.30917,0.04800813,28.271259999999998,0.90115
413.521,130.60917,0.04820475,28.195590000000003,0.90051
414.44901,130.90917,0.05246153,28.07586,0.8998700000000001
415.36499,131.20917,0.05314813,28.05057,0.89925
416.298,131.50916999999998,0.05578822,27.94981,0.89861
417.21898999999996,131.80917,0.05517634,27.867820000000002,0.8979799999999999
418.14801,132.10917,0.05619278,27.81724,0.8973399999999999
419.07001,132.40917,0.05688443,27.74176,0.89671
420.00201,132.70917,0.05871933,27.6136,0.89607
420.91299000000004,133.00916999999998,0.05843404,27.575670000000002,0.89544
421.82999,133.30917,0.06108879,27.5,0.89481
422.763,133.60917,0.06325777,27.424329999999998,0.8941600000000001
423.67899000000006,133.90917,0.06591982,27.34866,0.8935299999999999
424.62,134.20917,0.06449475,27.24789,0.8928799999999999
425.526,134.50916999999998,0.06617829,27.222609999999996,0.89225
426.45599000000004,134.80917,0.06622628,27.128159999999998,0.8916
427.36899000000005,135.10917,0.07053867,27.07759,0.89097
428.298,135.40917,0.06976919,27.001920000000002,0.8903200000000001
429.21700999999996,135.70917,0.07064093,26.91398,0.8896799999999999
430.13699,136.00916999999998,0.07167846,26.882179999999998,0.8890299999999999
431.05399000000006,136.30917,0.07370457,26.8067,0.88839
431.983,136.60917,0.075899,26.74349,0.88774
432.897,136.90917,0.0780958,26.67414,0.8871
433.80701,137.20917,0.07881172,26.59866,0.88646
434.728,137.50916999999998,0.08101445,26.54808,0.88581
435.65302,137.80917,0.08256027,26.49789,0.88515
436.586,138.10917,0.08658766,26.422220000000003,0.88449
437.49701,138.40917,0.09045419,26.37165,0.88385
438.422,138.70917,0.09250718,26.27088,0.8831899999999999
439.33800999999994,139.00916999999998,0.09688115,26.264559999999996,0.88254
440.27300999999994,139.30917,0.10242000000000001,26.18889,0.8818799999999999
441.18701,139.60917,0.10282999999999999,26.16379,0.88123
442.09698,139.90917,0.10457000000000001,26.0818,0.8805799999999999
443.03299000000004,140.20917,0.10547999999999999,26.031229999999997,0.8799100000000001
443.95401,140.50916999999998,0.10805,25.98716,0.87925
444.87299,140.80917,0.11112000000000001,25.93678,0.8786
445.78699000000006,141.10917,0.11287,25.8864,0.8779399999999999
446.71399,141.40917,0.11379,25.86111,0.87728
447.63100999999995,141.70917,0.11571,25.785439999999998,0.8766200000000001
448.55099,142.00916999999998,0.11813,25.73295,0.87595
449.474,142.30917,0.11939000000000001,25.70766,0.87529
450.39300999999995,142.60917,0.12165,25.63199,0.8746299999999999
451.311,142.90917,0.12593,25.60057,0.8739600000000001
452.228,143.20917,0.12586,25.55019,0.8733
453.14499000000006,143.50916999999998,0.1283,25.531229999999997,0.8726299999999999
454.06,143.80917,0.12789,25.44923,0.87197
454.97500999999994,144.10917,0.13185,25.39885,0.87131
455.91,144.40917,0.13363,25.37356,0.8706200000000001
456.82100999999994,144.70917,0.13222,25.34828,0.8699600000000001
457.716,145.00916999999998,0.13417,25.29789,0.86931
458.638,145.30917,0.13612,25.247510000000002,0.8686299999999999
459.55899000000005,145.60917,0.13606,25.20326,0.8679600000000001
460.47101,145.90917,0.13885999999999998,25.146739999999998,0.86729
461.401,146.20917,0.14065999999999998,25.12146,0.86661
462.314,146.50916999999998,0.14127,25.071070000000002,0.8659399999999999
463.23099,146.80917,0.14121,25.04579,0.8652700000000001
464.15302,147.10917,0.14065,24.989079999999998,0.86459
465.04599,147.40917,0.14092000000000002,24.94502,0.86393
465.957,147.70917,0.1412,24.919729999999998,0.86326
466.87600999999995,148.00916999999998,0.14098,24.90709,0.8625799999999999
467.82199,148.30917,0.14109000000000002,24.84406,0.86188
468.711,148.60917,0.13967000000000002,24.81877,0.8612200000000001
469.638,148.90917,0.14165,24.76839,0.8605299999999999
470.561,149.20917,0.14107999999999998,24.73697,0.85985
471.47198,149.50916999999998,0.14205,24.71169,0.8591700000000001
472.38100999999995,149.80917,0.14199,24.6613,0.85849
473.28299000000004,150.10917,0.14295,24.62969,0.85782
474.19500999999997,150.40917,0.14306,24.61073,0.85714
475.10900999999996,150.70917,0.14301,24.56034,0.85646
476.021,151.00916999999998,0.1438,24.56034,0.85577
476.93701,151.30917,0.14545999999999998,24.50996,0.85509
477.86301,151.60917,0.14438,24.45939,0.85439
478.76800999999995,151.90917,0.14364000000000002,24.43429,0.8537100000000001
479.673,152.20917,0.14478,24.415329999999997,0.85303
480.57901,152.50916999999998,0.14558,24.377589999999998,0.85235
481.49799,152.80917,0.14536,24.38391,0.8516600000000001
482.414,153.10917,0.14548,24.308239999999998,0.8509700000000001
483.32500999999996,153.40917,0.14594000000000001,24.28314,0.8502799999999999
484.255,153.70917,0.14623,24.232570000000003,0.8495799999999999
485.17400999999995,154.00916999999998,0.14859,24.207279999999997,0.84888
486.06201,154.30917,0.14887999999999998,24.18218,0.84821
486.987,154.60917,0.14831,24.15709,0.84751
487.90200999999996,154.90917,0.14964,24.13812,0.8468100000000001
488.81799,155.20917,0.14959,24.10651,0.84611
489.716,155.50916999999998,0.14868,24.03716,0.8454299999999999
490.625,155.80917,0.14932,24.030839999999998,0.8447399999999999
491.54501,156.10917,0.14823,24.00575,0.84403
492.45901,156.40917,0.14835,23.955170000000003,0.84334
493.366,156.70917,0.14917,23.961489999999998,0.84264
494.263,157.00916999999998,0.14825,23.9364,0.84196
495.17999000000003,157.30917,0.14715999999999999,23.86686,0.84125
496.09,157.60917,0.14537,23.845979999999997,0.84055
496.996,157.90917,0.14775,23.82701,0.83986
497.896,158.20917,0.1477,23.78295,0.8391700000000001
498.806,158.50916999999998,0.1473,23.801920000000003,0.83846
499.71200999999996,158.80917,0.14602,23.73238,0.8377700000000001
500.617,159.10917,0.1458,23.72625,0.8370700000000001
501.51800999999995,159.40917,0.14889000000000002,23.732570000000003,0.8363700000000001
502.43701,159.70917,0.14622000000000002,23.68199,0.8356600000000001
503.34799000000004,160.00916999999998,0.14615999999999998,23.68199,0.83496
504.254,160.30917,0.14454,23.637929999999997,0.83425
505.17599,160.60917,0.14045,23.60651,0.83354
506.07599000000005,160.90917,0.13917000000000002,23.5749,0.8328399999999999
506.98599,161.20917,0.13840999999999998,23.524520000000003,0.8321299999999999
507.896,161.50916999999998,0.13712,23.524520000000003,0.83142
508.79900999999995,161.80917,0.13741,23.49943,0.8307200000000001
509.698,162.10917,0.13647,23.455170000000003,0.8300200000000001
510.59601,162.40917,0.13552999999999998,23.44885,0.8293200000000001
511.49899000000005,162.70917,0.13652,23.39847,0.8286100000000001
512.396,163.00916999999998,0.13505,23.39847,0.82791
513.2930299999999,163.30917,0.13393,23.37337,0.82721
514.2130099999999,163.60917,0.13298,23.34808,0.82649
515.117,163.90917,0.13221,23.3228,0.82578
516.026,164.20917,0.1302,23.28506,0.82506
516.95599,164.50916999999998,0.13315,23.27241,0.8243299999999999
517.8380099999999,164.80917,0.13504000000000002,23.25134,0.8236399999999999
518.74103,165.10917,0.13374,23.18199,0.8229299999999999
519.6279900000001,165.40917,0.13278,23.200960000000002,0.8222299999999999
520.521,165.70917,0.1313,23.150570000000002,0.82152
521.41998,166.00916999999998,0.13426,23.131610000000002,0.82081
522.32599,166.30917,0.13117,23.11897,0.8201
523.23297,166.60917,0.13093,23.081229999999998,0.8193799999999999
524.13202,166.90917,0.12908,23.081229999999998,0.81867
525.039,167.20917,0.12972999999999998,23.0749,0.81795
525.94,167.50916999999998,0.12947999999999998,23.024520000000003,0.81723
526.85498,167.80917,0.12835,22.98659,0.8165100000000001
527.74103,168.10917,0.12935,22.96762,0.8158
528.638,168.40917,0.13018,22.95498,0.81509
529.52802,168.70917,0.12886,22.92989,0.81438
530.43402,169.00916999999998,0.12951,22.92989,0.81365
531.336,169.30917,0.12855,22.89847,0.81293
532.22699,169.60917,0.13064,22.84789,0.8122199999999999
533.11902,169.90917,0.1304,22.84789,0.8115100000000001
534.01801,170.20917,0.13069,22.79751,0.81079
534.9119900000001,170.50916999999998,0.12774000000000002,22.79751,0.81007
535.80603,170.80917,0.13128,22.79119,0.8093600000000001
536.69598,171.10917,0.13104000000000002,22.75977,0.8086399999999999
537.5880099999999,171.40917,0.13007,22.75977,0.80793
538.48901,171.70917,0.13145,22.7092,0.8072
539.37,172.00916999999998,0.12903,22.7092,0.8064899999999999
540.271,172.30917,0.13024000000000002,22.6841,0.80577
541.15503,172.60917,0.13053,22.65881,0.80505
542.05701,172.90917,0.12883,22.67759,0.80433
542.94897,173.20917,0.12913,22.63352,0.80361
543.84497,173.50916999999998,0.12961,22.63352,0.80288
544.74597,173.80917,0.12736,22.60843,0.80215
545.651,174.10917,0.12803,22.60824,0.80142
546.54602,174.40917,0.12796,22.589270000000003,0.8007
547.44397,174.70917,0.12771,22.51379,0.79997
548.34601,175.00916999999998,0.13039,22.51379,0.79923
549.2139900000001,175.30917,0.12959,22.50134,0.7985300000000001
550.11401,175.60917,0.12897,22.46341,0.7978
551.0020099999999,175.90917,0.13019,22.48218,0.79708
551.89301,176.20917,0.13196,22.4569,0.79635
552.77399,176.50916999999998,0.13208,22.450770000000002,0.7956300000000001
553.6610099999999,176.80917,0.13072999999999999,22.40019,0.79491
554.55402,177.10917,0.13251,22.40651,0.79418
555.45099,177.40917,0.13373,22.40651,0.79345
556.34601,177.70917,0.13164,22.35613,0.79271
557.229,178.00916999999998,0.13047,22.35613,0.79199
558.12903,178.30917,0.13189,22.33716,0.7912600000000001
559.01001,178.60917,0.13477999999999998,22.30575,0.7905300000000001
559.90302,178.90917,0.13676,22.28678,0.7898
560.80103,179.20917,0.13466,22.299429999999997,0.78906
561.68597,179.50916999999998,0.1346,22.27433,0.7883399999999999
562.59497,179.80917,0.13527999999999998,22.24904,0.78759
563.48401,180.10917,0.13467,22.22375,0.78686
564.37402,180.40917,0.13665,22.20498,0.7861199999999999
565.263,180.70917,0.13622,22.17969,0.7853899999999999
566.15997,181.00916999999998,0.13691,22.154410000000002,0.78465
567.04901,181.30917,0.13815999999999998,22.14828,0.78392
567.93799,181.60917,0.13922,22.122989999999998,0.78318
568.82703,181.90917,0.13785,22.116670000000003,0.78245
569.72601,182.20917,0.13835999999999998,22.11034,0.78171
570.61603,182.50916999999998,0.13999,22.09157,0.7809699999999999
571.5020099999999,182.80917,0.14031,22.053639999999998,0.7802399999999999
572.39099,183.10917,0.14044,22.047320000000003,0.7795
573.289,183.40917,0.13963,22.041,0.77875
574.1799900000001,183.70917,0.13883,21.99061,0.7780100000000001
575.07098,184.00916999999998,0.14122,21.97165,0.77727
575.953,184.30917,0.13796,21.92759,0.77654
576.84802,184.60917,0.13998,21.952679999999997,0.7758
577.7310200000001,184.90917,0.14294,21.92739,0.7750600000000001
578.612,185.20917,0.14232,21.9023,0.77433
579.50897,185.50916999999998,0.1434,21.877010000000002,0.77358
580.38397,185.80917,0.14543,21.883329999999997,0.77285
581.27698,186.10917,0.14519,21.85192,0.7721
582.15997,186.40917,0.14628,21.80134,0.77137
583.0499900000001,186.70917,0.14718,21.7636,0.77062
583.93597,187.00916999999998,0.14808,21.74483,0.76988
584.80603,187.30917,0.15088,21.74483,0.76915
585.69098,187.60917,0.15255,21.75096,0.76841
586.586,187.90917,0.15422,21.69425,0.76766
587.4810200000001,188.20917,0.15018,21.69425,0.7669100000000001
588.3560200000001,188.50916999999998,0.1528,21.687929999999998,0.76618
589.23798,188.80917,0.15428,21.68161,0.76543
590.117,189.10917,0.15367,21.69425,0.7647
590.98999,189.40917,0.15477,21.65651,0.7639600000000001
591.90002,189.70917,0.15761,21.65019,0.7632
592.7520099999999,190.00916999999998,0.1568,21.63755,0.76248
593.6270099999999,190.30917,0.15465,21.63755,0.76174
594.50598,190.60917,0.15517999999999998,21.60594,0.761
595.396,190.90917,0.15784,21.61245,0.76025
596.29498,191.20917,0.15915,21.58084,0.75949
597.159,191.50916999999998,0.16065,21.54291,0.75876
598.0430299999999,191.80917,0.16254000000000002,21.55575,0.7580100000000001
598.93903,192.10917,0.16232,21.53046,0.75726
599.79602,192.40917,0.1646,21.50517,0.75653
600.69,192.70917,0.16535,21.45479,0.7557699999999999
601.54901,193.00916999999998,0.16783,21.45479,0.75505
602.4299900000001,193.30917,0.16585999999999998,21.41686,0.7543
603.315,193.60917,0.16797,21.39157,0.75355
604.19,193.90917,0.16833,21.39157,0.7528100000000001
605.07098,194.20917,0.17082999999999998,21.36648,0.7520600000000001
605.95398,194.50916999999998,0.17314000000000002,21.38525,0.75131
606.8389900000001,194.80917,0.17565,21.41054,0.75055
607.72699,195.10917,0.17465999999999998,21.34751,0.7498
608.59802,195.40917,0.17737,21.34751,0.7490600000000001
609.49597,195.70917,0.18126,21.334870000000002,0.74829
610.38202,196.00916999999998,0.18379,21.35383,0.74754
611.245,196.30917,0.18416,21.335060000000002,0.7468
612.133,196.60917,0.18866,21.31609,0.7460399999999999
613.01599,196.90917,0.18689,21.31609,0.74529
613.89301,197.20917,0.18983,21.28448,0.74454
614.77301,197.50916999999998,0.19493,21.284670000000002,0.74379
615.64099,197.80917,0.20063,21.2908,0.74305
616.534,198.10917,0.19985999999999998,21.22146,0.74228
617.41998,198.40917,0.19947,21.24674,0.74152
618.2880200000001,198.70917,0.20223,21.21513,0.74078
619.17102,199.00916999999998,0.20501,21.22778,0.74002
620.04602,199.30917,0.20462,21.20881,0.73927
620.92102,199.60917,0.20681,21.202679999999997,0.73852
621.78998,199.90917,0.20781,21.18372,0.73778
622.6560099999999,200.20917,0.21456999999999998,21.18372,0.73703
623.52899,200.50916999999998,0.21478000000000003,21.18985,0.73628
624.4119900000001,200.80917,0.21779,21.17739,0.73553
625.29102,201.10917,0.2204,21.17107,0.73477
626.17603,201.40917,0.22361,21.1205,0.73401
627.05402,201.70917,0.22763000000000003,21.126820000000002,0.73325
627.90698,202.00916999999998,0.22885999999999998,21.10172,0.73252
628.79102,202.30917,0.2293,21.06379,0.7317600000000001
629.67102,202.60917,0.23433,21.10805,0.731
630.54797,202.90917,0.23678000000000002,21.08276,0.73024
631.435,203.20917,0.23863,21.057660000000002,0.72947
632.31,203.50916999999998,0.23847,21.05134,0.72872
633.21503,203.80917,0.24034,21.05134,0.7279399999999999
634.0549900000001,204.10917,0.24038,21.04502,0.72721
634.9249900000001,204.40917,0.24586,21.007089999999998,0.72646
635.7930299999999,204.70917,0.24771999999999997,21.01973,0.7257100000000001
636.6560099999999,205.00916999999998,0.25281,20.99464,0.72496
637.534,205.30917,0.25025,20.96935,0.7242
638.40503,205.60917,0.25456,20.9567,0.72345
639.2810099999999,205.90917,0.25583,20.93161,0.7226899999999999
640.1439799999999,206.20917,0.25833,20.9569,0.7219399999999999
641.02399,206.50916999999998,0.25779,20.93161,0.72118
641.89001,206.80917,0.26029,20.95038,0.72043
642.78302,207.10917,0.26321,20.91897,0.71965
643.646,207.40917,0.26511,20.9251,0.7189
644.52502,207.70917,0.26661,20.9,0.71814
645.396,208.00916999999998,0.26934,20.91897,0.71738
646.258,208.30917,0.27023,20.90632,0.71663
647.1220099999999,208.60917,0.2744,20.89368,0.7158800000000001
647.99103,208.90917,0.27755,20.88736,0.71512
648.87097,209.20917,0.27948,20.84962,0.71436
649.745,209.50916999999998,0.28101,20.84962,0.71359
650.61102,209.80917000000002,0.28643,20.83065,0.7128399999999999
650.927,209.90917000000002,0.28531,20.83065,0.7125600000000001