File: 02_Data/MDF/STA/N2/30K_min/MDF_STA_N2_30KData_210311_R3.csv
##Temp./Â°C,Time/min,DSC/(mW/mg),Mass/%,Sensit./(uV/mW)
48.62,10.00583,0.0033510590000000004,101.17846,1.06797
48.603,10.105830000000001,0.003960313,101.15053,1.06797
48.597,10.20583,0.005026544,101.17164,1.06798
48.6,10.30583,0.005483509,101.17164,1.06798
48.632,10.40583,0.0065498380000000005,101.17164,1.06796
48.649,10.50583,0.009291699,101.17164,1.06795
48.713,10.605830000000001,0.01508039,101.17164,1.06792
48.794,10.70583,0.02147891,101.20425999999999,1.06788
48.907,10.80583,0.03199147,101.22303000000001,1.0678299999999998
49.069,10.90583,0.04448657,101.23241,1.06775
49.298,11.00583,0.06231799,101.2371,1.06765
49.567,11.105830000000001,0.08045924,101.23945,1.06752
49.926,11.20583,0.10196000000000001,101.24179000000001,1.06735
50.372,11.30583,0.13003,101.28614,1.06714
50.888,11.40583,0.15995,101.28166,1.06689
51.501,11.50583,0.1911,101.2887,1.0666
52.23,11.605830000000001,0.22824,101.28401,1.06625
53.081,11.70583,0.26785,101.29318,1.06585
54.002,11.80583,0.30873,101.2838,1.06541
55.064,11.90583,0.35196,101.29552,1.06491
56.221,12.00583,0.396,101.29552,1.06436
57.494,12.105830000000001,0.44118999999999997,101.30959,1.06375
58.852,12.20583,0.48522,101.29318,1.0631
60.315,12.30583,0.53163,101.30256,1.0624
61.872,12.40583,0.5738300000000001,101.30020999999999,1.06166
63.491,12.50583,0.61826,101.2629,1.0608799999999998
65.185,12.605830000000001,0.65756,101.30256,1.06007
66.951,12.70583,0.6987800000000001,101.31876,1.05922
68.78,12.80583,0.73502,101.31898000000001,1.05834
70.66,12.90583,0.7738,101.29083,1.05744
72.594,13.00583,0.80867,101.31429,1.0565
74.556,13.105830000000001,0.8440700000000001,101.2838,1.05556
76.57,13.205829999999999,0.87616,101.30256,1.0545799999999999
78.642,13.305829999999998,0.9074200000000001,101.29786999999999,1.05358
80.742,13.405829999999998,0.9399799999999999,101.29786999999999,1.05256
82.869,13.50583,0.9712200000000001,101.28145,1.0515299999999999
85.051,13.60583,1.0036399999999999,101.23945,1.05046
87.265,13.705829999999999,1.03614,101.22771999999999,1.04939
89.535,13.805829999999998,1.06765,101.24883,1.0482799999999999
91.851,13.905829999999998,1.09925,101.21834,1.04714
94.208,14.00583,1.13048,101.22068,1.04599
96.612,14.10583,1.16446,101.19254000000001,1.04481
99.092,14.205829999999999,1.19761,101.19979000000001,1.04359
101.569,14.305829999999998,1.23179,101.19957,1.04237
104.107,14.405829999999998,1.2653,101.17164,1.04112
106.687,14.50583,1.30158,101.19979000000001,1.03985
109.316,14.60583,1.3408,101.19979000000001,1.03855
112.005,14.705829999999999,1.3801700000000001,101.19979000000001,1.03722
114.696,14.805829999999998,1.4262299999999999,101.22068,1.03588
117.448,14.905829999999998,1.47042,101.2209,1.03451
120.25,15.00583,1.5128700000000002,101.19957,1.03312
123.076,15.10583,1.55767,101.19275,1.0317
125.952,15.205829999999999,1.599,101.17164,1.03027
128.888,15.305829999999998,1.64002,101.17164,1.0288
131.841,15.405829999999998,1.6848299999999998,101.17164,1.02732
134.84399,15.50583,1.72711,101.17164,1.02581
137.87399,15.60583,1.7692299999999999,101.19979000000001,1.0242799999999999
140.95399,15.705829999999999,1.8147,101.14115,1.02273
144.05,15.805829999999998,1.86368,101.11322,1.02116
147.198,15.905829999999998,1.9072799999999999,101.12026,1.01957
150.388,16.00583,1.95618,101.14115,1.01795
153.561,16.105829999999997,2.0024900000000003,101.15544,1.01634
156.78,16.20583,2.04533,101.23475,1.0147
160.024,16.30583,2.0846400000000003,101.20661,1.01304
163.28999,16.405829999999998,2.12202,101.17868,1.01137
166.573,16.50583,2.1585799999999997,101.16461,1.00969
169.879,16.605829999999997,2.19691,101.17164,1.008
173.22,16.70583,2.23671,101.17868,1.0062799999999998
176.56798999999998,16.80583,2.2784400000000002,101.19275,1.0045600000000001
179.939,16.905829999999998,2.3247299999999997,101.17164,1.00282
183.368,17.00583,2.36947,101.17164,1.00105
186.8,17.105829999999997,2.41813,101.1435,0.9992700000000001
190.26601000000002,17.20583,2.46277,101.11556999999999,0.9974700000000001
193.726,17.30583,2.51607,101.13667,0.99567
197.217,17.405829999999998,2.5666700000000002,101.10853,0.99385
200.74698999999998,17.50583,2.61965,101.08038,0.9920100000000001
204.276,17.605829999999997,2.6720099999999998,101.05245,0.99016
207.827,17.70583,2.72741,101.05245,0.9883
211.386,17.80583,2.7846900000000003,101.08742,0.9864299999999999
214.952,17.905829999999998,2.8394,101.05949,0.98456
218.554,18.00583,2.89555,101.03134,0.9826600000000001
222.157,18.105829999999997,2.9501,100.94243,0.98075
225.76801,18.20583,3.00655,100.86525,0.9788399999999999
229.40198999999998,18.30583,3.05595,100.74371,0.9769100000000001
233.02698999999998,18.405829999999998,3.10387,100.62431,0.97498
236.679,18.50583,3.15271,100.52367,0.97304
240.327,18.605829999999997,3.19957,100.38337,0.97109
243.995,18.70583,3.24365,100.28294,0.9691299999999999
247.67101,18.80583,3.28626,100.10064,0.96715
251.354,18.905829999999998,3.32772,99.91578,0.9651700000000001
255.048,19.00583,3.36516,99.70768000000001,0.9631799999999999
258.733,19.105829999999997,3.40056,99.44819,0.96119
262.431,19.20583,3.4142699999999997,99.20021,0.95919
266.10999,19.30583,3.4220699999999997,98.93113000000001,0.9572
269.81201,19.405829999999998,3.4349,98.63880999999999,0.95519
273.522,19.50583,3.4479900000000003,98.28316,0.95316
277.23499,19.605829999999997,3.4534599999999998,97.88101999999999,0.95114
280.93799,19.70583,3.4587800000000004,97.4226,0.94911
284.64999,19.80583,3.459,96.91045,0.9470700000000001
288.388,19.905829999999998,3.4596400000000003,96.30235,0.9450200000000001
292.10598999999996,20.00583,3.45871,95.60299,0.9429700000000001
295.83701,20.105829999999997,3.4659400000000002,94.82431,0.9409
299.58301,20.20583,3.4886800000000004,93.95885,0.9388299999999999
303.34,20.30583,3.5395199999999996,92.98849,0.93674
307.12,20.405829999999998,3.6225,91.98273,0.9346399999999999
310.91901,20.50583,3.73331,90.88826999999999,0.9325200000000001
314.74399,20.605829999999997,3.8677900000000003,89.73539,0.9303799999999999
318.55801,20.70583,4.00359,88.51684,0.92824
322.341,20.80583,4.104480000000001,87.24455999999999,0.92611
326.09201,20.905829999999998,4.16018,85.91386,0.92399
329.79199,21.00583,4.1923900000000005,84.51066,0.9219
333.49399,21.105829999999997,4.22176,83.04414,0.9198
337.14001,21.20583,4.25842,81.53582,0.9177299999999999
340.814,21.30583,4.30564,79.99701,0.9156299999999999
344.466,21.405829999999998,4.36712,78.34584,0.91355
348.12299,21.50583,4.43409,76.60341,0.91145
351.78601000000003,21.605829999999997,4.50983,74.79083,0.90935
355.427,21.70583,4.58983,72.88486,0.90725
359.06299,21.80583,4.6752400000000005,70.84307,0.90515
362.69299,21.905829999999998,4.7695300000000005,68.61429,0.90305
366.32501,22.00583,4.86267,66.24286,0.90094
369.94901,22.105829999999997,4.95843,63.71001999999999,0.8988299999999999
373.55499,22.20583,5.05225,60.96205,0.8967200000000001
377.16199,22.30583,5.13601,58.003409999999995,0.89461
380.75601,22.405829999999998,5.20265,54.864819999999995,0.8925
384.34299,22.50583,5.22687,51.61407,0.89039
387.927,22.605829999999997,5.19189,48.30959,0.8882700000000001
391.48499,22.70583,5.075,45.03753,0.8861600000000001
395.035,22.80583,4.863169999999999,42.08614,0.88405
398.57401,22.905829999999998,4.57709,39.64691,0.88195
402.08499,23.00583,4.26759,37.85309,0.87985
405.59299,23.105829999999997,4.019080000000001,36.77015,0.87775
409.103,23.20583,3.8470699999999995,36.13881,0.87564
412.60501,23.30583,3.7206,35.71535,0.8735299999999999
416.095,23.405829999999998,3.61685,35.31322,0.8714200000000001
419.57199,23.50583,3.51802,35.006820000000005,0.8693200000000001
423.04599,23.605829999999997,3.4245300000000003,34.70277,0.8672
426.509,23.70583,3.3319099999999997,34.41514,0.8650899999999999
429.94901,23.80583,3.2437,34.09957,0.8629899999999999
433.40700999999996,23.905829999999998,3.16571,33.84435,0.86087
436.82000999999997,24.00583,3.09691,33.601279999999996,0.85877
440.25,24.105829999999997,3.0403700000000002,33.2693,0.8566600000000001
443.698,24.20583,2.9910400000000004,33.0307,0.8545299999999999
447.077,24.30583,2.9474400000000003,32.78955,0.8524299999999999
450.483,24.405829999999998,2.91403,32.55352,0.8503200000000001
453.879,24.50583,2.88698,32.340509999999995,0.8482
457.27300999999994,24.605829999999997,2.86519,32.102129999999995,0.8460700000000001
460.65799000000004,24.70583,2.8479200000000002,31.877609999999997,0.84395
464.05099,24.80583,2.8340799999999997,31.653090000000002,0.8418200000000001
467.41900999999996,24.905829999999998,2.8211,31.43795,0.8396899999999999
470.802,25.00583,2.8108299999999997,31.211090000000002,0.83755
474.142,25.105829999999997,2.80375,31.03817,0.8354299999999999
477.51901,25.20583,2.8018099999999997,30.8322,0.8332799999999999
480.83401,25.30583,2.80189,30.635820000000002,0.83116
484.17999000000003,25.405829999999998,2.80443,30.4533,0.8290200000000001
487.52802,25.50583,2.8068,30.287209999999998,0.8268700000000001
490.85199000000006,25.605829999999997,2.80837,30.13518,0.82473
494.173,25.70583,2.8077799999999997,29.990190000000002,0.8225899999999999
497.479,25.80583,2.80698,29.852240000000002,0.82045
500.78101,25.905829999999998,2.80301,29.714290000000002,0.8183
504.07999,26.00583,2.80162,29.53412,0.81615
507.36400999999995,26.105829999999997,2.8010099999999998,29.4032,0.814
510.66101,26.20583,2.79905,29.25352,0.81184
513.93701,26.30583,2.79705,29.11791,0.8096899999999999
517.21503,26.405829999999998,2.7904299999999997,28.986990000000002,0.80753
520.479,26.50583,2.78417,28.858209999999996,0.80537
523.7470099999999,26.605829999999997,2.77589,28.73902,0.8032
526.992,26.70583,2.76326,28.58721,0.80105
530.23602,26.80583,2.75445,28.451390000000004,0.79888
533.47498,26.905829999999998,2.74315,28.3742,0.79672
536.72302,27.00583,2.73041,28.25245,0.7945399999999999
539.9450099999999,27.105829999999997,2.71837,28.12388,0.79237
543.19598,27.20583,2.70821,28.0162,0.79018
546.40198,27.30583,2.69563,27.92047,0.78801
549.60901,27.405829999999998,2.68571,27.82473,0.78584
552.823,27.50583,2.67306,27.726440000000004,0.78365
556.03198,27.605829999999997,2.65578,27.609379999999998,0.78146
559.23199,27.70583,2.63652,27.50661,0.77927
562.43103,27.80583,2.618,27.420040000000004,0.77708
565.61298,27.905829999999998,2.60356,27.32644,0.77489
568.784,28.00583,2.5869299999999997,27.23305,0.7727
571.96802,28.105829999999997,2.5708900000000003,27.174409999999998,0.7705
575.14001,28.20583,2.55856,27.057570000000002,0.7683
578.29901,28.30583,2.54572,26.968659999999996,0.7661100000000001
581.4569700000001,28.405829999999998,2.53219,26.90085,0.7639100000000001
584.60199,28.50583,2.51686,26.84243,0.76171
587.75897,28.605829999999997,2.50299,26.748829999999998,0.75949
590.90198,28.70583,2.48838,26.69275,0.75729
594.0360099999999,28.80583,2.47454,26.58742,0.75508
597.17102,28.905829999999998,2.46389,26.54307,0.7528600000000001
600.2930299999999,29.00583,2.45013,26.486990000000002,0.75065
603.409,29.105829999999997,2.43498,26.39552,0.74844
606.53003,29.20583,2.4237,26.32537,0.74622
609.646,29.30583,2.4154299999999997,26.25522,0.7439899999999999
612.75897,29.405829999999998,2.40382,26.194670000000002,0.7417600000000001
615.89099,29.50583,2.39837,26.166520000000002,0.73952
618.9689900000001,29.605829999999997,2.39299,26.11045,0.7373
622.05603,29.70583,2.38873,26.04009,0.7350800000000001
625.1560099999999,29.80583,2.3898200000000003,25.98166,0.7328399999999999
628.25403,29.905829999999998,2.39427,25.93945,0.73059