File: 02_Data/Polyester_Batting/STA/N2/10K_min/Polyester_Batting_STA_N2_10KData_210308_R3.csv
##Temp./Â°C,Time/min,DSC/(mW/mg),Mass/%,Sensit./(uV/mW)
47.501,10.00833,-0.017134,99.56031,1.0896
47.518,10.10833,-0.01659444,99.57938,1.0896
47.525,10.20833,-0.01632465,99.55414,1.08959
47.521,10.30833,-0.01618971,99.50328,1.08959
47.543,10.40833,-0.01659458,99.52871,1.08959
47.551,10.50833,-0.01524546,99.52871,1.08958
47.569,10.60833,-0.01511064,99.55395,1.08958
47.612,10.70833,-0.01335692,99.52871,1.08956
47.649,10.80833,-0.01173804,99.52871,1.08955
47.709,10.90833,-0.0076905969999999995,99.47148,1.0895299999999999
47.8,11.00833,-0.005801856,99.49691999999999,1.08949
47.858,11.10833,-0.002428728,99.52216,1.0894700000000002
47.965,11.20833,0.00161921,99.52235,1.08943
48.098,11.30833,0.006072312,99.52235,1.0893899999999999
48.249,11.40833,0.0114705,99.48439,1.08933
48.399,11.50833,0.01673427,99.52235,1.08928
48.581,11.60833,0.02186384,99.50328,1.08921
48.787,11.70833,0.02766911,99.52428,1.08913
49.032,11.80833,0.03320566,99.53083000000001,1.08905
49.3,11.90833,0.03955337,99.53699,1.08895
49.586,12.00833,0.04428242,99.53276,1.08884
49.896,12.10833,0.05022797,99.49904000000001,1.08873
50.249,12.20833,0.05631062,99.49268000000001,1.0886
50.594,12.30833,0.06293476,99.48631999999999,1.08847
50.982,12.40833,0.06807568,99.48631999999999,1.08833
51.383,12.50833,0.07429899,99.48208000000001,1.08818
51.81,12.60833,0.07903852,99.46301,1.0880299999999998
52.25,12.70833,0.08486083,99.45472,1.0878700000000001
52.712,12.80833,0.09095588,99.46724,1.0877
53.196,12.90833,0.09421497,99.45453,1.08752
53.699,13.00833,0.10031,99.4526,1.08733
54.211,13.108329999999999,0.10628,99.45472,1.08714
54.743,13.208329999999998,0.10941,99.44181,1.08694
55.289,13.308329999999998,0.11470999999999999,99.45472,1.08674
55.891,13.40833,0.11879,99.47995999999999,1.08651
56.414,13.508329999999999,0.12314000000000001,99.4738,1.0863200000000002
57.007,13.608329999999999,0.12533,99.44836,1.0861
57.61,13.708329999999998,0.12996,99.42716999999999,1.0858700000000001
58.221,13.808329999999998,0.13485999999999998,99.47784,1.08564
58.843,13.90833,0.13840999999999998,99.47784,1.08541
59.486,14.008329999999999,0.14305,99.47784,1.0851600000000001
60.131,14.108329999999999,0.14661,99.39538,1.08492
60.786,14.208329999999998,0.14976,99.42081,1.08467
61.449,14.308329999999998,0.15317999999999998,99.42081,1.0844200000000002
62.131,14.40833,0.15661,99.44605,1.08416
62.826,14.508329999999999,0.16166,99.41233000000001,1.0839
63.518,14.608329999999999,0.16577,99.38285,1.0836299999999999
64.237,14.708329999999998,0.16948,99.38266,1.08335
64.956,14.808329999999998,0.17549,99.40809,1.0830799999999998
65.673,14.90833,0.17757,99.43353,1.0828
66.415,15.008329999999999,0.18265,99.43353,1.0825200000000001
67.167,15.108329999999999,0.18487,99.43988,1.0822200000000002
67.923,15.208329999999998,0.18954000000000001,99.42505,1.0819299999999998
68.714,15.308329999999998,0.19285,99.4104,1.08162
69.451,15.40833,0.19698,99.37861,1.08134
70.253,15.508329999999999,0.1999,99.39114000000001,1.08102
71.028,15.608329999999999,0.20471,99.42929000000001,1.0807200000000001
71.831,15.708329999999998,0.20817,99.45453,1.0804
72.63,15.808329999999998,0.21259,99.42293000000001,1.08009
73.448,15.90833,0.21715,99.40385,1.0797700000000001
74.277,16.008329999999997,0.22035,99.40385,1.07944
75.114,16.10833,0.22476999999999997,99.3975,1.07911
75.947,16.20833,0.22866,99.42929000000001,1.0787799999999999
76.794,16.308329999999998,0.232,99.40405,1.07844
77.644,16.40833,0.23615999999999998,99.40385,1.0781
78.51,16.508329999999997,0.24033000000000002,99.37861,1.07775
79.379,16.60833,0.24423000000000003,99.40385,1.0774
80.248,16.70833,0.24854,99.37861,1.07705
81.143,16.808329999999998,0.25258,99.3659,1.07669
82.026,16.90833,0.25731,99.35318000000001,1.07633
82.918,17.008329999999997,0.26232,99.35318000000001,1.07597
83.813,17.10833,0.26609,99.35318000000001,1.0756
84.733,17.20833,0.27111,99.34682,1.07523
85.643,17.308329999999998,0.27366999999999997,99.32794,1.07486
86.571,17.40833,0.27855,99.32775,1.0744799999999999
87.496,17.508329999999997,0.28358,99.35318000000001,1.07409
88.438,17.60833,0.28505,99.35337,1.07371
89.378,17.70833,0.28995,99.35318000000001,1.07332
90.309,17.808329999999998,0.29443,99.32775,1.07293
91.278,17.90833,0.29825,99.32794,1.07253
92.237,18.008329999999997,0.30178,99.32794,1.07213
93.191,18.10833,0.30751999999999996,99.3657,1.0717299999999998
94.165,18.20833,0.31175,99.3659,1.07132
95.136,18.308329999999998,0.31613,99.34046,1.07091
96.096,18.40833,0.32009,99.32158000000001,1.07051
97.095,18.508329999999997,0.3231,99.31522,1.07008
98.07,18.60833,0.32845,99.34046,1.0696700000000001
99.061,18.70833,0.33271,99.3025,1.06925
100.053,18.808329999999998,0.33586,99.31522,1.06882
101.045,18.90833,0.3393,99.32158000000001,1.0684
102.055,19.008329999999997,0.34412,99.34066,1.06797
103.046,19.10833,0.34825,99.34046,1.06754
104.036,19.20833,0.35403,99.32775,1.06711
105.062,19.308329999999998,0.3568,99.34046,1.06667
106.058,19.40833,0.36025,99.31522,1.0662399999999999
107.07,19.508329999999997,0.36537,99.28979,1.0658
108.075,19.60833,0.36951999999999996,99.28979,1.06536
109.102,19.70833,0.37423,99.31522,1.06491
110.116,19.808329999999998,0.3795,99.27283,1.06447
111.129,19.90833,0.38283,99.3237,1.06402
112.191,20.008329999999997,0.3877,99.3237,1.06356
113.179,20.10833,0.39284,99.32351,1.06312
114.202,20.20833,0.39729000000000003,99.29827,1.06267
115.243,20.308329999999998,0.403,99.27283,1.06221
116.266,20.40833,0.40608,99.24759,1.06175
117.316,20.508329999999997,0.41152,99.27303,1.06128
118.336,20.60833,0.41668999999999995,99.27303,1.06083
119.392,20.70833,0.42298,99.23276,1.06035
120.426,20.808329999999998,0.42704,99.2158,1.05989
121.472,20.90833,0.43362,99.2158,1.05942
122.531,21.008329999999997,0.43923,99.26666999999999,1.05894
123.562,21.10833,0.44664,99.26647,1.05847
124.614,21.20833,0.45518000000000003,99.26647,1.05799
125.677,21.308329999999998,0.46608999999999995,99.2158,1.05751
126.735,21.40833,0.47408999999999996,99.20944,1.05702
127.798,21.508329999999997,0.48252,99.24123,1.05654
128.849,21.60833,0.4929,99.26031,1.05606
129.91901000000001,21.70833,0.50316,99.24123,1.05556
130.989,21.808329999999998,0.50897,99.25376,1.0550700000000002
132.05901,21.90833,0.51395,99.25376,1.05457
133.132,22.008329999999997,0.51531,99.31098,1.05408
134.202,22.10833,0.51443,99.26031,1.05358
135.284,22.20833,0.50756,99.26031,1.05308
136.356,22.308329999999998,0.50068,99.21599,1.0525799999999998
137.451,22.40833,0.4917,99.23699,1.05206
138.536,22.508329999999997,0.48621000000000003,99.23699,1.05155
139.61301,22.60833,0.4835,99.23699,1.05105
140.711,22.70833,0.48178000000000004,99.24951999999999,1.05053
141.80098999999998,22.808329999999998,0.48383999999999994,99.23699,1.05001
142.88499,22.90833,0.48422,99.24971,1.0495
143.99001,23.008329999999997,0.48838000000000004,99.24971,1.0489700000000002
145.095,23.10833,0.49171000000000004,99.22428000000001,1.04845
146.196,23.20833,0.49546999999999997,99.19884,1.04792
147.29601,23.308329999999998,0.49937,99.19884,1.0474
148.395,23.40833,0.5050899999999999,99.19884,1.04687
149.48801,23.508329999999997,0.509,99.19884,1.04634
150.595,23.60833,0.51165,99.22851999999999,1.0458100000000001
151.689,23.70833,0.51599,99.2158,1.04528
152.80098999999998,23.808329999999998,0.5201899999999999,99.20308,1.04474
153.911,23.90833,0.52412,99.22851999999999,1.0442
155.021,24.008329999999997,0.52791,99.20328,1.04366
156.12399,24.10833,0.53284,99.20308,1.04312
157.235,24.20833,0.53904,99.20944,1.0425799999999998
158.339,24.308329999999998,0.54186,99.22851999999999,1.0420399999999999
159.44298999999998,24.40833,0.54609,99.25395,1.0415
160.564,24.508329999999997,0.5496300000000001,99.24759,1.04094
161.666,24.60833,0.5544399999999999,99.2158,1.0404
162.772,24.70833,0.55784,99.20944,1.03985
163.89799,24.808329999999998,0.56097,99.24104,1.0393
165.0,24.90833,0.56452,99.2158,1.03875
166.106,25.008329999999997,0.56921,99.2158,1.0382
167.237,25.10833,0.5732,99.19037,1.0376299999999998
168.336,25.20833,0.5776100000000001,99.2158,1.03708
169.436,25.308329999999998,0.58118,99.21599,1.03653
170.556,25.40833,0.58746,99.24759,1.03597
171.66,25.508329999999997,0.58948,99.26031,1.03541
172.783,25.60833,0.59449,99.20963,1.03485
173.89799,25.70833,0.5980800000000001,99.18189,1.0342799999999999
175.013,25.808329999999998,0.6026699999999999,99.15665,1.03372
176.104,25.90833,0.60798,99.19461,1.03316
177.23398999999998,26.008329999999997,0.61088,99.19461,1.03259
178.34399,26.10833,0.61762,99.19461,1.0320200000000002
179.45799,26.20833,0.6208100000000001,99.17572,1.03145
180.59801000000002,26.308329999999998,0.62473,99.18844,1.0308700000000002
181.717,26.40833,0.62893,99.21368000000001,1.03029
182.832,26.508329999999997,0.6339899999999999,99.21368000000001,1.02972
183.95,26.60833,0.6392100000000001,99.23892,1.02914
185.075,26.70833,0.64185,99.20751,1.0285600000000001
186.201,26.808329999999998,0.64636,99.18825,1.02798
187.328,26.90833,0.65045,99.18825,1.02739
188.461,27.008329999999997,0.65412,99.16301,1.0268
189.57401000000002,27.10833,0.66022,99.13757,1.0262200000000001
190.70399,27.20833,0.66475,99.19055999999999,1.0256299999999998
191.83501,27.308329999999998,0.6693,99.19055999999999,1.02504
192.963,27.40833,0.6727,99.2158,1.02445
194.095,27.508329999999997,0.6763899999999999,99.19055999999999,1.02386
195.22301000000002,27.60833,0.6808,99.20328,1.02326
196.355,27.70833,0.68666,99.17784,1.02267
197.47099,27.808329999999998,0.6903699999999999,99.17784,1.0220799999999999
198.616,27.90833,0.69409,99.17784,1.02147
199.737,28.008329999999997,0.69852,99.1526,1.02088
200.866,28.10833,0.70398,99.1526,1.0202799999999999
202.00101,28.20833,0.70901,99.19037,1.01967
203.121,28.308329999999998,0.7126,99.19672,1.0190700000000001
204.24899,28.40833,0.71677,99.22216,1.01847
205.37601,28.508329999999997,0.72297,99.16936,1.01787
206.51601000000002,28.60833,0.72688,99.14393000000001,1.01725
207.631,28.70833,0.7317899999999999,99.14393000000001,1.0166600000000001
208.763,28.808329999999998,0.73787,99.16936,1.01605
209.881,28.90833,0.7430899999999999,99.16301,1.01544
211.026,29.008329999999997,0.74615,99.16936,1.01482
212.134,29.10833,0.7522399999999999,99.14393000000001,1.0142200000000001
213.27299,29.20833,0.75589,99.16936,1.0136
214.41298999999998,29.308329999999998,0.76158,99.16936,1.01298
215.55098999999998,29.40833,0.76684,99.16936,1.01236
216.65601,29.508329999999997,0.77165,99.18825,1.01176
217.798,29.60833,0.77794,99.13776,1.01114
218.918,29.70833,0.78293,99.08478000000001,1.01052
220.047,29.808329999999998,0.78923,99.09114,1.0099
221.17999,29.90833,0.7954,99.09114,1.00928
222.30499,30.008329999999997,0.80011,99.12909,1.0086600000000001
223.429,30.10833,0.80512,99.16936,1.00804
224.55701000000002,30.20833,0.81219,99.16936,1.00742
225.694,30.308329999999998,0.81912,99.16301,1.00679
226.814,30.40833,0.82576,99.13757,1.00616
227.944,30.508329999999997,0.8346100000000001,99.11233,1.0055399999999999
229.073,30.60833,0.8412799999999999,99.12505,1.00491
230.20399,30.70833,0.84957,99.09961,1.0042799999999998
231.33299,30.808329999999998,0.8583,99.09961,1.00365
232.457,30.90833,0.86734,99.16301,1.00302
233.57899,31.008329999999997,0.87654,99.18825,1.00239
234.705,31.10833,0.8864799999999999,99.18825,1.00176
235.826,31.20833,0.89849,99.16301,1.00112
236.957,31.308329999999998,0.91214,99.11233,1.0004899999999999
238.075,31.40833,0.92463,99.0869,0.9998600000000001
239.209,31.508329999999997,0.94126,99.11233,0.9992200000000001
240.34,31.60833,0.95894,99.13757,0.9985700000000001
241.481,31.70833,0.979,99.11214,0.9979299999999999
242.586,31.808329999999998,1.0032,99.11233,0.9973
243.709,31.90833,1.02833,99.11233,0.99666
244.83098999999999,32.00833,1.06205,99.11233,0.9960200000000001
245.963,32.10833,1.09922,99.07418,0.9953700000000001
247.076,32.20833,1.1463299999999998,99.09961,0.99474
248.203,32.30833,1.20282,99.12505,0.9940899999999999
249.314,32.40833,1.27491,99.09961,0.99345
250.425,32.50833,1.36576,99.11233,0.99282
251.55098999999998,32.60833,1.46725,99.12505,0.9921700000000001
252.659,32.70833,1.56901,99.09326,0.9915299999999999
253.776,32.80833,1.6534099999999998,99.08054,0.9908799999999999
254.88901,32.90833,1.7027299999999999,99.06146,0.99024
256.004,33.00833,1.6921099999999998,99.06146,0.98959
257.14301,33.10833,1.55589,99.06782,0.98893
258.25601,33.20833,1.35,99.04258,0.98829
259.379,33.30833,1.19044,99.04258,0.9876299999999999
260.52398999999997,33.40833,1.08952,99.08054,0.9869700000000001
261.677,33.50833,1.02826,99.10597,0.98629
262.79999,33.60833,0.99449,99.13141,0.98564
263.936,33.70833,0.97591,99.14412,0.9849700000000001
265.07401,33.80833,0.96806,99.13121,0.9843
266.20499,33.90833,0.96259,99.13121,0.98364
267.33701,34.00833,0.96309,99.12486,0.9829700000000001
268.466,34.10833,0.96329,99.09961,0.98231
269.595,34.20833,0.9666399999999999,99.05511,0.98164
270.72501,34.30833,0.9682,99.05511,0.98098
271.862,34.40833,0.97006,99.05511,0.9803
272.979,34.50833,0.9731200000000001,99.05511,0.97964
274.104,34.60833,0.9779899999999999,99.06146,0.9789700000000001
275.23499,34.70833,0.9824200000000001,99.06146,0.9783
276.36301000000003,34.80833,0.98159,99.06782,0.9776299999999999
277.491,34.90833,0.9860200000000001,99.0869,0.97696
278.61499,35.00833,0.98941,99.06782,0.97629
279.737,35.10833,0.99265,99.06782,0.97562
280.85901,35.20833,0.99711,99.01715,0.9749399999999999
281.992,35.30833,0.99946,98.99171,0.9742700000000001
283.095,35.40833,1.0046700000000002,98.98536,0.9736
284.22,35.50833,1.0061200000000001,99.03603000000001,0.97293
285.345,35.60833,1.00758,99.06146,0.97225
286.465,35.70833,1.0107,99.03603000000001,0.9715799999999999
287.57999,35.80833,1.01488,99.01079,0.9709
288.716,35.90833,1.0181799999999999,98.98343,0.9702200000000001
289.82001,36.00833,1.0229700000000002,98.97707,0.96955
290.94901,36.10833,1.02673,98.97707,0.96886
292.07001,36.20833,1.02988,99.0025,0.9681799999999999
293.17899,36.30833,1.03166,99.02775,0.96751
294.298,36.40833,1.03604,99.02775,0.96683
295.41101000000003,36.50833,1.0404200000000001,98.97707,0.96615
296.53,36.60833,1.04374,98.95164,0.96547
297.64898999999997,36.70833,1.04829,98.95164,0.96478
298.759,36.80833,1.05192,98.95164,0.96411
299.883,36.90833,1.05619,98.95164,0.96342
301.00101,37.00833,1.05984,98.93892,0.96273
302.104,37.10833,1.06364,98.93892,0.96205
303.22299,37.20833,1.06807,98.93892,0.9613700000000001
304.34201,37.30833,1.07174,98.93892,0.96068
305.448,37.40833,1.07542,98.91368,0.96
306.561,37.50833,1.08017,98.9264,0.95931
307.677,37.60833,1.08585,98.91368,0.95862
308.78601000000003,37.70833,1.0900100000000001,98.90096,0.95793
309.89999,37.80833,1.09509,98.9264,0.95724
311.009,37.90833,1.10341,98.90732,0.9565600000000001
312.11099,38.00833,1.1082,98.90732,0.9558700000000001
313.237,38.10833,1.11286,98.90096,0.9551700000000001
314.34698,38.20833,1.1193600000000001,98.88825,0.9544799999999999
315.45801,38.30833,1.1248,98.86281,0.9537899999999999
316.55899,38.40833,1.12931,98.83738000000001,0.9531
317.66901,38.50833,1.1349200000000002,98.83738000000001,0.9524100000000001
318.77398999999997,38.60833,1.13883,98.83121,0.9517200000000001
319.888,38.70833,1.1446100000000001,98.79961,0.9510200000000001
320.98801000000003,38.80833,1.1480700000000001,98.79961,0.9503299999999999
322.099,38.90833,1.15232,98.81214,0.94963
323.20901000000003,39.00833,1.1579700000000002,98.83757,0.9489299999999999
324.31601,39.10833,1.1644,98.79942,0.94824
325.41598999999997,39.20833,1.16743,98.79942,0.9475399999999999
326.526,39.30833,1.17171,98.78671,0.94684
327.64001,39.40833,1.17724,98.74875,0.94614
328.73599,39.50833,1.18137,98.77399,0.94545
329.83301,39.60833,1.18488,98.76127,0.94475
330.94199,39.70833,1.19059,98.72351,0.94405
332.05801,39.80833,1.1953799999999999,98.72351,0.94334
333.159,39.90833,1.2006299999999999,98.69807,0.9426399999999999
334.26001,40.00833,1.20371,98.72351,0.94194
335.36801,40.10833,1.20805,98.69807,0.94124
336.474,40.20833,1.21004,98.69807,0.94053
337.57198999999997,40.30833,1.2147,98.72331,0.9398299999999999
338.67599,40.40833,1.22031,98.69807,0.9391299999999999
339.78,40.50833,1.22405,98.72351,0.93842
340.90701,40.60833,1.22953,98.72351,0.9377
341.98499,40.70833,1.23389,98.70443,0.93701
343.07901,40.80833,1.23984,98.67283,0.9363100000000001
344.189,40.90833,1.2428299999999999,98.6474,0.9356
345.29098999999997,41.00833,1.2499,98.58381999999999,0.93489
346.39499,41.10833,1.2566700000000002,98.55221999999999,0.9341799999999999
347.48401,41.20833,1.26108,98.49518,0.93348
348.578,41.30833,1.26519,98.55221999999999,0.9327700000000001
349.70099,41.40833,1.2691700000000001,98.57765,0.93205
350.78601000000003,41.50833,1.27454,98.55221999999999,0.93135
351.888,41.60833,1.27852,98.55221999999999,0.93063
352.98999,41.70833,1.28282,98.52678,0.9299200000000001
354.07501,41.80833,1.2910700000000002,98.49923000000001,0.92922
355.18301,41.90833,1.29698,98.44855,0.9285
356.263,42.00833,1.3035,98.42331,0.9278
357.371,42.10833,1.3084799999999999,98.47610999999999,0.9270799999999999
358.465,42.20833,1.31345,98.50366,0.9263600000000001
359.56,42.30833,1.3222399999999999,98.47206,0.92565
360.655,42.40833,1.32978,98.40212,0.92494
361.76099,42.50833,1.33623,98.37688,0.92422
362.841,42.60833,1.34473,98.32601,0.92351
363.94299,42.70833,1.35104,98.27534,0.92279
365.039,42.80833,1.3583100000000001,98.29016999999999,0.9220700000000001
366.13199,42.90833,1.36814,98.23931,0.9213600000000001
367.22198,43.00833,1.38022,98.22041999999999,0.92064
368.30899,43.10833,1.39647,98.27745999999999,0.9199299999999999
369.401,43.20833,1.41099,98.22678,0.9192100000000001
370.492,43.30833,1.4241,98.18226999999999,0.9184899999999999
371.57599,43.40833,1.43369,98.13179000000001,0.9177799999999999
372.66501,43.50833,1.4421899999999999,98.10636,0.91706
373.759,43.60833,1.44766,98.0027,0.9163399999999999
374.83801,43.70833,1.4483,97.97958,0.9156299999999999
375.91199,43.80833,1.4465299999999999,97.92871,0.9149200000000001
376.99701,43.90833,1.44268,97.88015,0.9142
378.07001,44.00833,1.42852,97.8316,0.9134899999999999
379.14001,44.10833,1.41401,97.78921,0.9127799999999999
380.21201,44.20833,1.4006,97.71734000000001,0.91207
381.26401,44.30833,1.3847399999999999,97.6815,0.9113700000000001
382.328,44.40833,1.36483,97.59904,0.91066
383.388,44.50833,1.3495700000000002,97.47649,0.90996
384.46201,44.60833,1.34271,97.35588,0.9092399999999999
385.52898999999996,44.70833,1.33745,97.26089,0.90853
386.58499,44.80833,1.3328200000000001,97.16358000000001,0.9078299999999999
387.65302,44.90833,1.33241,97.00731999999999,0.90712
388.72299,45.00833,1.3341100000000001,96.8341,0.9064
389.79501,45.10833,1.34019,96.67765,0.90569
390.86801,45.20833,1.34581,96.54451,0.90497
391.935,45.30833,1.3551600000000001,96.40077,0.90425
393.01901000000004,45.40833,1.36861,96.24855,0.9035299999999999
394.09299,45.50833,1.38257,96.07534,0.90281
395.17099,45.60833,1.3962299999999999,95.81541,0.9020799999999999
396.23098999999996,45.70833,1.40304,95.5553,0.9013700000000001
397.29199,45.80833,1.39077,95.28497,0.90066
398.35699,45.90833,1.39645,95.01445,0.89994
399.42099,46.00833,1.39805,94.72485999999999,0.89922
400.48599,46.10833,1.38935,94.42042,0.8985
401.561,46.20833,1.3949,94.17746,0.8977799999999999
402.63101,46.30833,1.39831,93.9027,0.8970600000000001
403.70401,46.40833,1.39485,93.53931,0.89633
404.76401,46.50833,1.39449,93.19249,0.89561
405.83801,46.60833,1.39612,92.79326,0.89489
406.89999,46.70833,1.40004,92.42543,0.89417
407.97299,46.80833,1.40019,92.05125,0.89344
409.035,46.90833,1.4001700000000001,91.59056,0.8927200000000001
410.10199,47.00833,1.39076,91.19326,0.892
411.17001,47.10833,1.3683,90.81291,0.8912700000000001
412.23499,47.20833,1.3681,90.40713000000001,0.89055
413.332,47.30833,1.37916,89.96531999999999,0.8898
414.37,47.40833,1.39679,89.5131,0.8890899999999999
415.42899,47.50833,1.4191,88.95087,0.8883700000000001
416.508,47.60833,1.44065,88.41426,0.8876299999999999
417.56601,47.70833,1.46387,87.83314,0.8869100000000001
418.64401000000004,47.80833,1.49013,87.19884,0.8861700000000001
419.70499,47.90833,1.51958,86.45723000000001,0.88545
420.771,48.00833,1.55057,85.70694,0.8847200000000001
421.83499000000006,48.10833,1.58494,84.83622,0.8839899999999999
422.89899,48.20833,1.61837,83.98035,0.88326
423.953,48.30833,1.6583400000000001,83.01233,0.88254
425.01599000000004,48.40833,1.69639,81.979,0.88181
426.07599000000005,48.50833,1.741,80.89249000000001,0.88108
427.14499000000006,48.60833,1.7828700000000002,79.69422,0.88035
428.19199000000003,48.70833,1.8353,78.40096,0.8796299999999999
429.24399000000005,48.80833,1.88582,77.05877,0.8789
430.289,48.90833,1.9339,75.59421999999999,0.87818
431.37299,49.00833,1.97558,74.03468000000001,0.8774299999999999
432.40601,49.10833,2.0233,72.37746,0.87672
433.453,49.20833,2.06172,70.69114,0.876
434.50299,49.30833,2.1002099999999997,68.99191,0.8752700000000001
435.55099,49.40833,2.1248099999999996,67.22929,0.87455
436.612,49.50833,2.1594,65.39287,0.8738100000000001
437.65302,49.60833,2.18492,63.42736,0.8730899999999999
438.69901,49.70833,2.20342,61.44085,0.8723700000000001
439.74701,49.80833,2.2201,59.43314,0.87164
440.80399000000006,49.90833,2.23446,57.43988,0.8709100000000001
441.85101,50.00833,2.24612,55.41329,0.87018
442.896,50.10833,2.2501900000000004,53.39711,0.86946
443.95599000000004,50.20833,2.24973,51.285740000000004,0.86872
445.00699000000003,50.30833,2.24333,49.20193,0.8679899999999999
446.061,50.40833,2.2299700000000002,47.18362,0.86726
447.104,50.50833,2.2080900000000003,45.20963,0.8665299999999999
448.155,50.60833,2.1844900000000003,43.299040000000005,0.8658
449.203,50.70833,2.14946,41.59576,0.8650700000000001
450.25600999999995,50.80833,2.10894,39.81638,0.8643299999999999
451.32500999999996,50.90833,2.06055,38.18054,0.8635799999999999
452.379,51.00833,2.00711,36.608090000000004,0.86285
453.44901,51.10833,1.94934,35.22177,0.8621
454.49799,51.20833,1.8866599999999998,33.972640000000006,0.8613700000000001
455.56,51.30833,1.8211700000000002,32.89056,0.86062
456.62,51.40833,1.76154,31.96705,0.85988
457.68201,51.50833,1.70745,31.1237,0.85913
458.74701,51.60833,1.6585900000000002,30.371290000000002,0.85839
459.80899000000005,51.70833,1.61941,29.722540000000002,0.85764
460.86400999999995,51.80833,1.58581,29.13295,0.8569
461.92001,51.90833,1.55972,28.59827,0.85616
462.979,52.00833,1.53616,28.16917,0.85541
464.03299000000004,52.10833,1.51857,27.716959999999997,0.85467
465.11400999999995,52.20833,1.49841,27.347009999999997,0.8539100000000001
466.147,52.30833,1.4822799999999998,27.044890000000002,0.8531799999999999
467.19299,52.40833,1.46442,26.730059999999998,0.85245
468.23900999999995,52.50833000000001,1.4486,26.45318,0.8517100000000001
469.30301,52.60833,1.43244,26.178420000000003,0.85096
470.34601,52.708330000000004,1.4188100000000001,25.93545,0.8502200000000001
471.39499000000006,52.808330000000005,1.4043,25.75356,0.8494799999999999
472.44199000000003,52.90833000000001,1.39236,25.52119,0.8487399999999999
473.495,53.00833000000001,1.3804100000000001,25.35626,0.8479899999999999
474.54099,53.10833,1.3720700000000001,25.19152,0.84725
475.595,53.208330000000004,1.36217,25.020229999999998,0.84651
476.64300999999995,53.308330000000005,1.35693,24.85742,0.8457600000000001
477.694,53.40833000000001,1.3557,24.75607,0.8450200000000001
478.75100999999995,53.50833000000001,1.35881,24.64836,0.8442700000000001
479.797,53.60833,1.35513,24.5237,0.84352
480.83800999999994,53.708330000000004,1.35196,24.38825,0.84278
481.884,53.808330000000005,1.34425,24.29326,0.84204
482.91699000000006,53.90833000000001,1.3354700000000002,24.22775,0.84131
483.98000999999994,54.00833000000001,1.32827,24.13256,0.84055
485.01401,54.10833,1.3219100000000001,24.07341,0.8398100000000001
486.06,54.208330000000004,1.31695,23.9657,0.8390700000000001
487.09799000000004,54.308330000000005,1.31356,23.91079,0.8383299999999999
488.13100999999995,54.40833000000001,1.3112,23.83892,0.83759
489.18300999999997,54.50833000000001,1.30816,23.796529999999997,0.8368399999999999
490.22699000000006,54.60833,1.30388,23.7185,0.8361
491.241,54.708330000000004,1.30378,23.62967,0.8353700000000001
492.289,54.808330000000005,1.30195,23.5896,0.83462
493.32599000000005,54.90833000000001,1.29976,23.55568,0.83388
494.353,55.00833000000001,1.2989700000000002,23.50289,0.83315
495.392,55.10833,1.2964200000000001,23.44374,0.8324
496.422,55.208330000000004,1.29403,23.44355,0.8316600000000001
497.44500999999997,55.308330000000005,1.29146,23.43102,0.83093
498.47500999999994,55.40833000000001,1.2890700000000002,23.40559,0.83019
499.50600999999995,55.50833000000001,1.2856100000000001,23.36763,0.82945
500.54199000000006,55.60833,1.2839200000000002,23.30424,0.8287100000000001
501.57901,55.708330000000004,1.281,23.25337,0.82796
502.608,55.808330000000005,1.27912,23.25356,0.8272200000000001
503.62701,55.90833000000001,1.27883,23.18362,0.82649
504.647,56.00833000000001,1.27498,23.12659,0.82576
505.68799,56.10833,1.27347,23.07592,0.82501
506.715,56.208330000000004,1.24447,23.02505,0.8242700000000001
507.746,56.308330000000005,1.26183,23.02524,0.8235299999999999
508.76599000000004,56.40833000000001,1.26725,22.99981,0.8227899999999999
509.79000999999994,56.50833000000001,1.27304,22.94913,0.82205
510.815,56.60833,1.27651,22.92389,0.82132
511.85999000000004,56.708330000000004,1.27607,22.9237,0.8205600000000001
512.89697,56.808330000000005,1.27957,22.87303,0.81981
513.9110099999999,56.90833000000001,1.2826899999999999,22.87303,0.81908
514.94,57.00833000000001,1.28385,22.860310000000002,0.81834
515.97601,57.10833,1.28862,22.84759,0.8175899999999999
517.00598,57.208330000000004,1.28836,22.82235,0.81684
518.03198,57.308330000000005,1.29385,22.79692,0.8161
519.05902,57.40833000000001,1.29738,22.71676,0.8153600000000001
520.09302,57.50833000000001,1.3003799999999999,22.74836,0.8146100000000001
521.11401,57.60833,1.30318,22.7948,0.81387
522.1439799999999,57.708330000000004,1.30492,22.81387,0.81312
523.164,57.808330000000005,1.3097299999999998,22.788629999999998,0.81238
524.185,57.90833000000001,1.31328,22.7632,0.8116399999999999
525.20398,58.00833000000001,1.31792,22.70385,0.8109
526.22101,58.10833,1.32112,22.68478,0.81016
527.23999,58.208330000000004,1.32415,22.65954,0.80942
528.25702,58.308330000000005,1.32863,22.6341,0.8086800000000001
529.29498,58.40833000000001,1.3327799999999999,22.65973,0.80793
530.315,58.50833000000001,1.3358299999999999,22.64066,0.80718
531.3369799999999,58.60833,1.34016,22.58343,0.8064399999999999
532.35199,58.708330000000004,1.34358,22.58343,0.8057
533.383,58.808330000000005,1.34958,22.610979999999998,0.80495
534.4119900000001,58.90833000000001,1.35321,22.610979999999998,0.8042
535.42297,59.00833000000001,1.35592,22.566470000000002,0.8034600000000001
536.448,59.10833,1.36194,22.56012,0.80271
537.4689900000001,59.208330000000004,1.36614,22.54759,0.80197
538.48401,59.308330000000005,1.36979,22.54123,0.80123
539.51202,59.40833000000001,1.3751200000000001,22.509439999999998,0.80048
540.5360099999999,59.50833000000001,1.37916,22.53487,0.79973
541.55402,59.60833,1.38486,22.509629999999998,0.79899
542.56897,59.708330000000004,1.3902,22.47148,0.79824
543.58502,59.808330000000005,1.39389,22.45877,0.7975
544.61603,59.90833000000001,1.39724,22.433329999999998,0.79675
545.61902,60.00833000000001,1.40167,22.41445,0.79601
546.62903,60.10833,1.40667,22.389210000000002,0.79527
547.65002,60.208330000000004,1.41096,22.38285,0.79452
548.65698,60.308330000000005,1.4169,22.35742,0.79378
549.685,60.40833000000001,1.42251,22.32563,0.79303
550.698,60.50833000000001,1.4292200000000002,22.29403,0.7922899999999999
551.7139900000001,60.60833,1.43224,22.29383,0.7915399999999999
552.72498,60.708330000000004,1.43823,22.26859,0.7908
553.7470099999999,60.808330000000005,1.44574,22.27495,0.79005
554.75702,60.90833000000001,1.44989,22.26224,0.7893100000000001
555.77301,61.00833000000001,1.45574,22.27071,0.78856
556.79199,61.10833,1.4606700000000001,22.27071,0.78781
557.80402,61.208330000000004,1.46672,22.29615,0.7870699999999999
558.815,61.308330000000005,1.4699799999999998,22.27071,0.78632
559.82898,61.40833000000001,1.4728700000000001,22.22004,0.7855800000000001
560.84198,61.50833000000001,1.47446,22.22004,0.78483
561.84802,61.60833,1.47698,22.19461,0.78409
562.85999,61.708330000000004,1.47801,22.16936,0.7833399999999999
563.89001,61.808330000000005,1.48,22.143929999999997,0.78258
564.8770099999999,61.90833000000001,1.48195,22.11869,0.78186
565.89203,62.00833000000001,1.48224,22.143929999999997,0.7811100000000001
566.89301,62.10833,1.4855200000000002,22.12486,0.78037
567.90802,62.208330000000004,1.49261,22.16493,0.77962
568.901,62.308330000000005,1.49835,22.17129,0.77889
569.9180299999999,62.40833000000001,1.50377,22.14605,0.7781399999999999
570.92902,62.50833000000001,1.51013,22.10154,0.7773899999999999
571.9279799999999,62.60833,1.5142200000000001,22.10154,0.77665
572.94397,62.708330000000004,1.5225,22.06994,0.7759
573.95599,62.808330000000005,1.52606,22.06994,0.77515
574.9689900000001,62.90833000000001,1.52867,22.06994,0.7744
575.9810200000001,63.00833000000001,1.53604,22.05723,0.77365
576.99402,63.10833,1.54115,22.0447,0.7729
578.00897,63.208330000000004,1.54531,22.01291,0.77215
579.01703,63.308330000000005,1.5491,21.99383,0.7714
580.02301,63.40833000000001,1.55403,21.9684,0.77066
581.0369900000001,63.50833000000001,1.55879,21.96859,0.76991
582.06897,63.60833,1.56359,21.94316,0.7691399999999999
583.05103,63.708330000000004,1.5685200000000001,21.9368,0.76841
584.05701,63.808330000000005,1.57273,21.91137,0.76767
585.065,63.90833000000001,1.57829,21.87341,0.7669199999999999
586.0720200000001,64.00833,1.58385,21.886129999999998,0.76617
587.08099,64.10833000000001,1.59059,21.83545,0.76542
588.073,64.20833,1.5952,21.83526,0.76468
589.0750099999999,64.30833,1.6008,21.83545,0.76394
590.0670200000001,64.40833,1.60523,21.83545,0.7632
591.073,64.50833,1.6097,21.82909,0.76245
592.07098,64.60833000000001,1.61571,21.80366,0.76171
593.078,64.70833,1.62155,21.77842,0.7609600000000001
594.0750099999999,64.80833,1.62758,21.77842,0.76022
595.08099,64.90833,1.6284100000000001,21.79094,0.75947
596.10303,65.00833,1.6368200000000002,21.78882,0.75871
597.08301,65.10833000000001,1.6417,21.73815,0.75798
598.0939900000001,65.20833,1.6462400000000001,21.73815,0.7572300000000001
599.104,65.30833,1.6511799999999999,21.69807,0.75647
600.10797,65.40833,1.6536,21.68536,0.75572
601.11298,65.50833,1.65933,21.68536,0.75497
602.0889900000001,65.60833000000001,1.6644400000000001,21.68516,0.75425
603.0939900000001,65.70833,1.6501,21.65992,0.7535
604.0869799999999,65.80833,1.65504,21.65992,0.75276
605.078,65.90833,1.66097,21.60925,0.75202
606.08099,66.00833,1.66576,21.57765,0.75127
607.08099,66.10833000000001,1.6685900000000002,21.55857,0.75052
608.073,66.20833,1.6710200000000002,21.55857,0.74978
609.0819700000001,66.30833,1.6768299999999998,21.53314,0.74902
610.06799,66.40833,1.683,21.552220000000002,0.74829
611.06403,66.50833,1.68743,21.54586,0.74754
612.04797,66.60833000000001,1.6894799999999999,21.52678,0.7468100000000001
613.04797,66.70833,1.6921599999999999,21.50154,0.7460600000000001
614.0369900000001,66.80833,1.6962099999999998,21.50154,0.74532
615.03497,66.90833,1.6987,21.450670000000002,0.74457
616.03998,67.00833,1.7047700000000001,21.450870000000002,0.74382
617.03302,67.10833000000001,1.71102,21.450670000000002,0.74307
618.03302,67.20833,1.71533,21.450670000000002,0.74233
619.0189799999999,67.30833,1.71822,21.42524,0.74159
620.026,67.40833,1.71938,21.4,0.74083
621.01599,67.50833,1.7264599999999999,21.4,0.7400899999999999
622.034,67.60833000000001,1.73043,21.36821,0.73933
623.01001,67.70833,1.73334,21.36821,0.7386
623.9979900000001,67.80833,1.7410599999999998,21.317529999999998,0.73785
625.0,67.90833,1.74623,21.31118,0.7371
625.9970099999999,68.00833,1.7494,21.317529999999998,0.73635
626.97998,68.10833000000001,1.75595,21.292289999999998,0.7356199999999999
627.9810200000001,68.20833,1.75875,21.27958,0.7348600000000001
628.9810200000001,68.30833,1.76255,21.241429999999998,0.73411
629.96698,68.40833,1.7683400000000002,21.26686,0.73337
630.961,68.50833,1.77214,21.241429999999998,0.73263
631.94897,68.60833000000001,1.77876,21.23526,0.73188
632.9420200000001,68.70833,1.7819900000000002,21.203470000000003,0.73114
633.94098,68.80833,1.78965,21.1526,0.73039
634.92102,68.90833,1.79529,21.1526,0.72965
635.90997,69.00833,1.80055,21.1526,0.7289100000000001
636.90503,69.10833000000001,1.80603,21.15279,0.72816
637.896,69.20833,1.8119299999999998,21.12736,0.72741
638.88501,69.30833,1.8152,21.102120000000003,0.7266699999999999
639.8729900000001,69.40833,1.81908,21.07669,0.72592
640.86603,69.50833,1.8242,21.07669,0.72518
641.85699,69.60833000000001,1.83034,21.07669,0.72443
642.84003,69.70833,1.83526,21.07669,0.7236899999999999
643.8380099999999,69.80833,1.84266,21.05125,0.7229399999999999
644.8220200000001,69.90833,1.8469900000000001,21.00058,0.7222