File: 02_Data/OSB/STA/N2/10K_min/OSB_STA_N2_10KData_210315_R2.csv
##Temp./Â°C,Time/min,DSC/(mW/mg),Mass/%,Sensit./(uV/mW)
47.748,10.01,-0.02433632,101.09933000000001,1.08951
47.756,10.11,-0.02527844,101.09933000000001,1.08951
47.778,10.21,-0.02590667,101.09193,1.0895
47.778,10.31,-0.02543564,101.12151999999999,1.0895
47.793,10.41,-0.02606381,101.09933000000001,1.0895
47.796,10.51,-0.02574981,101.1509,1.08949
47.794,10.61,-0.02480773,101.09215,1.0895
47.843,10.71,-0.02339501,101.12151999999999,1.08948
47.874,10.81,-0.02088301,101.14372,1.0894700000000002
47.929,10.91,-0.01978426,101.14372,1.08945
48.007,11.01,-0.01805754,101.1509,1.08942
48.062,11.11,-0.01633059,101.17331999999999,1.0894
48.173,11.21,-0.0142898,101.18789,1.08936
48.3,11.31,-0.0113067,101.18049,1.08931
48.441,11.41,-0.007695193,101.14372,1.0892600000000001
48.615,11.51,-0.003298132,101.10673,1.0892
48.793,11.61,0.0001570632,101.13139,1.08913
49.001,11.71,0.0048692990000000005,101.17556,1.0890600000000001
49.242,11.81,0.008639782,101.17556,1.08897
49.518,11.91,0.01398203,101.17556,1.08887
49.799,12.01,0.01948241,101.19529,1.08877
50.112,12.11,0.02262712,101.19036,1.08865
50.447,12.21,0.02828709,101.18543000000001,1.08853
50.807,12.31,0.03143391,101.18789,1.0884
51.211,12.41,0.03631111,101.15111999999999,1.08825
51.582,12.51,0.04213245,101.18789,1.0881100000000001
52.019,12.61,0.04638399,101.18789,1.08795
52.445,12.71,0.05032211,101.19283,1.08779
52.912,12.81,0.05536309,101.19529,1.08762
53.43,12.91,0.05914827,101.1657,1.08743
53.899,13.01,0.06230441,101.19776,1.0872600000000001
54.432,13.11,0.06609246,101.20022,1.0870600000000001
54.967,13.21,0.07066892,101.19776,1.08686
55.516,13.31,0.07446034,101.19036,1.08665
56.055,13.41,0.07888274,101.16323,1.08645
56.624,13.51,0.08346515,101.23206,1.0862399999999999
57.232,13.61,0.08521531,101.17309,1.0860100000000001
57.829,13.71,0.08917158,101.17309,1.08579
58.457,13.81,0.09265777,101.17309,1.08555
59.094,13.91,0.09630344,101.17309,1.08531
59.707,14.01,0.09916169,101.17309,1.0850799999999998
60.352,14.11,0.10092000000000001,101.17331999999999,1.08484
61.023,14.21,0.10347,101.17309,1.0845799999999999
61.664,14.31,0.10586,101.20246999999999,1.0843399999999999
62.337,14.41,0.10967,101.20269,1.08408
63.029,14.51,0.11110999999999999,101.18789,1.08382
63.738,14.61,0.11241,101.20269,1.08355
64.44,14.71,0.11512,101.17309,1.08328
65.197,14.81,0.11862,101.14372,1.08299
65.883,14.91,0.1215,101.17309,1.0827200000000001
66.626,15.01,0.12311,101.18049,1.08243
67.39,15.11,0.1271,101.17309,1.0821399999999999
68.141,15.21,0.1276,101.17331999999999,1.08185
68.906,15.31,0.13033,101.14372,1.08155
69.674,15.41,0.134,101.1435,1.08125
70.47,15.51,0.1361,101.14372,1.08094
71.253,15.61,0.13693,101.1139,1.08063
72.044,15.71,0.13903,101.1435,1.0803200000000002
72.86,15.81,0.14081,101.09933000000001,1.08
73.675,15.91,0.14323,101.11413,1.07968
74.506,16.01,0.14502,101.09193,1.07935
75.355,16.11,0.14870999999999998,101.14372,1.07901
76.161,16.21,0.14859,101.1435,1.07869
77.013,16.31,0.15134,101.12892,1.07835
77.863,16.41,0.15234,101.07713000000001,1.0780100000000001
78.738,16.51,0.1535,101.08453,1.07766
79.603,16.61,0.15577,101.11413,1.07731
80.487,16.71,0.15471,101.09193,1.07695
81.359,16.81,0.15635,101.08475,1.0766
82.237,16.91,0.15815,101.08453,1.07625
83.138,17.01,0.15852,101.08453,1.07588
84.053,17.11,0.15825999999999998,101.09933000000001,1.07551
84.96,17.21,0.15911,101.08475,1.07514
85.871,17.31,0.16012,101.08453,1.07476
86.81,17.41,0.16065,101.05516,1.07438
87.728,17.51,0.16022999999999998,101.08475,1.074
88.67,17.61,0.16155999999999998,101.05516,1.07361
89.606,17.71,0.15987,101.05493,1.07322
90.552,17.81,0.16025,101.05516,1.07283
91.488,17.91,0.16047,101.06255999999999,1.07244
92.466,18.01,0.16021,101.05516,1.0720299999999998
93.408,18.11,0.15867,101.02556,1.07164
94.393,18.21,0.15921,101.02556,1.07122
95.346,18.31,0.15750999999999998,101.04035999999999,1.07082
96.333,18.41,0.15693,101.02556,1.0704
97.328,18.51,0.15796,101.02556,1.06998
98.315,18.61,0.1577,101.01816,1.06956
99.279,18.71,0.1592,100.99596,1.06915
100.27,18.81,0.15782000000000002,101.02556,1.06873
101.267,18.91,0.15868,100.99619,1.06831
102.261,19.01,0.1565,101.02556,1.06788
103.258,19.11,0.15769,101.02556,1.06745
104.272,19.21,0.15631,101.02556,1.06701
105.285,19.31,0.15702,101.03296,1.06657
106.273,19.41,0.15612,101.05516,1.06615
107.299,19.51,0.15779,101.05516,1.0657
108.3,19.61,0.15705,101.02556,1.06526
109.323,19.71,0.15550999999999998,101.02556,1.06482
110.355,19.81,0.15606,100.99619,1.06436
111.368,19.91,0.15564,101.02578000000001,1.06392
112.396,20.01,0.15474000000000002,101.01816,1.0634700000000001
113.421,20.11,0.15432,101.02556,1.06301
114.462,20.21,0.15487,101.02556,1.06255
115.483,20.31,0.15542,101.02556,1.0621
116.502,20.41,0.15662,101.02556,1.06164
117.541,20.51,0.15459,101.02556,1.06118
118.578,20.61,0.15547,101.05516,1.06072
119.62,20.71,0.15489,101.05516,1.06025
120.661,20.81,0.15399000000000002,101.05493,1.05978
121.696,20.91,0.1526,101.02556,1.05931
122.757,21.01,0.15316,101.05516,1.05883
123.801,21.11,0.1529,101.03296,1.05836
124.858,21.21,0.15216,101.06255999999999,1.05788
125.911,21.31,0.15288,101.02556,1.0574
126.961,21.41,0.15214,101.05516,1.05692
128.037,21.51,0.15237,101.05516,1.05643
129.10001,21.61,0.15244000000000002,101.05516,1.0559399999999999
130.157,21.71,0.15186,101.02556,1.05545
131.244,21.81,0.1508,101.02556,1.05495
132.302,21.91,0.15168,101.05493,1.05446
133.395,22.01,0.15078,101.05516,1.05396
134.448,22.11,0.14923,101.05516,1.0534700000000001
135.53798999999998,22.21,0.1506,101.02556,1.0529600000000001
136.61501,22.31,0.15245999999999998,101.05516,1.05245
137.686,22.41,0.15074,101.02556,1.05195
138.77499,22.51,0.15017,101.02556,1.05144
139.854,22.61,0.15267999999999998,101.04753000000001,1.05093
140.952,22.71,0.15341,101.00359,1.05041
142.049,22.81,0.15202000000000002,100.97399,1.0499
143.125,22.91,0.15095,101.00336,1.04939
144.229,23.01,0.15168,101.02556,1.0488600000000001
145.326,23.11,0.14979,101.04013,1.04834
146.416,23.21,0.14987,101.04013,1.04782
147.506,23.31,0.15011,101.01816,1.04729
148.61099,23.41,0.14822000000000002,101.00336,1.0467600000000001
149.71201000000002,23.51,0.14862,101.02556,1.04623
150.821,23.61,0.14640999999999998,101.03296,1.0457
151.91298999999998,23.71,0.14632,101.01076,1.0451700000000002
153.017,23.81,0.14328,101.00336,1.04464
154.125,23.91,0.14139000000000002,100.99619,1.0441
155.22701,24.01,0.14097,101.00359,1.04356
156.32401000000002,24.11,0.14023,100.97399,1.04303
157.42999,24.21,0.13849,100.97399,1.0424799999999999
158.545,24.31,0.13857,100.99596,1.0419399999999999
159.651,24.41,0.13634000000000002,100.99596,1.04139
160.761,24.51,0.13493,100.99596,1.04085
161.87801000000002,24.61,0.13434000000000001,101.00336,1.0403
162.98,24.71,0.13112000000000001,100.98879000000001,1.03975
164.09399,24.81,0.13301,100.97399,1.0392
165.215,24.91,0.13275,100.95919,1.03864
166.317,25.01,0.13298,100.9296,1.03809
167.433,25.11,0.12959,100.9296,1.0375299999999998
168.54401000000001,25.21,0.12933,100.9296,1.03698
169.66298999999998,25.31,0.13055999999999998,100.9296,1.0364200000000001
170.77499,25.41,0.12930999999999998,100.95919,1.03586
171.881,25.51,0.12838,100.937,1.0353
173.004,25.61,0.12564,100.95919,1.03473
174.117,25.71,0.12588,100.94439,1.03417
175.233,25.81,0.12595,100.94439,1.0336100000000001
176.339,25.91,0.12635,100.87063,1.03304
177.47701,26.01,0.12559,100.90021999999999,1.03246
178.57899,26.11,0.124,100.87803000000001,1.0319
179.69298999999998,26.21,0.12423,100.85583000000001,1.0313299999999999
180.82001,26.31,0.1253,100.84843000000001,1.03075
181.946,26.41,0.12404000000000001,100.84865,1.0301799999999999
183.06798999999998,26.51,0.12228,100.84125999999999,1.0296
184.18201000000002,26.61,0.12268,100.78945999999999,1.02902
185.313,26.71,0.12242,100.78206,1.02844
186.44,26.81,0.11999000000000001,100.78206,1.02785
187.569,26.91,0.11955999999999999,100.78206,1.0272700000000001
188.683,27.01,0.1183,100.78206,1.0266899999999999
189.82201,27.11,0.11803,100.75986999999999,1.0261
190.948,27.21,0.11627,100.73026999999999,1.0255100000000001
192.078,27.31,0.1165,100.73026999999999,1.02492
193.215,27.41,0.11523,100.7083,1.0243200000000001
194.325,27.51,0.11312,100.67152,1.0237399999999999
195.461,27.61,0.11118,100.67152,1.02314
196.597,27.71,0.11259000000000001,100.64193,1.02254
197.717,27.81,0.11064,100.62713000000001,1.02195
198.842,27.91,0.1097,100.60516,1.02135
199.983,28.01,0.10809,100.57556,1.02075
201.10201,28.11,0.10396,100.57556,1.02015
202.246,28.21,0.1047,100.54596,1.01954
203.37198999999998,28.31,0.10207000000000001,100.49417,1.01894
204.509,28.41,0.10365,100.487,1.01833
205.633,28.51,0.10152,100.45761999999999,1.01773
206.75999,28.61,0.09922786,100.42803,1.01712
207.88901,28.71,0.09945543,100.36906,1.01652
209.03798999999998,28.81,0.09833737,100.33946,1.0159
210.173,28.91,0.09772279,100.30986999999999,1.01528
211.289,29.01,0.09761238,100.30247,1.01468
212.41901000000001,29.11,0.09581575,100.2213,1.01407
213.564,29.21,0.09300507,100.1917,1.01345
214.701,29.31,0.09103513,100.13274,1.01283
215.815,29.41,0.09075175,100.12534000000001,1.0122200000000001
216.951,29.51,0.08793269,100.04439,1.0116
218.082,29.61,0.08781731,99.98543000000001,1.01098
219.21001,29.71,0.08719382,99.98543000000001,1.0103600000000001
220.33299,29.81,0.08656942,99.92623,1.0097399999999999
221.46899,29.91,0.08594497,99.86726,1.00912
222.623,30.01,0.08532068,99.83766999999999,1.0084799999999998
223.73599,30.11,0.08384517,99.78856999999999,1.00787
224.86,30.21,0.08185894,99.70246999999999,1.00725
225.987,30.31,0.08275941,99.63117,1.00662
227.11301,30.41,0.08128045,99.55717,1.006
228.23398999999998,30.51,0.07945921,99.5278,1.00537
229.364,30.61,0.07763619,99.47601,1.00475
230.502,30.71,0.07887784,99.43924,1.00411
231.62601,30.81,0.07654066,99.34326999999999,1.00348
232.76199,30.91,0.07454227,99.26973000000001,1.00285
233.881,31.01,0.07339417,99.19103,1.00222
235.006,31.11,0.07070782,99.12691,1.00159
236.13901,31.21,0.07126557,99.02848,1.00095
237.265,31.31,0.06874566,98.95470999999999,1.00031
238.396,31.41,0.06913182,98.89327,0.9996700000000001
239.52499,31.51,0.06609391,98.7926,0.9990399999999999
240.647,31.61,0.06373727,98.69664,0.9984
241.778,31.71,0.06394972,98.6352,0.9977600000000001
242.899,31.81,0.06261814,98.51210999999999,0.9971200000000001
244.03798999999998,31.91,0.05991221,98.40404000000001,0.9964700000000001
245.16901000000001,32.01,0.05634365,98.27848,0.9958299999999999
246.29601,32.11,0.0562082,98.20716999999999,0.99518
247.41701,32.21,0.05332043,98.1065,0.99454
248.55,32.31,0.05025722,98.00561,0.9938899999999999
249.679,32.41,0.0475344,97.90224,0.99324
250.799,32.51,0.04549719,97.79664,0.9926
251.923,32.61,0.04483708,97.64395,0.99195
253.048,32.71,0.04210545,97.53811999999999,0.9913
254.187,32.81,0.04040664,97.39798,0.99065
255.321,32.91,0.03905108,97.29238000000001,0.9899899999999999
256.43201,33.01,0.03648293,97.18408000000001,0.98935
257.56299,33.11,0.03512299,97.06591999999999,0.98869
258.67499,33.21,0.03185645,96.89888,0.9880399999999999
259.798,33.31,0.03153105,96.73161,0.98739
260.931,33.41,0.02739142,96.60874,0.9867299999999999
262.065,33.51,0.02654242,96.43901,0.9860700000000001
263.19698999999997,33.61,0.02499788,96.32848,0.9854
264.29098999999997,33.71,0.02119255,96.17108,0.9847600000000001
265.42899,33.81,0.01929482,95.98901,0.9841
266.53699,33.91,0.01913365,95.82668000000001,0.98344
267.67001,34.01,0.01549137,95.61995999999999,0.9827799999999999
268.789,34.11,0.01410835,95.46009000000001,0.9821200000000001
269.90302,34.21,0.01237486,95.25359,0.98146
271.034,34.31,0.009418283000000001,95.09371999999999,0.9807899999999999
272.15701,34.41,0.00750483,94.87241999999999,0.98013
273.271,34.51,0.0027943779999999997,94.67063,0.9794700000000001
274.41501,34.61,0.002272007,94.44193,0.9787899999999999
275.53201,34.71,-0.001224219,94.22309,0.9781200000000001
276.65398999999996,34.81,-0.004725214,93.9991,0.97746
277.798,34.91,-0.005779322,93.68205999999999,0.97677
278.905,35.01,-0.006133706,93.4509,0.97611
280.01999,35.11,-0.009645268,93.24664,0.97545
281.14099,35.21,-0.01333718,92.95404,0.97478
282.26501,35.31,-0.01527813,92.69843,0.9741
283.384,35.41,-0.01774892,92.39820999999999,0.9734299999999999
284.50101,35.51,-0.0195197,92.14506999999999,0.9727600000000001
285.63199,35.61,-0.02199705,91.85717,0.9720799999999999
286.74399,35.71,-0.02553419,91.52265,0.97141
287.87399,35.81,-0.02643327,91.24731,0.97072
288.995,35.91,-0.02997863,90.94238,0.97005
290.112,36.01,-0.03317596,90.59305,0.9693700000000001
291.23901,36.11,-0.03390573,90.27825,0.9686899999999999
292.35101000000003,36.21,-0.03410608,89.95852,0.96801
293.46799,36.31,-0.03466054,89.60942,0.9673299999999999
294.59201,36.41,-0.03981704,89.21839,0.96665
295.72101000000004,36.51,-0.04002249,88.86188,0.96596
296.823,36.61,-0.03880988,88.47332,0.96529
297.93201,36.71,-0.03777308,88.09215,0.9646100000000001
299.05801,36.81,-0.04117192,87.68139000000001,0.9639200000000001
300.17801000000003,36.91,-0.03942533,87.2583,0.96324
301.29098999999997,37.01,-0.03945329,86.89933,0.96255
302.40201,37.11,-0.03770285,86.46143000000001,0.9618700000000001
303.51401,37.21,-0.03594997,86.05807,0.96119
304.633,37.31,-0.03330429,85.6352,0.9605
305.75299,37.41,-0.03368471,85.19484,0.95981
306.86301000000003,37.51,-0.03121183,84.75224,0.9591200000000001
307.98001,37.61,-0.03248368,84.32175,0.9584299999999999
309.09201,37.71,-0.02822039,83.84955,0.9577399999999999
310.19601,37.81,-0.02681066,83.33565,0.95706
311.31601,37.91,-0.0259358,82.84125999999999,0.95636
312.42899,38.01,-0.0238066,82.30269,0.95567
313.53201,38.11,-0.02274895,81.85269,0.95499
314.63901,38.21,-0.01971804,81.31143,0.9543
315.755,38.31,-0.01775919,80.74596,0.9536
316.85999,38.41,-0.01472028,80.19753,0.95291
317.97198,38.51,-0.01221597,79.6222,0.9522200000000001
319.07999,38.61,-0.01222487,79.113,0.95152
320.186,38.71,-0.008635608000000001,78.51794,0.95083
321.285,38.81,-0.004500975,77.96211,0.95014
322.39801,38.91,-0.0027025729999999998,77.38161,0.94944
323.50699,39.01,0.001262128,76.77422,0.94875
324.603,39.11,0.004330443,76.14709,0.94806
325.711,39.21,0.005597611,75.56166,0.9473600000000001
326.823,39.31,0.01030001,74.94193,0.9466600000000001
327.935,39.41,0.01211602,74.31233,0.94595
329.034,39.51,0.01556334,73.70246999999999,0.94526
330.14001,39.61,0.01955914,73.0704,0.9445600000000001
331.23499,39.71,0.02392319,72.37691,0.9438700000000001
332.34799,39.81,0.02901952,71.70785,0.94316
333.452,39.91,0.03285276,71.04888000000001,0.9424600000000001
334.54599,40.01,0.0385079,70.38229,0.94176
335.65701,40.11,0.04199061,69.61995999999999,0.94105
336.75601,40.21,0.04711545,68.89686,0.94035
337.854,40.31,0.05261203,68.16906,0.93965
338.966,40.41,0.05921054,67.46794,0.93894
340.061,40.51,0.0623542,66.72287,0.93824
341.16101000000003,40.61,0.06623267,66.00717,0.9375399999999999
342.259,40.71,0.07413405,65.19058000000001,0.93684
343.358,40.81,0.08022009,64.43318000000001,0.9361299999999999
344.47699,40.91,0.08686518,63.59955,0.9354100000000001
345.55801,41.01,0.09333514,62.81233,0.9347200000000001
346.64499,41.11,0.10275,61.9787,0.9340200000000001
347.74899,41.21,0.10704000000000001,61.1843,0.9333100000000001
348.845,41.31,0.11281,60.32601,0.9326
349.94901,41.41,0.12079000000000001,59.49978,0.93189
351.03201,41.51,0.12565,58.59709,0.93119
352.133,41.61,0.13329000000000002,57.731390000000005,0.93048
353.22,41.71,0.13523,56.82399,0.9297700000000001
354.327,41.81,0.14288,55.91636999999999,0.92905
355.41699,41.91,0.14668,54.967259999999996,0.92835
356.50299,42.01,0.14845,54.07444,0.9276399999999999
357.59799,42.11,0.1517,53.11278000000001,0.9269299999999999
358.69,42.21,0.15477,52.21525,0.92622
359.78799,42.31,0.15304,51.25605,0.9255
360.88199,42.41,0.15223,50.30919,0.92479
361.96799,42.51,0.14735,49.3722,0.9240799999999999
363.05399,42.61,0.14043,48.45987,0.92337
364.14999,42.71,0.13385999999999998,47.46368,0.92265
365.241,42.81,0.12302,46.524440000000006,0.92194
366.327,42.91,0.109,45.61457,0.9212299999999999
367.41699,43.01,0.09235952,44.72422,0.92051
368.505,43.11,0.07085774,43.82646,0.9198
369.60001,43.21,0.04932285,42.9926,0.9190799999999999
370.677,43.31,0.02197957,42.14686,0.91837
371.758,43.41,-0.0072700690000000005,41.34013,0.91766
372.85598999999996,43.51,-0.03805807,40.61951,0.91694
373.95599,43.61,-0.07580301,39.92354,0.9162100000000001
375.035,43.71,-0.11062000000000001,39.239909999999995,0.9155
376.11099,43.81,-0.14904,38.67422,0.91479
377.21898999999996,43.91,-0.1864,38.14058,0.91405
378.29001,44.01,-0.22494,37.65359,0.9133399999999999
379.371,44.11,-0.26016999999999996,37.188790000000004,0.9126299999999999
380.46398999999997,44.21,-0.29583000000000004,36.79036,0.9119
381.552,44.31,-0.3276,36.42646,0.9111799999999999
382.62701,44.41,-0.35623,36.145959999999995,0.9104700000000001
383.72101000000004,44.51,-0.37927,35.91726,0.90974
384.80801,44.61,-0.40497,35.637,0.90901
385.89898999999997,44.71,-0.42244,35.45987,0.9082899999999999
386.99701,44.81,-0.43993000000000004,35.282740000000004,0.90755
388.07001,44.91,-0.45235,35.09596,0.90684
389.15799,45.01,-0.46612,34.923770000000005,0.9061100000000001
390.24701,45.11,-0.4784,34.78363,0.90538
391.31601,45.21,-0.48633999999999994,34.690129999999996,0.9046700000000001
392.40398999999996,45.31,-0.4926,34.5204,0.90394
393.47699,45.41,-0.50113,34.419509999999995,0.90322
394.55701,45.51,-0.50665,34.274440000000006,0.90249
395.642,45.61,-0.51218,34.19574,0.9017700000000001
396.71398999999997,45.71,-0.51791,34.07287,0.90105
397.785,45.81,-0.5242100000000001,33.95717,0.9003200000000001
398.86899,45.91,-0.52996,33.839240000000004,0.89959
399.935,46.01,-0.53476,33.726009999999995,0.8988799999999999
401.013,46.11,-0.5405300000000001,33.63498,0.89815
402.08401000000003,46.21,-0.54706,33.56368,0.89743
403.16,46.31,-0.55018,33.42354,0.8967
404.22699,46.41,-0.55635,33.39395,0.8959799999999999
405.30701,46.51,-0.56196,33.27108,0.89525
406.37799,46.61,-0.56318,33.11368,0.8945200000000001
407.45001,46.71,-0.56785,33.06682,0.8938
408.51599,46.81,-0.57099,32.882509999999996,0.89307
409.58801,46.91,-0.5751,32.81861,0.8923399999999999
410.668,47.01,-0.57826,32.72265,0.89161
411.742,47.11,-0.58411,32.61188,0.8908799999999999
412.811,47.21,-0.58824,32.52825,0.89015
413.91,47.31,-0.59085,32.37332,0.88941
414.98599,47.41,-0.5938399999999999,32.30202,0.8886700000000001
416.022,47.51,-0.59778,32.203590000000005,0.88797
417.08898999999997,47.61,-0.60116,32.112559999999995,0.8872399999999999
418.155,47.71,-0.6051300000000001,32.02892,0.88651
419.21898999999996,47.81,-0.60775,31.98722,0.8857799999999999
420.28799000000004,47.91,-0.61115,31.81502,0.88505
421.34799000000004,48.01,-0.61456,31.72399,0.8843200000000001
422.42001,48.11,-0.61642,31.66256,0.88359
423.48000999999994,48.21,-0.61964,31.57915,0.8828600000000001
424.543,48.31,-0.62345,31.47825,0.88213
425.61400999999995,48.41,-0.6257199999999999,31.347759999999997,0.8814
426.67499000000004,48.51,-0.62993,31.29372,0.8806700000000001
427.746,48.61,-0.63045,31.20785,0.8799299999999999
428.80899000000005,48.71,-0.6339,31.10695,0.8792
429.86899000000005,48.81,-0.63676,31.010990000000003,0.8784700000000001
430.92999000000003,48.91,-0.63826,30.91749,0.87774
431.99701,49.01,-0.6399699999999999,30.83632,0.877
433.056,49.11,-0.64148,30.710990000000002,0.8762700000000001
434.12,49.21,-0.64163,30.647090000000002,0.87554
435.18701,49.31,-0.6451,30.56839,0.8748
436.233,49.41,-0.64427,30.42803,0.87408
437.29000999999994,49.51,-0.64676,30.369059999999998,0.87335
438.35699000000005,49.61,-0.6477,30.285429999999998,0.87261
439.42400999999995,49.71,-0.65198,30.194390000000002,0.87187
440.46899,49.81,-0.65272,30.113229999999998,0.8711399999999999
441.521,49.91,-0.65445,30.044390000000003,0.87041
442.57000999999997,50.01,-0.65342,29.953359999999996,0.8696799999999999
443.634,50.11,-0.65575,29.85762,0.8689399999999999
444.69299,50.21,-0.6565,29.79843,0.86821
445.73999000000003,50.31,-0.65883,29.702690000000004,0.8674799999999999
446.802,50.41,-0.66038,29.6704,0.86674
447.83499000000006,50.51,-0.66172,29.55022,0.8660200000000001
448.896,50.61,-0.66169,29.483629999999998,0.8652799999999999
449.952,50.71,-0.66067,29.39283,0.86454
450.99300999999997,50.81,-0.6582600000000001,29.33117,0.86382
452.05099,50.91,-0.65803,29.267259999999997,0.86308
453.09399,51.01,-0.65878,29.1787,0.86235
454.14300999999995,51.11,-0.6615300000000001,29.11973,0.86161
455.202,51.21,-0.65991,29.0509,0.86087
456.25,51.31,-0.66008,28.98453,0.86014
457.30701,51.41,-0.66025,28.925559999999997,0.8594
458.35999000000004,51.51,-0.6612100000000001,28.84933,0.8586600000000001
459.41101,51.61,-0.66298,28.787670000000002,0.8579200000000001
460.45800999999994,51.71,-0.66155,28.69193,0.85719
461.50201,51.81,-0.66272,28.68453,0.85645
462.55800999999997,51.91,-0.66489,28.632740000000002,0.8557100000000001
463.603,52.01,-0.66486,28.57377,0.8549700000000001
464.664,52.11,-0.66705,28.5148,0.8542299999999999
465.70099000000005,52.21,-0.66501,28.453359999999996,0.8535
466.758,52.31,-0.6668,28.42377,0.85275
467.82599000000005,52.41,-0.66759,28.3574,0.852
468.84,52.51,-0.66755,28.268829999999998,0.8512799999999999
469.89300999999995,52.61,-0.66974,28.19507,0.85054
470.952,52.71,-0.66972,28.165470000000003,0.8497899999999999
471.98599,52.81,-0.6713100000000001,28.1139,0.84906
473.03,52.91,-0.67472,28.045070000000003,0.8483200000000001
474.07500999999996,53.01,-0.67591,27.9639,0.8475799999999999
475.11499000000003,53.11,-0.6746800000000001,27.9343,0.84685
476.155,53.21,-0.67891,27.87534,0.84611
477.189,53.31,-0.6801,27.845740000000003,0.8453799999999999
478.228,53.41,-0.68191,27.79417,0.84464
479.272,53.51,-0.6815,27.7574,0.8439
480.32401,53.61,-0.6825100000000001,27.72018,0.84315
481.353,53.71,-0.68533,27.653809999999996,0.8424200000000001
482.401,53.81,-0.6833,27.63161,0.84167
483.436,53.91,-0.6875600000000001,27.54327,0.8409399999999999
484.48900999999995,54.01,-0.6887800000000001,27.5065,0.84019
485.52399,54.11,-0.68918,27.447309999999998,0.83945
486.56201,54.21,-0.69081,27.41794,0.8387100000000001
487.60101,54.31,-0.69367,27.35874,0.8379700000000001
488.66599,54.41,-0.6947,27.32937,0.83721
489.69500999999997,54.51,-0.69634,27.29978,0.8364799999999999
490.737,54.61,-0.69757,27.2704,0.83573
491.767,54.71,-0.69839,27.240579999999998,0.835
492.814,54.81,-0.69799,27.17915,0.83425
493.83401,54.91,-0.69881,27.090809999999998,0.83352
494.86400999999995,55.01,-0.70025,27.06121,0.83278
495.90200999999996,55.11,-0.7019,27.031840000000003,0.83204
496.944,55.21,-0.70089,27.031609999999997,0.83129
497.96700999999996,55.31,-0.70295,27.00202,0.8305600000000001
499.013,55.41,-0.7042,26.911209999999997,0.82981
500.047,55.51,-0.70545,26.852240000000002,0.82906
501.07500999999996,55.61,-0.7067,26.79327,0.8283299999999999
502.11099,55.71,-0.70919,26.82265,0.82758
503.16299000000004,55.81,-0.71005,26.73408,0.82683
504.168,55.91,-0.7098399999999999,26.70471,0.8261
505.202,56.01,-0.70924,26.697309999999998,0.82536
506.23000999999994,56.11,-0.71091,26.66794,0.82462
507.25600999999995,56.21,-0.71259,26.57668,0.82388
508.298,56.31,-0.7155199999999999,26.517709999999997,0.8231299999999999
509.32401,56.41,-0.717,26.517709999999997,0.82239
510.35000999999994,56.51,-0.71702,26.45628,0.82165
511.41101,56.61,-0.71873,26.426679999999998,0.82089
512.409,56.71,-0.7202,26.397309999999997,0.82016
513.44299,56.81,-0.71939,26.36771,0.81942
514.46802,56.91,-0.7187899999999999,26.36031,0.81868
515.495,57.01,-0.71902,26.338340000000002,0.81793
516.53198,57.11,-0.72219,26.27937,0.81719
517.58502,57.21,-0.7216100000000001,26.22018,0.81642
518.59497,57.31,-0.7239399999999999,26.19081,0.8156899999999999
519.64801,57.41,-0.72377,26.16121,0.81493
520.65997,57.51,-0.72632,26.131610000000002,0.8142
521.67102,57.61,-0.73622,26.06525,0.8134600000000001
522.703,57.71,-0.74364,26.04305,0.81271
523.71997,57.81,-0.74895,26.013679999999997,0.81198
524.75702,57.91,-0.7509100000000001,25.98408,0.8112199999999999
525.78198,58.01,-0.75265,25.954710000000002,0.81048
526.80701,58.11,-0.7537699999999999,25.902910000000002,0.80974
527.8389900000001,58.21,-0.75573,25.902910000000002,0.80898
528.85901,58.31,-0.75685,25.866139999999998,0.80824
529.888,58.41,-0.75988,25.84372,0.8074899999999999
530.90997,58.51,-0.75974,25.81435,0.80675
531.966,58.61,-0.7600399999999999,25.77018,0.80598
532.97302,58.71,-0.76073,25.75538,0.80525
533.9979900000001,58.81,-0.76186,25.71121,0.8045
534.99597,58.91,-0.7619100000000001,25.71099,0.80377
536.02502,59.01,-0.76241,25.65202,0.80302
537.0430299999999,59.11,-0.76631,25.637220000000003,0.80228
538.07397,59.21,-0.76554,25.59305,0.80153
539.08502,59.31,-0.76689,25.563679999999998,0.80079
540.10101,59.41,-0.76567,25.53408,0.80005
541.1270099999999,59.51,-0.76746,25.52175,0.7993
542.14801,59.61,-0.76818,25.50695,0.79855
543.164,59.71,-0.76975,25.47735,0.79781
544.18597,59.81,-0.77327,25.447979999999998,0.79706
545.21002,59.91,-0.77185,25.447979999999998,0.7963100000000001
546.22101,60.01,-0.77557,25.41839,0.79557
547.242,60.11,-0.77673,25.41839,0.79482
548.2689799999999,60.21,-0.77898,25.38901,0.7940699999999999
549.2860099999999,60.31,-0.78014,25.32982,0.79332
550.3049900000001,60.41,-0.78843,25.30045,0.7925800000000001
551.32599,60.51,-0.78615,25.27085,0.79183
552.34601,60.61,-0.78387,25.24126,0.79108
553.36499,60.71,-0.78764,25.211879999999997,0.79033
554.38599,60.81,-0.78991,25.18229,0.7895800000000001
555.39001,60.91,-0.7902100000000001,25.152910000000002,0.78884
556.409,61.01,-0.79313,25.13812,0.78809
557.4249900000001,61.11,-0.79193,25.10112,0.78735
558.43402,61.21,-0.79551,25.09372,0.7866
559.44897,61.31,-0.7984399999999999,25.05695,0.78586
560.466,61.41,-0.79724,25.07915,0.7851100000000001
561.474,61.51,-0.8017,25.04955,0.7843600000000001
562.495,61.61,-0.80313,25.01996,0.78361
563.5029900000001,61.71,-0.8071699999999999,24.990579999999998,0.78287
564.526,61.81,-0.81013,24.93139,0.7821199999999999
565.53003,61.91,-0.81287,24.90202,0.78137
566.534,62.01,-0.81386,24.90202,0.78063
567.55402,62.11,-0.8175,24.87242,0.77988
568.57599,62.21,-0.81983,24.84305,0.77913
569.59601,62.31,-0.82106,24.81345,0.77837
570.59698,62.41,-0.82294,24.81345,0.77763
571.61499,62.51,-0.8268200000000001,24.80583,0.77688
572.61401,62.61,-0.82739,24.77646,0.7761399999999999
573.63599,62.71,-0.82775,24.717489999999998,0.7753899999999999
574.651,62.81,-0.8365,24.717489999999998,0.77464
575.65198,62.91,-0.83598,24.67309,0.77389
576.659,63.01,-0.8392200000000001,24.68789,0.77315
577.66699,63.11,-0.84424,24.658520000000003,0.7724
578.6920200000001,63.21,-0.8492799999999999,24.62892,0.77164
579.67297,63.31,-0.84919,24.59955,0.7709199999999999
580.68402,63.41,-0.8498,24.54776,0.77017
581.69098,63.51,-0.85596,24.57735,0.76942
582.698,63.61,-0.8599100000000001,24.55516,0.76867
583.7000099999999,63.71,-0.8578399999999999,24.55516,0.76793
584.7139900000001,63.81,-0.8624700000000001,24.51345,0.76718
585.71698,63.91,-0.86666,24.44955,0.7664300000000001
586.72998,64.01,-0.8708600000000001,24.44955,0.76568
587.729,64.11,-0.8732700000000001,24.44955,0.76494
588.745,64.21,-0.87705,24.41996,0.76418
589.75403,64.31,-0.87992,24.36099,0.76343
590.74902,64.41,-0.8868299999999999,24.38318,0.76269
591.76202,64.51,-0.8870399999999999,24.33139,0.76194
592.77698,64.61,-0.89061,24.302020000000002,0.76118
593.78003,64.71,-0.89194,24.30179,0.76044
594.7810099999999,64.81,-0.89484,24.30179,0.75969
595.77502,64.91,-0.89413,24.27242,0.75895
596.77899,65.01,-0.8961399999999999,24.21345,0.7582
597.77698,65.11,-0.9026700000000001,24.242829999999998,0.75746
598.78497,65.21,-0.9033399999999999,24.21323,0.75671
599.78497,65.31,-0.90604,24.21323,0.7559600000000001
600.79797,65.41,-0.9096700000000001,24.21345,0.75521
601.797,65.51,-0.91306,24.21345,0.75446
602.802,65.61,-0.91374,24.16906,0.75371
603.80103,65.71,-0.91351,24.13946,0.75297
604.81299,65.81,-0.91556,24.11009,0.75221
605.828,65.91,-0.91694,24.08049,0.75146
606.81097,66.01,-0.9208,24.04865,0.7507199999999999
607.8049900000001,66.11,-0.92285,24.03386,0.74998
608.81799,66.21,-0.92653,24.04865,0.74922
609.82098,66.31,-0.92425,24.01906,0.74847
610.815,66.41,-0.93066,23.98946,0.74773
611.81897,66.51,-0.93091,23.96009,0.74698
612.815,66.61,-0.93001,23.98969,0.7462300000000001
613.81598,66.71,-0.93484,23.96009,0.74548
614.82397,66.81,-0.93579,23.93049,0.74473
615.802,66.91,-0.93671,23.92309,0.744
616.81,67.01,-0.94065,23.893720000000002,0.74324
617.8079799999999,67.11,-0.93976,23.901120000000002,0.74249
618.802,67.21,-0.94232,23.87152,0.74175
619.79199,67.31,-0.9411799999999999,23.87152,0.7410100000000001
620.79901,67.41,-0.9426,23.84215,0.74025
621.784,67.51,-0.9426200000000001,23.84215,0.73951
622.79602,67.61,-0.95215,23.81256,0.7387600000000001
623.7810099999999,67.71,-0.94685,23.78296,0.73802
624.77502,67.81,-0.94711,23.76839,0.73727
625.78302,67.91,-0.94506,23.78296,0.73651
626.77698,68.01,-0.9457899999999999,23.775560000000002,0.73577
627.76501,68.11,-0.94605,23.76076,0.7350300000000001
628.76703,68.21,-0.95144,23.723770000000002,0.73427
629.7470099999999,68.31,-0.9535600000000001,23.6796,0.73354
630.729,68.41,-0.9575600000000001,23.65,0.7328
631.73602,68.51,-0.9573799999999999,23.65,0.7320399999999999
632.7119799999999,68.61,-0.95389,23.65,0.73131
633.7310200000001,68.71,-0.957,23.62063,0.73054
634.70502,68.81,-0.9591299999999999,23.62063,0.7298100000000001
635.68103,68.91,-0.95752,23.62063,0.7290800000000001
636.6779799999999,69.01,-0.96085,23.59103,0.72833
637.67401,69.11,-0.9616100000000001,23.57623,0.72758
638.67902,69.21,-0.96473,23.57623,0.72682
639.65997,69.31,-0.9657100000000001,23.57623,0.7260800000000001
640.6610099999999,69.41,-0.97072,23.58386,0.72533
641.6610099999999,69.51,-0.9686600000000001,23.51726,0.72458
642.65802,69.61,-0.9746299999999999,23.51726,0.72383
643.6439799999999,69.71,-0.9739700000000001,23.510089999999998,0.72309
644.64203,69.81,-0.9652799999999999,23.48789,0.72233
645.638,69.91,-0.96367,23.48789,0.72158