File: 01_Data/Polyurethane_Foam/STA/N2/3K_min/Polyurethane_Foam_STA_N2_3KData_210225_R2.csv
##Temp./Â°C,Time/min,DSC/(mW/mg),Mass/%,Sensit./(uV/mW)
49.086,10.00917,0.010576,100.19945,1.0532700000000002
49.108,10.30917,0.01037648,100.18154,1.05326
49.114,10.609169999999999,0.01217242,100.19945,1.05326
49.155,10.90917,0.01356932,100.20854,1.05326
49.217,11.20917,0.01855817,100.18154,1.05325
49.34,11.50917,0.0191571,100.21763,1.0532299999999999
49.517,11.80917,0.02494467,100.19036,1.05321
49.746,12.109169999999999,0.02913617,100.18127,1.05318
50.044,12.40917,0.03332817,100.20854,1.05315
50.373,12.70917,0.03931681,100.24463,1.0531
50.768,13.00917,0.04550589,100.19036,1.05305
51.188,13.309170000000002,0.04670578,100.24463,1.053
51.647,13.60917,0.0495029,100.20854,1.05294
52.15,13.909170000000001,0.05549458,100.17245,1.05288
52.656,14.20917,0.05669583,100.22672,1.05281
53.216,14.509170000000001,0.06029342,100.2449,1.05274
53.797,14.809170000000002,0.06349239,100.25399,1.05266
54.397,15.10917,0.06429589,100.21763,1.0525799999999998
54.992,15.409170000000001,0.06629767,100.21763,1.0525
55.65,15.70917,0.06989801,100.25399,1.05241
56.315,16.00917,0.07070291,100.17548000000001,1.0523200000000001
56.979,16.30917,0.07310594,100.21157,1.05223
57.687,16.609170000000002,0.07650868,100.22975,1.0521399999999999
58.391,16.90917,0.0777145,100.24766,1.0520399999999999
59.114,17.20917,0.07932041,100.18457,1.0519399999999999
59.848,17.50917,0.08052718,100.20248000000001,1.0518299999999998
60.596,17.80917,0.08413249,100.21185,1.05172
61.347,18.109170000000002,0.08254229,100.17548000000001,1.05162
62.149,18.40917,0.08415053,100.17520999999999,1.0515
62.932,18.70917,0.08575898,100.16639,1.05138
63.726,19.00917,0.0857686,100.17520999999999,1.0512700000000001
64.53,19.30917,0.08717808,100.1573,1.05115
65.32,19.609170000000002,0.08858781,100.18457,1.05103
66.138,19.90917,0.0903983,100.17520999999999,1.0509
66.995,20.20917,0.09240987,100.17548000000001,1.05077
67.798,20.50917,0.09022036,100.17548000000001,1.05064
68.62,20.80917,0.09443289,100.17520999999999,1.0505200000000001
69.467,21.109170000000002,0.09584562,100.17548000000001,1.0503799999999999
70.315,21.40917,0.09565786,100.22066,1.05025
71.168,21.70917,0.09727157,100.17520999999999,1.05011
72.01,22.00917,0.0976846,100.14820999999999,1.04997
72.863,22.30917,0.09869863,100.1573,1.0498299999999998
73.708,22.609170000000002,0.09891202,100.12094,1.04969
74.581,22.90917,0.09732373,100.17548000000001,1.04955
75.444,23.20917,0.10054,100.16639,1.0494
76.324,23.50917,0.09995514,100.16611999999999,1.04925
77.186,23.80917,0.10097,100.13003,1.0491
78.053,24.109170000000002,0.10259000000000001,100.13003,1.04895
78.941,24.40917,0.09999831,100.13003,1.0488
79.806,24.70917,0.10322,100.12094,1.04864
80.686,25.00917,0.10364000000000001,100.12094,1.04849
81.598,25.30917,0.10686,100.1573,1.04833
82.45,25.609170000000002,0.10708,100.12094,1.04817
83.356,25.90917,0.10729000000000001,100.17520999999999,1.04801
84.23,26.20917,0.10811,100.09366,1.04785
85.12,26.50917,0.10812999999999999,100.09366,1.04768
86.024,26.80917,0.10754000000000001,100.09394,1.04751
86.914,27.109170000000002,0.10815999999999999,100.09366,1.04734
87.82,27.40917,0.10818,100.09366,1.0471700000000002
88.716,27.70917,0.1084,100.09366,1.047
89.619,28.00917,0.10762000000000001,100.05758,1.04683
90.527,28.30917,0.10722999999999999,100.09394,1.04665
91.428,28.609170000000002,0.11207,100.10275,1.04647
92.348,28.90917,0.11149,100.09366,1.04629
93.252,29.20917,0.11130999999999999,100.13003,1.04611
94.155,29.50917,0.11012000000000001,100.05758,1.04593
95.074,29.80917,0.11215,100.02121,1.04575
95.974,30.109170000000002,0.11076,100.03939,1.04556
96.901,30.40917,0.11118,100.03939,1.0453700000000001
97.821,30.70917,0.11442000000000001,100.05758,1.04518
98.729,31.00917,0.11163,100.04848,1.0449899999999999
99.638,31.30917,0.11165,100.04821,1.0448
100.569,31.609170000000002,0.11247,100.06639,1.04461
101.494,31.90917,0.1141,100.0303,1.04441
102.418,32.20917,0.1107,100.04848,1.04421
103.331,32.509170000000005,0.11112999999999999,100.06639,1.04401
104.271,32.80917,0.11195,99.99421,1.0438100000000001
105.191,33.10917,0.11218,99.93966999999999,1.04361
106.114,33.40917,0.11400999999999999,99.96667,1.0434
107.051,33.70917,0.11524000000000001,100.01212,1.04319
107.975,34.009170000000005,0.11587,99.97603000000001,1.0429899999999999
108.894,34.30917,0.11790999999999999,99.94876,1.0427799999999998
109.828,34.60917,0.11854,99.93058,1.04257
110.757,34.90917,0.11977,99.90331,1.04235
111.675,35.20917,0.11475,99.93966999999999,1.04214
112.621,35.509170000000005,0.1176,99.95785,1.0419200000000002
113.545,35.80917,0.11763,99.89421,1.0417100000000001
114.473,36.10917,0.11563,99.95785,1.04149
115.404,36.40917,0.11727,99.93058,1.0412700000000001
116.335,36.70917,0.11669000000000002,99.95758000000001,1.04105
117.26,37.009170000000005,0.11672,99.95785,1.04083
118.194,37.30917,0.11694,99.93058,1.0406
119.13,37.60917,0.11535,99.93058,1.04037
120.074,37.90917,0.1174,99.93966999999999,1.04014
120.999,38.20917,0.11742999999999999,99.94876,1.0399100000000001
121.941,38.509170000000005,0.11685,99.90331,1.03968
122.859,38.80917,0.11849000000000001,99.93966999999999,1.03945
123.801,39.10917,0.11953,99.94876,1.03922
124.73,39.40917,0.12097000000000001,99.87603,1.03898
125.678,39.70917,0.11796,99.86721999999999,1.03874
126.617,40.009170000000005,0.11819,99.8854,1.0385
127.539,40.30917,0.1162,99.85813,1.03826
128.49899,40.60917,0.11703,99.87603,1.03801
129.436,40.90917,0.11504,99.88512,1.03777
130.38699,41.20917,0.11405,99.79449,1.03752
131.304,41.509170000000005,0.11266,99.86721999999999,1.03728
132.26199,41.80917,0.11309000000000001,99.83085,1.03703
133.198,42.10917,0.11474000000000001,99.78237,1.03678
134.13,42.40917,0.11274,99.8551,1.03653
135.075,42.70917,0.11235999999999999,99.82781999999999,1.03627
136.01801,43.009170000000005,0.11259000000000001,99.76446,1.03601
136.96899,43.30917,0.111,99.80055,1.03575
137.90601,43.60917,0.11285,99.74628,1.0355
138.854,43.90917,0.11166,99.78237,1.03524
139.799,44.20917,0.1121,99.77355,1.0349700000000002
140.741,44.509170000000005,0.11110999999999999,99.74628,1.03471
141.681,44.80917,0.11419000000000001,99.80991999999999,1.03445
142.64101000000002,45.10917,0.11095999999999999,99.76446,1.03417
143.58098999999999,45.40917,0.11099,99.71019,1.03391
144.53101,45.70917,0.1098,99.71019,1.03364
145.47701,46.009170000000005,0.11105,99.67383000000001,1.03336
146.41901000000001,46.30917,0.10905,99.70992,1.03309
147.36501,46.60917,0.10969000000000001,99.71901,1.03282
148.32201,46.90917,0.10930999999999999,99.66445999999999,1.03254
149.26601000000002,47.20917,0.10832,99.70083000000001,1.03226
150.22301000000002,47.509170000000005,0.10590999999999999,99.71019,1.03198
151.177,47.80917,0.10695,99.65565,1.03169
152.13699,48.10917,0.10678,99.67383000000001,1.03141
153.086,48.40917,0.10477,99.70083000000001,1.03112
154.02901,48.70917,0.10419,99.62836999999999,1.03084
155.002,49.009170000000005,0.10503,99.70083000000001,1.03054
155.96899,49.30917,0.10323,99.70083000000001,1.03025
156.92799,49.60917,0.10468,99.66474000000001,1.02995
157.87198999999998,49.90917,0.10307999999999999,99.7011,1.02966
158.836,50.20917,0.10107000000000001,99.68264,1.0293700000000001
159.79201,50.509170000000005,0.10089,99.68264,1.0290700000000002
160.758,50.80917,0.09928947,99.64628,1.02877
161.713,51.10917,0.09952282,99.63747,1.02847
162.68201000000002,51.40917,0.09914361,99.61928,1.02816
163.646,51.70917,0.09774178,99.71019,1.02785
164.59399,52.009170000000005,0.09613423,99.63747,1.02755
165.558,52.30917,0.09657237,99.61046999999999,1.02724
166.52299,52.60917,0.09537363,99.60138,1.02693
167.48199,52.909169999999996,0.09376466,99.60138,1.02662
168.435,53.20916999999999,0.09174512,99.61955999999999,1.02631
169.386,53.50917,0.09197778,99.58292,1.026
170.35699,53.809169999999995,0.09077691,99.58292,1.02568
171.30701000000002,54.10917,0.08916487,99.61928,1.0253700000000001
172.284,54.409169999999996,0.08878298,99.64656,1.02504
173.228,54.70916999999999,0.08922046,99.61046999999999,1.02473
174.202,55.00917,0.08637648,99.63747,1.0244
175.15198999999998,55.309169999999995,0.08640345,99.5832,1.0240799999999999
176.114,55.60917,0.08417261,99.5832,1.02376
177.08098999999999,55.909169999999996,0.08419966,99.62836999999999,1.0234299999999998
178.045,56.20916999999999,0.07909096,99.59201,1.0231
178.99001,56.50917,0.08178746,99.59201,1.0227700000000002
179.944,56.809169999999995,0.079347,99.59201,1.02245
180.907,57.10917,0.07793346,99.61019,1.02211
181.87,57.409169999999996,0.0769305,99.6011,1.02178
182.84,57.70916999999999,0.07695601,99.5741,1.02144
183.784,58.00917,0.07759845,99.5741,1.02111
184.755,58.309169999999995,0.07515365,99.5741,1.0207700000000002
185.724,58.60917,0.07085354,99.56501,1.02042
186.685,58.909169999999996,0.07355576,99.49256,1.0200799999999999
187.66,59.20916999999999,0.07131367,99.49256,1.01973
188.608,59.50917,0.07174981,99.49256,1.01939
189.561,59.809169999999995,0.07033024,99.52893,1.01905
190.52698999999998,60.10917,0.06725959,99.52893,1.0187
191.517,60.409169999999996,0.06728331,99.51074,1.01834
192.448,60.70916999999999,0.06524116,99.51074,1.018
193.42101,61.00917,0.06340523,99.51074,1.01765
194.381,61.309169999999995,0.060948,99.47438000000001,1.01729
195.367,61.60917,0.06303661,99.43802,1.01693
196.319,61.909169999999996,0.06140452,99.43802,1.0165799999999998
197.278,62.20916999999999,0.05977154,99.41074,1.0162200000000001
198.237,62.50917,0.05917196,99.38375,1.01586
199.209,62.809169999999995,0.05795146,99.48347,1.01549
200.17101,63.10917,0.05797218,99.34738,1.0151299999999999
201.13,63.409169999999996,0.05550752,99.38375,1.0147700000000002
202.101,63.70916999999999,0.05469896,99.41102,1.0144
203.062,64.00917,0.05471876,99.37465999999999,1.01403
204.033,64.30917,0.05225073,99.39256,1.01366
204.992,64.60916999999999,0.05081783,99.32948,1.01329
205.955,64.90916999999999,0.0512515,99.32948,1.01292
206.909,65.20917,0.05147781,99.38375,1.01255
207.88901,65.50917,0.05108194,99.27493,1.01217
208.84801000000002,65.80917,0.05110084,99.31102,1.01179
209.80901,66.10916999999999,0.05132772,99.21129,1.0114100000000001
210.778,66.40916999999999,0.05113923,99.24766,1.0110299999999999
211.73599,66.70917,0.04949473,99.22066,1.01065
212.714,67.00917,0.05221834,99.10275,1.01026
213.661,67.30917,0.05265411,99.12975,1.00989
214.627,67.60916999999999,0.05184149,99.09339,1.0095
215.589,67.90916999999999,0.05019513,99.09339,1.00911
216.552,68.20917,0.05083954,99.09366,1.00872
217.524,68.50917,0.04960875,99.06639,1.00833
218.48199,68.80917,0.04754272,98.98456999999999,1.00794
219.448,69.10916999999999,0.05027315,98.98456999999999,1.00755
220.40198999999998,69.40916999999999,0.05071002,99.02121,1.00715
221.35699,69.70917,0.04947721,98.92121,1.00676
222.332,70.00917,0.05137659,98.81267,1.0063600000000001
223.289,70.30917,0.05453079,98.81267,1.00596
224.246,70.60916999999999,0.05601545,98.76722,1.00557
225.19701,70.90916999999999,0.05666485,98.74022,1.0051700000000001
226.16499,71.20917,0.05668771,98.67658,1.00476
227.12801000000002,71.50917,0.05984951,98.63113,1.0043600000000001
228.097,71.80917,0.05861778,98.6314,1.00395
229.07201,72.10916999999999,0.06178342,98.5405,1.0035399999999999
230.026,72.40916999999999,0.0630655,98.4135,1.0031299999999999
230.996,72.70917,0.06497796,98.39559,1.00272
231.959,73.00917,0.06898883,98.30468,1.00231
232.92,73.30917,0.07006614,98.22341999999999,1.00189
233.882,73.60916999999999,0.07450231,98.14187,1.00148
234.85699,73.90916999999999,0.07663323,98.03305999999999,1.00106
235.80701000000002,74.20917,0.08128569,97.96061,1.00065
236.76199,74.50917,0.08215999,97.87906,1.00023
237.72099,74.80917,0.08618852,97.73388,0.9998100000000001
238.681,75.10916999999999,0.08832785,97.68871,0.99939
239.655,75.40916999999999,0.09678152,97.5708,0.9989600000000001
240.601,75.70917,0.09934777,97.42562,0.99854
241.57201,76.00917,0.10192000000000001,97.31376999999999,0.99811
242.52499,76.30917,0.10595999999999998,97.15344,0.99769
243.479,76.60916999999999,0.11107,96.98154,0.9972700000000001
244.44901000000002,76.90916999999999,0.1166,96.88154,0.9968299999999999
245.39999,77.20917,0.12170999999999998,96.79420999999999,0.9964
246.364,77.50917,0.13041,96.5854,0.99597
247.31798999999998,77.80917,0.13785999999999998,96.46777,0.99554
248.272,78.10916999999999,0.14109000000000002,96.23801999999999,0.99511
249.215,78.40916999999999,0.14981,95.98127,0.9946799999999999
250.18401,78.70917,0.15622,95.89366,0.99424
251.138,79.00917,0.16538,95.70936999999999,0.9938
252.099,79.30917,0.1754,95.38292,0.99336
253.05098999999998,79.60916999999999,0.18373,95.15316999999999,0.99292
254.01401,79.90916999999999,0.19483,94.93884,0.9924799999999999
254.974,80.20917,0.20551,94.63664,0.99203
255.92999,80.50917,0.21768,94.37355,0.99159
256.879,80.80917,0.22816999999999998,94.05344000000001,0.9911399999999999
257.84398999999996,81.10916999999999,0.23973000000000003,93.78154,0.99069
258.79901,81.40916999999999,0.25406,93.45206999999999,0.99024
259.75601,81.70917,0.26521999999999996,93.1135,0.98979
260.703,82.00917,0.27851,92.80248,0.98935
261.67499,82.30917,0.29033000000000003,92.41266999999999,0.9888899999999999
262.62601,82.60916999999999,0.30301,92.07106999999999,0.9884299999999999
263.60999,82.90916999999999,0.31932,91.60909000000001,0.9879600000000001
264.53201,83.20917,0.33436,91.24325,0.9875200000000001
265.50201,83.50917,0.34601,90.79008,0.98706
266.46398999999997,83.80917,0.35598,90.30660999999999,0.9866
267.41199,84.10916999999999,0.37041999999999997,89.8292,0.98614
268.379,84.40916999999999,0.38232,89.37603,0.98567
269.33499,84.70917,0.39573,88.77163,0.98521
270.29199,85.00917,0.40936,88.26116,0.98474
271.267,85.30917,0.42152,87.71405,0.98426
272.22299,85.60916999999999,0.43496999999999997,87.21543,0.9838
273.16699,85.90916999999999,0.44736000000000004,86.61708,0.9833299999999999
274.10901,86.20917,0.45803999999999995,85.99476999999999,0.98287
275.07901,86.50917,0.46896000000000004,85.30275,0.98239
276.035,86.80917,0.47925,84.69532,0.9819200000000001
276.992,87.10916999999999,0.48955,84.05481999999999,0.98144
277.94698999999997,87.40916999999999,0.49706999999999996,83.43829000000001,0.98096
278.90201,87.70917,0.50503,82.7314,0.98049
279.866,88.00917,0.5082800000000001,82.07273,0.98
280.81601,88.30917,0.50767,81.35344,0.9795299999999999
281.785,88.60916999999999,0.50578,80.68567,0.9790399999999999
282.73098999999996,88.90916999999999,0.49828999999999996,80.02094,0.97856
283.686,89.20917,0.48221,79.29256,0.97808
284.66101000000003,89.50917,0.46074,78.69752,0.9775799999999999
285.60699,89.80917,0.4315,78.12645,0.9771
286.586,90.10916999999999,0.40589000000000003,77.50689,0.9766
287.53799,90.40916999999999,0.38026,76.99008,0.97611
288.504,90.70917,0.35912,76.46115999999999,0.9756100000000001
289.46398999999997,91.00917,0.33646,75.95069000000001,0.9751200000000001
290.42999,91.30917,0.31096999999999997,75.52176,0.97462
291.39001,91.60916999999999,0.28157,75.09559,0.9741200000000001
292.34299,91.90916999999999,0.25386,74.71791,0.9736299999999999
293.297,92.20917,0.22354000000000002,74.32204,0.9731299999999999
294.25601,92.50917,0.19729000000000002,73.9989,0.9726299999999999
295.21301,92.80917,0.17275,73.72369,0.9721299999999999
296.16101000000003,93.10916999999999,0.14774,73.53939,0.9716299999999999
297.10699,93.40916999999999,0.1292,73.32176,0.9711299999999999
298.06799,93.70917,0.11953,73.17383000000001,0.9706299999999999
299.01801,94.00917,0.11135999999999999,72.98347,0.9701200000000001
299.98801000000003,94.30917,0.09949458,72.84738,0.9696100000000001
300.935,94.60916999999999,0.09629316,72.70248000000001,0.96911
301.90201,94.90916999999999,0.0917876,72.52121,0.96859
302.86499,95.20917,0.08597453,72.39421,0.9680700000000001
303.81601,95.50917,0.0866715,72.32176,0.9675600000000001
304.77802,95.80917,0.08258843,72.21295,0.96705
305.73001,96.10916999999999,0.08241481,72.1405,0.9665299999999999
306.67499,96.40916999999999,0.07962998,71.99531999999999,0.9660200000000001
307.62799,96.70917,0.07989023,71.8865,0.9655100000000001
308.57901,97.00917,0.08123979,71.77769,0.96499
309.521,97.30917,0.08237257,71.67796,0.9644799999999999
310.48098999999996,97.60916999999999,0.0821993,71.63278000000001,0.96395
311.40799,97.90916999999999,0.08376961,71.55124,0.96345
312.362,98.20917,0.08927184,71.4697,0.9629200000000001
313.306,98.50917,0.09215899,71.37906,0.96241
314.276,98.80917,0.09679887,71.29725,0.9618700000000001
315.21201,99.10916999999999,0.09991169,71.19752,0.96135
316.16901,99.40916999999999,0.10412,71.05261999999999,0.9608200000000001
317.12201,99.70917,0.11030999999999999,71.01625,0.9603
318.06799,100.00917,0.11322,70.88953000000001,0.9597700000000001
319.01501,100.30917,0.12007000000000001,70.75344,0.95924
319.953,100.60916999999999,0.12320999999999999,70.6719,0.9587200000000001
320.91598999999997,100.90916999999999,0.12722,70.55399,0.9581799999999999
321.84601000000004,101.20917,0.12905,70.49036,0.95765
322.785,101.50917,0.13483,70.20055,0.9571299999999999
323.75101,101.80917,0.13908,70.09174,0.9565799999999999
324.69901,102.10916999999999,0.14531,69.89229,0.95604
325.64001,102.40916999999999,0.14803,69.70193,0.9555100000000001
326.586,102.70917,0.15274000000000001,69.49036,0.9549700000000001
327.52301,103.00917,0.15921,69.34215,0.95444
328.47101000000004,103.30917,0.16944,69.11873,0.9539
329.41101000000003,103.60916999999999,0.18144000000000002,68.81956,0.95336
330.37201,103.90916999999999,0.18925999999999998,68.55372,0.95281
331.30801,104.20917,0.19445,68.28485,0.9522700000000001
332.23801000000003,104.50917,0.20405,68.00358,0.95173
333.19601,104.80917,0.2119,67.6595,0.9511799999999999
334.14099,105.10916999999999,0.21999000000000002,67.26364000000001,0.95063
335.091,105.40916999999999,0.23383,66.89477,0.9500799999999999
336.03,105.70917,0.24547,66.42342,0.9495399999999999
336.97601000000003,106.00917,0.2578,65.99752,0.94899
337.91598999999997,106.30917,0.27058000000000004,65.48980999999999,0.94844
338.85598999999996,106.60916999999999,0.28226,64.94601,0.94789
339.80301000000003,106.90916999999999,0.2953,64.40799,0.9473299999999999
340.746,107.20917,0.31168,63.73113000000001,0.94678
341.69901,107.50917,0.32697,63.021209999999996,0.94621
342.63599,107.80917,0.34294,62.32011,0.9456600000000001
343.58301,108.10916999999999,0.35915,61.52534,0.9451
344.53201,108.40916999999999,0.37761,60.673280000000005,0.9445399999999999
345.48999,108.70917,0.39142,59.72452,0.9439700000000001
346.422,109.00917,0.41193,58.91185,0.9434100000000001
347.375,109.30917,0.42933999999999994,57.84215,0.94285
348.31699,109.60916999999999,0.44588,56.65427,0.9422799999999999
349.29001,109.90916999999999,0.46334,55.566669999999995,0.9417
350.20099,110.20917,0.48125,54.5,0.94115
351.14499,110.50917,0.49562,53.082919999999994,0.94058
352.09,110.80917,0.51068,51.71102,0.94001
353.047,111.10916999999999,0.5241899999999999,50.25455,0.9394299999999999
353.983,111.40916999999999,0.5366,48.79201,0.9388700000000001
354.94,111.70917,0.55037,47.30551,0.93829
355.871,112.00917,0.55967,45.692009999999996,0.9377200000000001
356.80801,112.30917,0.56853,44.00275,0.93715
357.76198999999997,112.60916999999999,0.5756100000000001,42.355920000000005,0.9365700000000001
358.70099,112.90916999999999,0.5795600000000001,40.522040000000004,0.93599
359.65302,113.20917,0.58127,38.83278,0.9354100000000001
360.58499,113.50917,0.58275,36.99835,0.93484
361.52499,113.80917,0.58109,35.17025,0.9342600000000001
362.46301,114.10916999999999,0.57627,33.37879,0.93368
363.39999,114.40916999999999,0.5696399999999999,31.58072,0.9331
364.336,114.70917,0.56234,29.831129999999998,0.9325200000000001
365.28201,115.00917,0.54916,28.10275,0.9319299999999999
366.211,115.30917,0.53618,26.32617,0.9313600000000001
367.16199,115.60916999999999,0.52117,24.76667,0.93076
368.091,115.90916999999999,0.50003,23.12011,0.9301799999999999
369.02701,116.20917,0.48226,21.58209,0.9296
369.96398999999997,116.50917,0.46333,20.09532,0.92901
370.88698999999997,116.80917,0.44076000000000004,18.69339,0.92843
371.83301,117.10916999999999,0.42065,17.42149,0.92784
372.767,117.40916999999999,0.39893,16.146279999999997,0.92725
373.70499,117.70917,0.37628,14.928370000000001,0.92666
374.646,118.00917,0.35428000000000004,13.87686,0.92606
375.61401,118.30917,0.3309,12.8405,0.92545
376.534,118.60916999999999,0.31088000000000005,11.85234,0.92486
377.46898999999996,118.90916999999999,0.28698,10.96997,0.92427
378.41101000000003,119.20917,0.26691,10.15702,0.9236700000000001
379.332,119.50917,0.24591,9.40468,0.9230799999999999
380.271,119.80917,0.22807,8.72507,0.92248
381.20099,120.10916999999999,0.20656,8.06006,0.9218799999999999
382.13,120.40916999999999,0.19072,7.4135,0.9212899999999999
383.08401000000003,120.70917,0.17257999999999998,6.899719999999999,0.9206700000000001
384.01001,121.00917,0.15488,6.34077,0.9200799999999999
384.939,121.30917,0.13806,5.95399,0.91948
385.89099,121.60916999999999,0.1226,5.51295,0.91886
386.802,121.90916999999999,0.10985999999999999,5.16556,0.91827
387.745,122.20917,0.09642396,4.84518,0.91766
388.715,122.50917,0.08250951,4.527819999999999,0.9170299999999999
389.60901,122.80917,0.07017766,4.32562,0.9164399999999999
390.55801,123.10916999999999,0.06058637,4.10799,0.9158200000000001
391.491,123.40916999999999,0.05075194,3.8479300000000003,0.9152100000000001
392.40302,123.70917,0.04320179,3.66364,0.9146200000000001
393.33499,124.00917,0.03472252,3.5369099999999998,0.91401
394.26599,124.30917,0.02922327,3.33719,0.9133899999999999
395.21301,124.60916999999999,0.03108533,3.18017,0.9127700000000001
396.13199,124.90916999999999,0.02695852,3.07135,0.9121600000000001
397.069,125.20917,0.02167369,2.92617,0.91155
397.98999,125.50917,0.01615085,2.9628099999999997,0.91094
398.92801000000003,125.80917,0.01408393,2.77218,0.9103100000000001
399.83898999999997,126.10916999999999,0.01224501,2.69063,0.90971
400.78299,126.40916999999999,0.008554326999999999,2.6360900000000003,0.9090799999999999
401.72,126.70917,0.0004627099,2.58182,0.90846
402.64898999999997,127.00917,-0.0064823630000000005,2.49118,0.90784
403.58301,127.30917,-0.0192288,2.49118,0.9072100000000001
404.50699,127.60916999999999,-0.02828331,2.4548200000000002,0.90659
405.42999,127.90916999999999,-0.03503031,2.4369099999999997,0.9059799999999999
406.362,128.20917,-0.03528669,2.36446,0.90535
407.28101000000004,128.50916999999998,-0.03763389,2.3281,0.9047299999999999
408.198,128.80917,-0.04300635,2.3281,0.9041100000000001
409.12201,129.10917,-0.04489706,2.3281,0.90349
410.04098999999997,129.40917,-0.04702305,2.2829200000000003,0.9028700000000001
410.965,129.70917,-0.04985106,2.26474,0.9022399999999999
411.92099,130.00916999999998,-0.05035315,2.19201,0.90159
412.81799,130.30917,-0.05248668,2.26474,0.9009799999999999
413.745,130.60917,-0.05182315,2.21928,0.90035
414.67499,130.90917,-0.05115886,2.21928,0.8997200000000001
415.59299,131.20917,-0.05142828,2.1832,0.89909
416.52701,131.50916999999998,-0.04865767,2.1741,0.89845
417.44101,131.80917,-0.0486916,2.13774,0.8978299999999999
418.36499,132.10917,-0.05013155,2.19201,0.8971899999999999
419.284,132.40917,-0.04852589,2.15592,0.89656
420.202,132.70917,-0.05160977,2.11956,0.8959299999999999
421.134,133.00916999999998,-0.05023825,2.14683,0.8952899999999999
422.052,133.30917,-0.05567709,2.10138,0.89465
422.974,133.60917,-0.05360096,2.09229,0.89402
423.89099000000004,133.90917,-0.05528586,2.0925599999999998,0.89338
424.811,134.20917,-0.05603165,2.0562,0.89274
425.742,134.50916999999998,-0.05866384,2.06529,0.8921
426.67999000000003,134.80917,-0.05658484,2.10165,0.89145
427.57500999999996,135.10917,-0.05851192,2.06529,0.8908200000000001
428.51500999999996,135.40917,-0.05808281,2.04711,0.8901700000000001
429.42899000000006,135.70917,-0.05859706,2.04711,0.8895299999999999
430.362,136.00916999999998,-0.06029526,2.01074,0.88887
431.27499000000006,136.30917,-0.05891896,2.01377,0.88823
432.186,136.60917,-0.05919819,2.00468,0.8876
433.11099,136.90917,-0.05734585,2.02287,0.88695
434.03101,137.20917,-0.05786203,1.9955900000000002,0.8863
434.965,137.50916999999998,-0.05909162,1.9143299999999999,0.88564
435.871,137.80917,-0.05865935,1.96832,0.885
436.79599,138.10917,-0.05775207,1.9686,0.88435
437.728,138.40917,-0.05684383,1.9776900000000002,0.88369
438.642,138.70917,-0.05807562,1.90523,0.8830399999999999
439.57500999999996,139.00916999999998,-0.06002476,1.90523,0.8823799999999999
440.491,139.30917,-0.06126095,1.8958700000000002,0.8817200000000001
441.41,139.60917,-0.06226063,1.8658400000000002,0.88107
442.32901,139.90917,-0.05872611,1.90193,0.88041
443.25201,140.20917,-0.06187584,1.85675,0.87976
444.173,140.50916999999998,-0.06335668,1.8476599999999999,0.8791
445.086,140.80917,-0.06460013,1.8476599999999999,0.87844
446.00699000000003,141.10917,-0.06464873,1.8655599999999999,0.8777799999999999
446.92899000000006,141.40917,-0.0644579,1.86253,0.8771200000000001
447.836,141.70917,-0.06162828,1.85372,0.8764700000000001
448.74799,142.00916999999998,-0.06503418,1.8176299999999999,0.8758100000000001
449.673,142.30917,-0.06556406,1.7661200000000001,0.87515
450.59299000000004,142.60917,-0.06224905,1.79339,0.8744799999999999
451.51000999999997,142.90917,-0.06373943,1.81129,0.87382
452.42001,143.20917,-0.06258398,1.7661200000000001,0.87316
453.34601,143.50916999999998,-0.06552284,1.79339,0.87249
454.26099000000005,143.80917,-0.06292092,1.75702,0.87182
455.17899000000006,144.10917,-0.06272785,1.75702,0.87116
456.09299000000004,144.40917,-0.06156856,1.82066,0.87049
457.00600999999995,144.70917,-0.06209891,1.7661200000000001,0.8698299999999999
457.92400999999995,145.00916999999998,-0.06190496,1.72975,0.86916
458.84299000000004,145.30917,-0.06509886,1.74793,0.8684799999999999
459.755,145.60917,-0.06418016,1.7388400000000002,0.86782
460.668,145.90917,-0.06568392,1.6752099999999999,0.86715
461.578,146.20917,-0.06452171,1.6752099999999999,0.8664799999999999
462.495,146.50916999999998,-0.06287264,1.70248,0.8658100000000001
463.41,146.80917,-0.06316448,1.66612,0.86513
464.32000999999997,147.10917,-0.06272719,1.69366,0.86446
465.24799,147.40917,-0.06229023,1.6300299999999999,0.8637799999999999
466.14800999999994,147.70917,-0.05917257,1.6300299999999999,0.8631200000000001
467.05399000000006,148.00916999999998,-0.05800003,1.6300299999999999,0.86245
467.97101,148.30917,-0.05853349,1.6300299999999999,0.86177
468.89099000000004,148.60917,-0.06028841,1.64821,0.8610899999999999
469.802,148.90917,-0.06180141,1.57548,0.86041
470.70800999999994,149.20917,-0.06136086,1.59366,0.85974
471.61800999999997,149.50916999999998,-0.05896263,1.59366,0.85906
472.548,149.80917,-0.05925506,1.61185,0.8583700000000001
473.44500999999997,150.10917,-0.05758594,1.62094,0.8577
474.36099,150.40917,-0.05763189,1.62094,0.8570200000000001
475.28101,150.70917,-0.05816904,1.62094,0.8563299999999999
476.186,151.00916999999998,-0.05796945,1.6391200000000001,0.85565
477.09799000000004,151.30917,-0.0589991,1.62094,0.8549700000000001
478.01800999999995,151.60917,-0.05904677,1.62094,0.8542799999999999
478.92099,151.90917,-0.05860123,1.55758,0.8536
479.82599000000005,152.20917,-0.05692305,1.56639,0.8529200000000001
480.73000999999994,152.50916999999998,-0.05524219,1.49394,0.85224
481.638,152.80917,-0.05849518,1.5424200000000001,0.85155
482.552,153.10917,-0.05607244,1.56942,0.8508600000000001
483.45999000000006,153.40917,-0.05438718,1.50634,0.8501799999999999
484.358,153.70917,-0.05443067,1.5424200000000001,0.8495
485.27499000000006,154.00916999999998,-0.05472281,1.5424200000000001,0.8488
486.17099,154.30917,-0.05625352,1.52452,0.8481200000000001
487.08401,154.60917,-0.05530745,1.57879,0.8474299999999999
487.99899000000005,154.90917,-0.05138136,1.5424200000000001,0.8467399999999999
488.90700999999996,155.20917,-0.05365911,1.5424200000000001,0.84605
489.815,155.50916999999998,-0.0487305,1.52424,0.84535
490.729,155.80917,-0.04777539,1.5333299999999999,0.8446600000000001
491.63199000000003,156.10917,-0.0500557,1.5333299999999999,0.8439700000000001
492.56201,156.40917,-0.04810394,1.5181799999999999,0.84326
493.44,156.70917,-0.0463962,1.5181799999999999,0.84259
494.35199000000006,157.00916999999998,-0.0449368,1.5184600000000001,0.8418899999999999
495.25100999999995,157.30917,-0.04647274,1.50909,0.8412
496.16299000000004,157.60917,-0.04451095,1.473,0.8405
497.08800999999994,157.90917,-0.04329726,1.5,0.8397899999999999
497.97500999999994,158.20917,-0.03732103,1.5272700000000001,0.8391
498.88,158.50916999999998,-0.04010958,1.55455,0.83841
499.79400999999996,158.80917,-0.03562719,1.53636,0.8377
500.689,159.10917,-0.03666101,1.53636,0.83701
501.60000999999994,159.40917,-0.03819974,1.4818200000000001,0.83631
502.51401,159.70917,-0.03999274,1.4818200000000001,0.8356
503.41500999999994,160.00916999999998,-0.03876747,1.5181799999999999,0.8349
504.311,160.30917,-0.03754001,1.53636,0.83421
505.203,160.60917,-0.03479747,1.46391,0.83352
506.112,160.90917,-0.03886488,1.5,0.83281
507.01901,161.20917,-0.0391504,1.5272700000000001,0.83211
507.922,161.50916999999998,-0.03640273,1.53636,0.8314
508.82599000000005,161.80917,-0.03921671,1.50909,0.8307
509.73599,162.10917,-0.03899702,1.5121200000000001,0.82999
510.63901,162.40917,-0.03903017,1.5033100000000001,0.8292799999999999
511.534,162.70917,-0.03779483,1.5124,0.8285899999999999
512.44098,163.00916999999998,-0.03833497,1.5124,0.82788
513.3560200000001,163.30917,-0.03785999,1.5124,0.82716
514.25403,163.60917,-0.03738361,1.48512,0.8264600000000001
515.14001,163.90917,-0.04046938,1.49421,0.82576
516.05103,164.20917,-0.03719279,1.43967,0.82504
516.94598,164.50916999999998,-0.04512837,1.48512,0.82434
517.84802,164.80917,-0.04440172,1.48512,0.82363
518.73602,165.10917,-0.04469486,1.46694,0.8229299999999999
519.64301,165.40917,-0.04141066,1.48512,0.8222200000000001
520.5380200000001,165.70917,-0.04195795,1.43967,0.8215100000000001
521.4470200000001,166.00916999999998,-0.04045827,1.43967,0.8207899999999999
522.34998,166.30917,-0.04151865,1.47603,0.8200799999999999
523.25,166.60917,-0.04052871,1.47603,0.81937
524.15302,166.90917,-0.03979393,1.43967,0.81865
525.0380200000001,167.20917,-0.04162676,1.46694,0.81795
525.94098,167.50916999999998,-0.03934864,1.39449,0.81723
526.8369799999999,167.80917,-0.03577928,1.44876,0.81652
527.7470099999999,168.10917,-0.03632629,1.48512,0.8158
528.64301,168.40917,-0.03661594,1.44876,0.81508
529.53302,168.70917,-0.03716399,1.46694,0.8143699999999999
530.4180299999999,169.00916999999998,-0.036163,1.43058,0.81367
531.323,169.30917,-0.03567806,1.43058,0.81295
532.21698,169.60917,-0.03700326,1.43058,0.81223
533.11902,169.90917,-0.03729515,1.42149,0.8115100000000001
534.01501,170.20917,-0.03810581,1.45785,0.81079
534.9130200000001,170.50916999999998,-0.03917746,1.43967,0.81007
535.79797,170.80917,-0.04025054,1.44876,0.8093600000000001
536.7069700000001,171.10917,-0.04080668,1.43058,0.8086300000000001
537.59497,171.40917,-0.04110286,1.4066100000000001,0.80792
538.48297,171.70917,-0.04165996,1.45179,0.80721
539.3779900000001,172.00916999999998,-0.03856988,1.45179,0.8064899999999999
540.29498,172.30917,-0.0412137,1.43361,0.80575
541.18597,172.60917,-0.04046723,1.40634,0.80503
542.0700099999999,172.90917,-0.03606084,1.40634,0.80432
542.95898,173.20917,-0.03556997,1.4427,0.8036
543.86102,173.50916999999998,-0.03560227,1.42479,0.80287
544.73999,173.80917,-0.03641987,1.4157,0.80216
545.664,174.10917,-0.04064999,1.41543,0.8014100000000001
546.55902,174.40917,-0.04042432,1.37934,0.8006800000000001
547.45398,174.70917,-0.03599452,1.4066100000000001,0.79996
548.34302,175.00916999999998,-0.03628999,1.42479,0.79924
549.23999,175.30917,-0.033691,1.46088,0.79851
550.12402,175.60917,-0.03451169,1.4338799999999998,0.79779
551.02899,175.90917,-0.0369168,1.39752,0.79705
551.91901,176.20917,-0.03800613,1.39752,0.79633
552.81598,176.50916999999998,-0.03698435,1.43664,0.7956
553.7139900000001,176.80917,-0.0349031,1.41846,0.79487
554.61603,177.10917,-0.03837608,1.44573,0.79413
555.51001,177.40917,-0.03867631,1.40055,0.7934
556.39502,177.70917,-0.03791618,1.3732799999999998,0.79267
557.28003,178.00916999999998,-0.03715468,1.3911799999999999,0.79195
558.15997,178.30917,-0.03400093,1.40028,0.79123
559.04401,178.60917,-0.03190509,1.43664,0.79051
559.935,178.90917,-0.03246686,1.48209,0.78977
560.83002,179.20917,-0.03196435,1.42755,0.78904
561.7310200000001,179.50916999999998,-0.03412732,1.3911799999999999,0.7883
562.61603,179.80917,-0.03282452,1.40937,0.78757
563.508,180.10917,-0.0320538,1.40937,0.78684
564.396,180.40917,-0.03128152,1.3911799999999999,0.7861100000000001
565.28998,180.70917,-0.03398701,1.41846,0.78537
566.1799900000001,181.00916999999998,-0.03348307,1.43664,0.78464
567.06799,181.30917,-0.03110134,1.40028,0.7839
567.94397,181.60917,-0.03327697,1.40028,0.78318
568.83099,181.90917,-0.03062201,1.36419,0.78245
569.729,182.20917,-0.03307093,1.36116,0.7817
570.61298,182.50916999999998,-0.0341784,1.37934,0.7809699999999999
571.51703,182.80917,-0.03582748,1.3884299999999998,0.78022
572.41998,183.10917,-0.03181732,1.3884299999999998,0.77947
573.30402,183.40917,-0.0345462,1.35207,0.77874
574.17902,183.70917,-0.0324173,1.37934,0.7780100000000001
575.0549900000001,184.00916999999998,-0.03028448,1.3884299999999998,0.7772899999999999
575.94598,184.30917,-0.03383188,1.3884299999999998,0.77655
576.82098,184.60917,-0.03169635,1.38815,0.77582
577.7130099999999,184.90917,-0.03091322,1.35207,0.77508
578.59998,185.20917,-0.03392842,1.33416,0.7743399999999999
579.48401,185.50916999999998,-0.03368905,1.28871,0.7736
580.38397,185.80917,-0.03209008,1.31598,0.77285
581.26501,186.10917,-0.02694868,1.3068899999999999,0.7721100000000001
582.14203,186.40917,-0.02479454,1.3429799999999998,0.7713800000000001
583.0189799999999,186.70917,-0.02754539,1.3429799999999998,0.77065
583.91602,187.00916999999998,-0.02757224,1.3429799999999998,0.7699
584.7930299999999,187.30917,-0.02869157,1.3068899999999999,0.7691600000000001
585.70099,187.60917,-0.03063463,1.2614299999999998,0.7684
586.57703,187.90917,-0.02874744,1.2978,0.76767
587.46002,188.20917,-0.0337081,1.28871,0.76693
588.35199,188.50916999999998,-0.03511262,1.27052,0.76618
589.23798,188.80917,-0.03295009,1.25234,0.76543
590.1220099999999,189.10917,-0.0318827,1.27052,0.76469
591.0,189.40917,-0.02751165,1.3068899999999999,0.76395
591.875,189.70917,-0.02230593,1.24325,0.76322
592.77301,190.00916999999998,-0.01984716,1.2796100000000001,0.76246
593.64203,190.30917,-0.01848664,1.2159799999999998,0.76173
594.52698,190.60917,-0.01988572,1.2159799999999998,0.76098
595.41498,190.90917,-0.02018178,1.2614299999999998,0.7602300000000001
596.3029799999999,191.20917,-0.02324579,1.27052,0.75948
597.18201,191.50916999999998,-0.0216065,1.2341600000000001,0.75874
598.06403,191.80917,-0.02079591,1.2614299999999998,0.758
598.95898,192.10917,-0.01942892,1.2614299999999998,0.7572399999999999
599.84003,192.40917,-0.01778109,1.2253399999999999,0.75649
600.73297,192.70917,-0.01696456,1.18898,0.75574
601.60199,193.00916999999998,-0.018373,1.24325,0.755
602.49402,193.30917,-0.01950605,1.2614299999999998,0.7542399999999999
603.35999,193.60917,-0.0150622,1.22507,0.75351
604.25098,193.90917,-0.01479812,1.21625,0.75275
605.15503,194.20917,-0.01565172,1.24325,0.7519899999999999
605.99597,194.50916999999998,-0.01846421,1.2159799999999998,0.75127
606.86499,194.80917,-0.01736225,1.1798899999999999,0.75053
607.7479900000001,195.10917,-0.01429616,1.1798899999999999,0.74978
608.63898,195.40917,-0.01403003,1.1798899999999999,0.74902
609.52502,195.70917,-0.01292065,1.15262,0.74827
610.409,196.00916999999998,-0.01405834,1.18898,0.74751
611.29602,196.30917,-0.01182096,1.1798899999999999,0.7467600000000001
612.1749900000001,196.60917,-0.01239632,1.11625,0.7460100000000001
613.052,196.90917,-0.01212675,1.12534,0.74526
613.93799,197.20917,-0.009880646,1.11625,0.7445
614.82703,197.50916999999998,-0.007912592,1.0889799999999998,0.74374
615.69397,197.80917,-0.003960243,1.11625,0.743
616.591,198.10917,-0.00283167,1.16171,0.7422300000000001
617.4500099999999,198.40917,-0.005668956,1.13444,0.7415
618.336,198.70917,-0.001986167,1.13444,0.74074
619.19598,199.00916999999998,0.001136083,1.16171,0.74
620.07703,199.30917,0.00284311,1.15262,0.73925
620.95203,199.60917,-0.0002845999,1.11625,0.7385
621.8369799999999,199.90917,0.002279144,1.15262,0.73774
622.7189900000001,200.20917,0.003422229,1.11625,0.73698
623.60999,200.50916999999998,0.0022838579999999997,1.07107,0.73621
624.487,200.80917,0.001428874,1.13444,0.73546
625.367,201.10917,0.0017164160000000001,1.09835,0.7347
626.23297,201.40917,0.0028635970000000003,1.09835,0.7339600000000001
627.10303,201.70917,0.00257987,1.13471,0.73321
627.99103,202.00916999999998,0.002582564,1.12837,0.73244
628.8779900000001,202.30917,0.0031597640000000002,1.06501,0.73168
629.7479900000001,202.60917,0.0028754609999999997,1.06501,0.73093
630.63702,202.90917,0.00143924,1.06501,0.73016
631.513,203.20917,0.00403405,0.99256,0.72941
632.38501,203.50916999999998,0.008653325,1.0832,0.72865
633.25897,203.80917,0.01414842,1.05592,0.7279
634.13202,204.10917,0.01127267,1.05592,0.72715
635.00403,204.40917,0.01446715,1.09229,0.72639
635.87097,204.70917,0.01506138,1.06501,0.72564
636.74402,205.00916999999998,0.01594691,1.0741,0.7248899999999999
637.63397,205.30917,0.0177054,1.05592,0.72412
638.50598,205.60917,0.01452777,1.05592,0.72336
639.38501,205.90917,0.01512481,1.0377399999999999,0.7226
640.26202,206.20917,0.01455841,1.0377399999999999,0.7218399999999999
641.1229900000001,206.50916999999998,0.01078438,1.04683,0.72109
642.00598,206.80917,0.01021229,1.01074,0.72032
642.87097,207.10917,0.01460421,1.01074,0.7195699999999999
643.75702,207.40917,0.01111109,1.01074,0.7188
644.638,207.70917,0.01492814,1.01983,0.71804
645.51099,208.00916999999998,0.01699507,0.9743799999999999,0.71728
646.38702,208.30917,0.01994644,1.01983,0.7165199999999999
647.258,208.60917,0.02261032,1.01983,0.7157600000000001
648.1229900000001,208.90917,0.02175227,1.00165,0.71501
648.99597,209.20917,0.01942132,0.9834700000000001,0.71425
649.854,209.50916999999998,0.02356566,0.9562,0.7135
650.7310200000001,209.80917000000002,0.02123184,0.9834700000000001,0.7127399999999999
651.02301,209.90917000000002,0.02241939,1.01983,0.71248