File: 02_Data/Polyurethane_Foam/STA/N2/3K_min/Polyurethane_Foam_STA_N2_3KData_210222_R1.csv
##Temp./Â°C,Time/min,DSC/(mW/mg),Mass/%,Sensit./(uV/mW)
49.42,10.01,-0.02091974,101.61444,1.05322
49.366,10.31,-0.02263689,101.64289000000001,1.0532299999999999
49.371,10.61,-0.02013904,101.67134,1.0532299999999999
49.372,10.91,-0.01795341,101.67134,1.0532299999999999
49.429,11.21,-0.01529952,101.7069,1.05322
49.534,11.51,-0.00983553,101.74224,1.05321
49.684,11.81,-0.006244891999999999,101.75647,1.05319
49.913,12.11,-0.001405139,101.81315,1.05316
50.188,12.41,0.0034349,101.81315,1.05313
50.505,12.71,0.00608937,101.84159,1.0530899999999999
50.885,13.01,0.0104617,101.84138,1.05304
51.307,13.31,0.01249222,101.86983000000001,1.0529899999999999
51.758,13.61,0.01592846,101.89806,1.05293
52.241,13.91,0.01780345,101.89828,1.05287
52.75,14.21,0.02108435,101.95517,1.0528
53.282,14.51,0.02264766,101.95496,1.05273
53.843,14.81,0.02358645,102.01164,1.05266
54.437,15.11,0.02733734,101.95496,1.0525799999999998
55.032,15.41,0.02905788,101.98319000000001,1.0525
55.678,15.71,0.03109138,102.01185,1.05241
56.315,16.01,0.03328146,102.04009,1.0523200000000001
56.989,16.31,0.03344064,102.04009,1.05223
57.674,16.61,0.03359993,102.06832,1.0521399999999999
58.385,16.91,0.03547861,102.09698,1.0520399999999999
59.097,17.21,0.03673246,102.09676999999999,1.0519399999999999
59.821,17.51,0.03642339,102.10388,1.0518399999999999
60.565,17.81,0.03752146,102.12522,1.0517299999999998
61.339,18.11,0.03846358,102.15345,1.05162
62.1,18.41,0.04050048,102.15366,1.05151
62.884,18.71,0.03972298,102.15366,1.05139
63.667,19.01,0.04097862,102.13233000000001,1.0512700000000001
64.459,19.31,0.04145252,102.15366,1.05116
65.273,19.61,0.04114449,102.15345,1.05103
66.091,19.91,0.04287045,102.18211,1.05091
66.917,20.21,0.04381452,102.1819,1.0507799999999998
67.743,20.51,0.04616737,102.16078,1.05065
68.577,20.81,0.04554704,102.18211,1.0505200000000001
69.407,21.11,0.04805735,102.20323,1.05039
70.255,21.41,0.04665452,102.18901,1.05026
71.108,21.71,0.04822642,102.21034,1.0501200000000002
71.958,22.01,0.04744976,102.21746,1.04998
72.819,22.31,0.04620318,102.21034,1.0498399999999999
73.664,22.61,0.04824568,102.21034,1.0497
74.529,22.91,0.047469,102.23879000000001,1.04955
75.393,23.21,0.04998255,102.24569,1.04941
76.266,23.51,0.04889267,102.23879000000001,1.04926
77.134,23.81,0.04874288,102.23858,1.04911
78.023,24.11,0.04827977,102.23858,1.0489600000000001
78.904,24.41,0.0498546,102.23879000000001,1.0488
79.804,24.71,0.05017573,102.28125,1.04865
80.651,25.01,0.05065339,102.23858,1.04849
81.539,25.31,0.05066107,102.23168000000001,1.04834
82.436,25.61,0.04972767,102.25990999999999,1.04817
83.326,25.91,0.05146119,102.28836,1.04801
84.218,26.21,0.05099848,102.26703,1.04785
85.095,26.51,0.05132027,102.29547,1.04769
86.001,26.81,0.05070068,102.26703,1.04752
86.905,27.11,0.05023793,102.2528,1.04735
87.786,27.41,0.05260123,102.29547,1.04718
88.69,27.71,0.05182469,102.25990999999999,1.04701
89.608,28.01,0.05293295,102.26703,1.04683
90.526,28.31,0.051371,102.26703,1.04665
91.417,28.61,0.05247943,102.24569,1.0464799999999999
92.327,28.91,0.05170269,102.28836,1.0463
93.231,29.21,0.05139722,102.32370999999999,1.0461200000000002
94.151,29.51,0.05297835,102.30237,1.04593
95.058,29.81,0.05267317,102.33081999999999,1.04575
95.974,30.11,0.05189626,102.33081999999999,1.04556
96.889,30.41,0.05395035,102.33081999999999,1.0453700000000001
97.82,30.71,0.05254442,102.31681,1.04518
98.738,31.01,0.05349812,102.28836,1.0449899999999999
99.666,31.31,0.05445236,102.30237,1.0448
100.572,31.61,0.05336051,102.35216,1.0446
101.49,31.91,0.05478742,102.35194,1.04441
102.423,32.21,0.05416806,102.37349,1.04421
103.358,32.51,0.05496603,102.34504,1.04401
104.279,32.81,0.0562368,102.36616,1.0438100000000001
105.195,33.11,0.05404184,102.35927,1.04361
106.129,33.41,0.05389494,102.36638,1.0434
107.057,33.71,0.05532418,102.36616,1.04319
107.978,34.01,0.05580808,102.35905,1.0429899999999999
108.918,34.31,0.05550407,102.36638,1.04277
109.83,34.61,0.05551511,102.36638,1.04257
110.771,34.91,0.05552657,102.39461,1.04235
111.7,35.21,0.05680021,102.3875,1.04214
112.634,35.51,0.05618077,102.3875,1.0419200000000002
113.571,35.81,0.05603473,102.35927,1.0417
114.508,36.11,0.05762537,102.35927,1.04148
115.442,36.41,0.05763761,102.38772,1.04126
116.367,36.71,0.05764981,102.35927,1.04104
117.293,37.01,0.05876797,102.38772,1.04082
118.225,37.31,0.05846465,102.37349,1.04059
119.173,37.61,0.05910979,102.36638,1.04036
120.114,37.91,0.05991329,102.38039,1.04013
121.033,38.21,0.06055879,102.35927,1.0399100000000001
121.98,38.51,0.06104692,102.36638,1.03967
122.923,38.81,0.06264262,102.36638,1.03944
123.842,39.11,0.06328942,102.35927,1.0392
124.79,39.41,0.06393704,102.41595,1.0389700000000002
125.728,39.71,0.06268535,102.38772,1.03873
126.656,40.01,0.06254134,102.38772,1.03849
127.596,40.31,0.06540656,102.36638,1.03825
128.556,40.61,0.06431337,102.33081999999999,1.038
129.46899,40.91,0.06512032,102.35194,1.03776
130.408,41.21,0.06592818,102.33793,1.03752
131.356,41.51,0.06737074,102.33793,1.0372700000000001
132.28798999999998,41.81,0.06817958,102.3097,1.03702
133.22501,42.11,0.06740304,102.29547,1.03677
134.183,42.41,0.06726113,102.29526,1.03651
135.119,42.71,0.06934029,102.30237,1.03626
136.067,43.01,0.0703098,102.27414,1.036
137.00101,43.31,0.07080337,102.27414,1.03575
137.96201000000002,43.61,0.0712978,102.27414,1.03548
138.91701,43.91,0.07258664,102.29547,1.03522
139.85699,44.21,0.07260496,102.32370999999999,1.03496
140.8,44.51,0.07341803,102.32370999999999,1.0346899999999999
141.752,44.81,0.07375492,102.38039,1.03443
142.701,45.11,0.07345607,102.32370999999999,1.03416
143.664,45.41,0.07474782,102.32370999999999,1.03388
144.60001,45.71,0.07588072,102.29547,1.03362
145.55901,46.01,0.07749218,102.28125,1.03334
146.50999,46.31,0.07767197,102.25990999999999,1.0330700000000002
147.461,46.61,0.07864799,102.2528,1.0327899999999999
148.407,46.91,0.07882831,102.28125,1.03251
149.366,47.21,0.08187638,102.28125,1.03223
150.32401000000002,47.51,0.07919012,102.27414,1.03195
151.284,47.81,0.08192148,102.22457,1.03166
152.231,48.11,0.08178451,102.23168000000001,1.03138
153.17101,48.41,0.08435838,102.17478,1.0311
154.15198999999998,48.71,0.08326601,102.18901,1.0308
155.112,49.01,0.0842469,102.20323,1.03051
156.092,49.31,0.08570779,102.19612,1.03021
157.0,49.61,0.08732744,102.20323,1.02993
157.97,49.91,0.08751248,102.21746,1.0296299999999998
158.929,50.21,0.08721826,102.23147,1.02934
159.88699,50.51,0.09043927,102.18901,1.02904
160.841,50.81,0.09062535,102.18211,1.02874
161.81599,51.11,0.09097213,102.16789,1.02843
162.745,51.41,0.09083817,102.22457,1.02814
163.701,51.71,0.09230477,102.19612,1.0278399999999999
164.67101,52.01,0.09377279,102.16767,1.0275299999999998
165.629,52.31,0.09492133,102.19612,1.02722
166.582,52.61,0.09543009,102.18901,1.02691
167.53798999999998,52.91,0.09561905,102.21746,1.0266
168.496,53.21,0.09532768,102.21034,1.02629
169.44298999999998,53.51,0.09727962,102.20776,1.02598
170.403,53.81,0.09875236,102.15129,1.02566
171.37198999999998,54.11,0.099585,102.17953,1.02534
172.32401000000002,54.41,0.10153999999999999,102.1653,1.0250299999999999
173.286,54.71,0.10061,102.15108000000001,1.02471
174.244,55.01,0.10064,102.13707,1.02439
175.218,55.31,0.10132000000000001,102.12996,1.02406
176.162,55.61,0.10279,102.10151,1.0237399999999999
177.127,55.91,0.10555999999999999,102.12759,1.02341
178.084,56.21,0.10559,102.12047,1.02309
179.05299,56.51,0.10595,102.12047,1.02275
179.993,56.81,0.10534,102.14180999999999,1.02243
180.96201000000002,57.11,0.10859,102.11336,1.02209
181.92598999999998,57.41,0.10862000000000001,102.08491,1.02176
182.869,57.71,0.1085,102.07091,1.0214299999999998
183.843,58.01,0.11047,101.98815,1.02109
184.8,58.31,0.11275999999999999,102.04483,1.02075
185.774,58.61,0.11264,102.10862,1.02041
186.74698999999998,58.91,0.11250999999999999,102.08017,1.02006
187.70598999999999,59.21,0.11432,102.05194,1.0197200000000002
188.675,59.51,0.11565,102.10151,1.01937
189.655,59.81,0.11634000000000001,102.17974,1.01902
190.61301,60.11,0.11735,102.0875,1.01867
191.57001,60.41,0.11884000000000002,102.08039000000001,1.0183200000000001
192.52698999999998,60.71,0.12147000000000001,102.05194,1.01797
193.504,61.01,0.1228,102.04483,1.01762
194.46001,61.31,0.12284,102.03772,1.01726
195.422,61.61,0.12418,102.00927,1.01691
196.395,61.91,0.12519,101.96681,1.01655
197.36301,62.21,0.1267,101.95259,1.01619
198.353,62.51,0.1269,101.95259,1.0158200000000002
199.282,62.81,0.13067,101.93125,1.01547
200.25101,63.11,0.13185,101.92414000000001,1.0151
201.214,63.41,0.12979000000000002,101.86746,1.01474
202.20598999999999,63.71,0.13244,101.89591,1.01436
203.134,64.01,0.13264,101.86746,1.014
204.092,64.31,0.13448,101.86746,1.0136399999999999
205.054,64.61,0.13534000000000002,101.86034000000001,1.0132700000000001
206.03101,64.91,0.13587,101.81078000000001,1.01289
206.994,65.21,0.13917000000000002,101.81078000000001,1.01251
207.967,65.51,0.13874,101.78966,1.01213
208.925,65.81,0.14139000000000002,101.76120999999999,1.01176
209.881,66.11,0.14307,101.72565,1.01138
210.843,66.41,0.14556,101.71141999999999,1.01101
211.80098999999998,66.71,0.14789000000000002,101.71141999999999,1.01063
212.79401000000001,67.01,0.14828,101.67608,1.01023
213.73398999999998,67.31,0.14931,101.67608,1.00986
214.724,67.61,0.15083,101.64073,1.00946
215.651,67.91,0.15219000000000002,101.62651,1.00909
216.627,68.21,0.15486,101.57672,1.0086899999999999
217.578,68.51,0.15818,101.54849,1.00831
218.55299,68.81,0.15661,101.51293000000001,1.00791
219.51199,69.11,0.15847,101.47737,1.00752
220.47,69.41,0.16212000000000001,101.47737,1.0071299999999999
221.437,69.71,0.16414,101.39246,1.00673
222.39799,70.01,0.16633,101.36401,1.00633
223.354,70.31,0.16934000000000002,101.33578,1.00594
224.306,70.61,0.1717,101.30733000000001,1.0055399999999999
225.272,70.91,0.17356,101.25776,1.00514
226.23,71.21,0.17723,101.22931,1.00474
227.207,71.51,0.17878,101.1653,1.00433
228.164,71.81,0.18311,101.10862,1.0039200000000001
229.134,72.11,0.18499000000000002,101.08017,1.0035100000000001
230.104,72.41,0.18800999999999998,101.00237,1.0031
231.061,72.71,0.19055,100.93858,1.0026899999999999
232.022,73.01,0.19325,100.86766999999999,1.0022799999999998
232.987,73.31,0.19662000000000002,100.83211,1.00187
233.95399,73.61,0.199,100.7472,1.00145
234.918,73.91,0.20515999999999998,100.67608,1.0010299999999999
235.882,74.21,0.2082,100.55539,1.00061
236.83299,74.51,0.21223000000000003,100.49181,1.0002
237.793,74.81,0.21479,100.41358000000001,0.9997799999999999
238.77299,75.11,0.21883000000000002,100.32845,0.99935
239.698,75.41,0.22468000000000002,100.24353,0.9989399999999999
240.659,75.71,0.22939,100.10172,0.9985200000000001
241.63,76.01,0.23196,99.98836,0.9980899999999999
242.582,76.31,0.23715999999999998,99.89612,0.9976700000000001
243.543,76.61,0.24419000000000002,99.75409,0.99724
244.51401,76.91,0.24891999999999997,99.66207,0.9968
245.48199,77.21,0.25414000000000003,99.49892,0.9963700000000001
246.439,77.51,0.26019000000000003,99.37111999999999,0.9959399999999999
247.42999,77.81,0.26824000000000003,99.19849,0.99549
248.36301,78.11,0.27447,99.04267,0.9950700000000001
249.328,78.41,0.28285,98.90086,0.9946299999999999
250.299,78.71,0.28943,98.70453,0.99418
251.261,79.01,0.29767,98.51789000000001,0.99374
252.222,79.31,0.30558,98.3431,0.9933
253.168,79.61,0.313,98.1278,0.99287
254.12801000000002,79.91,0.32076,97.92694,0.9924200000000001
255.099,80.21,0.32886,97.71659,0.99197
256.064,80.51,0.33946,97.44698000000001,0.9915200000000001
257.03101000000004,80.81,0.34608,97.22241,0.9910700000000001
257.991,81.11,0.35653,96.94828000000001,0.9906200000000001
258.94901,81.41,0.36682,96.68341,0.9901700000000001
259.91199,81.71,0.37613,96.35710999999999,0.98972
260.866,82.01,0.38877,96.07585999999999,0.9892700000000001
261.82101,82.31,0.39726,95.72823000000001,0.98882
262.772,82.61,0.40909,95.38556,0.98836
263.737,82.91,0.42126,95.01918,0.9879
264.70599,83.21,0.43528,94.61509000000001,0.98744
265.66901,83.51,0.44714,94.24159,0.98698
266.61301000000003,83.81,0.45935,93.84203000000001,0.9865200000000001
267.59799,84.11,0.47223999999999994,93.43534,0.98605
268.54599,84.41,0.48348,93.0028,0.98559
269.49301,84.71,0.49772,92.49698000000001,0.98513
270.45599,85.01,0.51115,91.96509,0.9846600000000001
271.414,85.31,0.52125,91.49698000000001,0.98419
272.36499,85.61,0.53437,91.02888,0.9837299999999999
273.34,85.91,0.54801,90.49009000000001,0.98325
274.293,86.21,0.5603100000000001,89.925,0.9827799999999999
275.25299,86.51,0.5713,89.36228,0.9823
276.21799,86.81,0.58414,88.80216,0.98183
277.16501,87.11,0.59514,88.16853,0.98135
278.12799,87.41,0.6076699999999999,87.55388,0.98087
279.08499,87.71,0.6187,86.94159,0.9804
280.04401,88.01,0.6299100000000001,86.32478,0.9799200000000001
281.01198999999997,88.31,0.63727,85.67456999999999,0.9794299999999999
281.966,88.61,0.64347,85.00086,0.97895
282.92099,88.91,0.64899,84.30582,0.97846
283.87701,89.21,0.64931,83.61573,0.97798
284.836,89.51,0.64779,82.90431,0.97749
285.78201,89.81,0.63986,82.27521999999999,0.97701
286.74399,90.11,0.62537,81.5944,0.97652
287.703,90.41,0.60193,80.96099,0.97603
288.66101000000003,90.71,0.57863,80.35819000000001,0.9755299999999999
289.61099,91.01,0.55262,79.83103,0.97504
290.573,91.31,0.5291100000000001,79.27565,0.97455
291.55899,91.61,0.5108199999999999,78.73427,0.97404
292.50201,91.91,0.49131,78.22845,0.97355
293.47699,92.21,0.46656000000000003,77.72478000000001,0.97304
294.41299,92.51,0.43856000000000006,77.27565,0.97255
295.379,92.81,0.40868000000000004,76.86896999999999,0.97204
296.32999,93.11,0.37944,76.52866,0.97154
297.30099,93.41,0.34933000000000003,76.20474,0.97103
298.26401,93.71,0.31851,75.89741,0.97052
299.22299,94.01,0.29375999999999997,75.66099,0.9700200000000001
300.185,94.31,0.27441,75.38685,0.9695
301.14301,94.61,0.2603,75.20474,0.96899
302.09,94.91,0.24736,75.02736999999999,0.96849
303.048,95.21,0.23798000000000002,74.87845,0.96798
304.0,95.51,0.22944,74.7153,0.96747
304.957,95.81,0.22208000000000003,74.60194,0.96695
305.92899,96.11,0.21675999999999998,74.48599,0.9664299999999999
306.86099,96.41,0.21023000000000003,74.33017,0.9659200000000001
307.827,96.71,0.20626,74.24504,0.9654
308.78101000000004,97.01,0.20143,74.13168,0.96488
309.73401,97.31,0.19864,74.01831999999999,0.96436
310.73199,97.61,0.1967,73.91897,0.9638200000000001
311.64999,97.91,0.19339,73.86206999999999,0.9633200000000001
312.60598999999996,98.21,0.18905,73.74871,0.9627899999999999
313.58499,98.51,0.18830999999999998,73.66358000000001,0.96225
314.521,98.81,0.1855,73.57845,0.9617399999999999
315.47,99.11,0.18458,73.49332,0.96121
316.41699,99.41,0.18365,73.37996,0.9606899999999999
317.379,99.71,0.18478,73.2806,0.96015
318.33499,100.01,0.1842,73.18125,0.95962
319.285,100.31,0.18395999999999998,73.06789,0.95909
320.245,100.61,0.1844,72.9472,0.95855
321.20099,100.91,0.18828,72.8125,0.9580200000000001
322.14999,101.21,0.18993,72.67759000000001,0.9574799999999999
323.10101000000003,101.51,0.1933,72.56421999999999,0.95695
324.04001,101.81,0.19478,72.45065,0.95642
324.979,102.11,0.19868,72.30194,0.95588
325.935,102.41,0.20309000000000002,72.10819000000001,0.95534
326.896,102.71,0.20252,71.9472,0.9548
327.84698,103.01,0.20332,71.77694,0.95425
328.78601000000003,103.31,0.20603000000000002,71.54784000000001,0.9537200000000001
329.74899,103.61,0.21063,71.37284,0.9531700000000001
330.68399,103.91,0.21386,71.12931,0.95263
331.62201,104.21,0.22296,70.85517,0.95209
332.56699,104.51,0.22516,70.6069,0.9515399999999999
333.521,104.81,0.23238000000000003,70.28319,0.95099
334.45401,105.11,0.23561999999999997,69.95215999999999,0.95045
335.41699,105.41,0.24303000000000002,69.60948,0.94989
336.36099,105.71,0.25305,69.19332,0.94934
337.30899,106.01,0.26203000000000004,68.79871,0.9487899999999999
338.255,106.31,0.26964,68.35409,0.94824
339.19901,106.61,0.28003,67.84591,0.94768
340.14999,106.91,0.2894,67.24547,0.9471299999999999
341.08499,107.21,0.30069,66.70884000000001,0.94658
342.03699,107.51,0.31251,66.07047,0.9460200000000001
342.98001,107.81,0.32243,65.40625,0.9454600000000001
343.92801000000003,108.11,0.33568000000000003,64.65453000000001,0.9449
344.88101,108.41,0.34406,63.85323,0.9443299999999999
345.82198999999997,108.71,0.35873,62.99504,0.9437700000000001
346.76599,109.01,0.37044,62.066159999999996,0.94321
347.70099,109.31,0.38619000000000003,61.12047,0.94265
348.63698999999997,109.61,0.40055999999999997,60.05927,0.94209
349.578,109.91,0.41318999999999995,58.964659999999995,0.94153
350.51099,110.21,0.42777,57.75905,0.94096
351.46398999999997,110.51,0.44148999999999994,56.52284,0.94039
352.39801,110.81,0.45611,55.250859999999996,0.9398299999999999
353.332,111.11,0.47073000000000004,53.81142,0.93926
354.27701,111.41,0.48591000000000006,52.34806,0.9386899999999999
355.215,111.71,0.49918,50.74763,0.9381200000000001
356.15302,112.01,0.50948,49.192029999999995,0.93755
357.10999,112.31,0.52225,47.51142,0.9369700000000001
358.034,112.61,0.5317,45.76681,0.9364
358.96201,112.91,0.5387,43.97974,0.9358299999999999
359.897,113.21,0.54342,42.09806,0.9352600000000001
360.845,113.51,0.54499,40.228229999999996,0.93468
361.78201,113.81,0.5463899999999999,38.3181,0.9341
362.728,114.11,0.54391,36.38211,0.9335200000000001
363.66501,114.41,0.53773,34.48858,0.93294
364.61801,114.71,0.53101,32.60453,0.93235
365.561,115.01,0.5167,30.69935,0.93176
366.48801000000003,115.31,0.50307,28.83168,0.9311799999999999
367.44,115.61,0.49013999999999996,27.03987,0.9305899999999999
368.379,115.91,0.47189,25.359270000000002,0.93
369.32198999999997,116.21,0.45608999999999994,23.66422,0.9294100000000001
370.25201,116.51,0.43548000000000003,22.07565,0.9288299999999999
371.216,116.81,0.41168000000000005,20.49655,0.92822
372.15201,117.11,0.39244,19.0806,0.9276399999999999
373.08898999999997,117.41,0.37158,17.75194,0.92704
374.026,117.71,0.34822,16.50388,0.92645
374.96701,118.01,0.32713000000000003,15.33836,0.92586
375.90398999999996,118.31,0.30459,14.24634,0.9252600000000001
376.85598999999996,118.61,0.2815,13.23685,0.92466
377.79901,118.91,0.25855,12.27241,0.92406
378.73001,119.21,0.23913,11.404739999999999,0.9234600000000001
379.66901,119.51,0.21700999999999998,10.648489999999999,0.92286
380.60598999999996,119.81,0.19825,9.93448,0.9222600000000001
381.55099,120.11,0.17805,9.26315,0.92166
382.48098999999996,120.41,0.16138,8.67694,0.92106
383.418,120.71,0.1447,8.0931,0.9204600000000001
384.353,121.01,0.12602,7.61078,0.91985
385.285,121.31,0.1134,7.159269999999999,0.91925
386.229,121.61,0.10113,6.807110000000001,0.91864
387.16299,121.91,0.08776252,6.50431,0.91804
388.10598999999996,122.21,0.07348298,6.2064699999999995,0.9174200000000001
389.035,122.51,0.06025992,5.88513,0.9168200000000001
389.97299,122.81,0.05276257,5.64634,0.9162100000000001
390.94101,123.11,0.04453793,5.38858,0.9155700000000001
391.85101000000003,123.41,0.03558165,5.18772,0.9149799999999999
392.78101000000004,123.71,0.03075009,5.031680000000001,0.9143700000000001
393.71898999999996,124.01,0.02537242,4.8875,0.91375
394.659,124.31,0.0208879,4.76703,0.91314
395.57901,124.61,0.01639708,4.59203,0.91253
396.53101000000004,124.91,0.01244152,4.4336199999999995,0.9119
397.452,125.21,0.01064551,4.29181,0.9112899999999999
398.379,125.51,0.008486034,4.22802,0.9106799999999999
399.311,125.81,0.007227063000000001,4.17134,0.9100600000000001
400.23999,126.11,0.001084795,4.10043,0.9094399999999999
401.17001,126.41,0.0009046117999999999,4.06487,0.9088200000000001
402.108,126.71,-0.001267329,4.00819,0.9082
403.035,127.01,-0.0028987270000000002,3.95151,0.9075799999999999
403.95599,127.31,-0.009064675999999999,3.8734900000000003,0.90696
404.90398999999996,127.61,-0.0123366,3.8097,0.90633
405.819,127.91,-0.01851745,3.79526,0.90571
406.73499,128.21,-0.02343506,3.76703,0.9051
407.673,128.51,-0.03145036,3.71034,0.9044700000000001
408.60001,128.81,-0.03329131,3.6961199999999996,0.90384
409.52499,129.11,-0.03568094,3.6819,0.90322
410.44501,129.41,-0.03625207,3.6892199999999997,0.90259
411.38501,129.71,-0.03901217,3.6607800000000004,0.90196
412.29901,130.01,-0.04049849,3.6678900000000003,0.9013399999999999
413.23901,130.31,-0.04235278,3.63944,0.9007
414.159,130.61,-0.04658394,3.61099,0.90007
415.09299,130.91,-0.04954192,3.58276,0.89943
416.022,131.21,-0.05104043,3.5543099999999996,0.8988
416.95499,131.51,-0.05254128,3.58276,0.8981600000000001
417.862,131.81,-0.05422645,3.54009,0.89754
418.784,132.11,-0.05389806,3.5116400000000003,0.89691
419.71300999999994,132.41,-0.05393647,3.4834099999999997,0.8962700000000001
420.63100999999995,132.71,-0.05507606,3.51875,0.8956299999999999
421.552,133.01,-0.05621745,3.51875,0.895
422.47699000000006,133.31,-0.05883149,3.4905199999999996,0.89436
423.39899,133.61,-0.05942541,3.51875,0.8937200000000001
424.319,133.91,-0.06038838,3.51875,0.8930899999999999
425.23499000000004,134.21,-0.05987866,3.51875,0.89245
426.159,134.51,-0.05973741,3.5329699999999997,0.89181
427.08800999999994,134.81,-0.0631019,3.5045300000000004,0.8911600000000001
428.00201,135.11,-0.06259312,3.44806,0.8905200000000001
428.92899000000006,135.41,-0.06448639,3.44095,0.8898799999999999
429.85699000000005,135.71,-0.06545799,3.4267199999999995,0.88923
430.77300999999994,136.01,-0.06791079,3.47629,0.88859
431.69699,136.31,-0.06647892,3.41961,0.88794
432.62201,136.61,-0.06782479,3.4620699999999998,0.8872899999999999
433.54099,136.91,-0.06861602,3.4407300000000003,0.88664
434.46700999999996,137.21,-0.06848095,3.4407300000000003,0.8859899999999999
435.39000999999996,137.51,-0.06871703,3.4267199999999995,0.88534
436.31600999999995,137.81,-0.07025471,3.38405,0.88469
437.23900999999995,138.11,-0.06844663,3.37004,0.88403
438.14999000000006,138.41,-0.0694273,3.3769400000000003,0.88339
439.06299,138.71,-0.07078212,3.3769400000000003,0.88274
439.98999000000003,139.01,-0.0715806,3.33448,0.88208
440.90799000000004,139.31,-0.07293946,3.34849,0.8814299999999999
441.823,139.61,-0.07691381,3.3911599999999997,0.8807799999999999
442.75600999999995,139.91,-0.07678516,3.3911599999999997,0.8801100000000001
443.67499000000004,140.21,-0.07553373,3.3627199999999995,0.87945
444.59,140.51,-0.07652552,3.3342699999999996,0.8788
445.51000999999997,140.81,-0.07808092,3.3342699999999996,0.8781399999999999
446.42400999999995,141.11,-0.0766402,3.3342699999999996,0.8774799999999999
447.336,141.41,-0.07932281,3.29892,0.8768299999999999
448.259,141.71,-0.07769393,3.3271599999999997,0.87616
449.17499000000004,142.01,-0.07756468,3.29892,0.8755
450.08499000000006,142.31,-0.07781084,3.29892,0.87485
451.00201,142.61,-0.08163163,3.2847,0.8741899999999999
451.91699000000006,142.91,-0.08075231,3.31315,0.8735200000000001
452.827,143.21,-0.08081329,3.29181,0.8728600000000001
453.74899000000005,143.51,-0.08087525,3.3060300000000002,0.8722
454.67599,143.81,-0.0816924,3.3202599999999998,0.8715200000000001
455.59601,144.11,-0.08043349,3.26336,0.87085
456.48900999999995,144.41,-0.08351683,3.27759,0.8702
457.40601,144.71,-0.08377015,3.3060300000000002,0.8695299999999999
458.32901,145.01,-0.08402436,3.3202599999999998,0.8688600000000001
459.241,145.31,-0.08711912,3.27759,0.86819
460.15700999999996,145.61,-0.08699693,3.27759,0.8675200000000001
461.07901,145.91,-0.08896159,3.24935,0.86685
461.98400999999996,146.21,-0.08466374,3.27759,0.86618
462.90601,146.51,-0.08586989,3.26358,0.86551
463.81299,146.81,-0.08669665,3.24935,0.8648399999999999
464.733,147.11,-0.08600356,3.26358,0.86416
465.647,147.41,-0.08549945,3.2422400000000002,0.86349
466.55800999999997,147.71,-0.08632842,3.22091,0.8628100000000001
467.47,148.01,-0.08754027,3.2069,0.86214
468.384,148.31,-0.0885634,3.23513,0.86146
469.284,148.61,-0.08844103,3.22091,0.8607899999999999
470.202,148.91,-0.09061396,3.2069,0.86011
471.116,149.21,-0.08762448,3.2069,0.8594299999999999
472.01500999999996,149.51,-0.08654393,3.2069,0.8587600000000001
472.927,149.81,-0.08833705,3.22091,0.8580899999999999
473.84299000000004,150.11,-0.09185937,3.22091,0.8574
474.75699000000003,150.41,-0.09039716,3.22802,0.85672
475.67001,150.71,-0.09392668,3.22802,0.8560399999999999
476.57599000000005,151.01,-0.09380894,3.22802,0.85536
477.491,151.31,-0.09330707,3.19246,0.85467
478.40601,151.61,-0.09338211,3.22091,0.8539899999999999
479.311,151.91,-0.0911442,3.21379,0.85331
480.21399,152.21,-0.09083113,3.22802,0.8526299999999999
481.11800999999997,152.51,-0.09051772,3.23513,0.85195
482.034,152.81,-0.09290907,3.20668,0.85125
482.936,153.11,-0.09201689,3.2069,0.85057
483.849,153.41,-0.09093079,3.20668,0.84988
484.754,153.71,-0.08964874,3.21401,0.8492
485.681,154.01,-0.08952916,3.21401,0.8485
486.57500999999996,154.31,-0.09347959,3.19267,0.84782
487.495,154.61,-0.09258617,3.1713400000000003,0.8471200000000001
488.40799000000004,154.91,-0.0965473,3.1713400000000003,0.8464299999999999
489.30800999999997,155.21,-0.09409807,3.1713400000000003,0.8457399999999999
490.20800999999994,155.51,-0.09553646,3.22823,0.84505
491.11301,155.81,-0.09288829,3.1713400000000003,0.84436
492.02499000000006,156.11,-0.09374455,3.1713400000000003,0.84367
492.936,156.41,-0.09421212,3.19978,0.8429700000000001
493.84698,156.71,-0.09448533,3.15711,0.8422700000000001
494.74300999999997,157.01,-0.09085025,3.15711,0.84159
495.64899,157.31,-0.09366287,3.14289,0.8408899999999999
496.552,157.61,-0.09295737,3.1879299999999997,0.8402
497.46200999999996,157.91,-0.09440587,3.15948,0.8395
498.379,158.21,-0.09409325,3.18082,0.8387899999999999
499.293,158.51,-0.0943685,3.17371,0.83809
500.202,158.81,-0.09503658,3.15948,0.83739
501.104,159.11,-0.09452613,3.18772,0.8366899999999999
502.005,159.41,-0.09145793,3.18772,0.836
502.91199000000006,159.71,-0.09035368,3.1597,0.83529
503.80499000000003,160.01,-0.08865545,3.15948,0.8346
504.729,160.31,-0.09030908,3.13125,0.8338899999999999
505.612,160.61,-0.09058071,3.13815,0.8332
506.52499000000006,160.91,-0.08986785,3.15237,0.83249
507.41101,161.21,-0.09270976,3.17371,0.8318
508.328,161.51,-0.09437217,3.1806,0.83109
509.23099,161.81,-0.09544222,3.14526,0.8303799999999999
510.151,162.11,-0.09532661,3.14526,0.82967
511.02899,162.41,-0.09600051,3.13815,0.8289799999999999
511.92499000000004,162.71,-0.09667725,3.1665900000000002,0.8282799999999999
512.815,163.01,-0.09377838,3.13815,0.82758
513.70801,163.31,-0.09246576,3.13815,0.82688
514.62903,163.61,-0.09354172,3.1170299999999997,0.82616
515.5189799999999,163.91,-0.09382007,3.15948,0.8254600000000001
516.43701,164.21,-0.09190846,3.13103,0.8247399999999999
517.33099,164.51,-0.09358318,3.1170299999999997,0.82404
518.22699,164.81,-0.09486161,3.0956900000000003,0.8233299999999999
519.125,165.11,-0.09634238,3.08858,0.82263
520.01099,165.41,-0.0956241,3.1170299999999997,0.8219299999999999
520.901,165.71,-0.09370371,3.07435,0.8212200000000001
521.81097,166.01,-0.09659141,3.08147,0.8205
522.70898,166.31,-0.09507055,3.06034,0.81979
523.60101,166.61,-0.09414882,3.08858,0.81909
524.508,166.91,-0.09965636,3.08858,0.8183699999999999
525.41699,167.21,-0.10336,3.05065,0.81765
526.32397,167.51,-0.10346,3.0790900000000003,0.81693
527.22601,167.81,-0.10274000000000001,3.06509,0.81621
528.14697,168.11,-0.09980805,3.0933200000000003,0.81548
529.01398,168.41,-0.09868181,3.0933200000000003,0.81479
529.9119900000001,168.71,-0.10038,3.10043,0.81407
530.8220200000001,169.01,-0.09986756,3.10043,0.81335
531.71002,169.31,-0.10076,3.07198,0.8126399999999999
532.61902,169.61,-0.10207000000000001,3.05065,0.81191
533.51801,169.91,-0.10317,3.0933200000000003,0.81119
534.40802,170.21,-0.10347,3.0933200000000003,0.81048
535.323,170.51,-0.10437,3.10043,0.80974
536.18903,170.81,-0.10365,3.1146599999999998,0.80905
537.09198,171.11,-0.10517,3.08621,0.8083199999999999
537.98499,171.41,-0.10709,3.10043,0.80761
538.8770099999999,171.71,-0.10535,3.04375,0.80689
539.77399,172.01,-0.10749,3.08621,0.8061699999999999
540.67902,172.31,-0.10677,3.0722,0.8054399999999999
541.573,172.61,-0.10768,3.0722,0.80472
542.46002,172.91,-0.10594,3.02953,0.804
543.36902,173.21,-0.10603,3.0722,0.8032699999999999
544.25702,173.51,-0.10755999999999999,3.05797,0.80255
545.14899,173.81,-0.10765999999999999,3.04375,0.80183
546.04102,174.11,-0.10590999999999999,3.05776,0.8011
546.92902,174.41,-0.10642,3.07198,0.80038
547.81799,174.71,-0.10795,3.05065,0.79966
548.729,175.01,-0.10949,3.05065,0.79892
549.61798,175.31,-0.11062000000000001,3.04353,0.7982
550.50098,175.61,-0.10928,3.04353,0.79748
551.38397,175.91,-0.10711,3.05065,0.79676
552.28302,176.21,-0.10905999999999999,3.05065,0.79603
553.16498,176.51,-0.10770999999999999,3.02241,0.7953100000000001
554.06799,176.81,-0.10926,3.07198,0.7945800000000001
554.95898,177.11,-0.10998,3.05065,0.79385
555.85498,177.41,-0.11382,3.07198,0.7931199999999999
556.755,177.71,-0.1104,3.0790900000000003,0.79238
557.64502,178.01,-0.11382,3.0508599999999997,0.79165
558.5360099999999,178.31,-0.11309000000000001,3.02241,0.79092
559.43799,178.61,-0.11277999999999999,3.02241,0.79018
560.32098,178.91,-0.11164,3.02241,0.78946
561.21002,179.21,-0.11299000000000001,3.0081900000000004,0.78873
562.0889900000001,179.51,-0.11143,2.98707,0.78801
562.987,179.81,-0.1155,3.0153,0.78727
563.88599,180.11,-0.11435,3.00108,0.7865300000000001
564.7689799999999,180.41,-0.11655,3.04353,0.7858
565.65198,180.71,-0.11394000000000001,3.04353,0.7850699999999999
566.54401,181.01,-0.11488,3.04353,0.7843399999999999
567.43402,181.31,-0.11478,3.0790900000000003,0.7836
568.31201,181.61,-0.11782999999999999,3.02953,0.78288
569.20599,181.91,-0.11815,3.0153,0.78214
570.09302,182.21,-0.12078,3.0153,0.7814
570.99298,182.51,-0.11857999999999999,3.02241,0.78066
571.87903,182.81,-0.11785,3.02241,0.77992
572.7520099999999,183.11,-0.11775,3.04375,0.7792
573.64899,183.41,-0.11681,2.98685,0.77845
574.5310099999999,183.71,-0.1184,3.0153,0.77772
575.41998,184.01,-0.11807999999999999,3.0153,0.77698
576.31097,184.31,-0.11882999999999999,2.99397,0.7762399999999999
577.198,184.61,-0.12043,3.00108,0.7755
578.091,184.91,-0.1197,3.00108,0.77476
578.987,185.21,-0.12215,2.97284,0.7740100000000001
579.86401,185.51,-0.12333,3.0081900000000004,0.77328
580.74902,185.81,-0.12217,3.0081900000000004,0.77254
581.63202,186.11,-0.12399,3.0081900000000004,0.77181
582.51202,186.41,-0.12539,2.99397,0.77107
583.401,186.71,-0.12444000000000001,3.0150900000000003,0.7703300000000001
584.30402,187.01,-0.12691,3.0150900000000003,0.76957
585.15997,187.31,-0.12618,3.05065,0.76886
586.0529799999999,187.61,-0.12587,3.0222,0.7681100000000001
586.94299,187.91,-0.12599000000000002,3.0222,0.76736
587.82599,188.21,-0.12719,3.0293099999999997,0.76662
588.70398,188.51,-0.12774000000000002,2.98685,0.76588
589.57898,188.81,-0.1298,2.99397,0.76515
590.461,189.11,-0.12971,2.98685,0.76441
591.34802,189.41,-0.13177,3.0081900000000004,0.76366
592.23901,189.71,-0.13513,2.98685,0.7629100000000001
593.15399,190.01,-0.13355,2.96552,0.7621399999999999
594.03497,190.31,-0.13324,3.00108,0.7614
594.9060099999999,190.61,-0.13359000000000001,2.97974,0.76066
595.77802,190.91,-0.1322,2.97974,0.75993
596.651,191.21,-0.13276,2.97974,0.7591899999999999
597.5360099999999,191.51,-0.13505999999999999,3.00108,0.75844
598.4119900000001,191.81,-0.13454000000000002,3.00108,0.7577
599.3029799999999,192.11,-0.13685,2.98685,0.75695
600.1920200000001,192.41,-0.13851,2.98685,0.7562
601.08099,192.71,-0.13712,2.9657299999999998,0.75544
601.9639900000001,193.01,-0.13617,2.95151,0.75469
602.841,193.31,-0.135,2.9657299999999998,0.75395
603.7310200000001,193.61,-0.13426,2.97284,0.7531899999999999
604.60101,193.91,-0.13483,2.95151,0.75246
605.48499,194.21,-0.13584000000000002,2.97263,0.75171
606.362,194.51,-0.13838,2.97263,0.7509600000000001
607.255,194.81,-0.1372,2.94418,0.7502
608.12598,195.11,-0.13668,2.94418,0.74946
608.99402,195.41,-0.13901,2.94418,0.7487199999999999
609.8729900000001,195.71,-0.14245,2.97263,0.74797
610.75897,196.01,-0.14171,2.97263,0.74722
611.63202,196.31,-0.14075,2.97263,0.74647
612.51001,196.61,-0.142,2.99397,0.7457199999999999
613.39099,196.91,-0.14501,2.9657299999999998,0.74497
614.27197,197.21,-0.14361,2.9657299999999998,0.74422
615.15302,197.51,-0.14752,2.99418,0.74346
616.03003,197.81,-0.14855,2.9586200000000002,0.74271
616.927,198.11,-0.14737,2.9799599999999997,0.74195
617.802,198.41,-0.15063,2.9444,0.7412
618.6920200000001,198.71,-0.15745,2.9657299999999998,0.74043
619.565,199.01,-0.15805,2.95151,0.73969
620.44299,199.31,-0.15843,2.96552,0.73893
621.31097,199.61,-0.15859,2.92306,0.73819
622.19098,199.91,-0.16054000000000002,2.92306,0.73743
623.07098,200.21,-0.16115,2.93017,0.73668
623.94897,200.51,-0.16065,2.95129,0.73592
624.8200099999999,200.81,-0.1626,2.9444,0.73517
625.71802,201.11,-0.16165,2.9444,0.7344
626.57599,201.41,-0.15957000000000002,2.97284,0.7336600000000001
627.44299,201.71,-0.16063,2.95151,0.73292
628.32397,202.01,-0.16372,2.9586200000000002,0.73216
629.1920200000001,202.31,-0.16388,3.0081900000000004,0.73141
630.07397,202.61,-0.16405999999999998,2.95151,0.73065
630.9500099999999,202.91,-0.16985999999999998,2.9586200000000002,0.7298899999999999
631.8250099999999,203.21,-0.17296,2.95151,0.72914
632.68701,203.51,-0.17269,2.9444,0.72839
633.5750099999999,203.81,-0.17739000000000002,2.92306,0.72763
634.45099,204.11,-0.17961,2.95151,0.72687
635.32703,204.41,-0.17912,2.92328,0.72611
636.211,204.71,-0.17999,2.93017,0.72535
637.0889900000001,205.01,-0.17882,2.93017,0.72459
637.95398,205.31,-0.18264,2.92328,0.7238399999999999
638.82397,205.61,-0.18442,2.90194,0.7230800000000001
639.7130099999999,205.91,-0.18848,2.92328,0.72231
640.5670200000001,206.21,-0.19119,2.89246,0.7215699999999999
641.44098,206.51,-0.19207,2.89224,0.7208100000000001
642.33002,206.81,-0.1941,2.92069,0.72004
643.20398,207.11,-0.19727999999999998,2.90647,0.71928
644.09998,207.41,-0.19566,2.94203,0.71851
644.953,207.71,-0.19724,2.92069,0.7177600000000001
645.8170200000001,208.01,-0.20134000000000002,2.93491,0.71701
646.6970200000001,208.31,-0.20087,2.8853400000000002,0.71625
647.5700099999999,208.61,-0.19833,2.92069,0.71549
648.4470200000001,208.91,-0.19992000000000001,2.9278,0.71473
649.3319700000001,209.21,-0.20129,2.9278,0.71395
650.185,209.51,-0.20334000000000002,2.9560299999999997,0.71321
651.04199,209.81,-0.20355,2.9278,0.71246
651.341,209.91,-0.20409000000000002,2.94203,0.7122